Workbook
Name _: #N/A
Name _____________________________BRD1: #REF!
Name _____________________________BRD2: #REF!
Name _____________________________BRD3: #REF!
Name _____________________________BRD4: #REF!
Name _____________________________BRD5: #REF!
Name _____________________________BRD6: #REF!
Name _____________________________BRD7: #REF!
Name _____________________________INT1: #REF!
Name _____________________________INT2: #REF!
Name _____________________________INT3: #REF!
Name _____________________________INT4: #REF!
Name _____________________________INT5: #REF!
Name _____________________________INT6: #REF!
Name _____________________________INT7: #REF!
Name _____________________________LIC1: #REF!
Name _____________________________LIC2: #REF!
Name _____________________________LIC3: #REF!
Name _____________________________LIC4: #REF!
Name _____________________________LIC5: #REF!
Name _____________________________LIC6: #REF!
Name _____________________________LIC7: #REF!
Name _____________________________PG1: #REF!
Name _____________________________PG11: #REF!
Name _____________________________PG13: #REF!
Name _____________________________PG17: #REF!
Name _____________________________PG2: #REF!
Name _____________________________PG3: #REF!
Name _____________________________PG4: #REF!
Name _____________________________PG5: #REF!
Name _____________________________PG6: #REF!
Name _____________________________PG7: #REF!
Name _____________________________PG9: #REF!
Name _____________________________SUM25: #REF!
Name ____________________________BRD1: #REF!
Name ____________________________BRD2: #REF!
Name ____________________________BRD3: #REF!
Name ____________________________BRD4: #REF!
Name ____________________________BRD5: #REF!
Name ____________________________BRD6: #REF!
Name ____________________________BRD7: #REF!
Name ____________________________INT1: #REF!
Name ____________________________INT2: #REF!
Name ____________________________INT3: #REF!
Name ____________________________INT4: #REF!
Name ____________________________INT5: #REF!
Name ____________________________INT6: #REF!
Name ____________________________INT7: #REF!
Name ____________________________LIC1: #REF!
Name ____________________________LIC2: #REF!
Name ____________________________LIC3: #REF!
Name ____________________________LIC4: #REF!
Name ____________________________LIC5: #REF!
Name ____________________________LIC6: #REF!
Name ____________________________LIC7: #REF!
Name ____________________________PG1: #REF!
Name ____________________________PG11: #REF!
Name ____________________________PG13: #REF!
Name ____________________________PG17: #REF!
Name ____________________________PG2: #REF!

Sheet 요약(보고)
A1: 26년 CMO 매출 예상실적
Y2: 2026.03.26
A3: ■ 2분기 매출 | F3: 2분기
F4: 1분기 | J4: 4월 | N4: 5월 | R4: 6월 | Y4: 단위 : 억원
A5: 구분 | D5: 25년 실적 | E5: 26년 목표 | F5: 26년 1분기 | J5: 2분기 | V5: 2분기 소계 | Z5: 2분기 누계
J6: 4월 | N6: 5월 | R6: 6월
F7: 25년 실적 | G7: 사업 계획 | H7: 실적 | I7: 차이 | J7: 25년 실적 | K7: 사업 계획 | L7: 실적 | M7: 차이 | N7: 25년 실적 | O7: 사업 계획 | P7: 실적 | Q7: 차이 | R7: 25년 실적 | S7: 사업 계획 | T7: 실적 | U7: 차이 | V7: 25년 실적 | W7: 사업 계획 | X7: 실적 | Y7: 차이 | Z7: 25년 실적 | AA7: 사업 계획 | AB7: 실적 | AC7: 차이
B8: CMO 합계 | D8: =SUM(D15,D12,D9) -> 1392.7058 | E8: =AA8 -> 695.9094 | F8: 275.49898 | G8: 313.38771 | H8: 336.29575 | I8: 22.908034 | J8: =J9+J12+J15 -> 94.002954 | K8: =K9+K12+K15 -> 106.71881 | L8: =L9+L12+L15 -> 106.71881 | M8: =L8-K8 -> 0 | N8: =N9+N12+N15 -> 107.35319 | O8: =O9+O12+O15 -> 162.4121 | P8: =P9+P12+P15 -> 162.4121 | Q8: =P8-O8 -> 0 | R8: =R9+R12+R15 -> 122.55739 | S8: =S9+S12+S15 -> 113.39078 | T8: =T9+T12+T15 -> 113.39078 | U8: =T8-S8 -> 0 | V8: =V9+V12+V15 -> 323.91353 | W8: =W9+W12+W15 -> 382.52169 | X8: =X9+X12+X15 -> 382.52169 | Y8: =X8-W8 -> 0 | Z8: =F8+V8 -> 599.41252 | AA8: =G8+W8 -> 695.9094 | AB8: =H8+X8 -> 718.81744 | AC8: =I8+Y8 -> 22.908034 | AE8: 24년
B9: 케미컬 상업 | D9: =SUM(D10:D11) -> 152.99419 | E9: =AA9 -> 58.863894 | F9: 17.979459 | G9: 25.134453 | H9: 27.58882 | I9: 2.4543664 | J9: =SUM(J10:J11) -> 6.0472936 | K9: =SUM(K10:K11) -> 12.331896 | L9: =SUM(L10:L11) -> 12.331896 | M9: =SUM(M10:M11) -> 0 | N9: =SUM(N10:N11) -> 17.855413 | O9: =SUM(O10:O11) -> 18.142962 | P9: =SUM(P10:P11) -> 18.142962 | Q9: =SUM(Q10:Q11) -> 0 | ... Y9: =SUM(Y10:Y11) -> 0 | Z9: =F9+V9 -> 53.839441 | AA9: =G9+W9 -> 58.863894 | AB9: =H9+X9 -> 61.31826 | AC9: =I9+Y9 -> 2.4543664 | AE9: 25년
C10: 내재화 | D10: 152.99419 | E10: =AA10 -> 57.841204 | F10: 17.979459 | G10: 24.623108 | H10: 27.58882 | I10: 2.9657114 | J10: =SUMIFS('상세 자료 작성'!$I:$I,'상세 자료 작성'!$C:$C,'요약(보고)'!$C10,'상세 자료 작성'!$A:$A,'요약(보고)'!$AE$9,'상세 자료 작성'!$D:$D,$J$4)/10^8 -> 6.0472936 | K10: =SUMIFS('상세 자료 작성'!$J:$J,'상세 자료 작성'!$C:$C,'요약(보고)'!$C10,'상세 자료 작성'!$A:$A,$AE$11,'상세 자료 작성'!$D:$D,'요약(보고)'!$J$4)/10^8 -> 12.161448 | L10: =SUMIFS('상세 자료 작성'!$K:$K,'상세 자료 작성'!$C:$C,'요약(보고)'!$C10,'상세 자료 작성'!$A:$A,$AE$11,'상세 자료 작성'!$D:$D,$J$4)/10^8 -> 12.161448 | M10: =L10-K10 -> 0 | N10: =SUMIFS('상세 자료 작성'!$I:$I,'상세 자료 작성'!$C:$C,'요약(보고)'!$C10,'상세 자료 작성'!$A:$A,'요약(보고)'!$AE$9,'상세 자료 작성'!$D:$D,$N$4)/10^8 -> 17.855413 | O10: =SUMIFS('상세 자료 작성'!$J:$J,'상세 자료 작성'!$C:$C,'요약(보고)'!$C10,'상세 자료 작성'!$A:$A,$AE$11,'상세 자료 작성'!$D:$D,$N$4)/10^8 -> 17.972514 | P10: =SUMIFS('상세 자료 작성'!$K:$K,'상세 자료 작성'!$C:$C,'요약(보고)'!$C10,'상세 자료 작성'!$A:$A,$AE$11,'상세 자료 작성'!$D:$D,$N$4)/10^8 -> 17.972514 | Q10: =P10-O10 -> 0 | R10: =SUMIFS('상세 자료 작성'!$I:$I,'상세 자료 작성'!$C:$C,'요약(보고)'!$C10,'상세 자료 작성'!$A:$A,'요약(보고)'!$AE$9,'상세 자료 작성'!$D:$D,$R$4)/10^8 -> 11.957274 | S10: =SUMIFS('상세 자료 작성'!$J:$J,'상세 자료 작성'!$C:$C,'요약(보고)'!$C10,'상세 자료 작성'!$A:$A,$AE$11,'상세 자료 작성'!$D:$D,$R$4)/10^8 -> 3.0841335 | T10: =SUMIFS('상세 자료 작성'!$K:$K,'상세 자료 작성'!$C:$C,'요약(보고)'!$C10,'상세 자료 작성'!$A:$A,$AE$11,'상세 자료 작성'!$D:$D,$R$4)/10^8 -> 3.0841335 | U10: =T10-S10 -> 0 | V10: =R10+J10+N10 -> 35.859981 | W10: =S10+K10+O10 -> 33.218096 | X10: =T10+L10+P10 -> 33.218096 | Y10: =X10-W10 -> 0 | Z10: =F10+V10 -> 53.839441 | AA10: =G10+W10 -> 57.841204 | AB10: =H10+X10 -> 60.806915 | AC10: =I10+Y10 -> 2.9657114
C11: 기타(위임형 등) | D11: 0 | E11: =AA11 -> 1.02269 | F11: 0 | G11: 0.511345 | H11: 0 | I11: -0.511345 | J11: =SUMIFS('상세 자료 작성'!$I:$I,'상세 자료 작성'!$C:$C,'요약(보고)'!$C11,'상세 자료 작성'!$A:$A,'요약(보고)'!$AE$9,'상세 자료 작성'!$D:$D,$J$4)/10^8 -> 0 | K11: =SUMIFS('상세 자료 작성'!$J:$J,'상세 자료 작성'!$C:$C,'요약(보고)'!$C11,'상세 자료 작성'!$A:$A,$AE$11,'상세 자료 작성'!$D:$D,'요약(보고)'!$J$4)/10^8 -> 0.17044833 | L11: =SUMIFS('상세 자료 작성'!$K:$K,'상세 자료 작성'!$C:$C,'요약(보고)'!$C11,'상세 자료 작성'!$A:$A,$AE$11,'상세 자료 작성'!$D:$D,$J$4)/10^8 -> 0.17044833 | M11: =L11-K11 -> 0 | N11: =SUMIFS('상세 자료 작성'!$I:$I,'상세 자료 작성'!$C:$C,'요약(보고)'!$C11,'상세 자료 작성'!$A:$A,'요약(보고)'!$AE$9,'상세 자료 작성'!$D:$D,$N$4)/10^8 -> 0 | O11: =SUMIFS('상세 자료 작성'!$J:$J,'상세 자료 작성'!$C:$C,'요약(보고)'!$C11,'상세 자료 작성'!$A:$A,$AE$11,'상세 자료 작성'!$D:$D,$N$4)/10^8 -> 0.17044833 | P11: =SUMIFS('상세 자료 작성'!$K:$K,'상세 자료 작성'!$C:$C,'요약(보고)'!$C11,'상세 자료 작성'!$A:$A,$AE$11,'상세 자료 작성'!$D:$D,$N$4)/10^8 -> 0.17044833 | Q11: =P11-O11 -> 0 | R11: =SUMIFS('상세 자료 작성'!$I:$I,'상세 자료 작성'!$C:$C,'요약(보고)'!$C11,'상세 자료 작성'!$A:$A,'요약(보고)'!$AE$9,'상세 자료 작성'!$D:$D,$R$4)/10^8 -> 0 | S11: =SUMIFS('상세 자료 작성'!$J:$J,'상세 자료 작성'!$C:$C,'요약(보고)'!$C11,'상세 자료 작성'!$A:$A,$AE$11,'상세 자료 작성'!$D:$D,$R$4)/10^8 -> 0.17044833 | T11: =SUMIFS('상세 자료 작성'!$K:$K,'상세 자료 작성'!$C:$C,'요약(보고)'!$C11,'상세 자료 작성'!$A:$A,$AE$11,'상세 자료 작성'!$D:$D,$R$4)/10^8 -> 0.17044833 | U11: =T11-S11 -> 0 | V11: =R11+J11+N11 -> 0 | W11: =S11+K11+O11 -> 0.511345 | X11: =T11+L11+P11 -> 0.511345 | Y11: =X11-W11 -> 0 | Z11: =F11+V11 -> 0 | AA11: =G11+W11 -> 1.02269 | AB11: =H11+X11 -> 0.511345 | AC11: =I11+Y11 -> -0.511345 | AE11: 26년
B12: 바이오 상업 | D12: =SUM(D13:D14) -> 1088.9227 | E12: =AA12 -> 525.25501 | F12: 203.6367 | G12: 246.45126 | H12: 268.65375 | I12: 22.202486 | J12: =SUM(J13:J14) -> 87.102624 | K12: =SUM(K13:K14) -> 83.548162 | L12: =SUM(L13:L14) -> 83.548162 | M12: =SUM(M13:M14) -> 0 | N12: =SUM(N13:N14) -> 61.024993 | O12: =SUM(O13:O14) -> 106.37289 | P12: =SUM(P13:P14) -> 106.37289 | Q12: =SUM(Q13:Q14) -> 0 | ... Y12: =SUM(Y13:Y14) -> 0 | Z12: =F12+V12 -> 452.14618 | AA12: =G12+W12 -> 525.25501 | AB12: =H12+X12 -> 547.45749 | AC12: =I12+Y12 -> 22.202486
C13: PFS | D13: 1041.7819 | E13: =AA13 -> 504.99231 | F13: 189.04806 | G13: 238.39926 | H13: 259.1118 | I13: 20.712539 | J13: =SUMIFS('상세 자료 작성'!$I:$I,'상세 자료 작성'!$C:$C,'요약(보고)'!$C13,'상세 자료 작성'!$A:$A,'요약(보고)'!$AE$9,'상세 자료 작성'!$D:$D,$J$4)/10^8 -> 80.069775 | K13: =SUMIFS('상세 자료 작성'!$J:$J,'상세 자료 작성'!$C:$C,'요약(보고)'!$C13,'상세 자료 작성'!$A:$A,$AE$11,'상세 자료 작성'!$D:$D,'요약(보고)'!$J$4)/10^8 -> 79.349504 | L13: =SUMIFS('상세 자료 작성'!$K:$K,'상세 자료 작성'!$C:$C,'요약(보고)'!$C13,'상세 자료 작성'!$A:$A,$AE$11,'상세 자료 작성'!$D:$D,$J$4)/10^8 -> 79.349504 | M13: =L13-K13 -> 0 | N13: =SUMIFS('상세 자료 작성'!$I:$I,'상세 자료 작성'!$C:$C,'요약(보고)'!$C13,'상세 자료 작성'!$A:$A,'요약(보고)'!$AE$9,'상세 자료 작성'!$D:$D,$N$4)/10^8 -> 56.971188 | O13: =SUMIFS('상세 자료 작성'!$J:$J,'상세 자료 작성'!$C:$C,'요약(보고)'!$C13,'상세 자료 작성'!$A:$A,$AE$11,'상세 자료 작성'!$D:$D,$N$4)/10^8 -> 101.581 | P13: =SUMIFS('상세 자료 작성'!$K:$K,'상세 자료 작성'!$C:$C,'요약(보고)'!$C13,'상세 자료 작성'!$A:$A,$AE$11,'상세 자료 작성'!$D:$D,$N$4)/10^8 -> 101.581 | Q13: =P13-O13 -> 0 | R13: =SUMIFS('상세 자료 작성'!$I:$I,'상세 자료 작성'!$C:$C,'요약(보고)'!$C13,'상세 자료 작성'!$A:$A,'요약(보고)'!$AE$9,'상세 자료 작성'!$D:$D,$R$4)/10^8 -> 95.072609 | S13: =SUMIFS('상세 자료 작성'!$J:$J,'상세 자료 작성'!$C:$C,'요약(보고)'!$C13,'상세 자료 작성'!$A:$A,$AE$11,'상세 자료 작성'!$D:$D,$R$4)/10^8 -> 85.662553 | T13: =SUMIFS('상세 자료 작성'!$K:$K,'상세 자료 작성'!$C:$C,'요약(보고)'!$C13,'상세 자료 작성'!$A:$A,$AE$11,'상세 자료 작성'!$D:$D,$R$4)/10^8 -> 85.662553 | U13: =T13-S13 -> 0 | V13: =R13+J13+N13 -> 232.11357 | W13: =S13+K13+O13 -> 266.59305 | X13: =T13+L13+P13 -> 266.59305 | Y13: =X13-W13 -> 0 | Z13: =F13+V13 -> 421.16163 | AA13: =G13+W13 -> 504.99231 | AB13: =H13+X13 -> 525.70485 | AC13: =I13+Y13 -> 20.712539
C14: L&P | D14: 47.140793 | E14: =AA14 -> 20.262697 | F14: 14.588646 | G14: 8.0520014 | H14: 9.5419484 | I14: 1.489947 | J14: =SUMIFS('상세 자료 작성'!$I:$I,'상세 자료 작성'!$C:$C,'요약(보고)'!$C14,'상세 자료 작성'!$A:$A,'요약(보고)'!$AE$9,'상세 자료 작성'!$D:$D,$J$4)/10^8 -> 7.0328488 | K14: =SUMIFS('상세 자료 작성'!$J:$J,'상세 자료 작성'!$C:$C,'요약(보고)'!$C14,'상세 자료 작성'!$A:$A,$AE$11,'상세 자료 작성'!$D:$D,'요약(보고)'!$J$4)/10^8 -> 4.198658 | L14: =SUMIFS('상세 자료 작성'!$K:$K,'상세 자료 작성'!$C:$C,'요약(보고)'!$C14,'상세 자료 작성'!$A:$A,$AE$11,'상세 자료 작성'!$D:$D,$J$4)/10^8 -> 4.198658 | M14: =L14-K14 -> 0 | N14: =SUMIFS('상세 자료 작성'!$I:$I,'상세 자료 작성'!$C:$C,'요약(보고)'!$C14,'상세 자료 작성'!$A:$A,'요약(보고)'!$AE$9,'상세 자료 작성'!$D:$D,$N$4)/10^8 -> 4.053805 | O14: =SUMIFS('상세 자료 작성'!$J:$J,'상세 자료 작성'!$C:$C,'요약(보고)'!$C14,'상세 자료 작성'!$A:$A,$AE$11,'상세 자료 작성'!$D:$D,$N$4)/10^8 -> 4.7918944 | P14: =SUMIFS('상세 자료 작성'!$K:$K,'상세 자료 작성'!$C:$C,'요약(보고)'!$C14,'상세 자료 작성'!$A:$A,$AE$11,'상세 자료 작성'!$D:$D,$N$4)/10^8 -> 4.7918944 | Q14: =P14-O14 -> 0 | R14: =SUMIFS('상세 자료 작성'!$I:$I,'상세 자료 작성'!$C:$C,'요약(보고)'!$C14,'상세 자료 작성'!$A:$A,'요약(보고)'!$AE$9,'상세 자료 작성'!$D:$D,$R$4)/10^8 -> 5.30925 | S14: =SUMIFS('상세 자료 작성'!$J:$J,'상세 자료 작성'!$C:$C,'요약(보고)'!$C14,'상세 자료 작성'!$A:$A,$AE$11,'상세 자료 작성'!$D:$D,$R$4)/10^8 -> 3.2201436 | T14: =SUMIFS('상세 자료 작성'!$K:$K,'상세 자료 작성'!$C:$C,'요약(보고)'!$C14,'상세 자료 작성'!$A:$A,$AE$11,'상세 자료 작성'!$D:$D,$R$4)/10^8 -> 3.2201436 | U14: =T14-S14 -> 0 | V14: =R14+J14+N14 -> 16.395904 | W14: =S14+K14+O14 -> 12.210696 | X14: =T14+L14+P14 -> 12.210696 | Y14: =X14-W14 -> 0 | Z14: =F14+V14 -> 30.98455 | AA14: =G14+W14 -> 20.262697 | AB14: =H14+X14 -> 21.752644 | AC14: =I14+Y14 -> 1.489947
B15: 개발 용역 | D15: =SUM(D16:D19) -> 150.78896 | E15: =AA15 -> 111.7905 | F15: 53.882818 | G15: 41.802 | H15: 40.053182 | I15: -1.7488176 | J15: =SUM(J16:J19) -> 0.85303671 | K15: =SUM(K16:K19) -> 10.83875 | L15: =SUM(L16:L19) -> 10.83875 | M15: =SUM(M16:M19) -> 0 | N15: =SUM(N16:N19) -> 28.472787 | O15: =SUM(O16:O19) -> 37.89625 | P15: =SUM(P16:P19) -> 37.89625 | Q15: =SUM(Q16:Q19) -> 0 | ... Y15: =SUM(Y16:Y19) -> 0 | Z15: =F15+V15 -> 93.426895 | AA15: =G15+W15 -> 111.7905 | AB15: =H15+X15 -> 110.04168 | AC15: =I15+Y15 -> -1.7488176
C16: PFS 개발 | D16: 116.21935 | E16: =AA16 -> 99.3605 | F16: 42.27486 | G16: 35.327 | H16: 34.321651 | I16: -1.0053493 | J16: =SUMIFS('상세 자료 작성'!$I:$I,'상세 자료 작성'!$C:$C,'요약(보고)'!$C16,'상세 자료 작성'!$A:$A,'요약(보고)'!$AE$9,'상세 자료 작성'!$D:$D,$J$4)/10^8 -> 0.44295337 | K16: =SUMIFS('상세 자료 작성'!$J:$J,'상세 자료 작성'!$C:$C,'요약(보고)'!$C16,'상세 자료 작성'!$A:$A,$AE$11,'상세 자료 작성'!$D:$D,'요약(보고)'!$J$4)/10^8 -> 8.34 | L16: =SUMIFS('상세 자료 작성'!$K:$K,'상세 자료 작성'!$C:$C,'요약(보고)'!$C16,'상세 자료 작성'!$A:$A,$AE$11,'상세 자료 작성'!$D:$D,$J$4)/10^8 -> 8.34 | M16: =L16-K16 -> 0 | N16: =SUMIFS('상세 자료 작성'!$I:$I,'상세 자료 작성'!$C:$C,'요약(보고)'!$C16,'상세 자료 작성'!$A:$A,'요약(보고)'!$AE$9,'상세 자료 작성'!$D:$D,$N$4)/10^8 -> 25.766953 | O16: =SUMIFS('상세 자료 작성'!$J:$J,'상세 자료 작성'!$C:$C,'요약(보고)'!$C16,'상세 자료 작성'!$A:$A,$AE$11,'상세 자료 작성'!$D:$D,$N$4)/10^8 -> 36.1775 | P16: =SUMIFS('상세 자료 작성'!$K:$K,'상세 자료 작성'!$C:$C,'요약(보고)'!$C16,'상세 자료 작성'!$A:$A,$AE$11,'상세 자료 작성'!$D:$D,$N$4)/10^8 -> 36.1775 | Q16: =P16-O16 -> 0 | R16: =SUMIFS('상세 자료 작성'!$I:$I,'상세 자료 작성'!$C:$C,'요약(보고)'!$C16,'상세 자료 작성'!$A:$A,'요약(보고)'!$AE$9,'상세 자료 작성'!$D:$D,$R$4)/10^8 -> 6.7929534 | S16: =SUMIFS('상세 자료 작성'!$J:$J,'상세 자료 작성'!$C:$C,'요약(보고)'!$C16,'상세 자료 작성'!$A:$A,$AE$11,'상세 자료 작성'!$D:$D,$R$4)/10^8 -> 19.516 | T16: =SUMIFS('상세 자료 작성'!$K:$K,'상세 자료 작성'!$C:$C,'요약(보고)'!$C16,'상세 자료 작성'!$A:$A,$AE$11,'상세 자료 작성'!$D:$D,$R$4)/10^8 -> 19.516 | U16: =T16-S16 -> 0 | V16: =R16+J16+N16 -> 33.00286 | W16: =S16+K16+O16 -> 64.0335 | X16: =T16+L16+P16 -> 64.0335 | Y16: =X16-W16 -> 0 | Z16: =F16+V16 -> 75.27772 | AA16: =G16+W16 -> 99.3605 | AB16: =H16+X16 -> 98.355151 | AC16: =I16+Y16 -> -1.0053493
C17: LCM | D17: 14.12375 | E17: =AA17 -> 7.27375 | F17: 3.66 | G17: 1.7875 | H17: 0 | I17: -1.7875 | J17: =SUMIFS('상세 자료 작성'!$I:$I,'상세 자료 작성'!$C:$C,'요약(보고)'!$C17,'상세 자료 작성'!$A:$A,'요약(보고)'!$AE$9,'상세 자료 작성'!$D:$D,$J$4)/10^8 -> 0 | K17: =SUMIFS('상세 자료 작성'!$J:$J,'상세 자료 작성'!$C:$C,'요약(보고)'!$C17,'상세 자료 작성'!$A:$A,$AE$11,'상세 자료 작성'!$D:$D,'요약(보고)'!$J$4)/10^8 -> 2.03 | L17: =SUMIFS('상세 자료 작성'!$K:$K,'상세 자료 작성'!$C:$C,'요약(보고)'!$C17,'상세 자료 작성'!$A:$A,$AE$11,'상세 자료 작성'!$D:$D,$J$4)/10^8 -> 2.03 | M17: =L17-K17 -> 0 | N17: =SUMIFS('상세 자료 작성'!$I:$I,'상세 자료 작성'!$C:$C,'요약(보고)'!$C17,'상세 자료 작성'!$A:$A,'요약(보고)'!$AE$9,'상세 자료 작성'!$D:$D,$N$4)/10^8 -> 0 | O17: =SUMIFS('상세 자료 작성'!$J:$J,'상세 자료 작성'!$C:$C,'요약(보고)'!$C17,'상세 자료 작성'!$A:$A,$AE$11,'상세 자료 작성'!$D:$D,$N$4)/10^8 -> 1.71875 | P17: =SUMIFS('상세 자료 작성'!$K:$K,'상세 자료 작성'!$C:$C,'요약(보고)'!$C17,'상세 자료 작성'!$A:$A,$AE$11,'상세 자료 작성'!$D:$D,$N$4)/10^8 -> 1.71875 | Q17: =P17-O17 -> 0 | R17: =SUMIFS('상세 자료 작성'!$I:$I,'상세 자료 작성'!$C:$C,'요약(보고)'!$C17,'상세 자료 작성'!$A:$A,'요약(보고)'!$AE$9,'상세 자료 작성'!$D:$D,$R$4)/10^8 -> 2.09 | S17: =SUMIFS('상세 자료 작성'!$J:$J,'상세 자료 작성'!$C:$C,'요약(보고)'!$C17,'상세 자료 작성'!$A:$A,$AE$11,'상세 자료 작성'!$D:$D,$R$4)/10^8 -> 1.7375 | T17: =SUMIFS('상세 자료 작성'!$K:$K,'상세 자료 작성'!$C:$C,'요약(보고)'!$C17,'상세 자료 작성'!$A:$A,$AE$11,'상세 자료 작성'!$D:$D,$R$4)/10^8 -> 1.7375 | U17: =T17-S17 -> 0 | V17: =R17+J17+N17 -> 2.09 | W17: =S17+K17+O17 -> 5.48625 | X17: =T17+L17+P17 -> 5.48625 | Y17: =X17-W17 -> 0 | Z17: =F17+V17 -> 5.75 | AA17: =G17+W17 -> 7.27375 | AB17: =H17+X17 -> 5.48625 | AC17: =I17+Y17 -> -1.7875
C18: 내재화 개발 | D18: 13.015667 | E18: =AA18 -> 5.15625 | F18: 5.2999167 | G18: 4.6875 | H18: 4.9429167 | I18: 0.25541668 | J18: =SUMIFS('상세 자료 작성'!$I:$I,'상세 자료 작성'!$C:$C,'요약(보고)'!$C18,'상세 자료 작성'!$A:$A,'요약(보고)'!$AE$9,'상세 자료 작성'!$D:$D,$J$4)/10^8 -> 0.41008334 | K18: =SUMIFS('상세 자료 작성'!$J:$J,'상세 자료 작성'!$C:$C,'요약(보고)'!$C18,'상세 자료 작성'!$A:$A,$AE$11,'상세 자료 작성'!$D:$D,'요약(보고)'!$J$4)/10^8 -> 0.46875 | L18: =SUMIFS('상세 자료 작성'!$K:$K,'상세 자료 작성'!$C:$C,'요약(보고)'!$C18,'상세 자료 작성'!$A:$A,$AE$11,'상세 자료 작성'!$D:$D,$J$4)/10^8 -> 0.46875 | M18: =L18-K18 -> 0 | N18: =SUMIFS('상세 자료 작성'!$I:$I,'상세 자료 작성'!$C:$C,'요약(보고)'!$C18,'상세 자료 작성'!$A:$A,'요약(보고)'!$AE$9,'상세 자료 작성'!$D:$D,$N$4)/10^8 -> 2.7058333 | O18: =SUMIFS('상세 자료 작성'!$J:$J,'상세 자료 작성'!$C:$C,'요약(보고)'!$C18,'상세 자료 작성'!$A:$A,$AE$11,'상세 자료 작성'!$D:$D,$N$4)/10^8 -> 0 | P18: =SUMIFS('상세 자료 작성'!$K:$K,'상세 자료 작성'!$C:$C,'요약(보고)'!$C18,'상세 자료 작성'!$A:$A,$AE$11,'상세 자료 작성'!$D:$D,$N$4)/10^8 -> 0 | Q18: =P18-O18 -> 0 | R18: =SUMIFS('상세 자료 작성'!$I:$I,'상세 자료 작성'!$C:$C,'요약(보고)'!$C18,'상세 자료 작성'!$A:$A,'요약(보고)'!$AE$9,'상세 자료 작성'!$D:$D,$R$4)/10^8 -> 0.36208334 | S18: =SUMIFS('상세 자료 작성'!$J:$J,'상세 자료 작성'!$C:$C,'요약(보고)'!$C18,'상세 자료 작성'!$A:$A,$AE$11,'상세 자료 작성'!$D:$D,$R$4)/10^8 -> 0 | T18: =SUMIFS('상세 자료 작성'!$K:$K,'상세 자료 작성'!$C:$C,'요약(보고)'!$C18,'상세 자료 작성'!$A:$A,$AE$11,'상세 자료 작성'!$D:$D,$R$4)/10^8 -> 0 | U18: =T18-S18 -> 0 | V18: =R18+J18+N18 -> 3.478 | W18: =S18+K18+O18 -> 0.46875 | X18: =T18+L18+P18 -> 0.46875 | Y18: =X18-W18 -> 0 | Z18: =F18+V18 -> 8.7779167 | AA18: =G18+W18 -> 5.15625 | AB18: =H18+X18 -> 5.4116667 | AC18: =I18+Y18 -> 0.25541668
C19: 기타(QA위임등)* | D19: 7.4302005 | E19: =AA19 -> 0 | F19: 2.6480417 | G19: 0 | H19: 0.78861501 | I19: 0.78861501 | J19: =SUMIFS('상세 자료 작성'!$I:$I,'상세 자료 작성'!$C:$C,'요약(보고)'!$C19,'상세 자료 작성'!$A:$A,'요약(보고)'!$AE$9,'상세 자료 작성'!$D:$D,$J$4)/10^8 -> 0 | K19: =SUMIFS('상세 자료 작성'!$J:$J,'상세 자료 작성'!$C:$C,'요약(보고)'!$C19,'상세 자료 작성'!$A:$A,$AE$11,'상세 자료 작성'!$D:$D,'요약(보고)'!$J$4)/10^8 -> 0 | L19: =SUMIFS('상세 자료 작성'!$K:$K,'상세 자료 작성'!$C:$C,'요약(보고)'!$C19,'상세 자료 작성'!$A:$A,$AE$11,'상세 자료 작성'!$D:$D,$J$4)/10^8 -> 0 | M19: =L19-K19 -> 0 | N19: =SUMIFS('상세 자료 작성'!$I:$I,'상세 자료 작성'!$C:$C,'요약(보고)'!$C19,'상세 자료 작성'!$A:$A,'요약(보고)'!$AE$9,'상세 자료 작성'!$D:$D,$N$4)/10^8 -> 0 | O19: =SUMIFS('상세 자료 작성'!$J:$J,'상세 자료 작성'!$C:$C,'요약(보고)'!$C19,'상세 자료 작성'!$A:$A,$AE$11,'상세 자료 작성'!$D:$D,$N$4)/10^8 -> 0 | P19: =SUMIFS('상세 자료 작성'!$K:$K,'상세 자료 작성'!$C:$C,'요약(보고)'!$C19,'상세 자료 작성'!$A:$A,$AE$11,'상세 자료 작성'!$D:$D,$N$4)/10^8 -> 0 | Q19: =P19-O19 -> 0 | R19: =SUMIFS('상세 자료 작성'!$I:$I,'상세 자료 작성'!$C:$C,'요약(보고)'!$C19,'상세 자료 작성'!$A:$A,'요약(보고)'!$AE$9,'상세 자료 작성'!$D:$D,$R$4)/10^8 -> 0.973216 | S19: =SUMIFS('상세 자료 작성'!$J:$J,'상세 자료 작성'!$C:$C,'요약(보고)'!$C19,'상세 자료 작성'!$A:$A,$AE$11,'상세 자료 작성'!$D:$D,$R$4)/10^8 -> 0 | T19: =SUMIFS('상세 자료 작성'!$K:$K,'상세 자료 작성'!$C:$C,'요약(보고)'!$C19,'상세 자료 작성'!$A:$A,$AE$11,'상세 자료 작성'!$D:$D,$R$4)/10^8 -> 0 | U19: =T19-S19 -> 0 | V19: =R19+J19+N19 -> 0.973216 | W19: =S19+K19+O19 -> 0 | X19: =T19+L19+P19 -> 0 | Y19: =X19-W19 -> 0 | Z19: =F19+V19 -> 3.6212577 | AA19: =G19+W19 -> 0 | AB19: =H19+X19 -> 0.78861501 | AC19: =I19+Y19 -> 0.78861501
B20: 국내영업 | D20: =SUM(D21:D23) -> 0 | E20: =SUM(E21:E23) -> 3392.2517 | F20: =SUM(F21:F23) -> 0 | G20: =SUM(G21:G23) -> 672.24237 | H20: =SUM(H21:H23) -> 672.24237 | I20: =SUM(I21:I23) -> 0 | J20: =SUM(J21:J23) -> 0 | K20: =SUM(K21:K23) -> 236.81199 | ... Q20: =SUM(Q21:Q23) -> 0 | R20: ='상세 자료 작성'!I39 -> 9532347466 | S20: =SUM(S21:S23) -> 364.64057 | T20: =SUM(T21:T23) -> 364.64057 | U20: =SUM(U21:U23) -> 0 | V20: =SUM(V21:V23) -> 0 | W20: =SUM(W21:W23) -> 882.06849 | X20: =SUM(X21:X23) -> 882.06849 | Y20: =SUM(Y21:Y23) -> 0
C21: 케미컬 | D21: 0 | E21: 1869.8805 | F21: 0 | G21: 404.56184 | H21: 404.56184 | I21: =H21-G21 -> 0 | J21: 0 | K21: 157.15481 | L21: 157.15481 | M21: =L21-K21 -> 0 | N21: 0 | O21: 170.53756 | P21: 170.53756 | Q21: =P21-O21 -> 0 | R21: ='상세 자료 작성'!I40 -> 26963794201 | S21: 194.32657 | T21: 194.32657 | U21: =T21-S21 -> 0 | V21: 0 | W21: =K21+O21+S21 -> 522.01894 | X21: =L21+P21+T21 -> 522.01894 | Y21: =X21-W21 -> 0
C22: 바이오 | D22: 0 | E22: 1000 | F22: 0 | G22: 214.70497 | H22: 214.70497 | I22: =H22-G22 -> 0 | J22: 0 | K22: 57.938842 | L22: 57.938842 | M22: =L22-K22 -> 0 | N22: 0 | O22: 86.908263 | P22: 86.908263 | Q22: =P22-O22 -> 0 | R22: ='상세 자료 작성'!I41 -> 1151454672 | S22: 144.97406 | T22: 144.97406 | U22: =T22-S22 -> 0 | V22: 0 | W22: =K22+O22+S22 -> 289.82116 | X22: =L22+P22+T22 -> 289.82116 | Y22: =X22-W22 -> 0
C23: APAC | D23: 0 | E23: 522.37127 | F23: 0 | G23: 52.975551 | H23: 52.975551 | I23: =H23-G23 -> 0 | J23: 0 | K23: 21.718335 | L23: 21.718335 | M23: =L23-K23 -> 0 | N23: 0 | O23: 23.17011 | P23: 23.17011 | Q23: =P23-O23 -> 0 | R23: ='상세 자료 작성'!I42 -> 0 | S23: 25.339943 | T23: 25.339943 | U23: =T23-S23 -> 0 | V23: 0 | W23: =K23+O23+S23 -> 70.228388 | X23: =L23+P23+T23 -> 70.228388 | Y23: =X23-W23 -> 0
B24: *기타 : 약물감시, IIT 용역 추가 반영
B26: 1) 2분기 매출 변동사항 | F26: 3월 | W26: * : 매출 미반영
B27: 구분 | E27: 계획 | G27: 실질 롤링 | I27: 사업계획 대비 | K27: 변경사유 / 특이사항
B28: 케미컬 상업 | E28: =W9 -> 33.729441 | G28: =X9 -> 33.729441 | I28: =G28-E28 -> 0 | K28: - 4월 이달비클로정40/12.5mg 28T TH향 수율반영(+3억)
B29: 바이오상업 | E29: =W12 -> 278.80375 | G29: =X12 -> 278.80375 | I29: =G29-E29 -> 0
C30: PFS | E30: =W13 -> 266.59305 | G30: =X13 -> 266.59305 | I30: =G30-E30 -> 0 | K30: - 상반기 충전 개발/평가일정 23일 감소(+47억원, 1백만 시린지 추가 생산) -> 4월 8억, 5월 14억, 6월 26억 증가 영향 - 상반기 조립 개발/평가일정 10일 감소(+58억원, 0.3백만 시린지 추가 생산) -> 4월 7억, 5월 16억, 6월 35억 증가 영향
C31: L&P | E31: =W14 -> 12.210696 | G31: =X14 -> 12.210696 | I31: =G31-E31 -> 0
B32: 개발용역 | E32: =W15 -> 69.9885 | G32: =X15 -> 69.9885 | I32: =G32-E32 -> 0
C33: PFS 개발 | E33: =W16 -> 64.0335 | G33: =X16 -> 64.0335 | I33: =G33-E33 -> 0 | K33: [감소 요인] - CT-P41 120mg 일정 조정(-3억원, 충전PV protocol 6월 -> 8월) - CT-P39 300mg 일정 조정(-4억원, 충전PV protocol 6월 -> 8월) - CT-P52 80mg 일정 조정(-13억원, 충전PV(-11억), PKV(-2억) 6월 -> 7월) [증가 요인] - CT-P42 2mg 충전 PV protocol 3월 -> 4월 이월(+3억원) - CT-P55 75mg, 150mg PKV 추가(+2억원)
C34: LCM | E34: =W17 -> 5.48625 | G34: =X17 -> 5.48625 | I34: =G34-E34 -> 0 | K34: - CT-L02 EBP 3월에서 이월(+0.8억원, 3월 -> 4월) - CT-L03 IMP 일정 연기(-1.2억원, 5월 -> 7월) 및 위약 안정성 추가(+0.7억)
C35: 내재화 개발 | E35: =W18 -> 0.46875 | G35: =X18 -> 0.46875 | I35: =G35-E35 -> 0
C36: 기타(QA위임등)* | E36: =W19 -> 0 | G36: =X19 -> 0 | I36: =G36-E36 -> 0
B37: 총합 | E37: =E28+E29+E32 -> 382.52169 | G37: =G28+G29+G32 -> 382.52169 | I37: =G37-E37 -> 0
B39: 2) 3분기 매출 특이사항
B40: 구분 | E40: 계획 | G40: 전주 보고 (경영회의) | I40: 금주 보고 (경영회의) | K40: 전주 대비 | M40: 변경사유 / 특이사항
B41: 케미컬 상업 | E41: =W9 -> 33.729441 | G41: =SUM('상세 자료 작성'!M215:M217,'상세 자료 작성'!M226:M228,'상세 자료 작성'!M237:M239)/10^8 -> 44.626386 | I41: =X9 -> 33.729441 | K41: =I41-G41 -> -10.896945 | M41: 상동
B42: 바이오상업 | E42: =SUM(E43:F44) -> 278.80375 | G42: =SUM(G43:H44) -> 286.88217 | I42: =SUM(I43:J44) -> 278.80375 | K42: =I42-G42 -> -8.0784199
...

Sheet 상세 자료 작성
D1: ■ 주간 매출보고 자료
D2: 1) PO 기준 : | F2: 케미컬상업 | G2: 실질 PO 접수 기준
F3: PFS 상업 | G3: 2개월 100% Binding FCST 기준
F4: L&P 상업 | G4: 2개월 100% Binding FCST 기준
N5: 기준일자 : 2025-06-26
A6: 연 | B6: 분기 | D6: 월 | E6: 주차 | F6: 법인 | G6: 구분 | H6: 상세구분 | I6: 매출실적 | J6: 사업계획 | K6: 예상마감 | L6: 달성률 | M6: 전주 예상 실적 | N6: Gap
A7: 24년 | B7: 1분기 | C7: G07 | D7: 1월 | E7: 1주차 | F7: 셀트리온제약 | G7: 용역 | H7: CMO상업_조달 | I7: 302597280 | J7: 736312500 | K7: 302597280 | L7: 0.41096312 | M7: 302597280 | N7: 0 | P7: 302597280 | Q7: =P7-I7 -> 0
A8: 24년 | B8: 1분기 | C8: 기타 | D8: 1월 | E8: 1주차 | F8: 셀트리온제약 | G8: 용역 | H8: CMO상업_미국 | I8: 0 | J8: 0 | K8: 0 | M8: 0 | N8: 0 | P8: 0 | Q8: =P8-I8 -> 0
A9: 24년 | B9: 1분기 | C9: 내재화 | D9: 1월 | E9: 1주차 | F9: 셀트리온제약 | G9: 용역 | H9: CMO상업_내재화 | I9: 0 | J9: 0 | K9: 0 | M9: 0 | N9: 0 | P9: 0 | Q9: =P9-I9 -> 0
A10: 24년 | B10: 1분기 | C10: L&P | D10: 1월 | E10: 1주차 | F10: 셀트리온제약 | G10: 용역 | H10: CMO상업_L&P | I10: 1013747020 | J10: 9.5931083e+08 | K10: 1013747020 | L10: 1.0567451 | M10: 1013747020 | N10: 0 | P10: 1013747020 | Q10: =P10-I10 -> 0
A11: 24년 | B11: 1분기 | C11: PFS | D11: 1월 | E11: 1주차 | F11: 셀트리온제약 | G11: 용역 | H11: CMO상업_PFS | I11: 4869898150 | J11: 4405740000 | K11: 4869898150 | L11: 1.1053531 | M11: 4869898150 | N11: 0 | P11: 4869898150 | Q11: =P11-I11 -> 0 | R11: =R12-K133 -> 0 | S11: =S12-K144 -> 0
A12: 24년 | B12: 1분기 | C12: GCP | D12: 1월 | E12: 1주차 | F12: 셀트리온제약 | G12: 용역 | H12: CMO용역_GCP | I12: 0 | J12: 0 | K12: 0 | M12: 0 | N12: 0 | P12: 0 | Q12: =P12-I12 -> 0 | R12: =SUM(R14:R25) -> 12361988503 | S12: =SUM(S14:S25) -> 15101542896 | T12: =SUM(T14:T25) -> 27463531399
A13: 24년 | B13: 1분기 | C13: LCM | D13: 1월 | E13: 1주차 | F13: 셀트리온제약 | G13: 용역 | H13: CMO용역_LCM | I13: 0 | J13: 490500000 | K13: 0 | L13: 0 | M13: 0 | N13: 0 | P13: 0 | Q13: =P13-I13 -> 0 | R13: 11월 | S13: 12월 | T13: 합계
A14: 24년 | B14: 1분기 | C14: PFS 개발 | D14: 1월 | E14: 1주차 | F14: 셀트리온제약 | G14: 용역 | H14: CMO용역_PFS | I14: 439139429 | J14: 0 | K14: 439139429 | M14: 439139429 | N14: 0 | P14: 439139429 | Q14: =P14-I14 -> 0 | R14: =SUM(K123:K124) -> 0 | S14: =SUM(K134:K135) -> 0 | T14: =SUM(R14:S14) -> 0
A15: 24년 | B15: 1분기 | C15: 내재화 개발 | D15: 1월 | E15: 1주차 | F15: 셀트리온제약 | G15: 용역 | H15: CMO용역_내재화 | I15: 67266666 | J15: 0 | K15: 67266666 | M15: 67266666 | N15: 0 | P15: 67266666 | Q15: =P15-I15 -> 0 | R15: =K126 -> 166471840 | S15: =K137 -> 190623740 | T15: =SUM(R15:S15) -> 357095580
A16: 24년 | B16: 1분기 | C16: 기타(QA위임등)* | D16: 1월 | E16: 1주차 | F16: 셀트리온제약 | G16: 용역 | H16: 용역_QA위임 | I16: 39867000 | J16: 0 | K16: 39867000 | M16: 39867000 | N16: 0 | P16: 39867000 | Q16: =P16-I16 -> 0 | R16: =K127 -> 7377697800 | S16: =K138 -> 8035017050 | T16: =SUM(R16:S16) -> 15412714850
E17: 1월 예상 실적 | I17: 6732515545 | J17: 6.5918633e+09 | K17: 6732515545 | L17: 1.0213372 | M17: 6732515545 | N17: 0 | P17: 6732515545 | Q17: =P17-I17 -> 0 | R17: =K125 -> 4528225660 | S17: =K136 -> 6019051822 | T17: =SUM(R17:S17) -> 10547277482
A18: 24년 | B18: 1분기 | C18: G07 | D18: 2월 | E18: 1주차 | F18: 셀트리온제약 | G18: 용역 | H18: CMO상업_조달 | I18: 5372064744 | J18: 3253527000 | K18: 5372064744 | L18: 1.6511511 | M18: 5372064744 | N18: 0 | P18: 5372064744 | Q18: =P18-I18 -> 0 | R18: =K128 -> 0 | S18: =K139 -> 134600000 | T18: =SUM(R18:S18) -> 134600000
A19: 24년 | B19: 1분기 | C19: 기타 | D19: 2월 | E19: 1주차 | F19: 셀트리온제약 | G19: 용역 | H19: CMO상업_미국 | I19: 0 | J19: 0 | K19: 0 | M19: 0 | N19: 0 | P19: 0 | Q19: =P19-I19 -> 0 | R19: =K129 -> 38500000 | S19: =K140 -> 46875000 | T19: =SUM(R19:S19) -> 85375000
A20: 24년 | B20: 1분기 | C20: 내재화 | D20: 2월 | E20: 1주차 | F20: 셀트리온제약 | G20: 용역 | H20: CMO상업_내재화 | I20: 0 | J20: 0 | K20: 0 | M20: 0 | N20: 0 | P20: 0 | Q20: =P20-I20 -> 0 | R20: =K130 -> 110001036 | S20: =K141 -> 476323136 | T20: =SUM(R20:S20) -> 586324172
A21: 24년 | B21: 1분기 | C21: L&P | D21: 2월 | E21: 1주차 | F21: 셀트리온제약 | G21: 용역 | H21: CMO상업_L&P | I21: 684982200 | J21: 9.5931083e+08 | K21: 684982200 | L21: 0.71403572 | M21: 684982200 | N21: 0 | P21: 684982200 | Q21: =P21-I21 -> 0 | R21: =K131 -> 125354167 | S21: =K142 -> 31604167 | T21: =SUM(R21:S21) -> 156958334
A22: 24년 | B22: 1분기 | C22: PFS | D22: 2월 | E22: 1주차 | F22: 셀트리온제약 | G22: 용역 | H22: CMO상업_PFS | I22: 4437683550 | J22: 4.7866246e+08 | K22: 4437683550 | M22: 4437683550 | N22: 0 | P22: 4437683550 | Q22: =P22-I22 -> 0 | R22: =K132 -> 15738000 | S22: =K143 -> 167447981 | T22: =SUM(R22:S22) -> 183185981
A23: 24년 | B23: 1분기 | C23: GCP | D23: 2월 | E23: 1주차 | F23: 셀트리온제약 | G23: 용역 | H23: CMO용역_GCP | I23: 40000000 | J23: 40000000 | K23: 40000000 | L23: 1 | M23: 40000000 | N23: 0 | P23: 40000000 | Q23: =P23-I23 -> 0 | T23: =SUM(R23:S23) -> 0
A24: 24년 | B24: 1분기 | C24: LCM | D24: 2월 | E24: 1주차 | F24: 셀트리온제약 | G24: 용역 | H24: CMO용역_LCM | I24: 0 | J24: 766500000 | K24: 0 | L24: 0 | M24: 0 | N24: 0 | P24: 0 | Q24: =P24-I24 -> 0
A25: 24년 | B25: 1분기 | C25: PFS 개발 | D25: 2월 | E25: 1주차 | F25: 셀트리온제약 | G25: 용역 | H25: CMO용역_PFS | I25: 14069429 | J25: 162000000 | K25: 14069429 | L25: 0.086848327 | M25: 14069429 | N25: 0 | P25: 14069429 | Q25: =P25-I25 -> 0
A26: 24년 | B26: 1분기 | C26: 내재화 개발 | D26: 2월 | E26: 1주차 | F26: 셀트리온제약 | G26: 용역 | H26: CMO용역_내재화 | I26: 119041667 | J26: 93750000 | K26: 119041667 | L26: 1.2697778 | M26: 119041667 | N26: 0 | P26: 119041667 | Q26: =P26-I26 -> 0
A27: 24년 | B27: 1분기 | C27: 기타(QA위임등)* | D27: 2월 | E27: 1주차 | F27: 셀트리온제약 | G27: 용역 | H27: 용역_QA위임 | I27: 31089600 | J27: 0 | K27: 31089600 | M27: 31089600 | N27: 0 | P27: 31089600 | Q27: =P27-I27 -> 0
E28: 2월 실적 | I28: 10698931190 | J28: 5.7537503e+09 | K28: 10698931190 | L28: 1.8594709 | M28: 10698931190 | N28: 0 | P28: 10698931190 | Q28: =P28-I28 -> 0
A29: 24년 | B29: 1분기 | C29: G07 | D29: 3월 | E29: 4주차 | F29: 셀트리온제약 | G29: 용역 | H29: CMO상업_조달 | I29: 2967439150 | J29: 2762644500 | K29: 2967439150 | L29: 1.0741299 | M29: 2967439150 | N29: 0 | P29: 2967439150 | Q29: =P29-I29 -> 0
A30: 24년 | B30: 1분기 | C30: 기타 | D30: 3월 | E30: 4주차 | F30: 셀트리온제약 | G30: 용역 | H30: CMO상업_미국 | I30: 0 | J30: 0 | K30: 0 | L30: #DIV/0! | M30: 0 | N30: 0 | P30: 0 | Q30: =P30-I30 -> 0
A31: 24년 | B31: 1분기 | C31: 내재화 | D31: 3월 | E31: 1주차 | F31: 셀트리온제약 | G31: 용역 | H31: CMO상업_내재화 | I31: 0 | J31: 0 | K31: 0 | M31: 0 | N31: 0 | P31: 0 | Q31: =P31-I31 -> 0
A32: 24년 | B32: 1분기 | C32: L&P | D32: 3월 | E32: 4주차 | F32: 셀트리온제약 | G32: 용역 | H32: CMO상업_L&P | I32: 1047403520 | J32: 9.5931083e+08 | K32: 1047403520 | L32: 1.0918291 | M32: 1047403520 | N32: 0 | P32: 1047403520 | Q32: =P32-I32 -> 0
A33: 24년 | B33: 1분기 | C33: PFS | D33: 3월 | E33: 4주차 | F33: 셀트리온제약 | G33: 용역 | H33: CMO상업_PFS | I33: 4508694300 | J33: 4.7344899e+09 | K33: 4508694300 | L33: 0.95230835 | M33: 4508694300 | N33: 0 | P33: 4508694300 | Q33: =P33-I33 -> 0
A34: 24년 | B34: 1분기 | C34: GCP | D34: 3월 | E34: 4주차 | F34: 셀트리온제약 | G34: 용역 | H34: CMO용역_GCP | I34: 0 | J34: 0 | K34: 0 | M34: 0 | N34: 0 | P34: 0 | Q34: =P34-I34 -> 0 | R34: =R14/10^8 -> 0 | S34: =S14/10^8 -> 0 | T34: =T14/10^8 -> 0
A35: 24년 | B35: 1분기 | C35: LCM | D35: 3월 | E35: 4주차 | F35: 셀트리온제약 | G35: 용역 | H35: CMO용역_LCM | I35: 520375000 | J35: 1666750000 | K35: 520375000 | L35: 0.31220939 | M35: 520375000 | N35: 0 | P35: 520375000 | Q35: =P35-I35 -> 0 | R35: =R15/10^8 -> 1.6647184 | S35: =S15/10^8 -> 1.9062374 | T35: =T15/10^8 -> 3.5709558
A36: 24년 | B36: 1분기 | C36: PFS 개발 | D36: 3월 | E36: 4주차 | F36: 셀트리온제약 | G36: 용역 | H36: CMO용역_PFS | I36: 421269829 | J36: 5.06e+08 | K36: 421269829 | L36: 0.83254907 | M36: 421269829 | N36: 0 | P36: 421269829 | Q36: =P36-I36 -> 0 | R36: =R16/10^8 -> 73.776978 | S36: =S16/10^8 -> 80.350171 | T36: =T16/10^8 -> 154.12715
A37: 24년 | B37: 1분기 | C37: 내재화 개발 | D37: 3월 | E37: 4주차 | F37: 셀트리온제약 | G37: 용역 | H37: CMO용역_내재화 | I37: 25291667 | J37: 361875000 | K37: 25291667 | L37: 0.069890617 | M37: 25291667 | N37: 0 | P37: 25291667 | Q37: =P37-I37 -> 0 | R37: =R17/10^8 -> 45.282257 | S37: =S17/10^8 -> 60.190518 | T37: =T17/10^8 -> 105.47277
A38: 24년 | B38: 1분기 | C38: 기타(QA위임등)* | D38: 3월 | E38: 1주차 | F38: 셀트리온제약 | G38: 용역 | H38: 용역_QA위임 | I38: 41874000 | J38: 0 | K38: 41874000 | L38: #DIV/0! | M38: 41874000 | N38: 0 | P38: 41874000 | Q38: =P38-I38 -> 0 | R38: =R18/10^8 -> 0 | S38: =S18/10^8 -> 1.346 | T38: =T18/10^8 -> 1.346
E39: 3월 실적 | I39: 9532347466 | J39: 1.099107e+10 | K39: 9532347466 | L39: 0.8672811 | M39: 9532347466 | N39: 0 | P39: 9532347466 | Q39: =P39-I39 -> 0 | R39: =R19/10^8 -> 0.385 | S39: =S19/10^8 -> 0.46875 | T39: =T19/10^8 -> 0.85375
D40: 1분기 실적 | I40: 26963794201 | J40: 2.3336684e+10 | K40: 26963794201 | L40: 1.1554253 | M40: 26963794201 | N40: 0 | P40: 26963794201 | Q40: =P40-I40 -> 0 | R40: =R20/10^8 -> 1.1000104 | S40: =S20/10^8 -> 4.7632314 | T40: =T20/10^8 -> 5.8632417
...

Sheet 2024년 계획
B2: □ 2024년 매출 계획
B4: 사업계획_구분1 | C4: 경영정보통합 | D4: 사업계획_구분3 | E4: 사업계획_구분4 | F4: 1월 | G4: 2월 | H4: 3월 | I4: 4월 | J4: 5월 | K4: 6월 | L4: 7월 | M4: 8월 | N4: 9월 | O4: 10월 | P4: 11월 | Q4: 12월 | R4: 2024년 계획 합계 | T4: 2월 누계 | U4: 3월 누계 | V4: 4월 누계 | W4: 5월 누계 | X4: 6월 누계 | Y4: 7월 누계 | Z4: 8월 누계 | AA4: 9월 누계 | AB4: 10월 누계 | AC4: 11월 누계 | AE4: 1분기 | AF4: 2분기 | AG4: 3분기 | AH4: 4분기
B5: 케미컬 | C5: 고덱스 | D5: 고덱스 | E5: 고덱스캡슐 | F5: 2.8215448e+09 | G5: 4.2323172e+09 | H5: 7.0538621e+09 | I5: 3.775695e+09 | J5: 5.6635424e+09 | K5: 9.4392374e+09 | L5: 3.0837976e+09 | M5: 4.6256963e+09 | N5: 7.7094939e+09 | O5: 3.3189627e+09 | P5: 4.978444e+09 | Q5: 8.2974066e+09 | R5: =SUM(F5:Q5) -> 6.5e+10 | T5: =SUM(F5:G5) -> 7.0538621e+09 | U5: =T5+H5 -> 1.4107724e+10 | V5: =U5+I5 -> 1.7883419e+10 | W5: =V5+J5 -> 2.3546962e+10 | X5: =W5+K5 -> 3.2986199e+10 | Y5: =X5+L5 -> 3.6069996e+10 | Z5: =Y5+M5 -> 4.0695693e+10 | AA5: =Z5+N5 -> 4.8405187e+10 | AB5: =AA5+O5 -> 5.1724149e+10 | AC5: =AB5+P5 -> 5.6702593e+10 | AE5: =SUM(F5:H5) -> 1.4107724e+10 | AF5: =SUM(I5:K5) -> 1.8878475e+10 | AG5: =SUM(L5:N5) -> 1.5418988e+10 | AH5: =SUM(O5:Q5) -> 1.6594813e+10
B6: 케미컬 | C6: 고덱스 | D6: 고덱스 | E6: 고덱스정 | F6: 0 | G6: 0 | H6: 0 | I6: 0 | J6: 0 | K6: 0 | L6: 0 | M6: 0 | N6: 0 | O6: 0 | P6: 0 | Q6: 0 | R6: =SUM(F6:Q6) -> 0 | T6: =SUM(F6:G6) -> 0 | U6: =T6+H6 -> 0 | V6: =U6+I6 -> 0 | W6: =V6+J6 -> 0 | X6: =W6+K6 -> 0 | Y6: =X6+L6 -> 0 | Z6: =Y6+M6 -> 0 | AA6: =Z6+N6 -> 0 | AB6: =AA6+O6 -> 0 | AC6: =AB6+P6 -> 0 | AE6: =SUM(F6:H6) -> 0 | AF6: =SUM(I6:K6) -> 0 | AG6: =SUM(L6:N6) -> 0 | AH6: =SUM(O6:Q6) -> 0
B7: 케미컬 | C7: 제품기타 | D7: 약가보상(케미컬) | E7: 약가보상(케미컬) | F7: 0 | G7: 0 | H7: 0 | I7: 0 | J7: 0 | K7: 0 | L7: 0 | M7: 0 | N7: 0 | O7: 0 | P7: 0 | Q7: 0 | R7: =SUM(F7:Q7) -> 0 | T7: =SUM(F7:G7) -> 0 | U7: =T7+H7 -> 0 | V7: =U7+I7 -> 0 | W7: =V7+J7 -> 0 | X7: =W7+K7 -> 0 | Y7: =X7+L7 -> 0 | Z7: =Y7+M7 -> 0 | AA7: =Z7+N7 -> 0 | AB7: =AA7+O7 -> 0 | AC7: =AB7+P7 -> 0 | AE7: =SUM(F7:H7) -> 0 | AF7: =SUM(I7:K7) -> 0 | AG7: =SUM(L7:N7) -> 0 | AH7: =SUM(O7:Q7) -> 0
B8: 케미컬 | C8: 도네리온 | D8: 도네리온 | E8: 도네리온 | F8: 99309184 | G8: 1.4896378e+08 | H8: 2.4827296e+08 | I8: 1.3289216e+08 | J8: 1.9933824e+08 | K8: 3.322304e+08 | L8: 1.0853963e+08 | M8: 1.6280944e+08 | N8: 2.7134907e+08 | O8: 1.1686812e+08 | P8: 1.7530218e+08 | Q8: 2.921703e+08 | R8: =SUM(F8:Q8) -> 2.2880455e+09 | T8: =SUM(F8:G8) -> 2.4827296e+08 | U8: =T8+H8 -> 4.9654592e+08 | V8: =U8+I8 -> 6.2943808e+08 | W8: =V8+J8 -> 8.2877632e+08 | X8: =W8+K8 -> 1.1610067e+09 | Y8: =X8+L8 -> 1.2695463e+09 | Z8: =Y8+M8 -> 1.4323558e+09 | AA8: =Z8+N8 -> 1.7037049e+09 | AB8: =AA8+O8 -> 1.820573e+09 | AC8: =AB8+P8 -> 1.9958752e+09 | AE8: =SUM(F8:H8) -> 4.9654592e+08 | AF8: =SUM(I8:K8) -> 6.644608e+08 | AG8: =SUM(L8:N8) -> 5.4269813e+08 | AH8: =SUM(O8:Q8) -> 5.843406e+08
B9: 케미컬 | C9: 공동판매 | D9: 케미컬쌍방코프로 | E9: 케미컬쌍방코프로 | F9: 9.1157602e+08 | G9: 1.367364e+09 | H9: 2.27894e+09 | I9: 1.2198399e+09 | J9: 1.8297599e+09 | K9: 3.0495998e+09 | L9: 9.9630383e+08 | M9: 1.4944557e+09 | N9: 2.4907596e+09 | O9: 1.0722802e+09 | P9: 1.6084204e+09 | Q9: 2.6807006e+09 | R9: =SUM(F9:Q9) -> 2.1e+10 | T9: =SUM(F9:G9) -> 2.27894e+09 | U9: =T9+H9 -> 4.5578801e+09 | V9: =U9+I9 -> 5.77772e+09 | W9: =V9+J9 -> 7.6074799e+09 | X9: =W9+K9 -> 1.065708e+10 | Y9: =X9+L9 -> 1.1653383e+10 | Z9: =Y9+M9 -> 1.3147839e+10 | AA9: =Z9+N9 -> 1.5638599e+10 | AB9: =AA9+O9 -> 1.6710879e+10 | AC9: =AB9+P9 -> 1.8319299e+10 | AE9: =SUM(F9:H9) -> 4.5578801e+09 | AF9: =SUM(I9:K9) -> 6.0991996e+09 | AG9: =SUM(L9:N9) -> 4.9815191e+09 | AH9: =SUM(O9:Q9) -> 5.3614012e+09
B10: 케미컬 | C10: CSO | D10: CSO | E10: CSO-자사 | F10: 1.5840357e+09 | G10: 2.3760535e+09 | H10: 3.8386408e+09 | I10: 2.1197025e+09 | J10: 3.1795537e+09 | K10: 4.2262497e+09 | L10: 1.7312663e+09 | M10: 2.5968994e+09 | N10: 4.3281657e+09 | O10: 2.2217791e+09 | P10: 3.1538343e+09 | Q10: 4.4107027e+09 | R10: =SUM(F10:Q10) -> 3.5766883e+10 | T10: =SUM(F10:G10) -> 3.9600892e+09 | U10: =T10+H10 -> 7.79873e+09 | V10: =U10+I10 -> 9.9184325e+09 | W10: =V10+J10 -> 1.3097986e+10 | X10: =W10+K10 -> 1.7324236e+10 | Y10: =X10+L10 -> 1.9055502e+10 | Z10: =Y10+M10 -> 2.1652402e+10 | AA10: =Z10+N10 -> 2.5980567e+10 | AB10: =AA10+O10 -> 2.8202346e+10 | AC10: =AB10+P10 -> 3.1356181e+10 | AE10: =SUM(F10:H10) -> 7.79873e+09 | AF10: =SUM(I10:K10) -> 9.5255059e+09 | AG10: =SUM(L10:N10) -> 8.6563313e+09 | AH10: =SUM(O10:Q10) -> 9.7863161e+09
B11: 케미컬 | C11: CSO | D11: CSO | E11: CSO-위탁 | F11: 2.3751765e+09 | G11: 3.5331353e+09 | H11: 5.6835746e+09 | I11: 3.1562229e+09 | J11: 4.7086872e+09 | K11: 6.2476423e+09 | L11: 2.579273e+09 | M11: 3.8520117e+09 | N11: 6.3636937e+09 | O11: 3.2666776e+09 | P11: 4.6370765e+09 | Q11: 6.4850477e+09 | R11: =SUM(F11:Q11) -> 5.2888219e+10 | T11: =SUM(F11:G11) -> 5.9083118e+09 | U11: =T11+H11 -> 1.1591886e+10 | V11: =U11+I11 -> 1.4748109e+10 | W11: =V11+J11 -> 1.9456796e+10 | X11: =W11+K11 -> 2.5704439e+10 | Y11: =X11+L11 -> 2.8283712e+10 | Z11: =Y11+M11 -> 3.2135723e+10 | AA11: =Z11+N11 -> 3.8499417e+10 | AB11: =AA11+O11 -> 4.1766095e+10 | AC11: =AB11+P11 -> 4.6403171e+10 | AE11: =SUM(F11:H11) -> 1.1591886e+10 | AF11: =SUM(I11:K11) -> 1.4112552e+10 | AG11: =SUM(L11:N11) -> 1.2794978e+10 | AH11: =SUM(O11:Q11) -> 1.4388802e+10
B12: 케미컬 | C12: CSO | D12: 약가보상(전략) | E12: 약가보상(전략) | F12: -1.5083263e+08 | G12: 0 | H12: 0 | I12: 0 | J12: 0 | K12: 0 | L12: 0 | M12: 0 | N12: 0 | O12: 0 | P12: 0 | Q12: 0 | R12: =SUM(F12:Q12) -> -1.5083263e+08 | T12: =SUM(F12:G12) -> -1.5083263e+08 | U12: =T12+H12 -> -1.5083263e+08 | V12: =U12+I12 -> -1.5083263e+08 | W12: =V12+J12 -> -1.5083263e+08 | X12: =W12+K12 -> -1.5083263e+08 | Y12: =X12+L12 -> -1.5083263e+08 | Z12: =Y12+M12 -> -1.5083263e+08 | AA12: =Z12+N12 -> -1.5083263e+08 | AB12: =AA12+O12 -> -1.5083263e+08 | AC12: =AB12+P12 -> -1.5083263e+08 | AE12: =SUM(F12:H12) -> -1.5083263e+08 | AF12: =SUM(I12:K12) -> 0 | AG12: =SUM(L12:N12) -> 0 | AH12: =SUM(O12:Q12) -> 0
B13: 케미컬 | C13: 제품기타 | D13: 트레블정 | E13: 트레블정 | F13: 66242577 | G13: 99363865 | H13: 1.6052761e+08 | I13: 88643555 | J13: 1.3296533e+08 | K13: 1.7673697e+08 | L13: 72399593 | M13: 1.0859939e+08 | N13: 1.8099898e+08 | O13: 92912285 | P13: 1.3188977e+08 | Q13: 1.8445059e+08 | R13: =SUM(F13:Q13) -> 1.4957305e+09 | T13: =SUM(F13:G13) -> 1.6560644e+08 | U13: =T13+H13 -> 3.2613405e+08 | V13: =U13+I13 -> 4.147776e+08 | W13: =V13+J13 -> 5.4774294e+08 | X13: =W13+K13 -> 7.2447991e+08 | Y13: =X13+L13 -> 7.968795e+08 | Z13: =Y13+M13 -> 9.0547889e+08 | AA13: =Z13+N13 -> 1.0864779e+09 | AB13: =AA13+O13 -> 1.1793902e+09 | AC13: =AB13+P13 -> 1.3112799e+09 | AE13: =SUM(F13:H13) -> 3.2613405e+08 | AF13: =SUM(I13:K13) -> 3.9834586e+08 | AG13: =SUM(L13:N13) -> 3.6199796e+08 | AH13: =SUM(O13:Q13) -> 4.0925265e+08
B14: 케미컬 | C14: 제품기타 | D14: 제품기타 | E14: 기타-자사 | F14: 79656086 | G14: 1.1948413e+08 | H14: 1.9914021e+08 | I14: 1.0659305e+08 | J14: 1.5988958e+08 | K14: 2.6648264e+08 | L14: 87059841 | M14: 1.3058976e+08 | N14: 2.176496e+08 | O14: 93698874 | P14: 1.4054831e+08 | Q14: 2.3424719e+08 | R14: =SUM(F14:Q14) -> 1.8350393e+09 | T14: =SUM(F14:G14) -> 1.9914021e+08 | U14: =T14+H14 -> 3.9828043e+08 | V14: =U14+I14 -> 5.0487348e+08 | W14: =V14+J14 -> 6.6476307e+08 | X14: =W14+K14 -> 9.312457e+08 | Y14: =X14+L14 -> 1.0183055e+09 | Z14: =Y14+M14 -> 1.1488953e+09 | AA14: =Z14+N14 -> 1.3665449e+09 | AB14: =AA14+O14 -> 1.4602438e+09 | AC14: =AB14+P14 -> 1.6007921e+09 | AE14: =SUM(F14:H14) -> 3.9828043e+08 | AF14: =SUM(I14:K14) -> 5.3296527e+08 | AG14: =SUM(L14:N14) -> 4.352992e+08 | AH14: =SUM(O14:Q14) -> 4.6849437e+08
B15: 케미컬 | C15: 제품기타 | D15: 제품기타 | E15: 기타-위탁 | F15: 1.9381672e+08 | G15: 2.9072508e+08 | H15: 4.845418e+08 | I15: 2.5935892e+08 | J15: 3.8903838e+08 | K15: 6.483973e+08 | L15: 2.1183131e+08 | M15: 3.1774696e+08 | N15: 5.2957827e+08 | O15: 2.279852e+08 | P15: 3.419778e+08 | Q15: 5.69963e+08 | R15: =SUM(F15:Q15) -> 4.4649607e+09 | T15: =SUM(F15:G15) -> 4.845418e+08 | U15: =T15+H15 -> 9.690836e+08 | V15: =U15+I15 -> 1.2284425e+09 | W15: =V15+J15 -> 1.6174809e+09 | X15: =W15+K15 -> 2.2658782e+09 | Y15: =X15+L15 -> 2.4777095e+09 | Z15: =Y15+M15 -> 2.7954565e+09 | AA15: =Z15+N15 -> 3.3250347e+09 | AB15: =AA15+O15 -> 3.5530199e+09 | AC15: =AB15+P15 -> 3.8949977e+09 | AE15: =SUM(F15:H15) -> 9.690836e+08 | AF15: =SUM(I15:K15) -> 1.2967946e+09 | AG15: =SUM(L15:N15) -> 1.0591565e+09 | AH15: =SUM(O15:Q15) -> 1.139926e+09
B16: 케미컬 | C16: 제품기타 | D16: OTC | E16: OTC-가네진 | F16: 66819000 | G16: 66819000 | H16: 106910400 | I16: 22273000 | J16: 60600938 | K16: 51691738 | L16: 69510138 | M16: 69510138 | N16: 69510138 | O16: 71737438 | P16: 71737438 | Q16: 71737438 | R16: =SUM(F16:Q16) -> 798856800 | T16: =SUM(F16:G16) -> 133638000 | U16: =T16+H16 -> 240548400 | V16: =U16+I16 -> 262821400 | W16: =V16+J16 -> 3.2342234e+08 | X16: =W16+K16 -> 375114075 | Y16: =X16+L16 -> 4.4462421e+08 | Z16: =Y16+M16 -> 514134350 | AA16: =Z16+N16 -> 5.8364449e+08 | AB16: =AA16+O16 -> 655381925 | AC16: =AB16+P16 -> 7.2711936e+08 | AE16: =SUM(F16:H16) -> 240548400 | AF16: =SUM(I16:K16) -> 134565675 | AG16: =SUM(L16:N16) -> 2.0853041e+08 | AH16: =SUM(O16:Q16) -> 2.1521231e+08
... B55: 기타 | C55: 제품기타 | D55: 반품부채 | E55: 반품부채 | F55: 0 | G55: 0 | H55: -100000000 | I55: 0 | J55: 0 | K55: -100000000 | L55: 0 | M55: 0 | N55: -100000000 | O55: 0 | P55: 0 | Q55: -100000000 | R55: =SUM(F55:Q55) -> -400000000 | T55: =SUM(F55:G55) -> 0 | U55: =T55+H55 -> -100000000 | V55: =U55+I55 -> -100000000 | W55: =V55+J55 -> -100000000 | X55: =W55+K55 -> -200000000 | Y55: =X55+L55 -> -200000000 | Z55: =Y55+M55 -> -200000000 | AA55: =Z55+N55 -> -300000000 | AB55: =AA55+O55 -> -300000000 | AC55: =AB55+P55 -> -300000000 | AE55: =SUM(F55:H55) -> -100000000 | AF55: =SUM(I55:K55) -> -100000000 | AG55: =SUM(L55:N55) -> -100000000 | AH55: =SUM(O55:Q55) -> -100000000
B56: 합계 | F56: =SUM(F5:F55) -> 1.986792e+10 | G56: =SUM(G5:G55) -> 2.6258909e+10 | H56: =SUM(H5:H55) -> 4.4234092e+10 | I56: =SUM(I5:I55) -> 2.3663557e+10 | J56: =SUM(J5:J55) -> 3.2515276e+10 | K56: =SUM(K5:K55) -> 5.2768862e+10 | L56: =SUM(L5:L55) -> 2.2305237e+10 | M56: =SUM(M5:M55) -> 3.8465807e+10 | ... R56: =SUM(R5:R55) -> 4.4852408e+11 | T56: =SUM(T5:T55) -> 4.6126829e+10 | U56: =SUM(U5:U55) -> 9.0360921e+10 | V56: =SUM(V5:V55) -> 1.1402448e+11 | W56: =SUM(W5:W55) -> 1.4653975e+11 | X56: =SUM(X5:X55) -> 1.9930861e+11 | Y56: =SUM(Y5:Y55) -> 2.2161385e+11 | Z56: =SUM(Z5:Z55) -> 2.6007966e+11 | AA56: =SUM(AA5:AA55) -> 3.1553611e+11 | ... AC56: =SUM(AC5:AC55) -> 3.8536578e+11 | AE56: =SUM(AE5:AE55) -> 9.0360921e+10 | AF56: =SUM(AF5:AF55) -> 1.0894769e+11 | AG56: =SUM(AG5:AG55) -> 1.1622749e+11 | AH56: =SUM(AH5:AH55) -> 1.3298797e+11
T57: =ROUND(T56,0)=ROUND(SUM($F$56:G$56),0) -> TRUE | U57: =ROUND(U56,0)=ROUND(SUM($F$56:H$56),0) -> TRUE | V57: =ROUND(V56,0)=ROUND(SUM($F$56:I$56),0) -> TRUE | W57: =ROUND(W56,0)=ROUND(SUM($F$56:J$56),0) -> TRUE | X57: =ROUND(X56,0)=ROUND(SUM($F$56:K$56),0) -> TRUE | Y57: =ROUND(Y56,0)=ROUND(SUM($F$56:L$56),0) -> TRUE | Z57: =ROUND(Z56,0)=ROUND(SUM($F$56:M$56),0) -> TRUE | AA57: =ROUND(AA56,0)=ROUND(SUM($F$56:N$56),0) -> TRUE | ... AC57: =ROUND(AC56,0)=ROUND(SUM($F$56:P$56),0) -> TRUE | AE57: =ROUND(AE56,0)=ROUND(SUM(F56:H56),0) -> TRUE | AF57: =ROUND(AF56,0)=ROUND(SUM(I56:K56),0) -> TRUE | AG57: =ROUND(AG56,0)=ROUND(SUM(L56:N56),0) -> TRUE | AH57: =ROUND(AH56,0)=ROUND(SUM(O56:Q56),0) -> TRUE

Sheet 연간 에상 (사장님보고)
A1: 23년 CMO 매출 예상실적
AD2: 2023.09.05
A3: ■ 3분기 매출 : 사업계획 대비 11억 미달 예상되나, 3분기 누적 23억 초과 예상됨
AD4: 단위 : 억원
A5: 구분 | D5: 22년 실적 | E5: 23년 목표 | F5: 상반기 | I5: 3분기 | U5: 3분기 누적 | X5: 4분기 | AB5: 연간 합계
F6: 목표 | G6: 실적 | H6: 차이 | I6: 7월 | L6: 8월 | O6: 9월 | R6: 3분기 소계 | U6: 목표 | V6: 전망 | W6: 차이 | X6: 목표 | Y6: 전망 | Z6: 차이 | AB6: 목표 | AC6: 전망 | AD6: 차이
I7: 목표 | J7: 실적 | K7: 차이 | L7: 목표 | M7: 실적 | N7: 차이 | O7: 목표 | P7: 전망 | Q7: 차이 | R7: 목표 | S7: 전망 | T7: 차이
B8: CMO 합계 | D8: =D9+D12+D15 -> #REF! | E8: =E9+E12+E15 -> #REF! | F8: =F9+F12+F15 -> #REF! | G8: =G9+G12+G15 -> #REF! | H8: =H9+H12+H15 -> #REF! | I8: =I9+I12+I15 -> #REF! | J8: =J9+J12+J15 -> #REF! | K8: =J8-I8 -> #REF! | L8: =L9+L12+L15 -> #REF! | M8: =M9+M12+M15 -> #REF! | N8: =M8-L8 -> #REF! | O8: =O9+O12+O15 -> #REF! | P8: =P9+P12+P15 -> #REF! | Q8: =P8-O8 -> #REF! | R8: =R9+R12+R15 -> #REF! | S8: =S9+S12+S15 -> #REF! | T8: =S8-R8 -> #REF! | U8: =U9+U12+U15 -> #REF! | V8: =V9+V12+V15 -> #REF! | W8: =V8-U8 -> #REF! | X8: =X9+X12+X15 -> #REF! | Y8: =Y9+Y12+Y15 -> #REF! | Z8: =Y8-X8 -> #REF! | AB8: =AB9+AB12+AB15 -> #REF! | AC8: =AC9+AC12+AC15 -> #REF! | AD8: =AC8-AB8 -> #REF!
B9: 케미컬 상업 | D9: =SUM(D10:D11) -> 549.53106 | E9: =SUM(E10:E11) -> 595.19048 | F9: =SUM(F10:F11) -> #REF! | G9: =SUM(G10:G11) -> #REF! | H9: =SUM(H10:H11) -> #REF! | I9: =SUM(I10:I11) -> #REF! | J9: =SUM(J10:J11) -> #REF! | K9: =J9-I9 -> #REF! | L9: =SUM(L10:L11) -> #REF! | M9: =SUM(M10:M11) -> #REF! | N9: =M9-L9 -> #REF! | O9: =SUM(O10:O11) -> #REF! | P9: =SUM(P10:P11) -> #REF! | Q9: =P9-O9 -> #REF! | R9: =SUM(R10:R11) -> #REF! | S9: =SUM(S10:S11) -> #REF! | T9: =S9-R9 -> #REF! | U9: =SUM(U10:U11) -> #REF! | V9: =SUM(V10:V11) -> #REF! | W9: =V9-U9 -> #REF! | X9: =SUM(X10:X11) -> #REF! | Y9: =SUM(Y10:Y11) -> #REF! | Z9: =Y9-X9 -> #REF! | AB9: =SUM(AB10:AB11) -> #REF! | AC9: =SUM(AC10:AC11) -> #REF! | AD9: =AC9-AB9 -> #REF!
C10: G07 | D10: 529.0366 | E10: 586.22559 | F10: =#REF!+#REF! -> #REF! | G10: =#REF!+#REF! -> #REF! | H10: =G10-F10 -> #REF! | I10: =#REF! -> #REF! | J10: =#REF! -> #REF! | K10: =J10-I10 -> #REF! | L10: =#REF! -> #REF! | M10: =#REF! -> #REF! | N10: =M10-L10 -> #REF! | O10: =#REF! -> #REF! | P10: =#REF! -> #REF! | Q10: =P10-O10 -> #REF! | R10: =I10+L10+O10 -> #REF! | S10: =J10+M10+P10 -> #REF! | T10: =S10-R10 -> #REF! | U10: =R10+F10 -> #REF! | V10: =S10+G10 -> #REF! | W10: =V10-U10 -> #REF! | X10: =#REF! -> #REF! | Y10: =#REF! -> #REF! | Z10: =Y10-X10 -> #REF! | AB10: =F10+R10+X10 -> #REF! | AC10: =G10+S10+Y10 -> #REF! | AD10: =AC10-AB10 -> #REF!
C11: 기타 | D11: 20.494454 | E11: 8.964888 | F11: =#REF!+#REF! -> #REF! | G11: =#REF!+#REF! -> #REF! | H11: =G11-F11 -> #REF! | I11: =#REF! -> #REF! | J11: =#REF! -> #REF! | K11: =J11-I11 -> #REF! | L11: =#REF! -> #REF! | M11: =#REF! -> #REF! | N11: =M11-L11 -> #REF! | O11: =#REF! -> #REF! | P11: =#REF! -> #REF! | Q11: =P11-O11 -> #REF! | R11: =I11+L11+O11 -> #REF! | S11: =J11+M11+P11 -> #REF! | T11: =S11-R11 -> #REF! | U11: =R11+F11 -> #REF! | V11: =S11+G11 -> #REF! | W11: =V11-U11 -> #REF! | X11: =#REF! -> #REF! | Y11: =#REF! -> #REF! | Z11: =Y11-X11 -> #REF! | AB11: =F11+R11+X11 -> #REF! | AC11: =G11+S11+Y11 -> #REF! | AD11: =AC11-AB11 -> #REF!
B12: 바이오 상업 | D12: =SUM(D13:D14) -> 75.481553 | E12: =SUM(E13:E14) -> 118.82992 | F12: =SUM(F13:F14) -> #REF! | G12: =SUM(G13:G14) -> #REF! | H12: =SUM(H13:H14) -> #REF! | I12: =SUM(I13:I14) -> #REF! | J12: =SUM(J13:J14) -> #REF! | K12: =J12-I12 -> #REF! | L12: =SUM(L13:L14) -> #REF! | M12: =SUM(M13:M14) -> #REF! | N12: =M12-L12 -> #REF! | O12: =SUM(O13:O14) -> #REF! | P12: =SUM(P13:P14) -> #REF! | Q12: =P12-O12 -> #REF! | R12: =SUM(R13:R14) -> #REF! | S12: =SUM(S13:S14) -> #REF! | T12: =S12-R12 -> #REF! | U12: =SUM(U13:U14) -> #REF! | V12: =SUM(V13:V14) -> #REF! | W12: =V12-U12 -> #REF! | X12: =SUM(X13:X14) -> #REF! | Y12: =SUM(Y13:Y14) -> #REF! | Z12: =Y12-X12 -> #REF! | AB12: =SUM(AB13:AB14) -> #REF! | AC12: =SUM(AC13:AC14) -> #REF! | AD12: =AC12-AB12 -> #REF! | AF12: 3분기 기존 보고대비 +4.0억
C13: L&P | D13: 65.199322 | E13: 85.205765 | F13: =#REF!+#REF! -> #REF! | G13: =#REF!+#REF! -> #REF! | H13: =G13-F13 -> #REF! | I13: =#REF! -> #REF! | J13: =#REF! -> #REF! | K13: =J13-I13 -> #REF! | L13: =#REF! -> #REF! | M13: =#REF! -> #REF! | N13: =M13-L13 -> #REF! | O13: =#REF! -> #REF! | P13: =#REF! -> #REF! | Q13: =P13-O13 -> #REF! | R13: =I13+L13+O13 -> #REF! | S13: =J13+M13+P13 -> #REF! | T13: =S13-R13 -> #REF! | U13: =R13+F13 -> #REF! | V13: =S13+G13 -> #REF! | W13: =V13-U13 -> #REF! | X13: =#REF! -> #REF! | Y13: =#REF! -> #REF! | Z13: =Y13-X13 -> #REF! | AB13: =F13+R13+X13 -> #REF! | AC13: =G13+S13+Y13 -> #REF! | AD13: =AC13-AB13 -> #REF! | AF13: 9월 자동라인 2교대 적용으로 물량 증가 +4.5억
C14: PFS | D14: 10.282231 | E14: 33.624157 | F14: =#REF!+#REF! -> #REF! | G14: =#REF!+#REF! -> #REF! | H14: =G14-F14 -> #REF! | I14: =#REF! -> #REF! | J14: =#REF! -> #REF! | K14: =J14-I14 -> #REF! | L14: =#REF! -> #REF! | M14: =#REF! -> #REF! | N14: =M14-L14 -> #REF! | O14: =#REF! -> #REF! | P14: =#REF! -> #REF! | Q14: =P14-O14 -> #REF! | R14: =I14+L14+O14 -> #REF! | S14: =J14+M14+P14 -> #REF! | T14: =S14-R14 -> #REF! | U14: =R14+F14 -> #REF! | V14: =S14+G14 -> #REF! | W14: =V14-U14 -> #REF! | X14: =#REF! -> #REF! | Y14: =#REF! -> #REF! | Z14: =Y14-X14 -> #REF! | AB14: =F14+R14+X14 -> #REF! | AC14: =G14+S14+Y14 -> #REF! | AD14: =AC14-AB14 -> #REF! | AF14: PFS 3분기 실질 PO수량 조정 -0.5억
B15: 개발 용역 | D15: =SUM(D16:D20) -> #REF! | E15: =SUM(E16:E20) -> #REF! | F15: =SUM(F16:F20) -> #REF! | G15: =SUM(G16:G20) -> #REF! | H15: =SUM(H16:H20) -> #REF! | I15: =SUM(I16:I20) -> #REF! | J15: =SUM(J16:J20) -> #REF! | K15: =J15-I15 -> #REF! | L15: =SUM(L16:L20) -> #REF! | M15: =SUM(M16:M20) -> #REF! | N15: =M15-L15 -> #REF! | O15: =SUM(O16:O20) -> #REF! | P15: =SUM(P16:P20) -> #REF! | Q15: =P15-O15 -> #REF! | R15: =SUM(R16:R20) -> #REF! | S15: =SUM(S16:S20) -> #REF! | T15: =S15-R15 -> #REF! | U15: =SUM(U16:U20) -> #REF! | V15: =SUM(V16:V20) -> #REF! | W15: =V15-U15 -> #REF! | X15: =SUM(X16:X20) -> #REF! | Y15: =SUM(Y16:Y20) -> #REF! | Z15: =Y15-X15 -> #REF! | AB15: =SUM(AB16:AB20) -> #REF! | AC15: =SUM(AC16:AC20) -> #REF! | AD15: =AC15-AB15 -> #REF! | AF15: 3분기 기존 보고대비 +2.9억
C16: GCP | D16: 29.709 | E16: 11.77 | F16: =#REF!+#REF! -> #REF! | G16: 5.08 | H16: =G16-F16 -> #REF! | I16: =#REF! -> #REF! | J16: =#REF! -> #REF! | K16: =J16-I16 -> #REF! | L16: =#REF! -> #REF! | M16: =#REF! -> #REF! | N16: =M16-L16 -> #REF! | O16: =#REF! -> #REF! | P16: =#REF! -> #REF! | Q16: =P16-O16 -> #REF! | R16: =I16+L16+O16 -> #REF! | S16: =J16+M16+P16 -> #REF! | T16: =S16-R16 -> #REF! | U16: =R16+F16 -> #REF! | V16: =S16+G16 -> #REF! | W16: =V16-U16 -> #REF! | X16: =#REF! -> #REF! | Y16: =#REF! -> #REF! | Z16: =Y16-X16 -> #REF! | AB16: =F16+R16+X16 -> #REF! | AC16: =G16+S16+Y16 -> #REF! | AD16: =AC16-AB16 -> #REF! | AF16: 1) GCP (+0.3억) : G07 WHO IR 안정성 18개월 1개월 단축 +0.3억
C17: LCM | D17: 27.535 | E17: 19.09875 | F17: =#REF!+#REF! -> #REF! | G17: 7.4675 | H17: =G17-F17 -> #REF! | I17: =#REF! -> #REF! | J17: =#REF! -> #REF! | K17: =J17-I17 -> #REF! | L17: =#REF! -> #REF! | M17: =#REF! -> #REF! | N17: =M17-L17 -> #REF! | O17: =#REF! -> #REF! | P17: =#REF! -> #REF! | Q17: =P17-O17 -> #REF! | R17: =I17+L17+O17 -> #REF! | S17: =J17+M17+P17 -> #REF! | T17: =S17-R17 -> #REF! | U17: =R17+F17 -> #REF! | V17: =S17+G17 -> #REF! | W17: =V17-U17 -> #REF! | X17: =#REF! -> #REF! | Y17: =#REF! -> #REF! | Z17: =Y17-X17 -> #REF! | AB17: =F17+R17+X17 -> #REF! | AC17: =G17+S17+Y17 -> #REF! | AD17: =AC17-AB17 -> #REF! | AF17: 2) LCM (+0.2억) : CT-L05 임상3상 월렛 리라벨링 용역비 추가 (0.2억)
C18: PFS 개발 | D18: 75.070822 | E18: 30.988331 | F18: =#REF!+#REF! -> #REF! | G18: 12.225666 | H18: =G18-F18 -> #REF! | I18: =#REF! -> #REF! | J18: =#REF! -> #REF! | K18: =J18-I18 -> #REF! | L18: =#REF! -> #REF! | M18: =#REF! -> #REF! | N18: =M18-L18 -> #REF! | O18: =#REF! -> #REF! | P18: =#REF! -> #REF! | Q18: =P18-O18 -> #REF! | R18: =I18+L18+O18 -> #REF! | S18: =J18+M18+P18 -> #REF! | T18: =S18-R18 -> #REF! | U18: =R18+F18 -> #REF! | V18: =S18+G18 -> #REF! | W18: =V18-U18 -> #REF! | X18: =#REF! -> #REF! | Y18: =#REF! -> #REF! | Z18: =Y18-X18 -> #REF! | AB18: =F18+R18+X18 -> #REF! | AC18: =G18+S18+Y18 -> #REF! | AD18: =AC18-AB18 -> #REF! | AF18: 3) PFS (+1.4억) : P41 충전PVP 추가 (+3.2억), 유플라이마 안정성 시험항목 축소 변경계약 (-0.6억), P39 150mg PFS-S PKV 변경계약 지연 (-0.8억), , NO2 IOQ 조정 (-0.3억)
C19: 내재화 | D19: 11.9 | E19: 5.95 | F19: =#REF!+#REF! -> #REF! | G19: 27.00625 | H19: =G19-F19 -> #REF! | I19: =#REF! -> #REF! | J19: =#REF! -> #REF! | K19: =J19-I19 -> #REF! | L19: =#REF! -> #REF! | M19: =#REF!-0.27252 -> #REF! | N19: =M19-L19 -> #REF! | O19: =#REF! -> #REF! | P19: =#REF! -> #REF! | Q19: =P19-O19 -> #REF! | R19: =I19+L19+O19 -> #REF! | S19: =J19+M19+P19 -> #REF! | T19: =S19-R19 -> #REF! | U19: =R19+F19 -> #REF! | V19: =S19+G19 -> #REF! | W19: =V19-U19 -> #REF! | X19: =#REF! -> #REF! | Y19: =#REF! -> #REF! | Z19: =Y19-X19 -> #REF! | AB19: =F19+R19+X19 -> #REF! | AC19: =G19+S19+Y19 -> #REF! | AD19: =AC19-AB19 -> #REF! | AF19: 4) 내재화 (+0.9억) : CT-M02, M05 안정성 각 1개월 단축 (0.9억)
C20: 기타(QA위임) | D20: =W39 -> #REF! | E20: =AB20 -> #REF! | F20: =SUM(#REF!)/10^8 -> #REF! | G20: =L39 -> #REF! | H20: =G20-F20 -> #REF! | I20: =#REF!/10^8 -> #REF! | J20: =#REF!/10^8 -> #REF! | K20: =J20-I20 -> #REF! | L20: =#REF!/10^8 -> #REF! | M20: =#REF! -> #REF! | N20: =M20-L20 -> #REF! | O20: =#REF!/10^8 -> #REF! | P20: =#REF! -> #REF! | Q20: =P20-O20 -> #REF! | R20: =I20+L20+O20 -> #REF! | S20: =J20+M20+P20 -> #REF! | T20: =S20-R20 -> #REF! | U20: =R20+F20 -> #REF! | V20: =S20+G20 -> #REF! | W20: =V20-U20 -> #REF! | X20: =SUM(#REF!)/10^8 -> #REF! | Y20: =X20 -> #REF! | Z20: =Y20-X20 -> #REF! | AB20: =F20+R20+X20 -> #REF! | AC20: =G20+S20+Y20 -> #REF! | AD20: =AC20-AB20 -> #REF!
B21: ※ 약물감시 용역 추가
A22: ■ 22년 대비 매출 비교 | Z22: 단위 : 억원 | AF22: 연간 추가 사항 +24억
B23: 구분 | E23: 상반기 | N23: 하반기 | W23: 연간
E24: 1분기 | H24: 2분기 | K24: 상반기 | N24: 3분기 | Q24: 4분기 | T24: 하반기
E25: 22년 실적 | F25: 23년 실적 | G25: 차이 | H25: 22년 실적 | I25: 23년 실적 | J25: 차이 | K25: 22년 실적 | L25: 23년 실적 | M25: 차이 | N25: 22년 실적 | O25: 23년 예상 | P25: 차이 | Q25: 22년 실적 | R25: 23년 예상 | S25: 차이 | T25: 22년 실적 | U25: 23년 예상 | V25: 차이 | W25: 22년 실적 | X25: 23년 예상 | Y25: 차이 | Z25: 증감
C27: CMO 합계 | E27: =E28+E31+E34 -> #REF! | F27: =F28+F31+F34 -> #REF! | G27: =F27-E27 -> #REF! | H27: =H28+H31+H34 -> #REF! | I27: =I28+I31+I34 -> #REF! | J27: =I27-H27 -> #REF! | K27: =K28+K31+K34 -> #REF! | L27: =L28+L31+L34 -> #REF! | M27: =L27-K27 -> #REF! | N27: =N28+N31+N34 -> #REF! | O27: =O28+O31+O34 -> #REF! | P27: =O27-N27 -> #REF! | Q27: =Q28+Q31+Q34 -> #REF! | R27: =R28+R31+R34 -> #REF! | S27: =R27-Q27 -> #REF! | T27: =T28+T31+T34 -> #REF! | U27: =U28+U31+U34 -> #REF! | V27: =U27-T27 -> #REF! | W27: =W28+W31+W34 -> #REF! | X27: =X28+X31+X34 -> #REF! | Y27: =X27-W27 -> #REF! | Z27: =X27/W27-1 -> #REF!
C28: 케미컬 상업 | E28: =SUM(E29:E30) -> #REF! | F28: =SUM(F29:F30) -> #REF! | G28: =F28-E28 -> #REF! | H28: =SUM(H29:H30) -> #REF! | I28: =SUM(I29:I30) -> #REF! | J28: =I28-H28 -> #REF! | K28: =SUM(K29:K30) -> #REF! | L28: =SUM(L29:L30) -> #REF! | M28: =L28-K28 -> #REF! | N28: =SUM(N29:N30) -> #REF! | O28: =SUM(O29:O30) -> #REF! | P28: =O28-N28 -> #REF! | Q28: =SUM(Q29:Q30) -> #REF! | R28: =SUM(R29:R30) -> #REF! | S28: =R28-Q28 -> #REF! | T28: =SUM(T29:T30) -> #REF! | U28: =SUM(U29:U30) -> #REF! | V28: =U28-T28 -> #REF! | W28: =SUM(W29:W30) -> #REF! | X28: =SUM(X29:X30) -> #REF! | Y28: =X28-W28 -> #REF! | Z28: =X28/W28-1 -> #REF!
D29: G07 | E29: =#REF! -> #REF! | F29: =#REF! -> #REF! | G29: =F29-E29 -> #REF! | H29: =#REF! -> #REF! | I29: =#REF! -> #REF! | J29: =I29-H29 -> #REF! | K29: =E29+H29 -> #REF! | L29: =F29+I29 -> #REF! | M29: =L29-K29 -> #REF! | N29: =#REF! -> #REF! | O29: =S10 -> #REF! | P29: =O29-N29 -> #REF! | Q29: =#REF! -> #REF! | R29: =Y10 -> #REF! | S29: =R29-Q29 -> #REF! | T29: =N29+Q29 -> #REF! | U29: =O29+R29 -> #REF! | V29: =U29-T29 -> #REF! | W29: =E29+H29+N29+Q29 -> #REF! | X29: =F29+I29+O29+R29 -> #REF! | Y29: =X29-W29 -> #REF! | Z29: =X29/W29-1 -> #REF!
D30: 기타 | E30: =#REF! -> #REF! | F30: =#REF! -> #REF! | G30: =F30-E30 -> #REF! | H30: =#REF! -> #REF! | I30: =#REF! -> #REF! | J30: =I30-H30 -> #REF! | K30: =E30+H30 -> #REF! | L30: =F30+I30 -> #REF! | M30: =L30-K30 -> #REF! | N30: =#REF! -> #REF! | O30: =S11 -> #REF! | P30: =O30-N30 -> #REF! | Q30: =#REF! -> #REF! | R30: =Y11 -> #REF! | S30: =R30-Q30 -> #REF! | T30: =N30+Q30 -> #REF! | U30: =O30+R30 -> #REF! | V30: =U30-T30 -> #REF! | W30: =E30+H30+N30+Q30 -> #REF! | X30: =F30+I30+O30+R30 -> #REF! | Y30: =X30-W30 -> #REF! | Z30: =X30/W30-1 -> #REF!
C31: 바이오 상업 | E31: =SUM(E32:E33) -> #REF! | F31: =SUM(F32:F33) -> #REF! | G31: =F31-E31 -> #REF! | H31: =SUM(H32:H33) -> #REF! | I31: =SUM(I32:I33) -> #REF! | J31: =I31-H31 -> #REF! | K31: =SUM(K32:K33) -> #REF! | L31: =SUM(L32:L33) -> #REF! | M31: =L31-K31 -> #REF! | N31: =SUM(N32:N33) -> #REF! | O31: =SUM(O32:O33) -> #REF! | P31: =O31-N31 -> #REF! | Q31: =SUM(Q32:Q33) -> #REF! | R31: =SUM(R32:R33) -> #REF! | S31: =R31-Q31 -> #REF! | T31: =SUM(T32:T33) -> #REF! | U31: =SUM(U32:U33) -> #REF! | V31: =U31-T31 -> #REF! | W31: =SUM(W32:W33) -> #REF! | X31: =SUM(X32:X33) -> #REF! | Y31: =X31-W31 -> #REF! | Z31: =X31/W31-1 -> #REF!
D32: L&P | E32: =#REF! -> #REF! | F32: =#REF! -> #REF! | G32: =F32-E32 -> #REF! | H32: =#REF! -> #REF! | I32: =#REF! -> #REF! | J32: =I32-H32 -> #REF! | K32: =E32+H32 -> #REF! | L32: =F32+I32 -> #REF! | M32: =L32-K32 -> #REF! | N32: =#REF! -> #REF! | O32: =S13 -> #REF! | P32: =O32-N32 -> #REF! | Q32: =#REF! -> #REF! | R32: =Y13 -> #REF! | S32: =R32-Q32 -> #REF! | T32: =N32+Q32 -> #REF! | U32: =O32+R32 -> #REF! | V32: =U32-T32 -> #REF! | W32: =E32+H32+N32+Q32 -> #REF! | X32: =F32+I32+O32+R32 -> #REF! | Y32: =X32-W32 -> #REF! | Z32: =X32/W32-1 -> #REF!
D33: PFS | E33: =#REF! -> #REF! | F33: =#REF! -> #REF! | G33: =F33-E33 -> #REF! | H33: =#REF! -> #REF! | I33: =#REF! -> #REF! | J33: =I33-H33 -> #REF! | K33: =E33+H33 -> #REF! | L33: =F33+I33 -> #REF! | M33: =L33-K33 -> #REF! | N33: =#REF! -> #REF! | O33: =S14 -> #REF! | P33: =O33-N33 -> #REF! | Q33: =#REF! -> #REF! | R33: =Y14 -> #REF! | S33: =R33-Q33 -> #REF! | T33: =N33+Q33 -> #REF! | U33: =O33+R33 -> #REF! | V33: =U33-T33 -> #REF! | W33: =E33+H33+N33+Q33 -> #REF! | X33: =F33+I33+O33+R33 -> #REF! | Y33: =X33-W33 -> #REF! | Z33: =X33/W33-1 -> #REF!
C34: 개발 용역 | E34: =SUM(E35:E39) -> #REF! | F34: =SUM(F35:F39) -> #REF! | G34: =F34-E34 -> #REF! | H34: =SUM(H35:H39) -> #REF! | I34: =SUM(I35:I39) -> #REF! | J34: =I34-H34 -> #REF! | K34: =SUM(K35:K39) -> #REF! | L34: =SUM(L35:L39) -> #REF! | M34: =L34-K34 -> #REF! | N34: =SUM(N35:N39) -> #REF! | O34: =SUM(O35:O39) -> #REF! | P34: =O34-N34 -> #REF! | Q34: =SUM(Q35:Q39) -> #REF! | R34: =SUM(R35:R39) -> #REF! | S34: =R34-Q34 -> #REF! | T34: =SUM(T35:T39) -> #REF! | U34: =SUM(U35:U39) -> #REF! | V34: =U34-T34 -> #REF! | W34: =SUM(W35:W39) -> #REF! | X34: =SUM(X35:X39) -> #REF! | Y34: =X34-W34 -> #REF! | Z34: =X34/W34-1 -> #REF!
D35: GCP | E35: =#REF! -> #REF! | F35: =#REF! -> #REF! | G35: =F35-E35 -> #REF! | H35: =#REF! -> #REF! | I35: =#REF! -> #REF! | J35: =I35-H35 -> #REF! | K35: =E35+H35 -> #REF! | L35: =F35+I35 -> #REF! | M35: =L35-K35 -> #REF! | N35: =#REF! -> #REF! | O35: =S16 -> #REF! | P35: =O35-N35 -> #REF! | Q35: =#REF! -> #REF! | R35: =Y16 -> #REF! | S35: =R35-Q35 -> #REF! | T35: =N35+Q35 -> #REF! | U35: =O35+R35 -> #REF! | V35: =U35-T35 -> #REF! | W35: =E35+H35+N35+Q35 -> #REF! | X35: =F35+I35+O35+R35 -> #REF! | Y35: =X35-W35 -> #REF! | Z35: =X35/W35-1 -> #REF!
D36: LCM | E36: =#REF! -> #REF! | F36: =#REF! -> #REF! | G36: =F36-E36 -> #REF! | H36: =#REF! -> #REF! | I36: =#REF! -> #REF! | J36: =I36-H36 -> #REF! | K36: =E36+H36 -> #REF! | L36: =F36+I36 -> #REF! | M36: =L36-K36 -> #REF! | N36: =#REF! -> #REF! | O36: =S17 -> #REF! | P36: =O36-N36 -> #REF! | Q36: =#REF! -> #REF! | R36: =Y17 -> #REF! | S36: =R36-Q36 -> #REF! | T36: =N36+Q36 -> #REF! | U36: =O36+R36 -> #REF! | V36: =U36-T36 -> #REF! | W36: =E36+H36+N36+Q36 -> #REF! | X36: =F36+I36+O36+R36 -> #REF! | Y36: =X36-W36 -> #REF! | Z36: =X36/W36-1 -> #REF!
D37: PFS 개발 | E37: =#REF! -> #REF! | F37: =#REF! -> #REF! | G37: =F37-E37 -> #REF! | H37: =#REF! -> #REF! | I37: =#REF! -> #REF! | J37: =I37-H37 -> #REF! | K37: =E37+H37 -> #REF! | L37: =F37+I37 -> #REF! | M37: =L37-K37 -> #REF! | N37: =#REF! -> #REF! | O37: =S18 -> #REF! | P37: =O37-N37 -> #REF! | Q37: =#REF! -> #REF! | R37: =Y18 -> #REF! | S37: =R37-Q37 -> #REF! | T37: =N37+Q37 -> #REF! | U37: =O37+R37 -> #REF! | V37: =U37-T37 -> #REF! | W37: =E37+H37+N37+Q37 -> #REF! | X37: =F37+I37+O37+R37 -> #REF! | Y37: =X37-W37 -> #REF! | Z37: =X37/W37-1 -> #REF!
D38: 내재화 | E38: =#REF! -> #REF! | F38: =#REF! -> #REF! | G38: =F38-E38 -> #REF! | H38: =#REF! -> #REF! | I38: =#REF! -> #REF! | J38: =I38-H38 -> #REF! | K38: =E38+H38 -> #REF! | L38: =F38+I38 -> #REF! | M38: =L38-K38 -> #REF! | N38: =#REF! -> #REF! | O38: =S19 -> #REF! | P38: =O38-N38 -> #REF! | Q38: =#REF! -> #REF! | R38: =Y19 -> #REF! | S38: =R38-Q38 -> #REF! | T38: =N38+Q38 -> #REF! | U38: =O38+R38 -> #REF! | V38: =U38-T38 -> #REF! | W38: =E38+H38+N38+Q38 -> #REF! | X38: =F38+I38+O38+R38 -> #REF! | Y38: =X38-W38 -> #REF! | Z38: =X38/W38-1 -> #REF!
D39: 기타 | E39: =#REF! -> #REF! | F39: =#REF! -> #REF! | G39: =F39-E39 -> #REF! | H39: =#REF! -> #REF! | I39: =#REF! -> #REF! | J39: =I39-H39 -> #REF! | K39: =E39+H39 -> #REF! | L39: =F39+I39 -> #REF! | M39: =L39-K39 -> #REF! | N39: =#REF! -> #REF! | O39: =S20 -> #REF! | P39: =O39-N39 -> #REF! | Q39: =#REF! -> #REF! | R39: =Y20 -> #REF! | S39: =R39-Q39 -> #REF! | T39: =N39+Q39 -> #REF! | U39: =O39+R39 -> #REF! | V39: =U39-T39 -> #REF! | W39: =E39+H39+N39+Q39 -> #REF! | X39: =F39+I39+O39+R39 -> #REF! | Y39: =X39-W39 -> #REF! | Z39: =X39/W39-1 -> #REF!
A42: ■ 3분기 특이사항
B43: 1) 9월 기존대비 변경사항 (9/3 보고) : 기보고 대비 +12.3억
...

Sheet 1분기 상세
B2: ■ 23년 1분기 CMO 매출 계획 (보고용) | Q2: ■ 23년 1분기 CMO 매출 계획 PO 기준
O3: 단위 : 억원 | AD3: 단위 : 억원
B4: 구분 | D4: 1분기 | Q4: 구분 | S4: 1분기
D5: 1분기 합 | G5: 1월 | J5: 2월 | M5: 3월 | S5: 1분기 합 | V5: 1월 | Y5: 2월 | AB5: 3월
D6: 계획 | E6: 예상실적 | F6: Gap | G6: 계획 | H6: 예상실적 | I6: Gap | J6: 계획 | K6: 예상실적 | L6: Gap | M6: 계획 | N6: 예상실적 | O6: Gap | S6: 계획 | T6: 예상실적 | U6: Gap | V6: 계획 | W6: 예상실적 | X6: Gap | Y6: 계획 | Z6: 예상실적 | AA6: Gap | AB6: 계획 | AC6: 예상실적 | AD6: Gap
