Workbook
Name _: #N/A
Name _____________________________BRD1: #REF!
Name _____________________________BRD1: #REF!
Name _____________________________BRD2: #REF!
Name _____________________________BRD2: #REF!
Name _____________________________BRD3: #REF!
Name _____________________________BRD3: #REF!
Name _____________________________BRD4: #REF!
Name _____________________________BRD4: #REF!
Name _____________________________BRD5: #REF!
Name _____________________________BRD5: #REF!
Name _____________________________BRD6: #REF!
Name _____________________________BRD6: #REF!
Name _____________________________BRD7: #REF!
Name _____________________________BRD7: #REF!
Name _____________________________INT1: #REF!
Name _____________________________INT1: #REF!
Name _____________________________INT2: #REF!
Name _____________________________INT2: #REF!
Name _____________________________INT3: #REF!
Name _____________________________INT3: #REF!
Name _____________________________INT4: #REF!
Name _____________________________INT4: #REF!
Name _____________________________INT5: #REF!
Name _____________________________INT5: #REF!
Name _____________________________INT6: #REF!
Name _____________________________INT6: #REF!
Name _____________________________INT7: #REF!
Name _____________________________INT7: #REF!
Name _____________________________LIC1: #REF!
Name _____________________________LIC1: #REF!
Name _____________________________LIC2: #REF!
Name _____________________________LIC2: #REF!
Name _____________________________LIC3: #REF!
Name _____________________________LIC3: #REF!
Name _____________________________LIC4: #REF!
Name _____________________________LIC4: #REF!
Name _____________________________LIC5: #REF!
Name _____________________________LIC5: #REF!
Name _____________________________LIC6: #REF!
Name _____________________________LIC6: #REF!
Name _____________________________LIC7: #REF!
Name _____________________________LIC7: #REF!
Name _____________________________PG1: #REF!
Name _____________________________PG1: #REF!
Name _____________________________PG11: #REF!
Name _____________________________PG11: #REF!
Name _____________________________PG13: #REF!
Name _____________________________PG13: #REF!
Name _____________________________PG17: #REF!
Name _____________________________PG17: #REF!
Name _____________________________PG2: #REF!
Name _____________________________PG2: #REF!
Name _____________________________PG3: #REF!
Name _____________________________PG3: #REF!
Name _____________________________PG4: #REF!
Name _____________________________PG4: #REF!
Name _____________________________PG5: #REF!
Name _____________________________PG5: #REF!
Name _____________________________PG6: #REF!

Sheet 그래프용
E10: 바이오 상업 | F10: 내재화 상업 | G10: 개발용역 | H10: 합계
D11: 2025년 | E11: =요약!F22 -> 1076.578 | F11: =요약!F27 -> 141.72946 | G11: =요약!F34 -> 145.64176 | H11: =SUM(E11:G11) -> 1363.9492
D12: 2026년 | E12: =요약!W22 -> 1191.1256 | F12: =요약!W27 -> 170.99974 | G12: =요약!W34 -> 197.10025 | H12: =SUM(E12:G12) -> 1559.2256
D13: 2027년 | E13: =요약!AB22 -> 1408.9332 | F13: =요약!AB27 -> 195.57521 | G13: =요약!AB34 -> 115.64475 | H13: =SUM(E13:G13) -> 1720.1532
D14: 2028년 | E14: =요약!AC22 -> 1728.6441 | F14: =요약!AC27 -> 190.4701 | G14: =요약!AC34 -> 74.3275 | H14: =SUM(E14:G14) -> 1993.4417
D15: 2029년 | E15: =요약!AD22 -> 1661.4906 | F15: =요약!AD27 -> 195.0597 | G15: =요약!AD34 -> 65.0735 | H15: =SUM(E15:G15) -> 1921.6238
D16: 2030년 | E16: =요약!AE22 -> 1517.4793 | F16: =요약!AE27 -> 201.17329 | G16: =요약!AE34 -> 68.0735 | H16: =SUM(E16:G16) -> 1786.7261

Sheet 250909_매출 변동 보고
B1: ◈ 제조부문 매출 변동 요약(25.09.09)
V2: (2025.09.09)
B3: ● '25년 대비 '26년 분기별 비교
B4: 구분 | C4: 제품 | N4: 2025년 대비 26년 차이
F5: 1월 | G5: 2월 | H5: 3월 | I5: 1분기 | J5: 4월 | K5: 5월 | L5: 6월 | M5: 2분기 | N5: 7월 | O5: 8월 | P5: 9월 | Q5: 3분기 | R5: 10월 | S5: 11월 | T5: 12월 | U5: 4분기 | V5: Total
B6: 합계 | F6: =F42-F24 -> 13.927964 | G6: =G42-G24 -> 24.900255 | H6: =H42-H24 -> 58.73409 | I6: =I42-I24 -> 97.562309 | J6: =J42-J24 -> 73.838945 | K6: =K42-K24 -> 33.005717 | L6: =L42-L24 -> 29.374636 | M6: =M42-M24 -> 136.2193 | ... V6: =V42-V24 -> 269.79117
B7: 25 vs. 26 차이 | C7: 바이오 상업 | D7: PFS상업 | E7: 충전 | F7: =F43-F25 -> -18.851523 | G7: =G43-G25 -> 4.933936 | H7: =H43-H25 -> 9.160193 | I7: =I43-I25 -> -4.757394 | J7: =J43-J25 -> 14.131875 | K7: =K43-K25 -> 30.04711 | L7: =L43-L25 -> -5.358083 | M7: =M43-M25 -> 38.820902 | ... V7: =V43-V25 -> 14.222881
E8: 조립 | F8: =F44-F26 -> 31.965375 | G8: =G44-G26 -> -20.728558 | H8: =H44-H26 -> 22.309142 | I8: =I44-I26 -> 33.545959 | J8: =J44-J26 -> 11.026511 | K8: =K44-K26 -> 38.306369 | L8: =L44-L26 -> 10.615799 | M8: =M44-M26 -> 59.94868 | ... V8: =V44-V26 -> 53.33869
E9: 포장 | F9: =F45-F27 -> 26.822166 | G9: =G45-G27 -> 25.070651 | H9: =H45-H27 -> 20.260514 | I9: =I45-I27 -> 72.153331 | J9: =J45-J27 -> 22.438187 | K9: =K45-K27 -> 3.976905 | L9: =L45-L27 -> 13.556874 | M9: =M45-M27 -> 39.971966 | ... V9: =V45-V27 -> 186.00788
F10: =F46-F28 -> 39.936018 | G10: =G46-G28 -> 9.276029 | H10: =H46-H28 -> 51.729849 | I10: =I46-I28 -> 100.9419 | J10: =J46-J28 -> 47.596573 | K10: =K46-K28 -> 72.330384 | L10: =L46-L28 -> 18.81459 | M10: =M46-M28 -> 138.74155 | ... V10: =V46-V28 -> 253.56945
D11: L&P 상업 | F11: =F47-F29 -> -1.6391878 | G11: =G47-G29 -> 0.1400432 | H11: =H47-H29 -> -1.0752506 | I11: =I47-I29 -> -2.5743952 | J11: =J47-J29 -> -1.8441908 | K11: =K47-K29 -> 0.7380894 | L11: =L47-L29 -> -2.0891064 | M11: =M47-M29 -> -3.1952078 | ... V11: =V47-V29 -> 3.0633753
C12: 바이오 상업 | F12: =F48-F30 -> 38.29683 | G12: =G48-G30 -> 9.4160722 | H12: =H48-H30 -> 50.654598 | I12: =I48-I30 -> 98.367501 | J12: =J48-J30 -> 45.752382 | K12: =K48-K30 -> 73.068474 | L12: =L48-L30 -> 16.725484 | M12: =M48-M30 -> 135.54634 | ... V12: =V48-V30 -> 256.63282
C13: 내재화 상업 | F13: =F49-F31 -> 6.4276116 | G13: =G49-G31 -> 12.739245 | H13: =H49-H31 -> -0.41481615 | I13: =I49-I31 -> 18.752041 | J13: =J49-J31 -> 12.918406 | K13: =K49-K31 -> -16.727663 | L13: =L49-L31 -> 12.351426 | M13: =M49-M31 -> 8.5421688 | ... V13: =V49-V31 -> 37.749102
C14: 케미컬 상업 | F14: =F50-F32 -> 6.4276116 | G14: =G50-G32 -> 12.739245 | H14: =H50-H32 -> -0.41481615 | I14: =I50-I32 -> 18.752041 | J14: =J50-J32 -> 12.918406 | K14: =K50-K32 -> -16.727663 | L14: =L50-L32 -> 12.351426 | M14: =M50-M32 -> 8.5421688 | ... V14: =V50-V32 -> 37.749102
C15: 개발용역 | D15: 케미컬 | E15: CMO용역 | F15: =F51-F33 -> -0.67 | G15: =G51-G33 -> 0 | H15: =H51-H33 -> 0 | I15: =I51-I33 -> -0.67 | J15: =J51-J33 -> 0.3 | K15: =K51-K33 -> 0 | L15: =L51-L33 -> 0 | M15: =M51-M33 -> 0.3 | ... V15: =V51-V33 -> -0.37
E16: LCM용역 | F16: =F52-F34 -> 0.9375 | G16: =G52-G34 -> 0.46875 | H16: =H52-H34 -> -2.7225 | I16: =I52-I34 -> -1.31625 | J16: =J52-J34 -> 0.9375 | K16: =K52-K34 -> 0.46875 | L16: =L52-L34 -> -1.62125 | M16: =M52-M34 -> -0.215 | ... V16: =V52-V34 -> -12.33625
E17: 내재화용역 | F17: =F53-F35 -> -1.4280417 | G17: =G53-G35 -> 2.2339583 | H17: =H53-H35 -> 1.2677083 | I17: =I53-I35 -> 2.073625 | J17: =J53-J35 -> 1.7586667 | K17: =K53-K35 -> -2.3058333 | L17: =L53-L35 -> 2.5554167 | M17: =M53-M35 -> 2.00825 | ... V17: =V53-V35 -> 1.4406249
E18: 기타(QA위임등) | F18: =F54-F36 -> -0.50392557 | G18: =G54-G36 -> -0.04176042 | H18: =H54-H36 -> -0.16489 | I18: =I54-I36 -> -0.71057599 | J18: =J54-J36 -> 0 | K18: =K54-K36 -> 0 | L18: =L54-L36 -> -0.26043 | M18: =M54-M36 -> -0.26043 | ... V18: =V54-V36 -> -0.97100599
F19: =F55-F37 -> -1.6644672 | G19: =G55-G37 -> 2.6609479 | H19: =H55-H37 -> -1.6196817 | I19: =I55-I37 -> -0.623201 | J19: =J55-J37 -> 2.9961667 | K19: =K55-K37 -> -1.8370833 | L19: =L55-L37 -> 0.67373666 | M19: =M55-M37 -> 1.83282 | ... V19: =V55-V37 -> -12.236631
D20: 바이오 | E20: PFS용역 | F20: =F56-F38 -> -29.13201 | G20: =G56-G38 -> 0.08398964 | H20: =H56-H38 -> 10.11399 | I20: =I56-I38 -> -18.934031 | J20: =J56-J38 -> 12.17199 | K20: =K56-K38 -> -21.49801 | L20: =L56-L38 -> -0.37601036 | M20: =M56-M38 -> -9.7020311 | ... V20: =V56-V38 -> -12.354124
C21: 개발용역 | F21: =F57-F39 -> -30.796478 | G21: =G57-G39 -> 2.7449375 | H21: =H57-H39 -> 8.494308 | I21: =I57-I39 -> -19.557232 | J21: =J57-J39 -> 15.168156 | K21: =K57-K39 -> -23.335094 | L21: =L57-L39 -> 0.2977263 | M21: =M57-M39 -> -7.8692111 | ... V21: =V57-V39 -> -24.590755
B22: 구분 | C22: 제품 | D22: 구분 | E22: 공정 | N22: 2025년(+81억 기준)
F23: 1월 | G23: 2월 | H23: 3월 | I23: 1분기 | J23: 4월 | K23: 5월 | L23: 6월 | M23: 2분기 | N23: 7월 | O23: 8월 | P23: 9월 | Q23: 3분기 | R23: 10월 | S23: 11월 | T23: 12월 | U23: 4분기 | V23: Total
B24: 합계 | F24: =F30+F32+F39 -> 112.80754 | G24: =G30+G32+G39 -> 67.552261 | H24: =H30+H32+H39 -> 93.744846 | I24: =I30+I32+I39 -> 274.10465 | J24: =J30+J32+J39 -> 92.986011 | K24: =K30+K32+K39 -> 107.32625 | L24: =L30+L32+L39 -> 121.81766 | M24: =M30+M32+M39 -> 322.12992 | ... V24: =V30+V32+V39 -> 1393.6532
B25: 25년 실질롤링 (+81억) | C25: 바이오 상업 | D25: PFS상업 | E25: 충전 | F25: 49.012503 | G25: 25.548524 | H25: 32.070624 | I25: =SUM(F25:H25) -> 106.63165 | J25: 34.032669 | K25: 19.915138 | L25: 44.855663 | M25: =SUM(J25:L25) -> 98.80347 | N25: 28.090427 | O25: 48.690204 | P25: 40.908414 | Q25: =SUM(N25:P25) -> 117.68904 | R25: 39.2997 | S25: 65.2608 | T25: 16.502508 | U25: =SUM(R25:T25) -> 121.06301 | V25: =SUM(U25,Q25,M25,I25) -> 444.18717
E26: 조립 | F26: 17.651358 | G26: 20.728558 | H26: 29.08802 | I26: =SUM(F26:H26) -> 67.467936 | J26: 37.604204 | K26: 11.535708 | L26: 33.269352 | M26: =SUM(J26:L26) -> 82.409264 | N26: 42.593114 | O26: 30.746592 | P26: 37.3354 | Q26: =SUM(N26:P26) -> 110.67511 | R26: 69.97583 | S26: 42.348454 | T26: 40.215502 | U26: =SUM(R26:T26) -> 152.53979 | V26: =SUM(U26,Q26,M26,I26) -> 413.09209
E27: 포장 | F27: 3.178928 | G27: 3.692459 | H27: 8.077084 | I27: =SUM(F27:H27) -> 14.948471 | J27: 8.432902 | K27: 25.520342 | L27: 16.947594 | M27: =SUM(J27:L27) -> 50.900838 | N27: 8.177828 | O27: 12.021219 | P27: 23.006758 | Q27: =SUM(N27:P27) -> 43.205805 | R27: 17.765504 | S27: 28.470045 | T27: 32.41644 | U27: =SUM(R27:T27) -> 78.651989 | V27: =SUM(U27,Q27,M27,I27) -> 187.7071
F28: =SUM(F25:F27) -> 69.842789 | G28: =SUM(G25:G27) -> 49.969541 | H28: =SUM(H25:H27) -> 69.235728 | I28: =SUM(I25:I27) -> 189.04806 | J28: =SUM(J25:J27) -> 80.069775 | K28: =SUM(K25:K27) -> 56.971188 | L28: =SUM(L25:L27) -> 95.072609 | M28: =SUM(M25:M27) -> 232.11357 | ... U28: =SUM(U25:U27) -> 352.25478 | V28: =SUM(U28,Q28,M28,I28) -> 1044.9864
D29: L&P 상업 | F29: 6.1868338 | G29: 4.3794528 | H29: 4.0223598 | I29: =SUM(F29:H29) -> 14.588646 | J29: 6.0428488 | K29: 4.053805 | L29: 5.30925 | M29: =SUM(J29:L29) -> 15.405904 | N29: 4.591475 | O29: 1.6958857 | P29: 0 | Q29: =SUM(N29:P29) -> 6.2873607 | R29: 3.0032128 | S29: 5.749334 | T29: 3.5385655 | U29: =SUM(R29:T29) -> 12.291112 | V29: =SUM(U29,Q29,M29,I29) -> 48.573023
C30: 바이오 상업 | F30: =F29+F28 -> 76.029623 | G30: =G29+G28 -> 54.348994 | H30: =H29+H28 -> 73.258088 | I30: =I29+I28 -> 203.6367 | J30: =J29+J28 -> 86.112624 | K30: =K29+K28 -> 61.024993 | L30: =L29+L28 -> 100.38186 | M30: =M29+M28 -> 247.51948 | ... V30: =V29+V28 -> 1093.5594
C31: 내재화 상업 | F31: 3.0051884 | G31: 12.609455 | H31: 2.3648161 | I31: =SUM(F31:H31) -> 17.979459 | J31: 6.0472936 | K31: 17.855413 | L31: 11.957274 | M31: =SUM(J31:L31) -> 35.859981 | N31: 10.993056 | O31: 27.990325 | P31: 5.4876663 | Q31: =SUM(N31:P31) -> 44.471047 | R31: 11.74176 | S31: 23.215005 | T31: 2.202795 | U31: =SUM(R31:T31) -> 37.15956 | V31: =SUM(U31,Q31,M31,I31) -> 135.47005
C32: 케미컬 상업 | F32: =F31 -> 3.0051884 | G32: =G31 -> 12.609455 | H32: =H31 -> 2.3648161 | I32: =I31 -> 17.979459 | J32: =J31 -> 6.0472936 | K32: =K31 -> 17.855413 | L32: =L31 -> 11.957274 | M32: =M31 -> 35.859981 | ... V32: =V31 -> 135.47005
C33: 개발용역 | D33: 케미컬 | E33: CMO용역 | F33: 0.67 | I33: =SUM(F33:H33) -> 0.67 | M33: =SUM(J33:L33) -> 0 | Q33: =SUM(N33:P33) -> 0 | U33: =SUM(R33:T33) -> 0 | V33: =SUM(U33,Q33,M33,I33) -> 0.67
E34: LCM용역 | F34: 0 | G34: 0 | H34: 3.66 | I34: =SUM(F34:H34) -> 3.66 | J34: 0 | K34: 0 | L34: 2.09 | M34: =SUM(J34:L34) -> 2.09 | N34: 2.85625 | O34: 1.18 | P34: 4.3375 | Q34: =SUM(N34:P34) -> 8.37375 | R34: 0 | S34: 0.85 | T34: 2.51875 | U34: =SUM(R34:T34) -> 3.36875 | V34: =SUM(U34,Q34,M34,I34) -> 17.4925
E35: 내재화용역 | F35: 2.7467917 | G35: 0.31604167 | H35: 2.1910417 | I35: =SUM(F35:H35) -> 5.253875 | J35: 0.41008334 | K35: 2.7058333 | L35: 0.36208334 | M35: =SUM(J35:L35) -> 3.478 | N35: 0.36208334 | O35: 0.36208334 | P35: 1.2995833 | Q35: =SUM(N35:P35) -> 2.02375 | R35: 0.36208334 | S35: 0.83083334 | T35: 1.2995833 | U35: =SUM(R35:T35) -> 2.4925 | V35: =SUM(U35,Q35,M35,I35) -> 13.248125
E36: 기타(QA위임등) | F36: 0.50392557 | G36: 0.04176042 | H36: 0.16489 | I36: =SUM(F36:H36) -> 0.71057599 | J36: 0 | K36: 0 | L36: 0.26043 | M36: =SUM(J36:L36) -> 0.26043 | N36: 0 | O36: 0 | P36: 0 | Q36: =SUM(N36:P36) -> 0 | R36: 0 | S36: 0 | T36: 0 | U36: =SUM(R36:T36) -> 0 | V36: =SUM(U36,Q36,M36,I36) -> 0.97100599
F37: 3.9207172 | G37: 0.35780209 | H37: 6.0159317 | I37: =SUM(F37:H37) -> 10.294451 | J37: 0.41008334 | K37: 2.7058333 | L37: 2.7125133 | M37: =SUM(J37:L37) -> 5.82843 | N37: 3.2183333 | O37: 1.5420833 | P37: 5.6370833 | Q37: =SUM(N37:P37) -> 10.3975 | R37: 0.36208334 | S37: 1.6808333 | T37: 3.8183333 | U37: =SUM(R37:T37) -> 5.86125 | V37: =SUM(U37,Q37,M37,I37) -> 32.381631
D38: 바이오 | E38: PFS용역 | F38: 29.85201 | G38: 0.23601036 | H38: 12.10601 | I38: =SUM(F38:H38) -> 42.194031 | J38: 0.41601036 | K38: 25.74001 | L38: 6.7660104 | M38: =SUM(J38:L38) -> 32.922031 | N38: 1.5760104 | O38: 20.40661 | P38: 17.02001 | Q38: =SUM(N38:P38) -> 39.002631 | R38: 0.23601036 | S38: 2.6830104 | T38: 15.20441 | U38: =SUM(R38:T38) -> 18.123431 | V38: =SUM(U38,Q38,M38,I38) -> 132.24212
C39: 개발용역 | F39: =F38+F37 -> 33.772728 | G39: =G38+G37 -> 0.59381245 | H39: =H38+H37 -> 18.121942 | I39: =I38+I37 -> 52.488482 | J39: =J38+J37 -> 0.8260937 | K39: =K38+K37 -> 28.445844 | L39: =L38+L37 -> 9.4785237 | M39: =M38+M37 -> 38.750461 | ... V39: =V38+V37 -> 164.62376
B40: 구분 | C40: 제품 | D40: 구분 | E40: 공정 | N40: 2026년
...

Sheet 260121_1분기재롤링,포장추가 요약
B1: ◈ 제조부문 매출 변경사항 요약_1분기 재롤링+포장30억 증가(26.01.21, P42 포함)
B3: 1. 매출 업데이트 | G3: 25년 분기별 매출 | I3: 1분기 | J3: 275.49898 | M3: 2분기 | N3: 323.91353 | Q3: 3분기 | R3: 382.18333 | U3: 4분기 | V3: 406.71726
F4: 2025년 (12/29) | O4: 2026년 | Z4: 2027년 | AB4: 2027년 | AC4: 2028년 | AD4: 2029년 | AE4: 2030년
B5: 구분 | C5: 제품 | D5: 구분 | E5: 공정 | G5: 1월 | H5: 2월 | I5: 3월 | J5: 1분기 | K5: 4월 | L5: 5월 | M5: 6월 | N5: 2분기 | O5: 7월 | P5: 8월 | Q5: 9월 | R5: 3분기 | S5: 10월 | T5: 11월 | U5: 12월 | V5: 4분기 | W5: Total | X5: 1분기 | Y5: 2분기 | Z5: 3분기 | AA5: 4분기 | AB5: Total | AC5: Total | AD5: Total | AE5: Total
F6: =SUM(F12,F17,F24) -> 1394.0521 | G6: 100.91695 | H6: 107.7245 | I6: 104.74626 | J6: 313.38771 | K6: 106.94506 | L6: 161.5621 | M6: 113.85953 | N6: 382.36669 | O6: 150.31887 | P6: 120.85891 | Q6: 140.78362 | R6: 411.9614 | S6: 119.41513 | T6: 152.76874 | U6: 179.17096 | V6: 451.35482 | W6: 1559.0706 | X6: 427.87927 | Y6: 462.06469 | Z6: 362.07235 | AA6: 468.13685 | AB6: 1720.1532 | AC6: 1993.4417 | AD6: 1921.6238 | AE6: 1786.7261
B7: 신규롤링 | C7: 바이오 상업 | D7: PFS상업 | E7: 충전 | F7: 474.91249 | G7: 27.258676 | H7: 24.13214 | I7: 23.07312 | J7: 74.463936 | K7: 29.963304 | L7: 45.593388 | M7: 29.166786 | N7: 104.72348 | O7: 45.772406 | P7: 39.399426 | Q7: 18.125316 | R7: 103.29715 | S7: 33.614154 | T7: 47.059542 | U7: 37.631628 | V7: 118.30532 | W7: 400.78989 | X7: 141 | Y7: 156 | Z7: 103 | AA7: 161 | AB7: 561 | AC7: 664 | AD7: 683 | AE7: 615
E8: 조립 | F8: 378.00117 | G8: 30.082792 | H8: 38.482422 | I8: 23.938824 | J8: 92.504038 | K8: 18.515111 | L8: 26.490361 | M8: 15.563747 | N8: 60.569218 | O8: 35.624332 | P8: 35.327342 | Q8: 47.045769 | R8: 117.99744 | S8: 25.34755 | T8: 15.563747 | U8: 41.92489 | V8: 82.836187 | W8: 353.90689 | X8: 109 | Y8: 120 | Z8: 82 | AA8: 109 | AB8: 420 | AC8: 634 | AD8: 545 | AE8: 466
E9: 포장 | F9: 189.01808 | G9: 11.649035 | H9: 25.462556 | I9: 34.319693 | J9: 71.431285 | K9: 30.871089 | L9: 29.497247 | M9: 40.93202 | N9: 101.30036 | O9: 26.838239 | P9: 33.507819 | Q9: 41.551265 | R9: 101.89732 | S9: 31.666133 | T9: 38.290916 | U9: 44.168708 | V9: 114.12576 | W9: 388.75472 | X9: 87.101802 | Y9: 90.872804 | Z9: 91.717377 | AA9: 104.023 | AB9: 373.71498 | AC9: 373.71498 | AD9: 373.71498 | AE9: 373.71498
F10: 1041.9317 | G10: 68.990503 | H10: 88.077118 | I10: 81.331637 | J10: 238.39926 | K10: 79.349504 | L10: 101.581 | M10: 85.662553 | N10: 266.59305 | O10: 108.23498 | P10: 108.23459 | Q10: 106.72235 | R10: 323.19191 | S10: 90.627837 | T10: 100.9142 | U10: 123.72523 | V10: 315.26727 | W10: 1143.4515 | X10: 337.1018 | Y10: 366.8728 | Z10: 276.71738 | AA10: 374.023 | AB10: 1354.715 | AC10: 1671.715 | AD10: 1601.715 | AE10: 1454.715
D11: L&P 상업 | F11: 47.201113 | G11: 2.652565 | H11: 2.7458164 | I11: 2.65362 | J11: 8.0520014 | K11: 4.198658 | L11: 4.7918944 | M11: 3.2201436 | N11: 12.210696 | O11: 5.0285436 | P11: 5.6127878 | Q11: 2.3312762 | R11: 12.972608 | S11: 5.2395568 | T11: 5.3743936 | U11: 3.8248932 | V11: 14.438844 | W11: 47.674149 | X11: 12.614964 | Y11: 12.821231 | Z11: 13.621238 | AA11: 15.160786 | AB11: 54.218218 | AC11: 56.929129 | AD11: 59.775586 | AE11: 62.764365
F12: =SUM(F10:F11) -> 1089.1329 | G12: 71.643068 | H12: 90.822934 | I12: 83.985258 | J12: 246.45126 | K12: 83.548162 | L12: 106.37289 | M12: 88.882697 | N12: 278.80375 | O12: 113.26352 | P12: 113.84737 | Q12: 109.05363 | R12: 336.16452 | S12: 95.867394 | T12: 106.2886 | U12: 127.55012 | V12: 329.70611 | W12: 1191.1256 | X12: 349.71677 | Y12: 379.69403 | Z12: 290.33861 | AA12: 389.18378 | AB12: 1408.9332 | AC12: 1728.6441 | AD12: 1661.4906 | AE12: 1517.4793
C13: 내재화 상업 | D13: APAC | E13: 네시나F | G13: 1.2854877 | H13: 11.632487 | I13: 0.245376 | J13: 13.16335 | K13: 0.214704 | L13: 10.496214 | M13: 1.685682 | N13: 12.3966 | O13: 10.318572 | P13: 1.932336 | Q13: 2.302956 | R13: 14.553864 | S13: 2.302956 | T13: 11.107098 | U13: 4.851288 | V13: 18.261342 | W13: 58.375156 | X13: 16.14824 | Y13: 16.02328 | Z13: 21.5272 | AA13: 16.89942 | AB13: 70.59814 | AC13: 70.59814 | AD13: 70.59814 | AE13: 70.59814
E14: 이달비F | G14: 1.8146918 | H14: 0.451134 | I14: 9.193932 | J14: 11.459758 | K14: 11.946744 | L14: 7.4763 | M14: 1.3984515 | N14: 20.821496 | O14: 22.996332 | P14: 0 | Q14: 7.717842 | R14: 30.714174 | S14: 16.286832 | T14: 7.717842 | U14: 23.5791 | V14: 47.583774 | W14: 110.5792 | X14: 23.76938 | Y14: 32.68201 | Z14: 26.48442 | AA14: 35.40628 | AB14: 118.34209 | AC14: 118.34209 | AD14: 118.34209 | AE14: 118.34209
F15: 155.93871 | G15: 3.1001795 | H15: 12.083621 | I15: 9.439308 | J15: 24.623108 | K15: 12.161448 | L15: 17.972514 | M15: 3.0841335 | N15: 33.218096 | O15: 33.314904 | P15: 1.932336 | Q15: 10.020798 | R15: 45.268038 | S15: 18.589788 | T15: 18.82494 | U15: 28.430388 | V15: 65.845116 | W15: 168.95436 | X15: 39.91762 | Y15: 48.70529 | Z15: 48.01162 | AA15: 52.3057 | AB15: 188.94023 | AC15: 188.94023 | AD15: 188.94023 | AE15: 188.94023
D16: CMO상업_위임형 | G16: 0.17044833 | H16: 0.17044833 | I16: 0.17044833 | J16: 0.511345 | K16: 0.17044833 | L16: 0.17044833 | M16: 0.17044833 | N16: 0.511345 | O16: 0.17044833 | P16: 0.17044833 | Q16: 0.17044833 | R16: 0.511345 | S16: 0.17044833 | T16: 0.17044833 | U16: 0.17044833 | V16: 0.511345 | W16: 2.04538 | X16: 2.04538 | Y16: 1.5298675 | Z16: 1.5298675 | AA16: 1.5298675 | AB16: 6.6349825 | AC16: 1.5298675 | AD16: 6.11947 | AE16: 12.233065
F17: 155.93871 | G17: 3.2706278 | H17: 12.254069 | I17: 9.6097563 | J17: 25.134453 | K17: 12.331896 | L17: 18.142962 | M17: 3.2545818 | N17: 33.729441 | O17: 33.485352 | P17: 2.1027843 | Q17: 10.191246 | R17: 45.779383 | S17: 18.760236 | T17: 18.995388 | U17: 28.600836 | V17: 66.356461 | W17: 170.99974 | X17: 41.963 | Y17: 50.235157 | Z17: 49.541488 | AA17: 53.835568 | AB17: 195.57521 | AC17: 190.4701 | AD17: 195.0597 | AE17: 201.17329
C18: 개발용역 | D18: 케미컬 | E18: CMO용역 | F18: 0.67 | G18: 0 | H18: 0 | I18: 0 | J18: 0 | K18: 0 | L18: 0 | M18: 0 | N18: 0 | O18: 0 | P18: 0 | Q18: 0 | R18: 0 | S18: 0 | T18: 0 | U18: 0 | V18: 0 | W18: 0 | X18: 0 | Y18: 0 | Z18: 0 | AA18: 0 | AB18: 0 | AC18: 0 | AD18: 0 | AE18: 0
E19: 내재화용역 | F19: 14.12375 | G19: 1.40625 | H19: 0.46875 | I19: 2.8125 | J19: 4.6875 | K19: 1.40625 | L19: 0.46875 | M19: 0.46875 | N19: 2.34375 | O19: 0 | P19: 0 | Q19: 0 | R19: 0 | S19: 0.9375 | T19: 0 | U19: 0 | V19: 0.9375 | W19: 7.96875 | X19: 0 | Y19: 0 | Z19: 0.46875 | AA19: 0.46875 | AB19: 0.9375 | AC19: 0 | AD19: 0 | AE19: 0
E20: LCM용역 | F20: 12.792667 | G20: 0 | H20: 0.46875 | I20: 1.31875 | J20: 1.7875 | K20: 1.31875 | L20: 0.4 | M20: 1.7375 | N20: 3.45625 | O20: 0.85 | P20: 0.46875 | Q20: 0.46875 | R20: 1.7875 | S20: 0.85 | T20: 1.31875 | U20: 0 | V20: 2.16875 | W20: 9.2 | X20: 0.9375 | Y20: 0.9375 | Z20: 0.9375 | AA20: 0.46875 | AB20: 3.28125 | AC20: 0.9375 | AD20: 0.9375 | AE20: 0.9375
E21: 기타(QA위임등) | F21: 5.0982021 | G21: 0 | H21: 0 | I21: 0 | K21: 0 | L21: 0 | M21: 0 | O21: 0 | P21: 0 | Q21: 0 | S21: 0 | T21: 0 | U21: 0 | X21: 0 | Y21: 0 | Z21: 0 | AA21: 0 | AC21: 0 | AD21: 0 | AE21: 0
F22: 28.129631 | G22: 1.40625 | H22: 0.9375 | I22: 4.13125 | J22: 6.475 | K22: 2.725 | L22: 0.86875 | M22: 2.20625 | N22: 5.8 | O22: 0.85 | P22: 0.46875 | Q22: 0.46875 | R22: 1.7875 | S22: 1.7875 | T22: 1.31875 | U22: 0 | V22: 3.10625 | W22: 17.16875 | X22: 0.9375 | Y22: 0.9375 | Z22: 1.40625 | AA22: 0.9375 | AB22: 4.21875 | AC22: 0.9375 | AD22: 0.9375 | AE22: 0.9375
D23: 바이오 | E23: PFS용역 | F23: 116.29589 | G23: 24.597 | H23: 3.71 | I23: 7.02 | J23: 35.327 | K23: 8.34 | L23: 36.1775 | M23: 19.516 | N23: 64.0335 | O23: 2.72 | P23: 4.44 | Q23: 21.07 | R23: 28.23 | S23: 3 | T23: 26.166 | U23: 23.02 | V23: 52.186 | W23: 179.7765 | X23: 35.262 | Y23: 31.198 | Z23: 20.786 | AA23: 24.18 | AB23: 111.426 | AC23: 73.39 | AD23: 64.136 | AE23: 67.136
F24: 148.98051 | G24: 26.00325 | H24: 4.6475 | I24: 11.15125 | J24: 41.802 | K24: 11.065 | L24: 37.04625 | M24: 21.72225 | N24: 69.8335 | O24: 3.57 | P24: 4.90875 | Q24: 21.53875 | R24: 30.0175 | S24: 4.7875 | T24: 27.48475 | U24: 23.02 | V24: 55.29225 | W24: 196.94525 | X24: 36.1995 | Y24: 32.1355 | Z24: 22.19225 | AA24: 25.1175 | AB24: 115.64475 | AC24: 74.3275 | AD24: 65.0735 | AE24: 68.0735
B26: 2. Gap
F27: 2025년 | O27: 2026년 | Z27: 2027년 | AC27: 2028년 | AD27: 2029년 | AE27: 2030년
B28: 구분 | C28: 제품 | D28: 구분 | E28: 공정 | G28: 1월 | H28: 2월 | I28: 3월 | J28: 1분기 | K28: 4월 | L28: 5월 | M28: 6월 | N28: 2분기 | O28: 7월 | P28: 8월 | Q28: 9월 | R28: 3분기 | S28: 10월 | T28: 11월 | U28: 12월 | V28: 4분기 | W28: Total | X28: 1분기 | Y28: 2분기 | Z28: 3분기 | AA28: 4분기 | AB28: Total | AC28: Total | AD28: Total | AE28: Total
F29: =F6-F52 -> 0 | G29: =G6-G52 -> -13.853245 | H29: =H6-H52 -> -3.483691 | I29: =I6-I52 -> 21.392507 | J29: =J6-J52 -> 4.0555718 | K29: =K6-K52 -> -10.195032 | L29: =L6-L52 -> 16.740664 | M29: =M6-M52 -> -11.605275 | ... AE29: =AE6-AE52 -> 0
B30: Gap | C30: 바이오 상업 | D30: PFS상업 | E30: 충전 | F30: =F7-F53 -> 0 | G30: =G7-G53 -> 0.935436 | H30: =H7-H53 -> 8.79984 | I30: =I7-I53 -> 4.21632 | J30: =J7-J53 -> 13.951596 | K30: =K7-K53 -> 0 | L30: =L7-L53 -> 0 | M30: =M7-M53 -> 0 | ... AE30: =AE7-AE53 -> 0
E31: 조립 | F31: =F8-F54 -> 0 | G31: =G8-G54 -> 7.01755 | H31: =H8-H54 -> 9.928532 | I31: =I8-I54 -> -2.336827 | J31: =J8-J54 -> 14.609255 | K31: =K8-K54 -> 0 | L31: =L8-L54 -> 0 | M31: =M8-M54 -> 0 | ... AE31: =AE8-AE54 -> 0
E32: 포장 | F32: =F9-F55 -> 0 | G32: =G9-G55 -> -18.352059 | H32: =H9-H55 -> -3.300554 | I32: =I9-I55 -> 5.9820955 | J32: =J9-J55 -> -15.670518 | K32: =K9-K55 -> 0 | L32: =L9-L55 -> 0 | M32: =M9-M55 -> 10.427552 | ... AE32: =AE9-AE55 -> 0
F33: =F10-F56 -> 0 | G33: =G10-G56 -> -10.399073 | H33: =H10-H56 -> 15.427818 | I33: =I10-I56 -> 7.8615885 | J33: =J10-J56 -> 12.890333 | K33: =K10-K56 -> 0 | L33: =L10-L56 -> 0 | M33: =M10-M56 -> 10.427552 | ... AE33: =AE10-AE56 -> 0
D34: L&P 상업 | F34: =F11-F57 -> 0 | G34: =G11-G57 -> -1.895081 | H34: =H11-H57 -> -1.7736796 | I34: =I11-I57 -> -0.2934892 | J34: =J11-J57 -> -3.9622498 | K34: =K11-K57 -> 0 | L34: =L11-L57 -> 0 | M34: =M11-M57 -> 0 | ... AE34: =AE11-AE57 -> 0
F35: =F12-F58 -> 0 | G35: =G12-G58 -> -12.294154 | H35: =H12-H58 -> 13.654138 | I35: =I12-I58 -> 7.5680993 | J35: =J12-J58 -> 8.9280837 | K35: =K12-K58 -> 0 | L35: =L12-L58 -> 0 | M35: =M12-M58 -> 10.427552 | ... AE35: =AE12-AE58 -> 0
C36: 내재화 상업 | D36: APAC | E36: 네시나F | F36: =F13-F59 -> 0 | G36: =G13-G59 -> -9.0180323 | H36: =H13-H59 -> 6.0092866 | I36: =I13-I59 -> 0.023856 | J36: =J13-J59 -> -2.9848897 | K36: =K13-K59 -> -14.683936 | L36: =L13-L59 -> 9.516414 | M36: =M13-M59 -> 1.540842 | ... AE36: =AE13-AE59 -> 0
E37: 이달비F | F37: =F14-F60 -> 0 | G37: =G14-G60 -> 0.11069184 | H37: =H14-H60 -> -21.345866 | I37: =I14-I60 -> 8.925552 | J37: =J14-J60 -> -12.309622 | K37: =K14-K60 -> 4.488904 | L37: =L14-L60 -> 7.22425 | M37: =M14-M60 -> -23.573669 | ... AE37: =AE14-AE60 -> 0
F38: =F15-F61 -> 0 | G38: =G15-G61 -> -8.9073405 | H38: =H15-H61 -> -15.336579 | I38: =I15-I61 -> 8.949408 | J38: =J15-J61 -> -15.294512 | K38: =K15-K61 -> -10.195032 | L38: =L15-L61 -> 16.740664 | M38: =M15-M61 -> -22.032826 | ... AE38: =AE15-AE61 -> 0
D39: CMO상업_위임형 | F39: =F16-F62 -> 0 | G39: =G16-G62 -> 0 | H39: =H16-H62 -> 0 | I39: =I16-I62 -> 0 | J39: =J16-J62 -> 0 | K39: =K16-K62 -> 0 | L39: =L16-L62 -> 0 | M39: =M16-M62 -> 0 | ... AE39: =AE16-AE62 -> 0
F40: =F17-F63 -> 0 | G40: =G17-G63 -> -8.9073405 | H40: =H17-H63 -> -15.336579 | I40: =I17-I63 -> 8.949408 | J40: =J17-J63 -> -15.294512 | K40: =K17-K63 -> -10.195032 | L40: =L17-L63 -> 16.740664 | M40: =M17-M63 -> -22.032826 | ... AE40: =AE17-AE63 -> 0
C41: 개발용역 | D41: 케미컬 | E41: CMO용역 | F41: =F18-F64 -> 0 | G41: =G18-G64 -> 0 | H41: =H18-H64 -> 0 | I41: =I18-I64 -> 0 | J41: =J18-J64 -> 0 | K41: =K18-K64 -> 0 | L41: =L18-L64 -> 0 | M41: =M18-M64 -> 0 | ... AE41: =AE18-AE64 -> 0
E42: 내재화용역 | F42: =F19-F65 -> 0 | G42: =G19-G65 -> 0 | H42: =H19-H65 -> 0 | I42: =I19-I65 -> 1.875 | J42: =J19-J65 -> 1.875 | K42: =K19-K65 -> 0 | L42: =L19-L65 -> 0 | M42: =M19-M65 -> 0 | ... AE42: =AE19-AE65 -> 0
...

Sheet 251219_변경사항 요약
B1: ◈ 제조부문 매출 변경사항 요약(P42 포함) | AE1: (2026.01.09)
W2: 합계
B3: 1. 매출 업데이트 | F3: ※ 25년 분기별 매출 : | I3: 1분기: | J3: 275.49898 | M3: 2분기: | N3: 323.91353 | Q3: 3분기: | R3: 382.18333 | U3: 4분기: | V3: 412.42057 | W3: =SUM(J3,N3,R3,V3) -> 1394.0164
B4: 구분 | C4: 제품 | D4: 구분 | E4: 공정 | F4: 2025년 | O4: 2026년 | Z4: 2027년 | AB4: 2027년 | AC4: 2028년 | AD4: 2029년 | AE4: 2030년
G5: 1월 | H5: 2월 | I5: 3월 | J5: 1분기 | K5: 4월 | L5: 5월 | M5: 6월 | N5: 2분기 | O5: 7월 | P5: 8월 | Q5: 9월 | R5: 3분기 | S5: 10월 | T5: 11월 | U5: 12월 | V5: 4분기 | W5: Total | X5: 1분기 | Y5: 2분기 | Z5: 3분기 | AA5: 4분기 | AB5: Total | AC5: Total | AD5: Total | AE5: Total
F6: =SUM(F12,F17,F24) -> 1394.0521 | G6: 114.77019 | H6: 111.20819 | I6: 83.353757 | J6: 309.33214 | K6: 117.14009 | L6: 144.82144 | M6: 125.4648 | N6: 387.42633 | O6: 130.09779 | P6: 132.64093 | Q6: 141.78632 | R6: 404.52504 | S6: 122.5059 | T6: 139.84816 | U6: 165.35859 | V6: 427.71265 | W6: 1528.9962 | X6: 427.87927 | Y6: 462.06469 | Z6: 362.07235 | AA6: 468.13685 | AB6: 1720.1532 | AC6: 1993.4417 | AD6: 1921.6238 | AE6: 1786.7261
B7: 신규롤링 | C7: 바이오 상업 | D7: PFS상업 | E7: 충전 | F7: 474.91249 | G7: 26.32324 | H7: 15.3323 | I7: 18.8568 | J7: 60.51234 | K7: 29.963304 | L7: 45.593388 | M7: 29.166786 | N7: 104.72348 | O7: 45.772406 | P7: 39.399426 | Q7: 18.125316 | R7: 103.29715 | S7: 33.614154 | T7: 47.059542 | U7: 37.631628 | V7: 118.30532 | W7: 386.83829 | X7: 141 | Y7: 156 | Z7: 103 | AA7: 161 | AB7: 561 | AC7: 664 | AD7: 683 | AE7: 615
E8: 조립 | F8: 378.00117 | G8: 23.065242 | H8: 28.55389 | I8: 26.275651 | J8: 77.894783 | K8: 18.515111 | L8: 26.490361 | M8: 15.563747 | N8: 60.569218 | O8: 35.624332 | P8: 35.327342 | Q8: 47.045769 | R8: 117.99744 | S8: 25.34755 | T8: 15.563747 | U8: 41.92489 | V8: 82.836187 | W8: 339.29763 | X8: 109 | Y8: 120 | Z8: 82 | AA8: 109 | AB8: 420 | AC8: 634 | AD8: 545 | AE8: 466
E9: 포장 | F9: 189.01808 | G9: 30.001094 | H9: 28.76311 | I9: 28.337598 | J9: 87.101802 | K9: 30.871089 | L9: 29.497247 | M9: 30.504468 | N9: 90.872804 | O9: 26.838239 | P9: 33.507819 | Q9: 31.371319 | R9: 91.717377 | S9: 31.666133 | T9: 38.290916 | U9: 34.065948 | V9: 104.023 | W9: 373.71498 | X9: 87.101802 | Y9: 90.872804 | Z9: 91.717377 | AA9: 104.023 | AB9: 373.71498 | AC9: 373.71498 | AD9: 373.71498 | AE9: 373.71498
F10: 1041.9317 | G10: 79.389576 | H10: 72.6493 | I10: 73.470049 | J10: 225.50893 | K10: 79.349504 | L10: 101.581 | M10: 75.235001 | N10: 256.1655 | O10: 108.23498 | P10: 108.23459 | Q10: 96.542404 | R10: 313.01197 | S10: 90.627837 | T10: 100.9142 | U10: 113.62247 | V10: 305.16451 | W10: 1099.8509 | X10: 337.1018 | Y10: 366.8728 | Z10: 276.71738 | AA10: 374.023 | AB10: 1354.715 | AC10: 1671.715 | AD10: 1601.715 | AE10: 1454.715
D11: L&P 상업 | F11: 47.201113 | G11: 4.547646 | H11: 4.519496 | I11: 2.9471092 | J11: 12.014251 | K11: 4.198658 | L11: 4.7918944 | M11: 3.2201436 | N11: 12.210696 | O11: 5.0285436 | P11: 5.6127878 | Q11: 2.3312762 | R11: 12.972608 | S11: 5.2395568 | T11: 5.3743936 | U11: 3.8248932 | V11: 14.438844 | W11: 51.636398 | X11: 12.614964 | Y11: 12.821231 | Z11: 13.621238 | AA11: 15.160786 | AB11: 54.218218 | AC11: 56.929129 | AD11: 59.775586 | AE11: 62.764365
F12: =SUM(F10:F11) -> 1089.1329 | G12: 83.937222 | H12: 77.168796 | I12: 76.417158 | J12: 237.52318 | K12: 83.548162 | L12: 106.37289 | M12: 78.455145 | N12: 268.3762 | O12: 113.26352 | P12: 113.84737 | Q12: 98.87368 | R12: 325.98458 | S12: 95.867394 | T12: 106.2886 | U12: 117.44736 | V12: 319.60335 | W12: 1151.4873 | X12: 349.71677 | Y12: 379.69403 | Z12: 290.33861 | AA12: 389.18378 | AB12: 1408.9332 | AC12: 1728.6441 | AD12: 1661.4906 | AE12: 1517.4793
C13: 내재화 상업 | D13: APAC | E13: 네시나F | G13: 10.30352 | H13: 5.6232 | I13: 0.22152 | J13: 16.14824 | K13: 14.89864 | L13: 0.9798 | M13: 0.14484 | N13: 16.02328 | O13: 11.38982 | P13: 5.39032 | Q13: 4.74706 | R13: 21.5272 | S13: 11.46508 | T13: 5.43434 | U13: 0 | V13: 16.89942 | W13: 70.59814 | X13: 16.14824 | Y13: 16.02328 | Z13: 21.5272 | AA13: 16.89942 | AB13: 70.59814 | AC13: 70.59814 | AD13: 70.59814 | AE13: 70.59814
E14: 이달비F | G14: 1.704 | H14: 21.797 | I14: 0.26838 | J14: 23.76938 | K14: 7.45784 | L14: 0.25205 | M14: 24.97212 | N14: 32.68201 | O14: 1.704 | P14: 8.32404 | Q14: 16.45638 | R14: 26.48442 | S14: 10.21548 | T14: 0.47002 | U14: 24.72078 | V14: 35.40628 | W14: 118.34209 | X14: 23.76938 | Y14: 32.68201 | Z14: 26.48442 | AA14: 35.40628 | AB14: 118.34209 | AC14: 118.34209 | AD14: 118.34209 | AE14: 118.34209
F15: 155.93871 | G15: 12.00752 | H15: 27.4202 | I15: 0.4899 | J15: 39.91762 | K15: 22.35648 | L15: 1.23185 | M15: 25.11696 | N15: 48.70529 | O15: 13.09382 | P15: 13.71436 | Q15: 21.20344 | R15: 48.01162 | S15: 21.68056 | T15: 5.90436 | U15: 24.72078 | V15: 52.3057 | W15: 188.94023 | X15: 39.91762 | Y15: 48.70529 | Z15: 48.01162 | AA15: 52.3057 | AB15: 188.94023 | AC15: 188.94023 | AD15: 188.94023 | AE15: 188.94023
D16: CMO상업_위임형 | G16: 0.17044833 | H16: 0.17044833 | I16: 0.17044833 | J16: 0.511345 | K16: 0.17044833 | L16: 0.17044833 | M16: 0.17044833 | N16: 0.511345 | O16: 0.17044833 | P16: 0.17044833 | Q16: 0.17044833 | R16: 0.511345 | S16: 0.17044833 | T16: 0.17044833 | U16: 0.17044833 | V16: 0.511345 | W16: 2.04538 | X16: 2.04538 | Y16: 1.5298675 | Z16: 1.5298675 | AA16: 1.5298675 | AB16: 6.6349825 | AC16: 1.5298675 | AD16: 6.11947 | AE16: 12.233065
F17: 155.93871 | G17: 12.177968 | H17: 27.590648 | I17: 0.66034833 | J17: 40.428965 | K17: 22.526928 | L17: 1.4022983 | M17: 25.287408 | N17: 49.216635 | O17: 13.264268 | P17: 13.884808 | Q17: 21.373888 | R17: 48.522965 | S17: 21.851008 | T17: 6.0748083 | U17: 24.891228 | V17: 52.817045 | W17: 190.98561 | X17: 41.963 | Y17: 50.235157 | Z17: 49.541488 | AA17: 53.835568 | AB17: 195.57521 | AC17: 190.4701 | AD17: 195.0597 | AE17: 201.17329
C18: 개발용역 | D18: 케미컬 | E18: CMO용역 | F18: 0.67 | G18: 0 | H18: 0 | I18: 0 | J18: 0 | K18: 0 | L18: 0 | M18: 0 | N18: 0 | O18: 0 | P18: 0 | Q18: 0 | R18: 0 | S18: 0 | T18: 0 | U18: 0 | V18: 0 | W18: 0 | X18: 0 | Y18: 0 | Z18: 0 | AA18: 0 | AB18: 0 | AC18: 0 | AD18: 0 | AE18: 0
E19: 내재화용역 | F19: 14.12375 | G19: 1.40625 | H19: 0.46875 | I19: 0.9375 | J19: 2.8125 | K19: 1.40625 | L19: 0.46875 | M19: 0.46875 | N19: 2.34375 | O19: 0 | P19: 0 | Q19: 0 | R19: 0 | S19: 0.9375 | T19: 0 | U19: 0 | V19: 0.9375 | W19: 6.09375 | X19: 0 | Y19: 0 | Z19: 0.46875 | AA19: 0.46875 | AB19: 0.9375 | AC19: 0 | AD19: 0 | AE19: 0
E20: LCM용역 | F20: 12.792667 | G20: 0.46875 | H20: 2.03 | I20: 1.31875 | J20: 3.8175 | K20: 1.31875 | L20: 0.4 | M20: 1.7375 | N20: 3.45625 | O20: 0.85 | P20: 0.46875 | Q20: 0.46875 | R20: 1.7875 | S20: 0.85 | T20: 1.31875 | U20: 0 | V20: 2.16875 | W20: 11.23 | X20: 0.9375 | Y20: 0.9375 | Z20: 0.9375 | AA20: 0.46875 | AB20: 3.28125 | AC20: 0.9375 | AD20: 0.9375 | AE20: 0.9375
E21: 기타 | F21: 5.0982021 | G21: 0 | H21: 0 | I21: 0 | K21: 0 | L21: 0 | M21: 0 | O21: 0 | P21: 0 | Q21: 0 | S21: 0 | T21: 0 | U21: 0 | X21: 0 | Y21: 0 | Z21: 0 | AA21: 0 | AC21: 0 | AD21: 0 | AE21: 0
F22: =SUM(F18:F21) -> 32.684619 | G22: 1.875 | H22: 2.49875 | I22: 2.25625 | J22: 6.63 | K22: 2.725 | L22: 0.86875 | M22: 2.20625 | N22: 5.8 | O22: 0.85 | P22: 0.46875 | Q22: 0.46875 | R22: 1.7875 | S22: 1.7875 | T22: 1.31875 | U22: 0 | V22: 3.10625 | W22: 17.32375 | X22: 0.9375 | Y22: 0.9375 | Z22: 1.40625 | AA22: 0.9375 | AB22: 4.21875 | AC22: 0.9375 | AD22: 0.9375 | AE22: 0.9375
D23: 바이오 | E23: PFS용역 | F23: 116.29589 | G23: 16.78 | H23: 3.95 | I23: 4.02 | J23: 24.75 | K23: 8.34 | L23: 36.1775 | M23: 19.516 | N23: 64.0335 | O23: 2.72 | P23: 4.44 | Q23: 21.07 | R23: 28.23 | S23: 3 | T23: 26.166 | U23: 23.02 | V23: 52.186 | W23: 169.1995 | X23: 35.262 | Y23: 31.198 | Z23: 20.786 | AA23: 24.18 | AB23: 111.426 | AC23: 73.39 | AD23: 64.136 | AE23: 67.136
F24: 148.98051 | G24: 18.655 | H24: 6.44875 | I24: 6.27625 | J24: 31.38 | K24: 11.065 | L24: 37.04625 | M24: 21.72225 | N24: 69.8335 | O24: 3.57 | P24: 4.90875 | Q24: 21.53875 | R24: 30.0175 | S24: 4.7875 | T24: 27.48475 | U24: 23.02 | V24: 55.29225 | W24: 186.52325 | X24: 36.1995 | Y24: 32.1355 | Z24: 22.19225 | AA24: 25.1175 | AB24: 115.64475 | AC24: 74.3275 | AD24: 65.0735 | AE24: 68.0735
F25: ※ 기타 : QA위임, 선급금 매출인식(PFS, 케미컬)
B26: ◈ 26년 매출 신규 Rolling 전제사항
B27: Update: 2026-01-06
B28: 구분 | D28: 공정 | E28: 전제사항 | P28: 구분 | R28: 전제사항
B30: PFS | D30: 충전 | E30: 1. 개발/평가 일정 1) '25.12.21 기준 최신 개발/평가 일정을 반영(+4.5일). 단, CT-P42 관련 일정 미반영 ① 충전기/아이솔레이터 Overall 일정 단축(-2일, 12→10일) → 운영지원 전달 파일에는 9일로 나와 있으나, 생산팀 확인결과 10일 필요 ② CT-P17 40mg S/up 30만 PV 일정 추가(+8일, 13→21일): CV 추가에 따른 #1과 #2사이에 8일 추가 필요 ③ CT-P52 80mg SV 샘플 제작 일정 삭제(-0.5일) :12월말 셧다운기간 수행 예정 ④ NO2 멸균기 정기 PQ 삭제(-1일) 2. 상업물량(상업) 1) 26년: 11월 Fcst 기준(최신) 3. 생산계획 1) 26년: 일별계획 수립 → 25년 생산/공급 현황 및 별도요청 사항 등 상세내용 반영 4. 단가 1) 26년: 현재 상업단가와 동일 적용 | F30: (충전) 개발/평가 일정: 사업계획 대비 7일 감소 & 표준공수 감소(36시간 → 32시간) | P30: PFS | R30: 충전 | S30: 1. 개발/평가 일정 1) '25.12.21 기준 최신 개발/평가 일정을 반영(+4.5일). 단, CT-P42 관련 일정 미반영 ① 충전기/아이솔레이터 Overall 일정 단축(-2일, 12→10일) → 운영지원 전달 파일에는 9일로 나와 있으나, 생산팀 확인결과 10일 필요 ② CT-P17 40mg S/up 30만 PV 일정 추가(+8일, 13→21일): CV 추가에 따른 #1과 #2사이에 8일 추가 필요 ③ CT-P52 80mg SV 샘플 제작 일정 삭제(-0.5일) :12월말 셧다운기간 수행 예정 ④ NO2 멸균기 정기 PQ 삭제(-1일) 2. 상업물량(상업) 1) 26년: 11월 Fcst 기준(최신) 3. 생산계획 1) 26년: 일별계획 수립 → 25년 생산/공급 현황 및 별도요청 사항 등 상세내용 반영 4. 단가 1) 26년: 현재 상업단가와 동일 적용 | T30: (충전) 개발/평가 일정: 사업계획 대비 7일 감소 & 표준공수 감소(36시간 → 32시간)
D31: AI 조립 | E31: 1. 개발/평가 일정 1) '25.12.21 기준 최신 개발/평가 일정을 반영. 단, CT-P42 관련 일정 미반영 ① Molly SE 셋업 일정 반영(+11일) 2. 상업물량(상업) 1) 26년: 11월 Fcst 기준(최신) 3. 생산계획 1) 26년: 일별계획 수립 → 충전계획과 align 4. 단가 1) 26년: 현재 상업단가와 동일 적용 | R31: AI 조립 | S31: 1. 개발/평가 일정 1) '25.12.21 기준 최신 개발/평가 일정을 반영. 단, CT-P42 관련 일정 미반영 ① Molly SE 셋업 일정 반영(+11일) 2. 상업물량(상업) 1) 26년: 11월 Fcst 기준(최신) 3. 생산계획 1) 26년: 일별계획 수립 → 충전계획과 align 4. 단가 1) 26년: 현재 상업단가와 동일 적용
D32: 수동조립 | R32: 수동조립
D33: 포장 | E33: 26년 사업계획과 동일 | R33: 포장 | S33: 26년 사업계획과 동일
B34: L&P | D34: - | P34: L&P | R34: -
B35: PFS | D35: 충전 | E35: 1. 개발/평가 일정 1) 최신 개발/평가 일정을 반영(총 207.5일 →개발 154.5일, 평가 53일) ① CT-P42 개발 일정 반영 (16일) ② P17, P13 30만 S/up 개발 일정 반영 (40일) ③ P45 임상, P52 PV, P68 PV, P55 300mg 임상, P41 120mg PV, P39 300mg PV 등 (98.5일) ④ 충전기/아이솔레이터 Overall (10일) ⑤ 정기 Mediafill (상반기/하반기, 0.5ml 파츠 포함), VHP 정기 PQ 등 (43일) 2. 상업물량(상업) 1) 26년: 25년 11월 Fcst 기준 2) CT-P42 2mg 상업 반영 ① 배치사이즈 5만 시린지 가정 ② 26년 총 60만 시린지(12배치) 3월부터 및 생산/공급 가정 ③ 표준공수는 준비/정리 시간은 고정, 충전속도는 시간당 7천개로 반영 3. 생산계획 1) 26년: 일별계획 수립 → 25년 생산/공급 현황 및 별도요청 사항 등 상세내용 반영 4. 단가 1) 26년: 현재 상업단가와 동일 적용 (P42도 현재 상업 단가 기준 동일 적용) ※ 셀트리온으로부터 수령한 26년 충전 물량은 협의 되지 않은 개발 제품 및 P42 물량이 반영 되어 있으며, 30만 스케일업에 대한 물량 정보도 없어 실질 계획과의 GAP으로 미 반영 함 | P35: 개발용역 | R35: 1. 케미컬(17억) - 추가되는 개발용역 없음. (내재화_안정성, LCM_L02, L03, 안정성) 2. PFS(169억) - '26년 개발제품 : 충전 기준 P17 40mg S/up, P39 300mg, P41 120mg, P42 2mg, P45 108mg, P52 80mg, P55 75mg/150mg/300mg, P68 100mg/200mg - 이연한 마일스톤은 미반영(총 10.6억) : 충전PV 6.5억 (P55 75mg(3.3억), P55 150mg(3.3억)), 안정성 2.3억 (P43 45mg/90mg), AI PKV 수동라벨링 등 1.8억 (P39 75mg/150mg, P13SC 27G) ※ 매출 적정수준 조정을 위해 이연 마일스톤 중 P41 60mg 충전 PV(16.1억)는 사업계획에 포함함. - 충전 기준 28년 6품목, 29년 4품목, 30년 3품목 반영 (평균적으로 도입되는 제품 수 및 연도별 감소 고려)
D36: AI 조립 | E36: 1. 개발/평가 일정 1) 최신 개발/평가 일정을 반영(총 47.5일 →개발 27일, 평가 20.5일) ① P55 150mg, 300mg, P52 80mg PKV, TBD 5개 제품 PKV 일정 반영 (27일) ② 재적격성 평가, TBD 5개 제품 OPQ, 자재적합성 TEST 평가 일정 반영 (9.5일) ③ Molly SE Set Up, OPQ 평가 일정 반영 (11일) ④ CT-P42 일정 미 반영 (조립/포장 컨셉 미정임에 따라 미반영) 2. 상업물량(상업) 1) 26년: 11월 Fcst 기준 (CT-P42 물량 미 반영, AI 수동 조립 물량 포함) 3. 생산계획 1) 26년: 일별계획 수립 → 충전계획과 align 4. 단가 1) 26년: 현재 상업단가와 동일 적용 | P36: 케미컬 | R36: 1. 상업 물량 1) 25년 8월 Hasten으로부터 수령한 FCST 반영 2. 상업 단가 1) 현재 계약 단가 + 환율 1,420원 반영 3. 기타 1) 로제핀정 (암로젯 녹십자 위임형 제네릭) 반영
D37: 포장 | E37: 1. 개발/상업 물량 및 단가 1) 개발 : P52, P41, P68, P42 PFS-S PKV 일정 반영 2) 상업 ① '25.8월에 수령한 26년 FCST 물량 반영 (from. 패키징 운영) ② 연간 최대 CAPA 720만 시린지의 85% 수준 물량 반영 (약 620만 시린지) 3) 단가 : 기존과 동일하게 반영
B38: L&P | E38: 1. 개발/상업 물량 및 단가 1) 개발 : 반영 無 2) 상업 ① '25.8월에 수령한 26년 FCST 물량 반영 (from. 패키징 운영) 3) 단가 : 기존과 동일하게 반영

Sheet 251230_변경사항요약2
H1: (2026.01.06
B2: ◈ 제조부문 매출 변경사항 요약(P42 포함)
B4: 1. 기존 사업계획 대비 변경사항 요약
B5: 구분 | D5: 연도 | E5: 기존 | F5: 변경 | G5: Gap | H5: 변경 사유
B6: 상업 | C6: 바이오 | D6: 26년 | E6: ='251219_변경사항 요약'!#REF! -> #REF! | F6: ='251219_변경사항 요약'!W12 -> 1151.4873 | G6: =SUM(F6-E6) -> #REF! | H6: - PFS 포장 및 L&P 기존과 동일 - 충전 (-72억) : 11월 Fcst 기준, 현재 상업단가와 동일하게 적용 최신 개발/평가 일정을 반영(+20.5일) → CT-P42 관련 일정(+24일) 포함 - 조립 (-127억) : 11월 Fcst 기준, 현재 상업단가와 동일하게 적용 최신 개발/평가 일정을 반영 → Molly SE 셋업 일정 포함(+11일), CT-P42 관련 일정 미반영
D7: 27년 | E7: ='251219_변경사항 요약'!#REF! -> #REF! | F7: ='251219_변경사항 요약'!AB12 -> 1408.9332 | G7: =SUM(F7-E7) -> #REF!
D8: 28년 | E8: ='251219_변경사항 요약'!#REF! -> #REF! | F8: ='251219_변경사항 요약'!AC12 -> 1728.6441 | G8: =SUM(F8-E8) -> #REF!
D9: 29년 | E9: ='251219_변경사항 요약'!#REF! -> #REF! | F9: ='251219_변경사항 요약'!AD12 -> 1661.4906 | G9: =SUM(F9-E9) -> #REF!
D10: 30년 | E10: ='251219_변경사항 요약'!#REF! -> #REF! | F10: ='251219_변경사항 요약'!AE12 -> 1517.4793 | G10: =SUM(F10-E10) -> #REF!
C11: 케미컬 | D11: 26년 | E11: ='251219_변경사항 요약'!#REF! -> #REF! | F11: ='251219_변경사항 요약'!W17 -> 190.98561 | G11: =SUM(F11-E11) -> #REF! | H11: 환율상승(1,300원->1,420원), 로제핀정(암로젯 위임형 제네릭) 반영
D12: 27년 | E12: ='251219_변경사항 요약'!#REF! -> #REF! | F12: ='251219_변경사항 요약'!AB17 -> 195.57521 | G12: =SUM(F12-E12) -> #REF! | H12: 프랑스제네릭 제외, 환율상승(1,300->1,420원), 로제핀정(암로젯 위임형 제네릭) 반영
D13: 28년 | E13: ='251219_변경사항 요약'!#REF! -> #REF! | F13: ='251219_변경사항 요약'!AC17 -> 190.4701 | G13: =SUM(F13-E13) -> #REF! | H13: 프랑스제네릭 제외, 환율상승(1,300->1,420원), 로제핀정(암로젯 위임형 제네릭) 반영
D14: 29년 | E14: ='251219_변경사항 요약'!#REF! -> #REF! | F14: ='251219_변경사항 요약'!AD17 -> 195.0597 | G14: =SUM(F14-E14) -> #REF! | H14: 프랑스제네릭 제외, 환율상승(1,300->1,420원), 로제핀정(암로젯 위임형 제네릭) 반영
D15: 30년 | E15: ='251219_변경사항 요약'!#REF! -> #REF! | F15: ='251219_변경사항 요약'!AE17 -> 201.17329 | G15: =SUM(F15-E15) -> #REF! | H15: 프랑스제네릭 제외, 환율상승(1,300->1,420원), 로제핀정(암로젯 위임형 제네릭) 반영
B16: 개발용역 | D16: 26년 | E16: ='251219_변경사항 요약'!#REF! -> #REF! | F16: ='251219_변경사항 요약'!W24 -> 186.52325 | G16: =SUM(F16-E16) -> #REF! | H16: - 케미컬(-3억) : 안정성 이연 마일스톤(+1억_M01, M02), CT-L03 PF/PE '25년에 기청구 완료(-3.5억) - 바이오(+49억) : 충전 PV 4제품 추가(+48.3억_P41 60mg, P42 2mg, P52 80mg, P55 300mg) 등
D17: 27년 | E17: ='251219_변경사항 요약'!#REF! -> #REF! | F17: ='251219_변경사항 요약'!AB24 -> 115.64475 | G17: =SUM(F17-E17) -> #REF!
D18: 28년 | E18: ='251219_변경사항 요약'!#REF! -> #REF! | F18: ='251219_변경사항 요약'!AC24 -> 74.3275 | G18: =SUM(F18-E18) -> #REF! | H18: - 바이오 : 28년 충전 기준 6품목 반영
D19: 29년 | E19: ='251219_변경사항 요약'!#REF! -> #REF! | F19: ='251219_변경사항 요약'!AD24 -> 65.0735 | G19: =SUM(F19-E19) -> #REF! | H19: - 바이오 : 29년 충전 기준 4품목 반영
D20: 30년 | E20: ='251219_변경사항 요약'!#REF! -> #REF! | F20: ='251219_변경사항 요약'!AE24 -> 68.0735 | G20: =SUM(F20-E20) -> #REF! | H20: - 바이오 : 30년 충전 기준 3품목 반영 (평균적으로 도입되는 제품 수 및 연도별 감소 고려)

Sheet 전제사항 요약
B2: ◈ 26년 매출 신규 Rolling 전제사항
B3: Update: 2026-01-06
B5: 구분 | C5: 구분2 | D5: 공정 | E5: 전제사항
B6: PFS | C6: Case1 | D6: 충전 | E6: 1. 개발/평가 일정 1) '25.12.21 기준 최신 개발/평가 일정을 반영(+4.5일). 단, CT-P42 관련 일정 미반영 ① 충전기/아이솔레이터 Overall 일정 단축(-2일, 12→10일) → 운영지원 전달 파일에는 9일로 나와 있으나, 생산팀 확인결과 10일 필요 ② CT-P17 40mg S/up 30만 PV 일정 추가(+8일, 13→21일): CV 추가에 따른 #1과 #2사이에 8일 추가 필요 ③ CT-P52 80mg SV 샘플 제작 일정 삭제(-0.5일) :12월말 셧다운기간 수행 예정 ④ NO2 멸균기 정기 PQ 삭제(-1일) 2. 상업물량(상업) 1) 26년: 11월 Fcst 기준(최신) 3. 생산계획 1) 26년: 일별계획 수립 → 25년 생산/공급 현황 및 별도요청 사항 등 상세내용 반영 4. 단가 1) 26년: 현재 상업단가와 동일 적용 | F6: (충전) 개발/평가 일정: 사업계획 대비 7일 감소 & 표준공수 감소(36시간 → 32시간)
D7: AI 조립 | E7: 1. 개발/평가 일정 1) '25.12.21 기준 최신 개발/평가 일정을 반영. 단, CT-P42 관련 일정 미반영 ① Molly SE 셋업 일정 반영(+11일) 2. 상업물량(상업) 1) 26년: 11월 Fcst 기준(최신) 3. 생산계획 1) 26년: 일별계획 수립 → 충전계획과 align 4. 단가 1) 26년: 현재 상업단가와 동일 적용
D8: 수동조립
D9: 포장 | E9: 26년 사업계획과 동일
B10: L&P | D10: -
B11: PFS | C11: Case2 | D11: 충전 | E11: 1. 개발/평가 일정 1) '25.12.21 기준 최신 개발/평가 일정을 반영(+20.5일). CT-P42 관련 일정 반영 ① 충전기/아이솔레이터 Overall 일정 단축(-2일, 12→10일) ② CT-P52 80mg SV 샘플 제작 일정 삭제(-0.5일) :12월말 셧다운기간 수행 예정 ③ NO2 멸균기 정기 PQ 삭제(-1일) ④ CT-P42 관련 일정 반영(+24일) CT-P42 2mg 셋업(feasability & OPQ): +4일 PV(10.5일) + 포멧 파츠 교체(1.5일): +12일 Media fill 상/하반기: +8일(10→18일) 2. 상업물량(상업) 1) 26년: 11월 Fcst 기준(최신) 2) CT-P42 2mg 상업(S/F 정보 없음) ① 배치사이즈 5만 시린지 가정 ② 26년 총 60만 시린지(12배치) 3월부터 및 생산/공급 가정 ③ 표준공수는 준비/정리 시간은 고정, 충전속도는 시간당 7천개로 반영 3. 생산계획 1) 26년: 일별계획 수립 → 25년 생산/공급 현황 및 별도요청 사항 등 상세내용 반영 4. 단가 1) 26년: 현재 상업단가와 동일 적용 2) CT-P42 2mg도 현재 상업단가 기준 동일 단가 적용(5,400원/syr)
D12: AI 조립 | E12: 1. 개발/평가 일정 1) '25.12.21 기준 최신 개발/평가 일정을 반영. 단, CT-P42 일정 미반영 ① CT-P42 조립/포장 관련 컨셉 미정임에 따라 관련일정 미반영 ② Molly SE 셋업 일정 반영(+11일) 2. 상업물량(상업) 1) 26년: 11월 Fcst 기준(최신) 3. 생산계획 1) 26년: 일별계획 수립 → 충전계획과 align 4. 단가 1) 26년: 현재 상업단가와 동일 적용
D13: 수동조립
D14: 포장 | E14: 26년 사업계획과 동일
B15: L&P | D15: -
B16: 케미컬 | E16: 1. 기존 사업계획과 동일 2. 환율 변경 (1,300원 → 1,420원) 3. 로제핀정(암로젯 녹십자 위임형제네릭) 반영
B17: 개발용역 | E17: 1. 케미컬(-3억) - 이연한 마일스톤(+1억) : 안정성 (M01(0.5억), M02(0.5억)) - CT-L03 PF/PE '25년에 청구 완료하여 '26년에서 제외(-3.5억) : 생동 비동 이슈가 있었으나, '25년에 청구로 양사 협의 2. PFS(+49억) - 이연한 마일스톤은 미반영(총 10.6억) : 충전PV 6.5억 (P55 75mg(3.3억), P55 150mg(3.3억)), 안정성 2.3억 (P43 45mg/90mg), AI PKV 수동라벨링 등 1.8억 (P39 75mg/150mg, P13SC 27G) ※ 매출 적정수준 조정을 위해 P41 60mg 충전 PV(16.1억)는 사업계획에 포함함. - '26년 개발제품 추가반영(총 +68.5억) : 충전 PV 48.3억 (P41 60mg(16.1억), P42 2mg(11억), P52 80mg(13.3억), P55 300mg(7.9억)), 임상충전 2억 (P55 300mg), AI/PFS-S PKV 문서 1.2억 (P39 75mg), 안정성 0.7억 (P43 45mg/90mg) PV자재 비용 추가반영 14.2억 (P17 40mg), PV 수행비용 증가 2.1억 (P39 300mg) - '26년 개발제품에서 제외(총 -19.7억) : 임상충전 6억 (P56 300mg 3배치), 충전PV 8억 (P68 200mg), TBD 2품목 제외 4.4억(TBD1 3.1억, TBD2 1.4억), PKV 문서 1.3억 (PP55 150mg) - 충전 기준 28년 6품목, 29년 4품목, 30년 3품목 반영 (평균적으로 도입되는 제품 수 및 연도별 감소 고려)

Sheet 요약
B1: ◈ 청주공장 CDMO 예상 매출_v1(25.08.26) | AE1: (2025.08.26)
B3: 1. 전제사항
AE12: (단위: 억원)
B13: 2. 매출 상세
F14: 2025년 (7/30, +50억) | O14: 2026년 | Z14: 2027년 | AC14: 2028년 | AD14: 2029년 | AE14: 2030년
B15: 구분 | C15: 제품 | D15: 구분 | E15: 공정 | G15: 1월 | H15: 2월 | I15: 3월 | J15: 1분기 | K15: 4월 | L15: 5월 | M15: 6월 | N15: 2분기 | O15: 7월 | P15: 8월 | Q15: 9월 | R15: 3분기 | S15: 10월 | T15: 11월 | U15: 12월 | V15: 4분기 | W15: Total | X15: 1분기 | Y15: 2분기 | Z15: 3분기 | AA15: 4분기 | AB15: Total | AC15: Total | AD15: Total | AE15: Total
F16: =F34+F22+F27 -> 1363.9492 | G16: =SUM(G27,G22,G34) -> 100.91695 | H16: =SUM(H27,H22,H34) -> 107.7245 | I16: =SUM(I27,I22,I34) -> 104.74626 | J16: =SUM(J27,J22,J34) -> 313.38771 | K16: =SUM(K27,K22,K34) -> 106.71881 | L16: =SUM(L27,L22,L34) -> 162.4121 | M16: =SUM(M27,M22,M34) -> 113.39078 | N16: =SUM(N27,N22,N34) -> 382.52169 | ... AE16: =SUM(AE27,AE22,AE34) -> 1786.7261
B17: 사업계획 | C17: 바이오 상업 | D17: PFS상업 | E17: 충전 | F17: 431.56358 | G17: ='2. PFS 충전, 조립 상업매출'!G9 -> 27.258676 | H17: ='2. PFS 충전, 조립 상업매출'!H9 -> 24.13214 | I17: ='2. PFS 충전, 조립 상업매출'!I9 -> 23.07312 | J17: =SUM(G17:I17) -> 74.463936 | K17: ='2. PFS 충전, 조립 상업매출'!J9 -> 29.963304 | L17: ='2. PFS 충전, 조립 상업매출'!K9 -> 45.593388 | M17: ='2. PFS 충전, 조립 상업매출'!L9 -> 29.166786 | N17: =SUM(K17:M17) -> 104.72348 | O17: ='2. PFS 충전, 조립 상업매출'!M9 -> 45.772406 | P17: ='2. PFS 충전, 조립 상업매출'!N9 -> 39.399426 | Q17: ='2. PFS 충전, 조립 상업매출'!O9 -> 18.125316 | R17: =SUM(O17:Q17) -> 103.29715 | S17: ='2. PFS 충전, 조립 상업매출'!P9 -> 33.614154 | T17: ='2. PFS 충전, 조립 상업매출'!Q9 -> 47.059542 | U17: ='2. PFS 충전, 조립 상업매출'!R9 -> 37.631628 | V17: =SUM(S17:U17) -> 118.30532 | W17: =+J17+N17+R17+V17 -> 400.78989 | X17: =SUM('2. PFS 충전, 조립 상업매출'!G18:I18) -> 141 | Y17: =SUM('2. PFS 충전, 조립 상업매출'!J18:L18) -> 156 | Z17: =SUM('2. PFS 충전, 조립 상업매출'!M18:O18) -> 103 | AA17: =SUM('2. PFS 충전, 조립 상업매출'!P18:R18) -> 161 | AB17: =SUM(X17:AA17) -> 561 | AC17: ='2. PFS 충전, 조립 상업매출'!S27 -> 664 | AD17: ='2. PFS 충전, 조립 상업매출'!S36 -> 683 | AE17: ='2. PFS 충전, 조립 상업매출'!S45 -> 615
E18: 조립 | F18: 409.14798 | G18: ='2. PFS 충전, 조립 상업매출'!G12 -> 30.082792 | H18: ='2. PFS 충전, 조립 상업매출'!H12 -> 38.482422 | I18: ='2. PFS 충전, 조립 상업매출'!I12 -> 23.938824 | J18: =SUM(G18:I18) -> 92.504038 | K18: ='2. PFS 충전, 조립 상업매출'!J12 -> 18.515111 | L18: ='2. PFS 충전, 조립 상업매출'!K12 -> 26.490361 | M18: ='2. PFS 충전, 조립 상업매출'!L12 -> 15.563747 | N18: =SUM(K18:M18) -> 60.569218 | O18: ='2. PFS 충전, 조립 상업매출'!M12 -> 35.624332 | P18: ='2. PFS 충전, 조립 상업매출'!N12 -> 35.327342 | Q18: ='2. PFS 충전, 조립 상업매출'!O12 -> 47.045769 | R18: =SUM(O18:Q18) -> 117.99744 | S18: ='2. PFS 충전, 조립 상업매출'!P12 -> 25.34755 | T18: ='2. PFS 충전, 조립 상업매출'!Q12 -> 15.563747 | U18: ='2. PFS 충전, 조립 상업매출'!R12 -> 41.92489 | V18: =SUM(S18:U18) -> 82.836187 | W18: =+J18+N18+R18+V18 -> 353.90689 | X18: =SUM('2. PFS 충전, 조립 상업매출'!G21:I21) -> 109 | Y18: =SUM('2. PFS 충전, 조립 상업매출'!J21:L21) -> 120 | Z18: =SUM('2. PFS 충전, 조립 상업매출'!M21:O21) -> 82 | AA18: =SUM('2. PFS 충전, 조립 상업매출'!P21:R21) -> 109 | AB18: =SUM(X18:AA18) -> 420 | AC18: ='2. PFS 충전, 조립 상업매출'!S30 -> 634 | AD18: ='2. PFS 충전, 조립 상업매출'!S39 -> 545 | AE18: ='2. PFS 충전, 조립 상업매출'!S48 -> 466
E19: 포장 | F19: 185.86048 | G19: ='3. 포장 상업매출'!C6 -> 11.649035 | H19: ='3. 포장 상업매출'!D6 -> 25.462556 | I19: ='3. 포장 상업매출'!E6 -> 34.319693 | J19: =SUM(G19:I19) -> 71.431285 | K19: ='3. 포장 상업매출'!F6 -> 30.871089 | L19: ='3. 포장 상업매출'!G6 -> 29.497247 | M19: ='3. 포장 상업매출'!H6 -> 40.93202 | N19: =SUM(K19:M19) -> 101.30036 | O19: ='3. 포장 상업매출'!I6 -> 26.838239 | P19: ='3. 포장 상업매출'!J6 -> 33.507819 | Q19: ='3. 포장 상업매출'!K6 -> 41.551265 | R19: =SUM(O19:Q19) -> 101.89732 | S19: ='3. 포장 상업매출'!L6 -> 31.666133 | T19: ='3. 포장 상업매출'!M6 -> 38.290916 | U19: ='3. 포장 상업매출'!N6 -> 44.168708 | V19: =SUM(S19:U19) -> 114.12576 | W19: =+J19+N19+R19+V19 -> 388.75472 | X19: ='3. 포장 상업매출'!P6 -> 87.101802 | Y19: ='3. 포장 상업매출'!Q6 -> 90.872804 | Z19: ='3. 포장 상업매출'!R6 -> 91.717377 | AA19: ='3. 포장 상업매출'!S6 -> 104.023 | AB19: =SUM(X19:AA19) -> 373.71498 | AC19: ='3. 포장 상업매출'!U6 -> 373.71498 | AD19: ='3. 포장 상업매출'!V6 -> 373.71498 | AE19: ='3. 포장 상업매출'!W6 -> 373.71498
F20: =SUM(F17:F19) -> 1026.572 | G20: =SUM(G17:G19) -> 68.990503 | H20: =SUM(H17:H19) -> 88.077118 | I20: =SUM(I17:I19) -> 81.331637 | J20: =SUM(G20:I20) -> 238.39926 | K20: =SUM(K17:K19) -> 79.349504 | L20: =SUM(L17:L19) -> 101.581 | M20: =SUM(M17:M19) -> 85.662553 | N20: =SUM(K20:M20) -> 266.59305 | O20: =SUM(O17:O19) -> 108.23498 | P20: =SUM(P17:P19) -> 108.23459 | Q20: =SUM(Q17:Q19) -> 106.72235 | R20: =SUM(O20:Q20) -> 323.19191 | S20: =SUM(S17:S19) -> 90.627837 | T20: =SUM(T17:T19) -> 100.9142 | U20: =SUM(U17:U19) -> 123.72523 | V20: =SUM(S20:U20) -> 315.26727 | W20: =+J20+N20+R20+V20 -> 1143.4515 | X20: =SUM(X17:X19) -> 337.1018 | Y20: =SUM(Y17:Y19) -> 366.8728 | Z20: =SUM(Z17:Z19) -> 276.71738 | AA20: =SUM(AA17:AA19) -> 374.023 | AB20: =SUM(X20:AA20) -> 1354.715 | AC20: =SUM(AC17:AC19) -> 1671.715 | AD20: =SUM(AD17:AD19) -> 1601.715 | AE20: =SUM(AE17:AE19) -> 1454.715
D21: L&P 상업 | F21: 50.005924 | G21: ='4. L&P 상업 매출'!C5 -> 2.652565 | H21: ='4. L&P 상업 매출'!D5 -> 2.7458164 | I21: ='4. L&P 상업 매출'!E5 -> 2.65362 | J21: =SUM(G21:I21) -> 8.0520014 | K21: ='4. L&P 상업 매출'!F5 -> 4.198658 | L21: ='4. L&P 상업 매출'!G5 -> 4.7918944 | M21: ='4. L&P 상업 매출'!H5 -> 3.2201436 | N21: =SUM(K21:M21) -> 12.210696 | O21: ='4. L&P 상업 매출'!I5 -> 5.0285436 | P21: ='4. L&P 상업 매출'!J5 -> 5.6127878 | Q21: ='4. L&P 상업 매출'!K5 -> 2.3312762 | R21: =SUM(O21:Q21) -> 12.972608 | S21: ='4. L&P 상업 매출'!L5 -> 5.2395568 | T21: ='4. L&P 상업 매출'!M5 -> 5.3743936 | U21: ='4. L&P 상업 매출'!N5 -> 3.8248932 | V21: =SUM(S21:U21) -> 14.438844 | W21: =+J21+N21+R21+V21 -> 47.674149 | X21: ='4. L&P 상업 매출'!P5 -> 12.614964 | Y21: ='4. L&P 상업 매출'!Q5 -> 12.821231 | Z21: ='4. L&P 상업 매출'!R5 -> 13.621238 | AA21: ='4. L&P 상업 매출'!S5 -> 15.160786 | AB21: =SUM(X21:AA21) -> 54.218218 | AC21: ='4. L&P 상업 매출'!U5 -> 56.929129 | AD21: ='4. L&P 상업 매출'!V5 -> 59.775586 | AE21: ='4. L&P 상업 매출'!W5 -> 62.764365
F22: =F20+F21 -> 1076.578 | G22: =+G20+G21 -> 71.643068 | H22: =+H20+H21 -> 90.822934 | I22: =+I20+I21 -> 83.985258 | J22: =+J20+J21 -> 246.45126 | K22: =+K20+K21 -> 83.548162 | L22: =+L20+L21 -> 106.37289 | M22: =+M20+M21 -> 88.882697 | N22: =+N20+N21 -> 278.80375 | ... AA22: =+AA20+AA21 -> 389.18378 | AB22: =SUM(X22:AA22) -> 1408.9332 | AC22: =+AC20+AC21 -> 1728.6441 | AD22: =+AD20+AD21 -> 1661.4906 | AE22: =+AE20+AE21 -> 1517.4793
C23: 내재화 상업 | D23: APAC | E23: 네시나F | G23: ='5. 케미컬상업'!E7 -> 1.2854877 | H23: ='5. 케미컬상업'!F7 -> 11.632487 | I23: ='5. 케미컬상업'!G7 -> 0.245376 | J23: =SUM(G23:I23) -> 13.16335 | K23: ='5. 케미컬상업'!H7 -> 0.214704 | L23: ='5. 케미컬상업'!I7 -> 10.496214 | M23: ='5. 케미컬상업'!J7 -> 1.685682 | N23: =SUM(K23:M23) -> 12.3966 | O23: ='5. 케미컬상업'!K7 -> 10.318572 | P23: ='5. 케미컬상업'!L7 -> 1.932336 | Q23: ='5. 케미컬상업'!M7 -> 2.302956 | R23: =SUM(O23:Q23) -> 14.553864 | S23: ='5. 케미컬상업'!N7 -> 2.302956 | T23: ='5. 케미컬상업'!O7 -> 11.107098 | U23: ='5. 케미컬상업'!P7 -> 4.851288 | V23: =SUM(S23:U23) -> 18.261342 | W23: =+J23+N23+R23+V23 -> 58.375156 | X23: ='5. 케미컬상업'!R7 -> 16.14824 | Y23: ='5. 케미컬상업'!S7 -> 16.02328 | Z23: ='5. 케미컬상업'!T7 -> 21.5272 | AA23: ='5. 케미컬상업'!U7 -> 16.89942 | AB23: =SUM(X23:AA23) -> 70.59814 | AC23: ='5. 케미컬상업'!V7 -> 70.59814 | AD23: ='5. 케미컬상업'!W7 -> 70.59814 | AE23: ='5. 케미컬상업'!X7 -> 70.59814
E24: 이달비F | G24: ='5. 케미컬상업'!E8 -> 1.8146918 | H24: ='5. 케미컬상업'!F8 -> 0.451134 | I24: ='5. 케미컬상업'!G8 -> 9.193932 | J24: =SUM(G24:I24) -> 11.459758 | K24: ='5. 케미컬상업'!H8 -> 11.946744 | L24: ='5. 케미컬상업'!I8 -> 7.4763 | M24: ='5. 케미컬상업'!J8 -> 1.3984515 | N24: =SUM(K24:M24) -> 20.821496 | O24: ='5. 케미컬상업'!K8 -> 22.996332 | P24: ='5. 케미컬상업'!L8 -> 0 | Q24: ='5. 케미컬상업'!M8 -> 7.717842 | R24: =SUM(O24:Q24) -> 30.714174 | S24: ='5. 케미컬상업'!N8 -> 16.286832 | T24: ='5. 케미컬상업'!O8 -> 7.717842 | U24: ='5. 케미컬상업'!P8 -> 23.5791 | V24: =SUM(S24:U24) -> 47.583774 | W24: =+J24+N24+R24+V24 -> 110.5792 | X24: ='5. 케미컬상업'!R8 -> 23.76938 | Y24: ='5. 케미컬상업'!S8 -> 32.68201 | Z24: ='5. 케미컬상업'!T8 -> 26.48442 | AA24: ='5. 케미컬상업'!U8 -> 35.40628 | AB24: =SUM(X24:AA24) -> 118.34209 | AC24: ='5. 케미컬상업'!V8 -> 118.34209 | AD24: ='5. 케미컬상업'!W8 -> 118.34209 | AE24: ='5. 케미컬상업'!X8 -> 118.34209
G25: =SUM(G23:G24) -> 3.1001795 | H25: =SUM(H23:H24) -> 12.083621 | I25: =SUM(I23:I24) -> 9.439308 | J25: =SUM(J23:J24) -> 24.623108 | K25: =SUM(K23:K24) -> 12.161448 | L25: =SUM(L23:L24) -> 17.972514 | M25: =SUM(M23:M24) -> 3.0841335 | N25: =SUM(N23:N24) -> 33.218096 | ... AE25: =SUM(AE23:AE24) -> 188.94023
D26: CMO상업_위임형 | G26: ='5. 케미컬상업'!E10 -> 0.17044833 | H26: ='5. 케미컬상업'!F10 -> 0.17044833 | I26: ='5. 케미컬상업'!G10 -> 0.17044833 | J26: =SUM(G26:I26) -> 0.511345 | K26: ='5. 케미컬상업'!H10 -> 0.17044833 | L26: ='5. 케미컬상업'!I10 -> 0.17044833 | M26: ='5. 케미컬상업'!J10 -> 0.17044833 | N26: =SUM(K26:M26) -> 0.511345 | O26: ='5. 케미컬상업'!K10 -> 0.17044833 | P26: ='5. 케미컬상업'!L10 -> 0.17044833 | Q26: ='5. 케미컬상업'!M10 -> 0.17044833 | R26: =SUM(O26:Q26) -> 0.511345 | S26: ='5. 케미컬상업'!N10 -> 0.17044833 | T26: ='5. 케미컬상업'!O10 -> 0.17044833 | U26: ='5. 케미컬상업'!P10 -> 0.17044833 | V26: =SUM(S26:U26) -> 0.511345 | W26: =+J26+N26+R26+V26 -> 2.04538 | X26: ='5. 케미컬상업'!R10 -> 2.04538 | Y26: ='5. 케미컬상업'!S10 -> 1.5298675 | Z26: ='5. 케미컬상업'!T10 -> 1.5298675 | AA26: ='5. 케미컬상업'!U10 -> 1.5298675 | AB26: =SUM(X26:AA26) -> 6.6349825 | AC26: ='5. 케미컬상업'!V10 -> 1.5298675 | AD26: ='5. 케미컬상업'!W10 -> 6.11947 | AE26: ='5. 케미컬상업'!X10 -> 12.233065
F27: 141.72946 | G27: =SUM(G25:G26) -> 3.2706278 | H27: =SUM(H25:H26) -> 12.254069 | I27: =SUM(I25:I26) -> 9.6097563 | J27: =SUM(J25:J26) -> 25.134453 | K27: =SUM(K25:K26) -> 12.331896 | L27: =SUM(L25:L26) -> 18.142962 | M27: =SUM(M25:M26) -> 3.2545818 | N27: =SUM(N25:N26) -> 33.729441 | ... AE27: =SUM(AE25:AE26) -> 201.17329
C28: 개발용역 | D28: 케미컬 | E28: CMO용역 | F28: 0.67 | G28: =SUMIF('1. 26-30년 개발용역'!$B$8:$B$14,요약!$E28,'1. 26-30년 개발용역'!D$8:D$14)/10^8 -> 0 | H28: =SUMIF('1. 26-30년 개발용역'!$B$8:$B$14,요약!$E28,'1. 26-30년 개발용역'!E$8:E$14)/10^8 -> 0 | I28: =SUMIF('1. 26-30년 개발용역'!$B$8:$B$14,요약!$E28,'1. 26-30년 개발용역'!F$8:F$14)/10^8 -> 0 | J28: =SUM(G28:I28) -> 0 | K28: =SUMIF('1. 26-30년 개발용역'!$B$8:$B$14,요약!$E28,'1. 26-30년 개발용역'!G$8:G$14)/10^8 -> 0 | L28: =SUMIF('1. 26-30년 개발용역'!$B$8:$B$14,요약!$E28,'1. 26-30년 개발용역'!H$8:H$14)/10^8 -> 0 | M28: =SUMIF('1. 26-30년 개발용역'!$B$8:$B$14,요약!$E28,'1. 26-30년 개발용역'!I$8:I$14)/10^8 -> 0 | N28: =SUM(K28:M28) -> 0 | O28: =SUMIF('1. 26-30년 개발용역'!$B$8:$B$14,요약!$E28,'1. 26-30년 개발용역'!J$8:J$14)/10^8 -> 0 | P28: =SUMIF('1. 26-30년 개발용역'!$B$8:$B$14,요약!$E28,'1. 26-30년 개발용역'!K$8:K$14)/10^8 -> 0 | Q28: =SUMIF('1. 26-30년 개발용역'!$B$8:$B$14,요약!$E28,'1. 26-30년 개발용역'!L$8:L$14)/10^8 -> 0 | R28: =SUM(O28:Q28) -> 0 | S28: =SUMIF('1. 26-30년 개발용역'!$B$8:$B$14,요약!$E28,'1. 26-30년 개발용역'!M$8:M$14)/10^8 -> 0 | T28: =SUMIF('1. 26-30년 개발용역'!$B$8:$B$14,요약!$E28,'1. 26-30년 개발용역'!N$8:N$14)/10^8 -> 0 | U28: =SUMIF('1. 26-30년 개발용역'!$B$8:$B$14,요약!$E28,'1. 26-30년 개발용역'!O$8:O$14)/10^8 -> 0 | V28: =SUM(S28:U28) -> 0 | W28: =+J28+N28+R28+V28 -> 0 | X28: =SUMIF('1. 26-30년 개발용역'!$B$24:$B$30,요약!$E28,'1. 26-30년 개발용역'!R$24:R$30)/10^8 -> 0 | Y28: =SUMIF('1. 26-30년 개발용역'!$B$24:$B$30,요약!$E28,'1. 26-30년 개발용역'!S$24:S$30)/10^8 -> 0 | Z28: =SUMIF('1. 26-30년 개발용역'!$B$24:$B$30,요약!$E28,'1. 26-30년 개발용역'!T$24:T$30)/10^8 -> 0 | AA28: =SUMIF('1. 26-30년 개발용역'!$B$24:$B$30,요약!$E28,'1. 26-30년 개발용역'!U$24:U$30)/10^8 -> 0 | AB28: =SUM(X28:AA28) -> 0 | AC28: =SUMIF('1. 26-30년 개발용역'!$B$40:$B$46,요약!$E28,'1. 26-30년 개발용역'!P$40:P$46)/10^8 -> 0 | AD28: =SUMIF('1. 26-30년 개발용역'!$B$56:$B$62,요약!$E28,'1. 26-30년 개발용역'!P$56:P$62)/10^8 -> 0 | AE28: =SUMIF('1. 26-30년 개발용역'!$B$72:$B$78,요약!$E28,'1. 26-30년 개발용역'!P$56:P$62)/10^8 -> 0
E29: 내재화용역 | F29: 12.8925 | G29: =SUMIF('1. 26-30년 개발용역'!$B$8:$B$14,요약!$E29,'1. 26-30년 개발용역'!D$8:D$14)/10^8 -> 1.40625 | H29: =SUMIF('1. 26-30년 개발용역'!$B$8:$B$14,요약!$E29,'1. 26-30년 개발용역'!E$8:E$14)/10^8 -> 0.46875 | I29: =SUMIF('1. 26-30년 개발용역'!$B$8:$B$14,요약!$E29,'1. 26-30년 개발용역'!F$8:F$14)/10^8 -> 2.8125 | J29: =SUM(G29:I29) -> 4.6875 | K29: =SUMIF('1. 26-30년 개발용역'!$B$8:$B$14,요약!$E29,'1. 26-30년 개발용역'!G$8:G$14)/10^8 -> 0.46875 | L29: =SUMIF('1. 26-30년 개발용역'!$B$8:$B$14,요약!$E29,'1. 26-30년 개발용역'!H$8:H$14)/10^8 -> 0 | M29: =SUMIF('1. 26-30년 개발용역'!$B$8:$B$14,요약!$E29,'1. 26-30년 개발용역'!I$8:I$14)/10^8 -> 0 | N29: =SUM(K29:M29) -> 0.46875 | O29: =SUMIF('1. 26-30년 개발용역'!$B$8:$B$14,요약!$E29,'1. 26-30년 개발용역'!J$8:J$14)/10^8 -> 0 | P29: =SUMIF('1. 26-30년 개발용역'!$B$8:$B$14,요약!$E29,'1. 26-30년 개발용역'!K$8:K$14)/10^8 -> 0 | Q29: =SUMIF('1. 26-30년 개발용역'!$B$8:$B$14,요약!$E29,'1. 26-30년 개발용역'!L$8:L$14)/10^8 -> 0 | R29: =SUM(O29:Q29) -> 0 | S29: =SUMIF('1. 26-30년 개발용역'!$B$8:$B$14,요약!$E29,'1. 26-30년 개발용역'!M$8:M$14)/10^8 -> 0.9375 | T29: =SUMIF('1. 26-30년 개발용역'!$B$8:$B$14,요약!$E29,'1. 26-30년 개발용역'!N$8:N$14)/10^8 -> 0 | U29: =SUMIF('1. 26-30년 개발용역'!$B$8:$B$14,요약!$E29,'1. 26-30년 개발용역'!O$8:O$14)/10^8 -> 0 | V29: =SUM(S29:U29) -> 0.9375 | W29: =+J29+N29+R29+V29 -> 6.09375 | X29: =SUMIF('1. 26-30년 개발용역'!$B$24:$B$30,요약!$E29,'1. 26-30년 개발용역'!R$24:R$30)/10^8 -> 0 | Y29: =SUMIF('1. 26-30년 개발용역'!$B$24:$B$30,요약!$E29,'1. 26-30년 개발용역'!S$24:S$30)/10^8 -> 0 | Z29: =SUMIF('1. 26-30년 개발용역'!$B$24:$B$30,요약!$E29,'1. 26-30년 개발용역'!T$24:T$30)/10^8 -> 0.46875 | AA29: =SUMIF('1. 26-30년 개발용역'!$B$24:$B$30,요약!$E29,'1. 26-30년 개발용역'!U$24:U$30)/10^8 -> 0.46875 | AB29: =SUM(X29:AA29) -> 0.9375 | AC29: =SUMIF('1. 26-30년 개발용역'!$B$40:$B$46,요약!$E29,'1. 26-30년 개발용역'!P$40:P$46)/10^8 -> 0 | AD29: =SUMIF('1. 26-30년 개발용역'!$B$56:$B$62,요약!$E29,'1. 26-30년 개발용역'!P$56:P$62)/10^8 -> 0 | AE29: =SUMIF('1. 26-30년 개발용역'!$B$72:$B$78,요약!$E29,'1. 26-30년 개발용역'!P$56:P$62)/10^8 -> 0
E30: LCM용역 | F30: 13.248125 | G30: =SUMIF('1. 26-30년 개발용역'!$B$8:$B$14,요약!$E30,'1. 26-30년 개발용역'!D$8:D$14)/10^8 -> 0 | H30: =SUMIF('1. 26-30년 개발용역'!$B$8:$B$14,요약!$E30,'1. 26-30년 개발용역'!E$8:E$14)/10^8 -> 0.46875 | I30: =SUMIF('1. 26-30년 개발용역'!$B$8:$B$14,요약!$E30,'1. 26-30년 개발용역'!F$8:F$14)/10^8 -> 1.31875 | J30: =SUM(G30:I30) -> 1.7875 | K30: =SUMIF('1. 26-30년 개발용역'!$B$8:$B$14,요약!$E30,'1. 26-30년 개발용역'!G$8:G$14)/10^8 -> 2.03 | L30: =SUMIF('1. 26-30년 개발용역'!$B$8:$B$14,요약!$E30,'1. 26-30년 개발용역'!H$8:H$14)/10^8 -> 1.71875 | M30: =SUMIF('1. 26-30년 개발용역'!$B$8:$B$14,요약!$E30,'1. 26-30년 개발용역'!I$8:I$14)/10^8 -> 1.7375 | N30: =SUM(K30:M30) -> 5.48625 | O30: =SUMIF('1. 26-30년 개발용역'!$B$8:$B$14,요약!$E30,'1. 26-30년 개발용역'!J$8:J$14)/10^8 -> 0.85 | P30: =SUMIF('1. 26-30년 개발용역'!$B$8:$B$14,요약!$E30,'1. 26-30년 개발용역'!K$8:K$14)/10^8 -> 0.46875 | Q30: =SUMIF('1. 26-30년 개발용역'!$B$8:$B$14,요약!$E30,'1. 26-30년 개발용역'!L$8:L$14)/10^8 -> 0.46875 | R30: =SUM(O30:Q30) -> 1.7875 | S30: =SUMIF('1. 26-30년 개발용역'!$B$8:$B$14,요약!$E30,'1. 26-30년 개발용역'!M$8:M$14)/10^8 -> 0.85 | T30: =SUMIF('1. 26-30년 개발용역'!$B$8:$B$14,요약!$E30,'1. 26-30년 개발용역'!N$8:N$14)/10^8 -> 1.31875 | U30: =SUMIF('1. 26-30년 개발용역'!$B$8:$B$14,요약!$E30,'1. 26-30년 개발용역'!O$8:O$14)/10^8 -> 0 | V30: =SUM(S30:U30) -> 2.16875 | W30: =+J30+N30+R30+V30 -> 11.23 | X30: =SUMIF('1. 26-30년 개발용역'!$B$24:$B$30,요약!$E30,'1. 26-30년 개발용역'!R$24:R$30)/10^8 -> 0.9375 | Y30: =SUMIF('1. 26-30년 개발용역'!$B$24:$B$30,요약!$E30,'1. 26-30년 개발용역'!S$24:S$30)/10^8 -> 0.9375 | Z30: =SUMIF('1. 26-30년 개발용역'!$B$24:$B$30,요약!$E30,'1. 26-30년 개발용역'!T$24:T$30)/10^8 -> 0.9375 | AA30: =SUMIF('1. 26-30년 개발용역'!$B$24:$B$30,요약!$E30,'1. 26-30년 개발용역'!U$24:U$30)/10^8 -> 0.46875 | AB30: =SUM(X30:AA30) -> 3.28125 | AC30: =SUMIF('1. 26-30년 개발용역'!$B$40:$B$46,요약!$E30,'1. 26-30년 개발용역'!P$40:P$46)/10^8 -> 0.9375 | AD30: =SUMIF('1. 26-30년 개발용역'!$B$56:$B$62,요약!$E30,'1. 26-30년 개발용역'!P$56:P$62)/10^8 -> 0.9375 | AE30: =SUMIF('1. 26-30년 개발용역'!$B$72:$B$78,요약!$E30,'1. 26-30년 개발용역'!P$56:P$62)/10^8 -> 0.9375
