Workbook
Name _: #N/A
Name _____________________________BRD1: #REF!
Name _____________________________BRD2: #REF!
Name _____________________________BRD3: #REF!
Name _____________________________BRD4: #REF!
Name _____________________________BRD5: #REF!
Name _____________________________BRD6: #REF!
Name _____________________________BRD7: #REF!
Name _____________________________INT1: #REF!
Name _____________________________INT2: #REF!
Name _____________________________INT3: #REF!
Name _____________________________INT4: #REF!
Name _____________________________INT5: #REF!
Name _____________________________INT6: #REF!
Name _____________________________INT7: #REF!
Name _____________________________LIC1: #REF!
Name _____________________________LIC2: #REF!
Name _____________________________LIC3: #REF!
Name _____________________________LIC4: #REF!
Name _____________________________LIC5: #REF!
Name _____________________________LIC6: #REF!
Name _____________________________LIC7: #REF!
Name _____________________________PG1: #REF!
Name _____________________________PG11: #REF!
Name _____________________________PG13: #REF!
Name _____________________________PG17: #REF!
Name _____________________________PG2: #REF!
Name _____________________________PG3: #REF!
Name _____________________________PG4: #REF!
Name _____________________________PG5: #REF!
Name _____________________________PG6: #REF!
Name _____________________________PG7: #REF!
Name _____________________________PG9: #REF!
Name _____________________________SUM25: #REF!
Name ____________________________BRD1: #REF!
Name ____________________________BRD2: #REF!
Name ____________________________BRD3: #REF!
Name ____________________________BRD4: #REF!
Name ____________________________BRD5: #REF!
Name ____________________________BRD6: #REF!
Name ____________________________BRD7: #REF!
Name ____________________________INT1: #REF!
Name ____________________________INT2: #REF!
Name ____________________________INT3: #REF!
Name ____________________________INT4: #REF!
Name ____________________________INT5: #REF!
Name ____________________________INT6: #REF!
Name ____________________________INT7: #REF!
Name ____________________________LIC1: #REF!
Name ____________________________LIC2: #REF!
Name ____________________________LIC3: #REF!
Name ____________________________LIC4: #REF!
Name ____________________________LIC5: #REF!
Name ____________________________LIC6: #REF!
Name ____________________________LIC7: #REF!
Name ____________________________PG1: #REF!
Name ____________________________PG11: #REF!
Name ____________________________PG13: #REF!
Name ____________________________PG17: #REF!
Name ____________________________PG2: #REF!

Sheet 요약(보고)
A1: 26년 CMO 매출 예상실적
Y2: 2026.02.26
A3: ■ 1분기 매출
F4: 1분기 | J4: 1월 | N4: 2월 | R4: 3월 | Y4: 단위 : 억원
A5: 구분 | D5: 25년 실적 | E5: 26년 목표 | F5: 25년 1분기 누계 | J5: 1분기 | V5: 1분기 소계 | Z5: 26년 예상 실적
J6: 1월 | N6: 2월 | R6: 3월
F7: 25년 실적 | G7: 사업 계획 | H7: 실적 | I7: 차이 | J7: 25년 실적 | K7: 사업 계획 | L7: 실적 | M7: 차이 | N7: 25년 실적 | O7: 사업 계획 | P7: 실적 | Q7: 차이 | R7: 25년 실적 | S7: 사업 계획 | T7: 실적 | U7: 차이 | V7: 25년 실적 | W7: 사업 계획 | X7: 실적 | Y7: 차이 | Z7: 25년 실적 | AA7: 사업 계획 | AB7: 실적 | AC7: 차이
B8: CMO 합계 | D8: =SUM(D15,D12,D9) -> 1392.7058 | E8: =AA8 -> 1559.0706 | F8: =V8 -> 275.49898 | G8: =W8 -> 313.38771 | H8: =X8 -> 313.40175 | I8: =Y8 -> 0.014034668 | J8: =J9+J12+J15 -> 112.83448 | K8: =K9+K12+K15 -> 100.91695 | L8: =L9+L12+L15 -> 101.87285 | M8: =L8-K8 -> 0.9559079 | N8: =N9+N12+N15 -> 67.616613 | O8: =O9+O12+O15 -> 107.7245 | P8: =P9+P12+P15 -> 116.3254 | Q8: =P8-O8 -> 8.600901 | R8: =R9+R12+R15 -> 95.047888 | S8: =S9+S12+S15 -> 104.74626 | T8: =T9+T12+T15 -> 95.20349 | U8: =T8-S8 -> -9.5427742 | V8: =V9+V12+V15 -> 275.49898 | W8: =W9+W12+W15 -> 313.38771 | X8: =X9+X12+X15 -> 313.40175 | Y8: =X8-W8 -> 0.014034668 | Z8: =Z9+Z12+Z15 -> 1393.0161 | AA8: =AA9+AA12+AA15 -> 1559.0706 | AB8: =AB9+AB12+AB15 -> 1559.0847 | AC8: =AB8-AA8 -> 0.014034668 | AE8: 24년
B9: 케미컬 상업 | D9: =SUM(D10:D11) -> 152.99419 | E9: =AA9 -> 170.99974 | F9: =V9 -> 17.979459 | G9: =W9 -> 25.134453 | H9: =X9 -> 24.999197 | I9: =Y9 -> -0.13525591 | J9: =SUM(J10:J11) -> 3.0051884 | K9: =SUM(K10:K11) -> 3.2706278 | L9: =SUM(L10:L11) -> 3.1851236 | M9: =SUM(M10:M11) -> -0.085504183 | N9: =SUM(N10:N11) -> 12.609455 | O9: =SUM(O10:O11) -> 12.254069 | P9: =SUM(P10:P11) -> 9.8442169 | Q9: =SUM(Q10:Q11) -> -2.409852 | ... AC9: =SUM(AC10:AC11) -> -0.13525591 | AE9: 25년
C10: 내재화 | D10: 152.99419 | E10: =AA10 -> 168.95436 | F10: =SUMIFS('상세 자료 작성'!$I:$I,'상세 자료 작성'!$C:$C,'요약(보고)'!$C10,'상세 자료 작성'!$A:$A,'요약(보고)'!$AE$9,'상세 자료 작성'!$B:$B,'요약(보고)'!$F$4)/10^8 -> 17.979459 | G10: =SUMIFS('상세 자료 작성'!$J:$J,'상세 자료 작성'!$C:$C,'요약(보고)'!$C10,'상세 자료 작성'!$A:$A,$AE$11,'상세 자료 작성'!$B:$B,'요약(보고)'!$F$4)/10^8 -> 24.623108 | H10: =SUMIFS('상세 자료 작성'!$K:$K,'상세 자료 작성'!$C:$C,'요약(보고)'!$C10,'상세 자료 작성'!$A:$A,$AE$11,'상세 자료 작성'!$B:$B,'요약(보고)'!$F$4)/10^8 -> 24.658301 | I10: =Y10 -> 0.035192421 | J10: =SUMIFS('상세 자료 작성'!$I:$I,'상세 자료 작성'!$C:$C,'요약(보고)'!$C10,'상세 자료 작성'!$A:$A,'요약(보고)'!$AE$9,'상세 자료 작성'!$D:$D,$J$4)/10^8 -> 3.0051884 | K10: =SUMIFS('상세 자료 작성'!$J:$J,'상세 자료 작성'!$C:$C,'요약(보고)'!$C10,'상세 자료 작성'!$A:$A,$AE$11,'상세 자료 작성'!$D:$D,'요약(보고)'!$J$4)/10^8 -> 3.1001795 | L10: =SUMIFS('상세 자료 작성'!$K:$K,'상세 자료 작성'!$C:$C,'요약(보고)'!$C10,'상세 자료 작성'!$A:$A,$AE$11,'상세 자료 작성'!$D:$D,$J$4)/10^8 -> 3.1851236 | M10: =L10-K10 -> 0.08494415 | N10: =SUMIFS('상세 자료 작성'!$I:$I,'상세 자료 작성'!$C:$C,'요약(보고)'!$C10,'상세 자료 작성'!$A:$A,'요약(보고)'!$AE$9,'상세 자료 작성'!$D:$D,$N$4)/10^8 -> 12.609455 | O10: =SUMIFS('상세 자료 작성'!$J:$J,'상세 자료 작성'!$C:$C,'요약(보고)'!$C10,'상세 자료 작성'!$A:$A,$AE$11,'상세 자료 작성'!$D:$D,$N$4)/10^8 -> 12.083621 | P10: =SUMIFS('상세 자료 작성'!$K:$K,'상세 자료 작성'!$C:$C,'요약(보고)'!$C10,'상세 자료 작성'!$A:$A,$AE$11,'상세 자료 작성'!$D:$D,$N$4)/10^8 -> 9.6737686 | Q10: =P10-O10 -> -2.409852 | R10: =SUMIFS('상세 자료 작성'!$I:$I,'상세 자료 작성'!$C:$C,'요약(보고)'!$C10,'상세 자료 작성'!$A:$A,'요약(보고)'!$AE$9,'상세 자료 작성'!$D:$D,$R$4)/10^8 -> 2.3648161 | S10: =SUMIFS('상세 자료 작성'!$J:$J,'상세 자료 작성'!$C:$C,'요약(보고)'!$C10,'상세 자료 작성'!$A:$A,$AE$11,'상세 자료 작성'!$D:$D,$R$4)/10^8 -> 9.439308 | T10: =SUMIFS('상세 자료 작성'!$K:$K,'상세 자료 작성'!$C:$C,'요약(보고)'!$C10,'상세 자료 작성'!$A:$A,$AE$11,'상세 자료 작성'!$D:$D,$R$4)/10^8 -> 11.799408 | U10: =T10-S10 -> 2.3601003 | V10: =R10+J10+N10 -> 17.979459 | W10: =S10+K10+O10 -> 24.623108 | X10: =T10+L10+P10 -> 24.658301 | Y10: =X10-W10 -> 0.035192421 | Z10: =SUMIFS('상세 자료 작성'!$I:$I,'상세 자료 작성'!$C:$C,'요약(보고)'!$C10,'상세 자료 작성'!$A:$A,'요약(보고)'!$AE$9)/10^8 -> 152.99419 | AA10: =SUMIFS('상세 자료 작성'!$J:$J,'상세 자료 작성'!$C:$C,'요약(보고)'!$C10,'상세 자료 작성'!$A:$A,'요약(보고)'!$AE$11)/10^8 -> 168.95436 | AB10: =SUMIFS('상세 자료 작성'!$K:$K,'상세 자료 작성'!$C:$C,'요약(보고)'!$C10,'상세 자료 작성'!$A:$A,'요약(보고)'!$AE$11)/10^8 -> 168.98955 | AC10: =AB10-AA10 -> 0.035192421
C11: 기타(위임형 등) | D11: 0 | E11: =AA11 -> 2.04538 | F11: =SUMIFS('상세 자료 작성'!$I:$I,'상세 자료 작성'!$C:$C,'요약(보고)'!$C11,'상세 자료 작성'!$A:$A,'요약(보고)'!$AE$9,'상세 자료 작성'!$B:$B,'요약(보고)'!$F$4)/10^8 -> 0 | G11: =SUMIFS('상세 자료 작성'!$J:$J,'상세 자료 작성'!$C:$C,'요약(보고)'!$C11,'상세 자료 작성'!$A:$A,$AE$11,'상세 자료 작성'!$B:$B,'요약(보고)'!$F$4)/10^8 -> 0.511345 | H11: =SUMIFS('상세 자료 작성'!$K:$K,'상세 자료 작성'!$C:$C,'요약(보고)'!$C11,'상세 자료 작성'!$A:$A,$AE$11,'상세 자료 작성'!$B:$B,'요약(보고)'!$F$4)/10^8 -> 0.34089667 | I11: =Y11 -> -0.17044833 | J11: =SUMIFS('상세 자료 작성'!$I:$I,'상세 자료 작성'!$C:$C,'요약(보고)'!$C11,'상세 자료 작성'!$A:$A,'요약(보고)'!$AE$9,'상세 자료 작성'!$D:$D,$J$4)/10^8 -> 0 | K11: =SUMIFS('상세 자료 작성'!$J:$J,'상세 자료 작성'!$C:$C,'요약(보고)'!$C11,'상세 자료 작성'!$A:$A,$AE$11,'상세 자료 작성'!$D:$D,'요약(보고)'!$J$4)/10^8 -> 0.17044833 | L11: =SUMIFS('상세 자료 작성'!$K:$K,'상세 자료 작성'!$C:$C,'요약(보고)'!$C11,'상세 자료 작성'!$A:$A,$AE$11,'상세 자료 작성'!$D:$D,$J$4)/10^8 -> 0 | M11: =L11-K11 -> -0.17044833 | N11: =SUMIFS('상세 자료 작성'!$I:$I,'상세 자료 작성'!$C:$C,'요약(보고)'!$C11,'상세 자료 작성'!$A:$A,'요약(보고)'!$AE$9,'상세 자료 작성'!$D:$D,$N$4)/10^8 -> 0 | O11: =SUMIFS('상세 자료 작성'!$J:$J,'상세 자료 작성'!$C:$C,'요약(보고)'!$C11,'상세 자료 작성'!$A:$A,$AE$11,'상세 자료 작성'!$D:$D,$N$4)/10^8 -> 0.17044833 | P11: =SUMIFS('상세 자료 작성'!$K:$K,'상세 자료 작성'!$C:$C,'요약(보고)'!$C11,'상세 자료 작성'!$A:$A,$AE$11,'상세 자료 작성'!$D:$D,$N$4)/10^8 -> 0.17044833 | Q11: =P11-O11 -> 0 | R11: =SUMIFS('상세 자료 작성'!$I:$I,'상세 자료 작성'!$C:$C,'요약(보고)'!$C11,'상세 자료 작성'!$A:$A,'요약(보고)'!$AE$9,'상세 자료 작성'!$D:$D,$R$4)/10^8 -> 0 | S11: =SUMIFS('상세 자료 작성'!$J:$J,'상세 자료 작성'!$C:$C,'요약(보고)'!$C11,'상세 자료 작성'!$A:$A,$AE$11,'상세 자료 작성'!$D:$D,$R$4)/10^8 -> 0.17044833 | T11: =SUMIFS('상세 자료 작성'!$K:$K,'상세 자료 작성'!$C:$C,'요약(보고)'!$C11,'상세 자료 작성'!$A:$A,$AE$11,'상세 자료 작성'!$D:$D,$R$4)/10^8 -> 0.17044833 | U11: =T11-S11 -> 0 | V11: =R11+J11+N11 -> 0 | W11: =S11+K11+O11 -> 0.511345 | X11: =T11+L11+P11 -> 0.34089667 | Y11: =X11-W11 -> -0.17044833 | Z11: =SUMIFS('상세 자료 작성'!$I:$I,'상세 자료 작성'!$C:$C,'요약(보고)'!$C11,'상세 자료 작성'!$A:$A,'요약(보고)'!$AE$9)/10^8 -> 0 | AA11: =SUMIFS('상세 자료 작성'!$J:$J,'상세 자료 작성'!$C:$C,'요약(보고)'!$C11,'상세 자료 작성'!$A:$A,'요약(보고)'!$AE$11)/10^8 -> 2.04538 | AB11: =SUMIFS('상세 자료 작성'!$K:$K,'상세 자료 작성'!$C:$C,'요약(보고)'!$C11,'상세 자료 작성'!$A:$A,'요약(보고)'!$AE$11)/10^8 -> 1.8749317 | AC11: =AB11-AA11 -> -0.17044833 | AE11: 26년
B12: 바이오 상업 | D12: =SUM(D13:D14) -> 1088.9227 | E12: =AA12 -> 1191.1256 | F12: =V12 -> 203.6367 | G12: =W12 -> 246.45126 | H12: =X12 -> 248.86353 | I12: =Y12 -> 2.4122721 | J12: =SUM(J13:J14) -> 76.029623 | K12: =SUM(K13:K14) -> 71.643068 | L12: =SUM(L13:L14) -> 71.637462 | M12: =SUM(M13:M14) -> -0.0056064 | N12: =SUM(N13:N14) -> 54.348994 | O12: =SUM(O13:O14) -> 90.822934 | P12: =SUM(P13:P14) -> 102.46369 | Q12: =SUM(Q13:Q14) -> 11.640753 | ... AC12: =SUM(AC13:AC14) -> 2.4122721
C13: PFS | D13: 1041.7819 | E13: =AA13 -> 1143.4515 | F13: =SUMIFS('상세 자료 작성'!$I:$I,'상세 자료 작성'!$C:$C,'요약(보고)'!$C13,'상세 자료 작성'!$A:$A,'요약(보고)'!$AE$9,'상세 자료 작성'!$B:$B,'요약(보고)'!$F$4)/10^8 -> 189.04806 | G13: =SUMIFS('상세 자료 작성'!$J:$J,'상세 자료 작성'!$C:$C,'요약(보고)'!$C13,'상세 자료 작성'!$A:$A,$AE$11,'상세 자료 작성'!$B:$B,'요약(보고)'!$F$4)/10^8 -> 238.39926 | H13: =SUMIFS('상세 자료 작성'!$K:$K,'상세 자료 작성'!$C:$C,'요약(보고)'!$C13,'상세 자료 작성'!$A:$A,$AE$11,'상세 자료 작성'!$B:$B,'요약(보고)'!$F$4)/10^8 -> 240.7224 | I13: =Y13 -> 2.3231443 | J13: =SUMIFS('상세 자료 작성'!$I:$I,'상세 자료 작성'!$C:$C,'요약(보고)'!$C13,'상세 자료 작성'!$A:$A,'요약(보고)'!$AE$9,'상세 자료 작성'!$D:$D,$J$4)/10^8 -> 69.842789 | K13: =SUMIFS('상세 자료 작성'!$J:$J,'상세 자료 작성'!$C:$C,'요약(보고)'!$C13,'상세 자료 작성'!$A:$A,$AE$11,'상세 자료 작성'!$D:$D,'요약(보고)'!$J$4)/10^8 -> 68.990503 | L13: =SUMIFS('상세 자료 작성'!$K:$K,'상세 자료 작성'!$C:$C,'요약(보고)'!$C13,'상세 자료 작성'!$A:$A,$AE$11,'상세 자료 작성'!$D:$D,$J$4)/10^8 -> 69.064124 | M13: =L13-K13 -> 0.073621 | N13: =SUMIFS('상세 자료 작성'!$I:$I,'상세 자료 작성'!$C:$C,'요약(보고)'!$C13,'상세 자료 작성'!$A:$A,'요약(보고)'!$AE$9,'상세 자료 작성'!$D:$D,$N$4)/10^8 -> 49.969541 | O13: =SUMIFS('상세 자료 작성'!$J:$J,'상세 자료 작성'!$C:$C,'요약(보고)'!$C13,'상세 자료 작성'!$A:$A,$AE$11,'상세 자료 작성'!$D:$D,$N$4)/10^8 -> 88.077118 | P13: =SUMIFS('상세 자료 작성'!$K:$K,'상세 자료 작성'!$C:$C,'요약(보고)'!$C13,'상세 자료 작성'!$A:$A,$AE$11,'상세 자료 작성'!$D:$D,$N$4)/10^8 -> 99.549516 | Q13: =P13-O13 -> 11.472398 | R13: =SUMIFS('상세 자료 작성'!$I:$I,'상세 자료 작성'!$C:$C,'요약(보고)'!$C13,'상세 자료 작성'!$A:$A,'요약(보고)'!$AE$9,'상세 자료 작성'!$D:$D,$R$4)/10^8 -> 69.235728 | S13: =SUMIFS('상세 자료 작성'!$J:$J,'상세 자료 작성'!$C:$C,'요약(보고)'!$C13,'상세 자료 작성'!$A:$A,$AE$11,'상세 자료 작성'!$D:$D,$R$4)/10^8 -> 81.331637 | T13: =SUMIFS('상세 자료 작성'!$K:$K,'상세 자료 작성'!$C:$C,'요약(보고)'!$C13,'상세 자료 작성'!$A:$A,$AE$11,'상세 자료 작성'!$D:$D,$R$4)/10^8 -> 72.108763 | U13: =T13-S13 -> -9.2228745 | V13: =R13+J13+N13 -> 189.04806 | W13: =S13+K13+O13 -> 238.39926 | X13: =T13+L13+P13 -> 240.7224 | Y13: =X13-W13 -> 2.3231443 | Z13: =SUMIFS('상세 자료 작성'!$I:$I,'상세 자료 작성'!$C:$C,'요약(보고)'!$C13,'상세 자료 작성'!$A:$A,'요약(보고)'!$AE$9)/10^8 -> 1041.7819 | AA13: =SUMIFS('상세 자료 작성'!$J:$J,'상세 자료 작성'!$C:$C,'요약(보고)'!$C13,'상세 자료 작성'!$A:$A,'요약(보고)'!$AE$11)/10^8 -> 1143.4515 | AB13: =SUMIFS('상세 자료 작성'!$K:$K,'상세 자료 작성'!$C:$C,'요약(보고)'!$C13,'상세 자료 작성'!$A:$A,'요약(보고)'!$AE$11)/10^8 -> 1145.7746 | AC13: =AB13-AA13 -> 2.3231443
C14: L&P | D14: 47.140793 | E14: =AA14 -> 47.674149 | F14: =SUMIFS('상세 자료 작성'!$I:$I,'상세 자료 작성'!$C:$C,'요약(보고)'!$C14,'상세 자료 작성'!$A:$A,'요약(보고)'!$AE$9,'상세 자료 작성'!$B:$B,'요약(보고)'!$F$4)/10^8 -> 14.588646 | G14: =SUMIFS('상세 자료 작성'!$J:$J,'상세 자료 작성'!$C:$C,'요약(보고)'!$C14,'상세 자료 작성'!$A:$A,$AE$11,'상세 자료 작성'!$B:$B,'요약(보고)'!$F$4)/10^8 -> 8.0520014 | H14: =SUMIFS('상세 자료 작성'!$K:$K,'상세 자료 작성'!$C:$C,'요약(보고)'!$C14,'상세 자료 작성'!$A:$A,$AE$11,'상세 자료 작성'!$B:$B,'요약(보고)'!$F$4)/10^8 -> 8.1411292 | I14: =Y14 -> 0.0891278 | J14: =SUMIFS('상세 자료 작성'!$I:$I,'상세 자료 작성'!$C:$C,'요약(보고)'!$C14,'상세 자료 작성'!$A:$A,'요약(보고)'!$AE$9,'상세 자료 작성'!$D:$D,$J$4)/10^8 -> 6.1868338 | K14: =SUMIFS('상세 자료 작성'!$J:$J,'상세 자료 작성'!$C:$C,'요약(보고)'!$C14,'상세 자료 작성'!$A:$A,$AE$11,'상세 자료 작성'!$D:$D,'요약(보고)'!$J$4)/10^8 -> 2.652565 | L14: =SUMIFS('상세 자료 작성'!$K:$K,'상세 자료 작성'!$C:$C,'요약(보고)'!$C14,'상세 자료 작성'!$A:$A,$AE$11,'상세 자료 작성'!$D:$D,$J$4)/10^8 -> 2.5733376 | M14: =L14-K14 -> -0.0792274 | N14: =SUMIFS('상세 자료 작성'!$I:$I,'상세 자료 작성'!$C:$C,'요약(보고)'!$C14,'상세 자료 작성'!$A:$A,'요약(보고)'!$AE$9,'상세 자료 작성'!$D:$D,$N$4)/10^8 -> 4.3794528 | O14: =SUMIFS('상세 자료 작성'!$J:$J,'상세 자료 작성'!$C:$C,'요약(보고)'!$C14,'상세 자료 작성'!$A:$A,$AE$11,'상세 자료 작성'!$D:$D,$N$4)/10^8 -> 2.7458164 | P14: =SUMIFS('상세 자료 작성'!$K:$K,'상세 자료 작성'!$C:$C,'요약(보고)'!$C14,'상세 자료 작성'!$A:$A,$AE$11,'상세 자료 작성'!$D:$D,$N$4)/10^8 -> 2.9141716 | Q14: =P14-O14 -> 0.1683552 | R14: =SUMIFS('상세 자료 작성'!$I:$I,'상세 자료 작성'!$C:$C,'요약(보고)'!$C14,'상세 자료 작성'!$A:$A,'요약(보고)'!$AE$9,'상세 자료 작성'!$D:$D,$R$4)/10^8 -> 4.0223598 | S14: =SUMIFS('상세 자료 작성'!$J:$J,'상세 자료 작성'!$C:$C,'요약(보고)'!$C14,'상세 자료 작성'!$A:$A,$AE$11,'상세 자료 작성'!$D:$D,$R$4)/10^8 -> 2.65362 | T14: =SUMIFS('상세 자료 작성'!$K:$K,'상세 자료 작성'!$C:$C,'요약(보고)'!$C14,'상세 자료 작성'!$A:$A,$AE$11,'상세 자료 작성'!$D:$D,$R$4)/10^8 -> 2.65362 | U14: =T14-S14 -> 0 | V14: =R14+J14+N14 -> 14.588646 | W14: =S14+K14+O14 -> 8.0520014 | X14: =T14+L14+P14 -> 8.1411292 | Y14: =X14-W14 -> 0.0891278 | Z14: =SUMIFS('상세 자료 작성'!$I:$I,'상세 자료 작성'!$C:$C,'요약(보고)'!$C14,'상세 자료 작성'!$A:$A,'요약(보고)'!$AE$9)/10^8 -> 48.130793 | AA14: =SUMIFS('상세 자료 작성'!$J:$J,'상세 자료 작성'!$C:$C,'요약(보고)'!$C14,'상세 자료 작성'!$A:$A,'요약(보고)'!$AE$11)/10^8 -> 47.674149 | AB14: =SUMIFS('상세 자료 작성'!$K:$K,'상세 자료 작성'!$C:$C,'요약(보고)'!$C14,'상세 자료 작성'!$A:$A,'요약(보고)'!$AE$11)/10^8 -> 47.763276 | AC14: =AB14-AA14 -> 0.0891278
B15: 개발 용역 | D15: =SUM(D16:D19) -> 150.78896 | E15: =AA15 -> 196.94525 | F15: =V15 -> 53.882818 | G15: =W15 -> 41.802 | H15: =X15 -> 39.539018 | I15: =Y15 -> -2.2629815 | J15: =SUM(J16:J19) -> 33.799671 | K15: =SUM(K16:K19) -> 26.00325 | L15: =SUM(L16:L19) -> 27.050268 | M15: =SUM(M16:M19) -> 1.0470185 | N15: =SUM(N16:N19) -> 0.65816414 | O15: =SUM(O16:O19) -> 4.6475 | P15: =SUM(P16:P19) -> 4.0175 | Q15: =SUM(Q16:Q19) -> -0.63 | ... AC15: =SUM(AC16:AC19) -> -2.2629815
C16: PFS 개발 | D16: 116.21935 | E16: =AA16 -> 179.7765 | F16: =SUMIFS('상세 자료 작성'!$I:$I,'상세 자료 작성'!$C:$C,'요약(보고)'!$C16,'상세 자료 작성'!$A:$A,'요약(보고)'!$AE$9,'상세 자료 작성'!$B:$B,'요약(보고)'!$F$4)/10^8 -> 42.27486 | G16: =SUMIFS('상세 자료 작성'!$J:$J,'상세 자료 작성'!$C:$C,'요약(보고)'!$C16,'상세 자료 작성'!$A:$A,$AE$11,'상세 자료 작성'!$B:$B,'요약(보고)'!$F$4)/10^8 -> 35.327 | H16: =SUMIFS('상세 자료 작성'!$K:$K,'상세 자료 작성'!$C:$C,'요약(보고)'!$C16,'상세 자료 작성'!$A:$A,$AE$11,'상세 자료 작성'!$B:$B,'요약(보고)'!$F$4)/10^8 -> 32.328658 | I16: =Y16 -> -2.998342 | J16: =SUMIFS('상세 자료 작성'!$I:$I,'상세 자료 작성'!$C:$C,'요약(보고)'!$C16,'상세 자료 작성'!$A:$A,'요약(보고)'!$AE$9,'상세 자료 작성'!$D:$D,$J$4)/10^8 -> 29.878953 | K16: =SUMIFS('상세 자료 작성'!$J:$J,'상세 자료 작성'!$C:$C,'요약(보고)'!$C16,'상세 자료 작성'!$A:$A,$AE$11,'상세 자료 작성'!$D:$D,'요약(보고)'!$J$4)/10^8 -> 24.597 | L16: =SUMIFS('상세 자료 작성'!$K:$K,'상세 자료 작성'!$C:$C,'요약(보고)'!$C16,'상세 자료 작성'!$A:$A,$AE$11,'상세 자료 작성'!$D:$D,$J$4)/10^8 -> 24.908658 | M16: =L16-K16 -> 0.31165804 | N16: =SUMIFS('상세 자료 작성'!$I:$I,'상세 자료 작성'!$C:$C,'요약(보고)'!$C16,'상세 자료 작성'!$A:$A,'요약(보고)'!$AE$9,'상세 자료 작성'!$D:$D,$N$4)/10^8 -> 0.26295337 | O16: =SUMIFS('상세 자료 작성'!$J:$J,'상세 자료 작성'!$C:$C,'요약(보고)'!$C16,'상세 자료 작성'!$A:$A,$AE$11,'상세 자료 작성'!$D:$D,$N$4)/10^8 -> 3.71 | P16: =SUMIFS('상세 자료 작성'!$K:$K,'상세 자료 작성'!$C:$C,'요약(보고)'!$C16,'상세 자료 작성'!$A:$A,$AE$11,'상세 자료 작성'!$D:$D,$N$4)/10^8 -> 3.08 | Q16: =P16-O16 -> -0.63 | R16: =SUMIFS('상세 자료 작성'!$I:$I,'상세 자료 작성'!$C:$C,'요약(보고)'!$C16,'상세 자료 작성'!$A:$A,'요약(보고)'!$AE$9,'상세 자료 작성'!$D:$D,$R$4)/10^8 -> 12.132953 | S16: =SUMIFS('상세 자료 작성'!$J:$J,'상세 자료 작성'!$C:$C,'요약(보고)'!$C16,'상세 자료 작성'!$A:$A,$AE$11,'상세 자료 작성'!$D:$D,$R$4)/10^8 -> 7.02 | T16: =SUMIFS('상세 자료 작성'!$K:$K,'상세 자료 작성'!$C:$C,'요약(보고)'!$C16,'상세 자료 작성'!$A:$A,$AE$11,'상세 자료 작성'!$D:$D,$R$4)/10^8 -> 4.34 | U16: =T16-S16 -> -2.68 | V16: =R16+J16+N16 -> 42.27486 | W16: =S16+K16+O16 -> 35.327 | X16: =T16+L16+P16 -> 32.328658 | Y16: =X16-W16 -> -2.998342 | Z16: =SUMIFS('상세 자료 작성'!$I:$I,'상세 자료 작성'!$C:$C,'요약(보고)'!$C16,'상세 자료 작성'!$A:$A,'요약(보고)'!$AE$9)/10^8 -> 116.73362 | AA16: =SUMIFS('상세 자료 작성'!$J:$J,'상세 자료 작성'!$C:$C,'요약(보고)'!$C16,'상세 자료 작성'!$A:$A,'요약(보고)'!$AE$11)/10^8 -> 179.7765 | AB16: =SUMIFS('상세 자료 작성'!$K:$K,'상세 자료 작성'!$C:$C,'요약(보고)'!$C16,'상세 자료 작성'!$A:$A,'요약(보고)'!$AE$11)/10^8 -> 176.77816 | AC16: =AB16-AA16 -> -2.998342
C17: LCM | D17: 14.12375 | E17: =AA17 -> 9.2 | F17: =SUMIFS('상세 자료 작성'!$I:$I,'상세 자료 작성'!$C:$C,'요약(보고)'!$C17,'상세 자료 작성'!$A:$A,'요약(보고)'!$AE$9,'상세 자료 작성'!$B:$B,'요약(보고)'!$F$4)/10^8 -> 3.66 | G17: =SUMIFS('상세 자료 작성'!$J:$J,'상세 자료 작성'!$C:$C,'요약(보고)'!$C17,'상세 자료 작성'!$A:$A,$AE$11,'상세 자료 작성'!$B:$B,'요약(보고)'!$F$4)/10^8 -> 1.7875 | H17: =SUMIFS('상세 자료 작성'!$K:$K,'상세 자료 작성'!$C:$C,'요약(보고)'!$C17,'상세 자료 작성'!$A:$A,$AE$11,'상세 자료 작성'!$B:$B,'요약(보고)'!$F$4)/10^8 -> 1.7875 | I17: =Y17 -> 0 | J17: =SUMIFS('상세 자료 작성'!$I:$I,'상세 자료 작성'!$C:$C,'요약(보고)'!$C17,'상세 자료 작성'!$A:$A,'요약(보고)'!$AE$9,'상세 자료 작성'!$D:$D,$J$4)/10^8 -> 0 | K17: =SUMIFS('상세 자료 작성'!$J:$J,'상세 자료 작성'!$C:$C,'요약(보고)'!$C17,'상세 자료 작성'!$A:$A,$AE$11,'상세 자료 작성'!$D:$D,'요약(보고)'!$J$4)/10^8 -> 0 | L17: =SUMIFS('상세 자료 작성'!$K:$K,'상세 자료 작성'!$C:$C,'요약(보고)'!$C17,'상세 자료 작성'!$A:$A,$AE$11,'상세 자료 작성'!$D:$D,$J$4)/10^8 -> 0 | M17: =L17-K17 -> 0 | N17: =SUMIFS('상세 자료 작성'!$I:$I,'상세 자료 작성'!$C:$C,'요약(보고)'!$C17,'상세 자료 작성'!$A:$A,'요약(보고)'!$AE$9,'상세 자료 작성'!$D:$D,$N$4)/10^8 -> 0 | O17: =SUMIFS('상세 자료 작성'!$J:$J,'상세 자료 작성'!$C:$C,'요약(보고)'!$C17,'상세 자료 작성'!$A:$A,$AE$11,'상세 자료 작성'!$D:$D,$N$4)/10^8 -> 0.46875 | P17: =SUMIFS('상세 자료 작성'!$K:$K,'상세 자료 작성'!$C:$C,'요약(보고)'!$C17,'상세 자료 작성'!$A:$A,$AE$11,'상세 자료 작성'!$D:$D,$N$4)/10^8 -> 0.46875 | Q17: =P17-O17 -> 0 | R17: =SUMIFS('상세 자료 작성'!$I:$I,'상세 자료 작성'!$C:$C,'요약(보고)'!$C17,'상세 자료 작성'!$A:$A,'요약(보고)'!$AE$9,'상세 자료 작성'!$D:$D,$R$4)/10^8 -> 3.66 | S17: =SUMIFS('상세 자료 작성'!$J:$J,'상세 자료 작성'!$C:$C,'요약(보고)'!$C17,'상세 자료 작성'!$A:$A,$AE$11,'상세 자료 작성'!$D:$D,$R$4)/10^8 -> 1.31875 | T17: =SUMIFS('상세 자료 작성'!$K:$K,'상세 자료 작성'!$C:$C,'요약(보고)'!$C17,'상세 자료 작성'!$A:$A,$AE$11,'상세 자료 작성'!$D:$D,$R$4)/10^8 -> 1.31875 | U17: =T17-S17 -> 0 | V17: =R17+J17+N17 -> 3.66 | W17: =S17+K17+O17 -> 1.7875 | X17: =T17+L17+P17 -> 1.7875 | Y17: =X17-W17 -> 0 | Z17: =SUMIFS('상세 자료 작성'!$I:$I,'상세 자료 작성'!$C:$C,'요약(보고)'!$C17,'상세 자료 작성'!$A:$A,'요약(보고)'!$AE$9)/10^8 -> 14.12375 | AA17: =SUMIFS('상세 자료 작성'!$J:$J,'상세 자료 작성'!$C:$C,'요약(보고)'!$C17,'상세 자료 작성'!$A:$A,'요약(보고)'!$AE$11)/10^8 -> 9.2 | AB17: =SUMIFS('상세 자료 작성'!$K:$K,'상세 자료 작성'!$C:$C,'요약(보고)'!$C17,'상세 자료 작성'!$A:$A,'요약(보고)'!$AE$11)/10^8 -> 9.2 | AC17: =AB17-AA17 -> 0
C18: 내재화 개발 | D18: 13.015667 | E18: =AA18 -> 7.96875 | F18: =SUMIFS('상세 자료 작성'!$I:$I,'상세 자료 작성'!$C:$C,'요약(보고)'!$C18,'상세 자료 작성'!$A:$A,'요약(보고)'!$AE$9,'상세 자료 작성'!$B:$B,'요약(보고)'!$F$4)/10^8 -> 5.2999167 | G18: =SUMIFS('상세 자료 작성'!$J:$J,'상세 자료 작성'!$C:$C,'요약(보고)'!$C18,'상세 자료 작성'!$A:$A,$AE$11,'상세 자료 작성'!$B:$B,'요약(보고)'!$F$4)/10^8 -> 4.6875 | H18: =SUMIFS('상세 자료 작성'!$K:$K,'상세 자료 작성'!$C:$C,'요약(보고)'!$C18,'상세 자료 작성'!$A:$A,$AE$11,'상세 자료 작성'!$B:$B,'요약(보고)'!$F$4)/10^8 -> 5.0495833 | I18: =Y18 -> 0.36208334 | J18: =SUMIFS('상세 자료 작성'!$I:$I,'상세 자료 작성'!$C:$C,'요약(보고)'!$C18,'상세 자료 작성'!$A:$A,'요약(보고)'!$AE$9,'상세 자료 작성'!$D:$D,$J$4)/10^8 -> 2.7467917 | K18: =SUMIFS('상세 자료 작성'!$J:$J,'상세 자료 작성'!$C:$C,'요약(보고)'!$C18,'상세 자료 작성'!$A:$A,$AE$11,'상세 자료 작성'!$D:$D,'요약(보고)'!$J$4)/10^8 -> 1.40625 | L18: =SUMIFS('상세 자료 작성'!$K:$K,'상세 자료 작성'!$C:$C,'요약(보고)'!$C18,'상세 자료 작성'!$A:$A,$AE$11,'상세 자료 작성'!$D:$D,$J$4)/10^8 -> 1.7683333 | M18: =L18-K18 -> 0.36208334 | N18: =SUMIFS('상세 자료 작성'!$I:$I,'상세 자료 작성'!$C:$C,'요약(보고)'!$C18,'상세 자료 작성'!$A:$A,'요약(보고)'!$AE$9,'상세 자료 작성'!$D:$D,$N$4)/10^8 -> 0.31604167 | O18: =SUMIFS('상세 자료 작성'!$J:$J,'상세 자료 작성'!$C:$C,'요약(보고)'!$C18,'상세 자료 작성'!$A:$A,$AE$11,'상세 자료 작성'!$D:$D,$N$4)/10^8 -> 0.46875 | P18: =SUMIFS('상세 자료 작성'!$K:$K,'상세 자료 작성'!$C:$C,'요약(보고)'!$C18,'상세 자료 작성'!$A:$A,$AE$11,'상세 자료 작성'!$D:$D,$N$4)/10^8 -> 0.46875 | Q18: =P18-O18 -> 0 | R18: =SUMIFS('상세 자료 작성'!$I:$I,'상세 자료 작성'!$C:$C,'요약(보고)'!$C18,'상세 자료 작성'!$A:$A,'요약(보고)'!$AE$9,'상세 자료 작성'!$D:$D,$R$4)/10^8 -> 2.2370833 | S18: =SUMIFS('상세 자료 작성'!$J:$J,'상세 자료 작성'!$C:$C,'요약(보고)'!$C18,'상세 자료 작성'!$A:$A,$AE$11,'상세 자료 작성'!$D:$D,$R$4)/10^8 -> 2.8125 | T18: =SUMIFS('상세 자료 작성'!$K:$K,'상세 자료 작성'!$C:$C,'요약(보고)'!$C18,'상세 자료 작성'!$A:$A,$AE$11,'상세 자료 작성'!$D:$D,$R$4)/10^8 -> 2.8125 | U18: =T18-S18 -> 0 | V18: =R18+J18+N18 -> 5.2999167 | W18: =S18+K18+O18 -> 4.6875 | X18: =T18+L18+P18 -> 5.0495833 | Y18: =X18-W18 -> 0.36208334 | Z18: =SUMIFS('상세 자료 작성'!$I:$I,'상세 자료 작성'!$C:$C,'요약(보고)'!$C18,'상세 자료 작성'!$A:$A,'요약(보고)'!$AE$9)/10^8 -> 12.811667 | AA18: =SUMIFS('상세 자료 작성'!$J:$J,'상세 자료 작성'!$C:$C,'요약(보고)'!$C18,'상세 자료 작성'!$A:$A,'요약(보고)'!$AE$11)/10^8 -> 7.96875 | AB18: =SUMIFS('상세 자료 작성'!$K:$K,'상세 자료 작성'!$C:$C,'요약(보고)'!$C18,'상세 자료 작성'!$A:$A,'요약(보고)'!$AE$11)/10^8 -> 8.3308333 | AC18: =AB18-AA18 -> 0.36208334
C19: 기타(QA위임등)* | D19: 7.4302005 | E19: =AA19 -> 0 | F19: =SUMIFS('상세 자료 작성'!$I:$I,'상세 자료 작성'!$C:$C,'요약(보고)'!$C19,'상세 자료 작성'!$A:$A,'요약(보고)'!$AE$9,'상세 자료 작성'!$B:$B,'요약(보고)'!$F$4)/10^8 -> 2.6480417 | G19: =SUMIFS('상세 자료 작성'!$J:$J,'상세 자료 작성'!$C:$C,'요약(보고)'!$C19,'상세 자료 작성'!$A:$A,$AE$11,'상세 자료 작성'!$B:$B,'요약(보고)'!$F$4)/10^8 -> 0 | H19: =SUMIFS('상세 자료 작성'!$K:$K,'상세 자료 작성'!$C:$C,'요약(보고)'!$C19,'상세 자료 작성'!$A:$A,$AE$11,'상세 자료 작성'!$B:$B,'요약(보고)'!$F$4)/10^8 -> 0.3732771 | I19: =Y19 -> 0.3732771 | J19: =SUMIFS('상세 자료 작성'!$I:$I,'상세 자료 작성'!$C:$C,'요약(보고)'!$C19,'상세 자료 작성'!$A:$A,'요약(보고)'!$AE$9,'상세 자료 작성'!$D:$D,$J$4)/10^8 -> 1.1739256 | K19: =SUMIFS('상세 자료 작성'!$J:$J,'상세 자료 작성'!$C:$C,'요약(보고)'!$C19,'상세 자료 작성'!$A:$A,$AE$11,'상세 자료 작성'!$D:$D,'요약(보고)'!$J$4)/10^8 -> 0 | L19: =SUMIFS('상세 자료 작성'!$K:$K,'상세 자료 작성'!$C:$C,'요약(보고)'!$C19,'상세 자료 작성'!$A:$A,$AE$11,'상세 자료 작성'!$D:$D,$J$4)/10^8 -> 0.3732771 | M19: =L19-K19 -> 0.3732771 | N19: =SUMIFS('상세 자료 작성'!$I:$I,'상세 자료 작성'!$C:$C,'요약(보고)'!$C19,'상세 자료 작성'!$A:$A,'요약(보고)'!$AE$9,'상세 자료 작성'!$D:$D,$N$4)/10^8 -> 0.0791691 | O19: =SUMIFS('상세 자료 작성'!$J:$J,'상세 자료 작성'!$C:$C,'요약(보고)'!$C19,'상세 자료 작성'!$A:$A,$AE$11,'상세 자료 작성'!$D:$D,$N$4)/10^8 -> 0 | P19: =SUMIFS('상세 자료 작성'!$K:$K,'상세 자료 작성'!$C:$C,'요약(보고)'!$C19,'상세 자료 작성'!$A:$A,$AE$11,'상세 자료 작성'!$D:$D,$N$4)/10^8 -> 0 | Q19: =P19-O19 -> 0 | R19: =SUMIFS('상세 자료 작성'!$I:$I,'상세 자료 작성'!$C:$C,'요약(보고)'!$C19,'상세 자료 작성'!$A:$A,'요약(보고)'!$AE$9,'상세 자료 작성'!$D:$D,$R$4)/10^8 -> 1.394947 | S19: =SUMIFS('상세 자료 작성'!$J:$J,'상세 자료 작성'!$C:$C,'요약(보고)'!$C19,'상세 자료 작성'!$A:$A,$AE$11,'상세 자료 작성'!$D:$D,$R$4)/10^8 -> 0 | T19: =SUMIFS('상세 자료 작성'!$K:$K,'상세 자료 작성'!$C:$C,'요약(보고)'!$C19,'상세 자료 작성'!$A:$A,$AE$11,'상세 자료 작성'!$D:$D,$R$4)/10^8 -> 0 | U19: =T19-S19 -> 0 | V19: =R19+J19+N19 -> 2.6480417 | W19: =S19+K19+O19 -> 0 | X19: =T19+L19+P19 -> 0.3732771 | Y19: =X19-W19 -> 0.3732771 | Z19: =SUMIFS('상세 자료 작성'!$I:$I,'상세 자료 작성'!$C:$C,'요약(보고)'!$C19,'상세 자료 작성'!$A:$A,'요약(보고)'!$AE$9)/10^8 -> 6.4402005 | AA19: =SUMIFS('상세 자료 작성'!$J:$J,'상세 자료 작성'!$C:$C,'요약(보고)'!$C19,'상세 자료 작성'!$A:$A,'요약(보고)'!$AE$11)/10^8 -> 0 | AB19: =SUMIFS('상세 자료 작성'!$K:$K,'상세 자료 작성'!$C:$C,'요약(보고)'!$C19,'상세 자료 작성'!$A:$A,'요약(보고)'!$AE$11)/10^8 -> 0.3732771 | AC19: =AB19-AA19 -> 0.3732771
B20: 국내영업 | D20: =SUM(D21:D23) -> 0 | E20: =SUM(E21:E23) -> 3392.2517 | F20: =SUM(F21:F23) -> 0 | G20: =SUM(G21:G23) -> 672.24237 | H20: =SUM(H21:H23) -> 672.24237 | I20: =SUM(I21:I23) -> 0 | J20: =SUM(J21:J23) -> 0 | K20: =SUM(K21:K23) -> 236.81199 | ... Q20: =SUM(Q21:Q23) -> 0 | R20: ='상세 자료 작성'!I39 -> 9532347466 | S20: =SUM(S21:S23) -> 364.64057 | T20: =SUM(T21:T23) -> 364.64057 | U20: =SUM(U21:U23) -> 0 | V20: =SUM(V21:V23) -> 0 | W20: =SUM(W21:W23) -> 882.06849 | X20: =SUM(X21:X23) -> 882.06849 | Y20: =SUM(Y21:Y23) -> 0
C21: 케미컬 | D21: 0 | E21: 1869.8805 | F21: 0 | G21: 404.56184 | H21: 404.56184 | I21: =H21-G21 -> 0 | J21: 0 | K21: 157.15481 | L21: 157.15481 | M21: =L21-K21 -> 0 | N21: 0 | O21: 170.53756 | P21: 170.53756 | Q21: =P21-O21 -> 0 | R21: ='상세 자료 작성'!I40 -> 26963794201 | S21: 194.32657 | T21: 194.32657 | U21: =T21-S21 -> 0 | V21: 0 | W21: =K21+O21+S21 -> 522.01894 | X21: =L21+P21+T21 -> 522.01894 | Y21: =X21-W21 -> 0
C22: 바이오 | D22: 0 | E22: 1000 | F22: 0 | G22: 214.70497 | H22: 214.70497 | I22: =H22-G22 -> 0 | J22: 0 | K22: 57.938842 | L22: 57.938842 | M22: =L22-K22 -> 0 | N22: 0 | O22: 86.908263 | P22: 86.908263 | Q22: =P22-O22 -> 0 | R22: ='상세 자료 작성'!I41 -> 1151454672 | S22: 144.97406 | T22: 144.97406 | U22: =T22-S22 -> 0 | V22: 0 | W22: =K22+O22+S22 -> 289.82116 | X22: =L22+P22+T22 -> 289.82116 | Y22: =X22-W22 -> 0
C23: APAC | D23: 0 | E23: 522.37127 | F23: 0 | G23: 52.975551 | H23: 52.975551 | I23: =H23-G23 -> 0 | J23: 0 | K23: 21.718335 | L23: 21.718335 | M23: =L23-K23 -> 0 | N23: 0 | O23: 23.17011 | P23: 23.17011 | Q23: =P23-O23 -> 0 | R23: ='상세 자료 작성'!I42 -> 0 | S23: 25.339943 | T23: 25.339943 | U23: =T23-S23 -> 0 | V23: 0 | W23: =K23+O23+S23 -> 70.228388 | X23: =L23+P23+T23 -> 70.228388 | Y23: =X23-W23 -> 0
B24: *기타 : 약물감시, IIT 용역 추가 반영
B26: 1) 2월 매출 특이사항 | F26: 2월 | W26: * : 매출 미반영
B27: 구분 | E27: 계획 | G27: 전주 보고 (경영회의) | I27: 금주 보고 (경영회의) | K27: 전주 대비 | M27: 변경사유 / 특이사항
B28: 케미컬 상업 | E28: =(SUMIFS('상세 자료 작성'!$J:$J,'상세 자료 작성'!$A:$A,'요약(보고)'!$AE$11,'상세 자료 작성'!$D:$D,'요약(보고)'!$F$26,'상세 자료 작성'!$C:$C,'요약(보고)'!#REF!)+SUMIFS('상세 자료 작성'!$J:$J,'상세 자료 작성'!$A:$A,'요약(보고)'!$AE$11,'상세 자료 작성'!$D:$D,'요약(보고)'!$F$26,'상세 자료 작성'!$C:$C,'요약(보고)'!$C$10)+SUMIFS('상세 자료 작성'!$J:$J,'상세 자료 작성'!$A:$A,'요약(보고)'!$AE$11,'상세 자료 작성'!$D:$D,'요약(보고)'!$F$26,'상세 자료 작성'!$C:$C,'요약(보고)'!$C$11))/10^8 -> 12.254069 | G28: =(SUMIFS('상세 자료 작성'!$M:$M,'상세 자료 작성'!$A:$A,'요약(보고)'!$AE$11,'상세 자료 작성'!$D:$D,'요약(보고)'!$F$26,'상세 자료 작성'!$C:$C,'요약(보고)'!#REF!)+SUMIFS('상세 자료 작성'!$M:$M,'상세 자료 작성'!$A:$A,'요약(보고)'!$AE$11,'상세 자료 작성'!$D:$D,'요약(보고)'!$F$26,'상세 자료 작성'!$C:$C,'요약(보고)'!C10)+SUMIFS('상세 자료 작성'!$M:$M,'상세 자료 작성'!$A:$A,'요약(보고)'!$AE$11,'상세 자료 작성'!$D:$D,'요약(보고)'!$F$26,'상세 자료 작성'!$C:$C,'요약(보고)'!C11))/10^8 -> 12.382509 | I28: =(SUMIFS('상세 자료 작성'!$K:$K,'상세 자료 작성'!$A:$A,'요약(보고)'!$AE$11,'상세 자료 작성'!$D:$D,'요약(보고)'!$F$26,'상세 자료 작성'!$C:$C,'요약(보고)'!#REF!)+SUMIFS('상세 자료 작성'!$K:$K,'상세 자료 작성'!$A:$A,'요약(보고)'!$AE$11,'상세 자료 작성'!$D:$D,'요약(보고)'!$F$26,'상세 자료 작성'!$C:$C,'요약(보고)'!$C$10)+SUMIFS('상세 자료 작성'!$K:$K,'상세 자료 작성'!$A:$A,'요약(보고)'!$AE$11,'상세 자료 작성'!$D:$D,'요약(보고)'!$F$26,'상세 자료 작성'!$C:$C,'요약(보고)'!$C$11))/10^8 -> 9.8442169 | K28: =I28-G28 -> -2.538292 | M28: *전주 대비 -2.5억 (사업계획 대비 -2.5억원) 1. 네시나 25mg 대만향 Hasten社 측 선적일정 지연
B29: 바이오상업 | E29: =SUM(E30:F31) -> 90.822934 | G29: =SUM(G30:H31) -> 103.50969 | I29: =SUM(I30:J31) -> 102.46369 | K29: =I29-G29 -> -1.0460065
C30: PFS | E30: =SUMIFS('상세 자료 작성'!$J:$J,'상세 자료 작성'!$A:$A,'요약(보고)'!$AE$11,'상세 자료 작성'!$D:$D,'요약(보고)'!$F$26,'상세 자료 작성'!$C:$C,'요약(보고)'!$C$13)/10^8 -> 88.077118 | G30: =SUMIFS('상세 자료 작성'!$M:$M,'상세 자료 작성'!$A:$A,'요약(보고)'!$AE$11,'상세 자료 작성'!$D:$D,'요약(보고)'!$F$26,'상세 자료 작성'!$C:$C,'요약(보고)'!$C$13)/10^8 -> 100.50397 | I30: =SUMIFS('상세 자료 작성'!$K:$K,'상세 자료 작성'!$A:$A,'요약(보고)'!$AE$11,'상세 자료 작성'!$D:$D,'요약(보고)'!$F$26,'상세 자료 작성'!$C:$C,'요약(보고)'!$C$13)/10^8 -> 99.549516 | K30: =I30-G30 -> -0.9544497 | M30: * 전주 대비 -1억 (사업계획 대비 +11.4억) 1. 스테키마 미국향 US 변경허가 지연에 따른 매출 이월(-1억원)
C31: L&P | E31: =SUMIFS('상세 자료 작성'!$J:$J,'상세 자료 작성'!$A:$A,'요약(보고)'!$AE$11,'상세 자료 작성'!$D:$D,'요약(보고)'!$F$26,'상세 자료 작성'!$C:$C,'요약(보고)'!$C$14)/10^8 -> 2.7458164 | G31: =SUMIFS('상세 자료 작성'!$M:$M,'상세 자료 작성'!$A:$A,'요약(보고)'!$AE$11,'상세 자료 작성'!$D:$D,'요약(보고)'!$F$26,'상세 자료 작성'!$C:$C,'요약(보고)'!$C$14)/10^8 -> 3.0057284 | I31: =SUMIFS('상세 자료 작성'!$K:$K,'상세 자료 작성'!$A:$A,'요약(보고)'!$AE$11,'상세 자료 작성'!$D:$D,'요약(보고)'!$F$26,'상세 자료 작성'!$C:$C,$C$14)/10^8 -> 2.9141716 | K31: =I31-G31 -> -0.0915568 | M31: *사업계획 대비 +0.2억 : 고객사 요청물량 변경
B32: 개발용역 | E32: =SUM(E33:F36) -> 4.6475 | G32: =SUM(G33:H36) -> 4.0175 | I32: =SUM(I33:J36) -> 4.0175 | K32: =I32-G32 -> 0
C33: PFS 개발 | E33: =SUMIFS('상세 자료 작성'!$J:$J,'상세 자료 작성'!$A:$A,'요약(보고)'!$AE$11,'상세 자료 작성'!$D:$D,'요약(보고)'!$F$26,'상세 자료 작성'!$C:$C,$C16)/10^8 -> 3.71 | G33: =SUMIFS('상세 자료 작성'!$M:$M,'상세 자료 작성'!$A:$A,'요약(보고)'!$AE$11,'상세 자료 작성'!$D:$D,'요약(보고)'!$F$26,'상세 자료 작성'!$C:$C,$C16)/10^8 -> 3.08 | I33: =SUMIFS('상세 자료 작성'!$K:$K,'상세 자료 작성'!$A:$A,'요약(보고)'!$AE$11,'상세 자료 작성'!$D:$D,'요약(보고)'!$F$26,'상세 자료 작성'!$C:$C,$C16)/10^8 -> 3.08 | K33: =I33-G33 -> 0 | M33: *사업계획 대비 -0.63억 : CT-P42 멸균 PV 레포트 일정조정 (Interim Report 완료 → Residual NO2 시험 완류 후 최종화(3월 예상))
C34: LCM | E34: =SUMIFS('상세 자료 작성'!$J:$J,'상세 자료 작성'!$A:$A,'요약(보고)'!$AE$11,'상세 자료 작성'!$D:$D,'요약(보고)'!$F$26,'상세 자료 작성'!$C:$C,$C17)/10^8 -> 0.46875 | G34: =SUMIFS('상세 자료 작성'!$M:$M,'상세 자료 작성'!$A:$A,'요약(보고)'!$AE$11,'상세 자료 작성'!$D:$D,'요약(보고)'!$F$26,'상세 자료 작성'!$C:$C,$C17)/10^8 -> 0.46875 | I34: =SUMIFS('상세 자료 작성'!$K:$K,'상세 자료 작성'!$A:$A,'요약(보고)'!$AE$11,'상세 자료 작성'!$D:$D,'요약(보고)'!$F$26,'상세 자료 작성'!$C:$C,$C17)/10^8 -> 0.46875 | K34: =I34-G34 -> 0
C35: 내재화 개발 | E35: =SUMIFS('상세 자료 작성'!$J:$J,'상세 자료 작성'!$A:$A,'요약(보고)'!$AE$11,'상세 자료 작성'!$D:$D,'요약(보고)'!$F$26,'상세 자료 작성'!$C:$C,$C18)/10^8 -> 0.46875 | G35: =SUMIFS('상세 자료 작성'!$M:$M,'상세 자료 작성'!$A:$A,'요약(보고)'!$AE$11,'상세 자료 작성'!$D:$D,'요약(보고)'!$F$26,'상세 자료 작성'!$C:$C,$C18)/10^8 -> 0.46875 | I35: =SUMIFS('상세 자료 작성'!$K:$K,'상세 자료 작성'!$A:$A,'요약(보고)'!$AE$11,'상세 자료 작성'!$D:$D,'요약(보고)'!$F$26,'상세 자료 작성'!$C:$C,$C18)/10^8 -> 0.46875 | K35: =I35-G35 -> 0
C36: 기타(QA위임등)* | E36: =SUMIFS('상세 자료 작성'!$J:$J,'상세 자료 작성'!$A:$A,'요약(보고)'!$AE$11,'상세 자료 작성'!$D:$D,'요약(보고)'!$F$26,'상세 자료 작성'!$C:$C,$C19)/10^8 -> 0 | G36: =SUMIFS('상세 자료 작성'!$M:$M,'상세 자료 작성'!$A:$A,'요약(보고)'!$AE$11,'상세 자료 작성'!$D:$D,'요약(보고)'!$F$26,'상세 자료 작성'!$C:$C,$C19)/10^8 -> 0 | I36: =SUMIFS('상세 자료 작성'!$K:$K,'상세 자료 작성'!$A:$A,'요약(보고)'!$AE$11,'상세 자료 작성'!$D:$D,'요약(보고)'!$F$26,'상세 자료 작성'!$C:$C,$C19)/10^8 -> 0 | K36: =I36-G36 -> 0
B37: 총합 | E37: =E28+E29+E32 -> 107.7245 | G37: =SUM(G28,G29,G32) -> 119.9097 | I37: =I28+I29+I32 -> 116.3254 | K37: =I37-G37 -> -3.5842985 | M37: 전주 대비 -3.6억원, 사업계획 대비 +8.6억원
B39: 2) 3분기 매출 특이사항
B40: 구분 | E40: 계획 | G40: 전주 보고 (경영회의) | I40: 금주 보고 (경영회의) | K40: 전주 대비 | M40: 변경사유 / 특이사항
B41: 케미컬 상업 | E41: =W9 -> 25.134453 | G41: =SUM('상세 자료 작성'!M215:M217,'상세 자료 작성'!M226:M228,'상세 자료 작성'!M237:M239)/10^8 -> 44.626386 | I41: =X9 -> 24.999197 | K41: =I41-G41 -> -19.627189 | M41: 상동
B42: 바이오상업 | E42: =SUM(E43:F44) -> 246.45126 | G42: =SUM(G43:H44) -> 286.83866 | I42: =SUM(I43:J44) -> 248.86353 | K42: =I42-G42 -> -37.975131
...

Sheet 상세 자료 작성
D1: ■ 주간 매출보고 자료
D2: 1) PO 기준 : | F2: 케미컬상업 | G2: 실질 PO 접수 기준
F3: PFS 상업 | G3: 2개월 100% Binding FCST 기준
F4: L&P 상업 | G4: 2개월 100% Binding FCST 기준
N5: 기준일자 : 2025-06-26
A6: 연 | B6: 분기 | D6: 월 | E6: 주차 | F6: 법인 | G6: 구분 | H6: 상세구분 | I6: 매출실적 | J6: 사업계획 | K6: 예상마감 | L6: 달성률 | M6: 전주 예상 실적 | N6: Gap
A7: 24년 | B7: 1분기 | C7: G07 | D7: 1월 | E7: 1주차 | F7: 셀트리온제약 | G7: 용역 | H7: CMO상업_조달 | I7: 302597280 | J7: ='2024년 계획_변경적용'!F45 -> 736312500 | K7: 302597280 | L7: =+K7/J7 -> 0.41096312 | M7: 302597280 | N7: =K7-M7 -> 0 | P7: 302597280 | Q7: =P7-I7 -> 0
A8: 24년 | B8: 1분기 | C8: 기타 | D8: =D7 -> 1월 | E8: 1주차 | F8: 셀트리온제약 | G8: 용역 | H8: CMO상업_미국 | I8: 0 | J8: ='2024년 계획_변경적용'!F44 -> 0 | K8: 0 | M8: 0 | N8: =K8-M8 -> 0 | P8: 0 | Q8: =P8-I8 -> 0
A9: 24년 | B9: 1분기 | C9: 내재화 | D9: =D8 -> 1월 | E9: 1주차 | F9: 셀트리온제약 | G9: 용역 | H9: CMO상업_내재화 | I9: 0 | J9: ='2024년 계획_변경적용'!F48 -> 0 | K9: 0 | M9: 0 | N9: =K9-M9 -> 0 | P9: 0 | Q9: =P9-I9 -> 0
A10: 24년 | B10: 1분기 | C10: L&P | D10: =D9 -> 1월 | E10: 1주차 | F10: 셀트리온제약 | G10: 용역 | H10: CMO상업_L&P | I10: 1013747020 | J10: ='2024년 계획_변경적용'!F46 -> 9.5931083e+08 | K10: 1013747020 | L10: =+K10/J10 -> 1.0567451 | M10: 1013747020 | N10: =K10-M10 -> 0 | P10: 1013747020 | Q10: =P10-I10 -> 0
A11: 24년 | B11: 1분기 | C11: PFS | D11: =D10 -> 1월 | E11: 1주차 | F11: 셀트리온제약 | G11: 용역 | H11: CMO상업_PFS | I11: 4869898150 | J11: ='2024년 계획_변경적용'!F47 -> 4405740000 | K11: 4869898150 | L11: =+K11/J11 -> 1.1053531 | M11: =5437734400-580000000 -> 4857734400 | N11: =K11-M11 -> 12163750 | P11: 4869898150 | Q11: =P11-I11 -> 0 | R11: =R12-K133 -> 0 | S11: =S12-K144 -> 0
A12: 24년 | B12: 1분기 | C12: GCP | D12: =D11 -> 1월 | E12: 1주차 | F12: 셀트리온제약 | G12: 용역 | H12: CMO용역_GCP | I12: 0 | J12: ='2024년 계획_변경적용'!F50 -> 0 | K12: 0 | M12: 0 | N12: =K12-M12 -> 0 | P12: 0 | Q12: =P12-I12 -> 0 | R12: =SUM(R14:R25) -> 12361988503 | S12: =SUM(S14:S25) -> 15101542896 | T12: =SUM(T14:T25) -> 27463531399
A13: 24년 | B13: 1분기 | C13: LCM | D13: =D12 -> 1월 | E13: 1주차 | F13: 셀트리온제약 | G13: 용역 | H13: CMO용역_LCM | I13: 0 | J13: ='2024년 계획_변경적용'!F53 -> 490500000 | K13: 0 | L13: =+K13/J13 -> 0 | M13: 0 | N13: =K13-M13 -> 0 | P13: 0 | Q13: =P13-I13 -> 0 | R13: 11월 | S13: 12월 | T13: 합계
A14: 24년 | B14: 1분기 | C14: PFS 개발 | D14: =D13 -> 1월 | E14: 1주차 | F14: 셀트리온제약 | G14: 용역 | H14: CMO용역_PFS | I14: 439139429 | J14: ='2024년 계획_변경적용'!F51 -> 0 | K14: 439139429 | M14: 404210000 | N14: =K14-M14 -> 34929429 | P14: 439139429 | Q14: =P14-I14 -> 0 | R14: =SUM(K123:K124) -> 0 | S14: =SUM(K134:K135) -> 0 | T14: =SUM(R14:S14) -> 0
A15: 24년 | B15: 1분기 | C15: 내재화 개발 | D15: =D14 -> 1월 | E15: 1주차 | F15: 셀트리온제약 | G15: 용역 | H15: CMO용역_내재화 | I15: 67266666 | J15: ='2024년 계획_변경적용'!F52 -> 0 | K15: 67266666 | M15: 42700000 | N15: =K15-M15 -> 24566666 | P15: 67266666 | Q15: =P15-I15 -> 0 | R15: =K126 -> 166471840 | S15: =K137 -> 190623740 | T15: =SUM(R15:S15) -> 357095580
A16: 24년 | B16: 1분기 | C16: 기타(QA위임등)* | D16: =D15 -> 1월 | E16: 1주차 | F16: 셀트리온제약 | G16: 용역 | H16: 용역_QA위임 | I16: 39867000 | J16: 0 | K16: 39867000 | M16: 39867000 | N16: =K16-M16 -> 0 | P16: 39867000 | Q16: =P16-I16 -> 0 | R16: =K127 -> 7377697800 | S16: =K138 -> 8035017050 | T16: =SUM(R16:S16) -> 15412714850
E17: 1월 예상 실적 | I17: =SUM(I7:I16) -> 6732515545 | J17: =SUM(J7:J16) -> 6.5918633e+09 | K17: =SUM(K7:K16) -> 6732515545 | L17: =I17/J17 -> 1.0213372 | M17: =SUM(M7:M16) -> 6660855700 | N17: =SUM(N7:N16) -> 71659845 | P17: 6732515545 | Q17: =P17-I17 -> 0 | R17: =K125 -> 4528225660 | S17: =K136 -> 6019051822 | T17: =SUM(R17:S17) -> 10547277482
A18: 24년 | B18: 1분기 | C18: G07 | D18: 2월 | E18: 1주차 | F18: 셀트리온제약 | G18: 용역 | H18: CMO상업_조달 | I18: 5372064744 | J18: ='2024년 계획_변경적용'!G45 -> 3253527000 | K18: 5372064744 | L18: =+I18/J18 -> 1.6511511 | M18: 5372064744 | N18: =K18-M18 -> 0 | P18: 5372064744 | Q18: =P18-I18 -> 0 | R18: =K128 -> 0 | S18: =K139 -> 134600000 | T18: =SUM(R18:S18) -> 134600000
A19: 24년 | B19: 1분기 | C19: 기타 | D19: =D18 -> 2월 | E19: 1주차 | F19: 셀트리온제약 | G19: 용역 | H19: CMO상업_미국 | I19: 0 | J19: ='2024년 계획_변경적용'!G44 -> 0 | K19: 0 | M19: 0 | N19: =K19-M19 -> 0 | P19: 0 | Q19: =P19-I19 -> 0 | R19: =K129 -> 38500000 | S19: =K140 -> 46875000 | T19: =SUM(R19:S19) -> 85375000
A20: 24년 | B20: 1분기 | C20: 내재화 | D20: =D19 -> 2월 | E20: 1주차 | F20: 셀트리온제약 | G20: 용역 | H20: CMO상업_내재화 | I20: 0 | J20: ='2024년 계획_변경적용'!G48 -> 0 | K20: 0 | M20: 0 | N20: =K20-M20 -> 0 | P20: 0 | Q20: =P20-I20 -> 0 | R20: =K130 -> 110001036 | S20: =K141 -> 476323136 | T20: =SUM(R20:S20) -> 586324172
A21: 24년 | B21: 1분기 | C21: L&P | D21: =D20 -> 2월 | E21: 1주차 | F21: 셀트리온제약 | G21: 용역 | H21: CMO상업_L&P | I21: 684982200 | J21: ='2024년 계획_변경적용'!G46 -> 9.5931083e+08 | K21: 684982200 | L21: =+I21/J21 -> 0.71403572 | M21: 684982200 | N21: =K21-M21 -> 0 | P21: 684982200 | Q21: =P21-I21 -> 0 | R21: =K131 -> 125354167 | S21: =K142 -> 31604167 | T21: =SUM(R21:S21) -> 156958334
A22: 24년 | B22: 1분기 | C22: PFS | D22: =D21 -> 2월 | E22: 1주차 | F22: 셀트리온제약 | G22: 용역 | H22: CMO상업_PFS | I22: 4437683550 | J22: ='2024년 계획_변경적용'!G47 -> 4.7866246e+08 | K22: 4437683550 | M22: 4437583550 | N22: =K22-M22 -> 100000 | P22: 4437683550 | Q22: =P22-I22 -> 0 | R22: =K132 -> 15738000 | S22: =K143 -> 167447981 | T22: =SUM(R22:S22) -> 183185981
A23: 24년 | B23: 1분기 | C23: GCP | D23: =D22 -> 2월 | E23: 1주차 | F23: 셀트리온제약 | G23: 용역 | H23: CMO용역_GCP | I23: 40000000 | J23: ='2024년 계획_변경적용'!G50 -> 40000000 | K23: 40000000 | L23: =+I23/J23 -> 1 | M23: 40000000 | N23: =K23-M23 -> 0 | P23: 40000000 | Q23: =P23-I23 -> 0 | T23: =SUM(R23:S23) -> 0
A24: 24년 | B24: 1분기 | C24: LCM | D24: =D23 -> 2월 | E24: 1주차 | F24: 셀트리온제약 | G24: 용역 | H24: CMO용역_LCM | I24: 0 | J24: ='2024년 계획_변경적용'!G53 -> 766500000 | K24: 0 | L24: =+I24/J24 -> 0 | M24: 0 | N24: =K24-M24 -> 0 | P24: 0 | Q24: =P24-I24 -> 0
A25: 24년 | B25: 1분기 | C25: PFS 개발 | D25: =D24 -> 2월 | E25: 1주차 | F25: 셀트리온제약 | G25: 용역 | H25: CMO용역_PFS | I25: 14069429 | J25: ='2024년 계획_변경적용'!G51 -> 162000000 | K25: 14069429 | L25: =+I25/J25 -> 0.086848327 | M25: 0 | N25: =K25-M25 -> 14069429 | P25: 14069429 | Q25: =P25-I25 -> 0
A26: 24년 | B26: 1분기 | C26: 내재화 개발 | D26: =D25 -> 2월 | E26: 1주차 | F26: 셀트리온제약 | G26: 용역 | H26: CMO용역_내재화 | I26: 119041667 | J26: ='2024년 계획_변경적용'!G52 -> 93750000 | K26: 119041667 | L26: =+I26/J26 -> 1.2697778 | M26: 93750000 | N26: =K26-M26 -> 25291667 | P26: 119041667 | Q26: =P26-I26 -> 0
A27: 24년 | B27: 1분기 | C27: 기타(QA위임등)* | D27: =D26 -> 2월 | E27: 1주차 | F27: 셀트리온제약 | G27: 용역 | H27: 용역_QA위임 | I27: 31089600 | J27: 0 | K27: 31089600 | M27: 0 | N27: =K27-M27 -> 31089600 | P27: 31089600 | Q27: =P27-I27 -> 0
E28: 2월 실적 | I28: =SUM(I18:I27) -> 10698931190 | J28: =SUM(J18:J27) -> 5.7537503e+09 | K28: =SUM(K18:K27) -> 10698931190 | L28: =I28/J28 -> 1.8594709 | M28: =SUM(M18:M27) -> 10628380494 | N28: =SUM(N18:N27) -> 70550696 | P28: 10698931190 | Q28: =P28-I28 -> 0
A29: 24년 | B29: 1분기 | C29: G07 | D29: 3월 | E29: 4주차 | F29: 셀트리온제약 | G29: 용역 | H29: CMO상업_조달 | I29: 2967439150 | J29: ='2024년 계획_변경적용'!H45 -> 2762644500 | K29: 2967439150 | L29: =+I29/J29 -> 1.0741299 | M29: 2953104000 | N29: =K29-M29 -> 14335150 | P29: 2967439150 | Q29: =P29-I29 -> 0
A30: 24년 | B30: 1분기 | C30: 기타 | D30: =D29 -> 3월 | E30: 4주차 | F30: 셀트리온제약 | G30: 용역 | H30: CMO상업_미국 | I30: 0 | J30: ='2024년 계획_변경적용'!H44 -> 0 | K30: 0 | L30: =+I30/J30 -> #DIV/0! | M30: 0 | N30: =K30-M30 -> 0 | P30: 0 | Q30: =P30-I30 -> 0
A31: 24년 | B31: 1분기 | C31: 내재화 | D31: =D30 -> 3월 | E31: 1주차 | F31: 셀트리온제약 | G31: 용역 | H31: CMO상업_내재화 | I31: 0 | J31: ='2024년 계획_변경적용'!H48 -> 0 | K31: 0 | M31: 0 | N31: =K31-M31 -> 0 | P31: 0 | Q31: =P31-I31 -> 0
A32: 24년 | B32: 1분기 | C32: L&P | D32: =D31 -> 3월 | E32: 4주차 | F32: 셀트리온제약 | G32: 용역 | H32: CMO상업_L&P | I32: 1047403520 | J32: 9.5931083e+08 | K32: 1047403520 | L32: =+I32/J32 -> 1.0918291 | M32: 9.5931083e+08 | N32: =K32-M32 -> 88092692 | P32: 1047403520 | Q32: =P32-I32 -> 0
A33: 24년 | B33: 1분기 | C33: PFS | D33: =D32 -> 3월 | E33: 4주차 | F33: 셀트리온제약 | G33: 용역 | H33: CMO상업_PFS | I33: 4508694300 | J33: 4.7344899e+09 | K33: 4508694300 | L33: =+I33/J33 -> 0.95230835 | M33: 4275201700 | N33: =K33-M33 -> 233492600 | P33: 4508694300 | Q33: =P33-I33 -> 0
A34: 24년 | B34: 1분기 | C34: GCP | D34: =D33 -> 3월 | E34: 4주차 | F34: 셀트리온제약 | G34: 용역 | H34: CMO용역_GCP | I34: 0 | J34: 0 | K34: 0 | M34: 0 | N34: =K34-M34 -> 0 | P34: 0 | Q34: =P34-I34 -> 0 | R34: =R14/10^8 -> 0 | S34: =S14/10^8 -> 0 | T34: =T14/10^8 -> 0
A35: 24년 | B35: 1분기 | C35: LCM | D35: =D34 -> 3월 | E35: 4주차 | F35: 셀트리온제약 | G35: 용역 | H35: CMO용역_LCM | I35: 520375000 | J35: 1666750000 | K35: 520375000 | L35: =+I35/J35 -> 0.31220939 | M35: 520375000 | N35: =K35-M35 -> 0 | P35: 520375000 | Q35: =P35-I35 -> 0 | R35: =R15/10^8 -> 1.6647184 | S35: =S15/10^8 -> 1.9062374 | T35: =T15/10^8 -> 3.5709558
A36: 24년 | B36: 1분기 | C36: PFS 개발 | D36: =D35 -> 3월 | E36: 4주차 | F36: 셀트리온제약 | G36: 용역 | H36: CMO용역_PFS | I36: 421269829 | J36: 5.06e+08 | K36: 421269829 | L36: =+I36/J36 -> 0.83254907 | M36: 422269429 | N36: =K36-M36 -> -999600 | P36: 421269829 | Q36: =P36-I36 -> 0 | R36: =R16/10^8 -> 73.776978 | S36: =S16/10^8 -> 80.350171 | T36: =T16/10^8 -> 154.12715
A37: 24년 | B37: 1분기 | C37: 내재화 개발 | D37: =D36 -> 3월 | E37: 4주차 | F37: 셀트리온제약 | G37: 용역 | H37: CMO용역_내재화 | I37: 25291667 | J37: 361875000 | K37: 25291667 | L37: =+I37/J37 -> 0.069890617 | M37: 212791667 | N37: =K37-M37 -> -187500000 | P37: 25291667 | Q37: =P37-I37 -> 0 | R37: =R17/10^8 -> 45.282257 | S37: =S17/10^8 -> 60.190518 | T37: =T17/10^8 -> 105.47277
A38: 24년 | B38: 1분기 | C38: 기타(QA위임등)* | D38: =D37 -> 3월 | E38: 1주차 | F38: 셀트리온제약 | G38: 용역 | H38: 용역_QA위임 | I38: 41874000 | J38: 0 | K38: 41874000 | L38: =+K38/J38 -> #DIV/0! | M38: 0 | N38: =K38-M38 -> 41874000 | P38: 41874000 | Q38: =P38-I38 -> 0 | R38: =R18/10^8 -> 0 | S38: =S18/10^8 -> 1.346 | T38: =T18/10^8 -> 1.346
E39: 3월 실적 | I39: =SUM(I29:I38) -> 9532347466 | J39: =SUM(J29:J38) -> 1.099107e+10 | K39: =SUM(K29:K38) -> 9532347466 | L39: =I39/J39 -> 0.8672811 | M39: =SUM(M29:M38) -> 9.3430526e+09 | N39: =SUM(N29:N38) -> 1.8929484e+08 | P39: 9532347466 | Q39: =P39-I39 -> 0 | R39: =R19/10^8 -> 0.385 | S39: =S19/10^8 -> 0.46875 | T39: =T19/10^8 -> 0.85375
D40: 1분기 실적 | I40: =I28+I17+I39 -> 26963794201 | J40: =J39+J28+J17 -> 2.3336684e+10 | K40: =K39+K28+K17 -> 26963794201 | L40: =K40/J40 -> 1.1554253 | M40: =M39+M28+M17 -> 2.6632289e+10 | N40: =N39+N28+N17 -> 3.3150538e+08 | P40: 26963794201 | Q40: =P40-I40 -> 0 | R40: =R20/10^8 -> 1.1000104 | S40: =S20/10^8 -> 4.7632314 | T40: =T20/10^8 -> 5.8632417
...

Sheet Hasten 단가 정보
B1: ■ 내재화 단가 차이
Q2: Hasten 단가 | V2: APAC 단가
B3: Territory | C3: Commercial Name | D3: SKU code | E3: Product name | F3: Size | G3: Unit | H3: Binding Forecast Period | I3: Order Lead Time | J3: Minimum Order Quantity | K3: UOM | L3: Permitted Delivery Deviation | M3: Bulk Facility | N3: Final Packaging Facility | O3: Product Supplied As | P3: Point-of-Delivery | Q3: Product Price(2024) | R3: Product Price (2025) 달러기준 | S3: Product Price (2025) 환율 1250원 | T3: Product Price (2025) 환율 1300원 | U3: Product Price (2025) 환율 1400 | V3: Product Price (2024) | W3: Product Price (2025) | X3: GAP
B4: TH
C5: Edarbi | D5: 30233TH | E5: Edarbi 40mg.2X14T IMP TH | F5: 28 | G5: tablet | H5: 4 months | I5: 3 months | J5: order by Product Family | K5: Pack | L5: 0.1 | M5: Celltrion Pharm | N5: Celltrion Pharm | O5: Finished Goods | P5: Korea - Cheongju - Ochang | Q5: 7800 | R5: 3.9 | S5: =+R5*1250 -> 4875 | T5: 5070 | U5: =+R5*1400 -> 5460 | V5: 5642 | W5: 4525 | X5: =W5-S5 -> -350
C6: Edarbi | D6: 30234TH | E6: Edarbi 80mg.2X14T IMP TH | F6: 28 | G6: tablet | H6: 4 months | I6: 3 months | J6: order by Product Family | K6: Pack | L6: 0.1 | M6: Celltrion Pharm | N6: Celltrion Pharm | O6: Finished Goods | P6: Korea - Cheongju - Ochang | Q6: 19500 | R6: 6.3 | S6: =+R6*1250 -> 7875 | T6: 8190 | U6: =+R6*1400 -> 8820 | V6: 10153 | W6: 7902 | X6: =W6-S6 -> 27
C7: Edarbyclor | D7: 30235TH | E7: EDARBYCLOR 40MG12.5MG TAB 28PC THA | F7: 28 | G7: tablet | H7: 4 months | I7: 3 months | J7: order by Product Family | K7: Pack | L7: 0.1 | M7: Celltrion Pharm | N7: Celltrion Pharm | O7: Finished Goods | P7: Korea - Cheongju - Ochang | Q7: 11700 | R7: 4.8 | S7: =+R7*1250 -> 6000 | T7: 6240 | U7: =+R7*1400 -> 6720 | V7: 6575 | W7: 5449 | X7: =W7-S7 -> -551
C8: Nesina | D8: 30264TH | E8: Nesina Tablets 25mg AA-14T×2 TH | F8: 28 | G8: tablet | H8: 4 months | I8: 3 months | J8: order by Product Family | K8: Pack | L8: 0.1 | M8: Celltrion Pharm | N8: Celltrion Pharm | O8: Finished Goods | P8: Korea - Cheongju - Ochang | Q8: 5070 | R8: 3.2 | S8: =+R8*1250 -> 4000 | T8: 4160 | U8: =+R8*1400 -> 4480 | V8: 4626 | W8: 4123 | X8: =W8-S8 -> 123
C9: NesinaAct/Oseni | D9: 30268TH | E9: Oseni 25mg/15mg AA-7T×4 TH | F9: 28 | G9: tablet | H9: 4 months | I9: 3 months | J9: order by Product Family | K9: Pack | L9: 0.1 | M9: Celltrion Pharm | N9: Celltrion Pharm | O9: Finished Goods | P9: Korea - Cheongju - Ochang | Q9: 5330 | R9: 3.3 | S9: =+R9*1250 -> 4125 | T9: 4290 | U9: =+R9*1400 -> 4620 | V9: 4820 | W9: 4838 | X9: =W9-S9 -> 713
C10: NesinaAct/Oseni | D10: 30269TH | E10: Oseni 25mg/30mg AA-7T×4 TH | F10: 28 | G10: tablet | H10: 4 months | I10: 3 months | J10: order by Product Family | K10: Pack | L10: 0.1 | M10: Celltrion Pharm | N10: Celltrion Pharm | O10: Finished Goods | P10: Korea - Cheongju - Ochang | Q10: 5720 | R10: 3.4 | S10: =+R10*1250 -> 4250 | T10: 4420 | U10: =+R10*1400 -> 4760 | V10: 5435 | W10: 5087 | X10: =W10-S10 -> 837
C11: Zafatek | D11: 30432TH | E11: Zafatek 100mg 20T | F11: 20 | G11: tablet | H11: 4 months | I11: 3 months | J11: order by Product Family | K11: Pack | L11: 0.1 | M11: Celltrion Pharm | N11: Celltrion Pharm | O11: Finished Goods | P11: Korea - Cheongju - Ochang | Q11: 26260 | R11: 19.8 | S11: =+R11*1250 -> 24750 | T11: 25740 | U11: =+R11*1400 -> 27720 | X11: =W11-S11 -> -24750
B12: TW | X12: =W12-S12 -> 0
C13: Edarbi | D13: 30233TW | E13: EDARBI 40MG TAB 28PC TWN | F13: 28 | G13: tablet | H13: 4 months | I13: 3 months | J13: order by Product Family | K13: Pack | L13: 0.1 | M13: Celltrion Pharm | N13: Celltrion Pharm | O13: Finished Goods | P13: Korea - Cheongju - Ochang | Q13: 5070 | R13: 3.8 | S13: =+R13*1250 -> 4750 | T13: 4940 | U13: =+R13*1400 -> 5320 | V13: 5642 | W13: 4525 | X13: =W13-S13 -> -225
C14: Nesina | D14: 30264TW | E14: Nesina Tablets 25mg AA-14T×2 TW | F14: 28 | G14: tablet | H14: 4 months | I14: 3 months | J14: order by Product Family | K14: Pack | L14: 0.1 | M14: Celltrion Pharm | N14: Celltrion Pharm | O14: Finished Goods | P14: Korea - Cheongju - Ochang | Q14: 5460 | R14: 3.3 | S14: =+R14*1250 -> 4125 | T14: 4290 | U14: =+R14*1400 -> 4620 | V14: 4626 | W14: 4123 | X14: =W14-S14 -> -2
C15: NesinaAct/Oseni | D15: 30269TW | E15: Oseni 25mg/30mg AA-7T×4 TW | F15: 28 | G15: tablet | H15: 4 months | I15: 3 months | J15: order by Product Family | K15: Pack | L15: 0.1 | M15: Celltrion Pharm | N15: Celltrion Pharm | O15: Finished Goods | P15: Korea - Cheongju - Ochang | Q15: 5590 | R15: 3.4 | S15: =+R15*1250 -> 4250 | T15: 4420 | U15: =+R15*1400 -> 4760 | V15: 5435 | W15: 5087 | X15: =W15-S15 -> 837
B16: HK | X16: =W16-S16 -> 0
C17: Edarbi | D17: 30234HK | E17: EDARBI 80MG 28T | F17: 28 | G17: tablet | H17: 4 months | I17: 3 months | J17: order by Product Family | K17: Pack | L17: 0.1 | M17: Celltrion Pharm | N17: Celltrion Pharm | O17: Finished Goods | P17: Korea - Cheongju - Ochang | Q17: 28470 | R17: 7.1 | S17: =+R17*1250 -> 8875 | T17: 9230 | U17: =+R17*1400 -> 9940 | V17: 10153 | W17: 7902 | X17: =W17-S17 -> -973
C18: Edarbi | D18: 30233HK | E18: EDARBI 40MG 28T | F18: 28 | G18: tablet | H18: 4 months | I18: 3 months | J18: order by Product Family | K18: Pack | L18: 0.1 | M18: Celltrion Pharm | N18: Celltrion Pharm | O18: Finished Goods | P18: Korea - Cheongju - Ochang | Q18: 11180 | R18: 4.1 | S18: =+R18*1250 -> 5125 | T18: 5330 | U18: =+R18*1400 -> 5740 | V18: 5642 | W18: 4525 | X18: =W18-S18 -> -600
C19: Edarbyclor | D19: 30235HK | E19: EDARBYCLOR 40MG/12.5MG TAB 28PC HKG | F19: 28 | G19: tablet | H19: 4 months | I19: 3 months | J19: order by Product Family | K19: Pack | L19: 0.1 | M19: Celltrion Pharm | N19: Celltrion Pharm | O19: Finished Goods | P19: Korea - Cheongju - Ochang | Q19: 11960 | R19: 4.9 | S19: =+R19*1250 -> 6125 | T19: 6370 | U19: =+R19*1400 -> 6860 | V19: 6575 | W19: 5449 | X19: =W19-S19 -> -676
C20: Nesina | D20: 30263HK | E20: Nesina Tablets 12.5mg AA-14T×2 HK | F20: 28 | G20: tablet | H20: 4 months | I20: 3 months | J20: order by Product Family | K20: Pack | L20: 0.1 | M20: Celltrion Pharm | N20: Celltrion Pharm | O20: Finished Goods | P20: Korea - Cheongju - Ochang | Q20: 5590 | R20: 2.3 | S20: =+R20*1250 -> 2875 | T20: 2990 | U20: =+R20*1400 -> 3220 | V20: 13147 | W20: 3517 | X20: =W20-S20 -> 642
C21: Nesina | D21: 30264HK | E21: Nesina Tablets 25mg AA-14T×2 HK | F21: 28 | G21: tablet | H21: 4 months | I21: 3 months | J21: order by Product Family | K21: Pack | L21: 0.1 | M21: Celltrion Pharm | N21: Celltrion Pharm | O21: Finished Goods | P21: Korea - Cheongju - Ochang | Q21: 6370 | R21: 4.9 | S21: =+R21*1250 -> 6125 | T21: 6370 | U21: =+R21*1400 -> 6860 | V21: 4626 | W21: 4123 | X21: =W21-S21 -> -2002
C22: NesinaAct/Oseni | D22: 30268HK | E22: Oseni 25mg/15mg AA-7T×4 HK | F22: 28 | G22: tablet | H22: 4 months | I22: 3 months | J22: order by Product Family | K22: Pack | L22: 0.1 | M22: Celltrion Pharm | N22: Celltrion Pharm | O22: Finished Goods | P22: Korea - Cheongju - Ochang | Q22: 5590 | R22: 3.3 | S22: =+R22*1250 -> 4125 | T22: 4290 | U22: =+R22*1400 -> 4620 | V22: 4820 | W22: 4838 | X22: =W22-S22 -> 713
C23: NesinaAct/Oseni | D23: 30269HK | E23: Oseni 25mg/30mg AA-7T×4 HK | F23: 28 | G23: tablet | H23: 4 months | I23: 3 months | J23: order by Product Family | K23: Pack | L23: 0.1 | M23: Celltrion Pharm | N23: Celltrion Pharm | O23: Finished Goods | P23: Korea - Cheongju - Ochang | Q23: 5720 | R23: 3.4 | S23: =+R23*1250 -> 4250 | T23: 4420 | U23: =+R23*1400 -> 4760 | V23: 5435 | W23: 5087 | X23: =W23-S23 -> 837
C24: NesinaMet | D24: 30229HK | E24: NesinaMet 12.5mg/1000mg AA-7T×4 HK | F24: 28 | G24: tablet | H24: 4 months | I24: 3 months | J24: order by Product Family | K24: Pack | L24: 0.1 | M24: Celltrion Pharm | N24: Celltrion Pharm | O24: Finished Goods | P24: Korea - Cheongju - Ochang | Q24: 11050 | R24: 5.6 | S24: =+R24*1250 -> 7000 | T24: 7280 | U24: =+R24*1400 -> 7840 | V24: 11594 | W24: 8454 | X24: =W24-S24 -> 1454
C25: NesinaMet | D25: 30227HK | E25: NesinaMet 12.5mg/500mg AA-7T×4 HK | F25: 28 | G25: tablet | H25: 4 months | I25: 3 months | J25: order by Product Family | K25: Pack | L25: 0.1 | M25: Celltrion Pharm | N25: Celltrion Pharm | O25: Finished Goods | P25: Korea - Cheongju - Ochang | Q25: 11440 | R25: 5.2 | S25: =+R25*1250 -> 6500 | T25: 6760 | U25: =+R25*1400 -> 7280 | V25: 7504 | W25: 7745 | X25: =W25-S25 -> 1245
S26: 사업계획 반영 단가 | W26: APAC 단가
B27: ■ 1분기 단가차이 영향
B47: Territory | C47: Product Family | D47: Batch Size (T) | E47: Minimum order Quatity (Pack) | F47: batch / Pack size | G47: Min | H47: Max | I47: Remarks | J47: Production Frequency for KR (approximated) | L47: Initial Production Shedule for KR
B48: N/A (TH+TW+HK) | C48: Edarbi 40mg | D48: 1400000 | E48: 50000 | F48: =D48/28 -> 50000 | G48: 1200000 | H48: 2550000
C49: Edarbi 80mg | D49: 700000 | E49: 25000 | F49: =D49/28 -> 25000 | G49: 25000 | H49: 50000 | I49: Co-planning Product | J49: Once / 3 Month | L49: on going
C50: Edarbyclor 40/12.5mg | D50: 800000 | E50: 28000 | F50: =D50/28 -> 28571.429 | G50: 84000 | H50: 196000
C51: Nesina 12.5mg | D51: 1000000 | E51: 35000 | F51: =D51/28 -> 35714.286 | G51: 70000 | H51: 105000 | I51: Co-planning Product | J51: Once / 2~3 Month | L51: Apr-25
C52: Nesina 25mg | D52: 1900000 | E52: 67000 | F52: =D52/28 -> 67857.143 | G52: 402000 | H52: 804000
C53: NesinaAct/Oseni 25/15mg | D53: 1500000 | E53: 53000 | F53: =D53/28 -> 53571.429 | G53: 159000 | H53: 265000
C54: NesinaAct/Oseni 25/30mg | D54: 1500000 | E54: 53000 | F54: =D54/28 -> 53571.429 | G54: 265000 | H54: 530000
C55: NesinaMet 12.5/500mg | D55: 300000 | E55: 10000 | F55: =D55/28 -> 10714.286 | G55: 10000 | H55: 10000 | I55: Co-planning Product | J55: Once / 2~3 Month | L55: Oct-25
C56: NesinaMet 12.5/1000mg | D56: 300000 | E56: 10000 | F56: =D56/28 -> 10714.286 | G56: 10000 | H56: 10000 | I56: Co-planning Product | J56: Once / 2~3 Month | L56: Sep-25

Sheet Sheet2

Sheet 상세 자료 작성 241025현실화
B1: ■ 주간 매출보고 자료 _ PO 기준
B2: 1) PO 기준 : | D2: 케미컬상업 | E2: 실질 PO 접수 기준
D3: PFS 상업 | E3: 2개월 100% Binding FCST 기준
D4: L&P 상업 | E4: 2개월 100% Binding FCST 기준
K5: 기준일자 : 2024-10-25
B6: 월 | C6: 주차 | D6: 법인 | E6: 구분 | F6: 상세구분 | G6: 매출실적 | H6: 사업계획 | I6: 예상마감 | J6: 달성률 | K6: 전주 예상 실적 | L6: Gap
B7: 1월 | C7: 1주차 | D7: 셀트리온제약 | E7: 용역 | F7: CMO상업_조달 | G7: 302597280 | H7: ='[1]2024년 계획_변경적용'!F45 -> 736312500 | I7: 302597280 | J7: =+I7/H7 -> 0.41096312 | K7: 302597280 | L7: =I7-K7 -> 0
C8: 1주차 | D8: 셀트리온제약 | E8: 용역 | F8: CMO상업_미국 | G8: 0 | H8: ='[1]2024년 계획_변경적용'!F44 -> 0 | I8: 0 | K8: 0 | L8: =I8-K8 -> 0
C9: 1주차 | D9: 셀트리온제약 | E9: 용역 | F9: CMO상업_내재화 | G9: 0 | H9: ='[1]2024년 계획_변경적용'!F48 -> 0 | I9: 0 | K9: 0 | L9: =I9-K9 -> 0
C10: 1주차 | D10: 셀트리온제약 | E10: 용역 | F10: CMO상업_L&P | G10: 1013747020 | H10: ='[1]2024년 계획_변경적용'!F46 -> 9.5931083e+08 | I10: 1013747020 | J10: =+I10/H10 -> 1.0567451 | K10: 1013747020 | L10: =I10-K10 -> 0
C11: 1주차 | D11: 셀트리온제약 | E11: 용역 | F11: CMO상업_PFS | G11: 4869898150 | H11: ='[1]2024년 계획_변경적용'!F47 -> 4405740000 | I11: 4869898150 | J11: =+I11/H11 -> 1.1053531 | K11: =5437734400-580000000 -> 4857734400 | L11: =I11-K11 -> 12163750
C12: 1주차 | D12: 셀트리온제약 | E12: 용역 | F12: CMO용역_GCP | G12: 0 | H12: ='[1]2024년 계획_변경적용'!F50 -> 0 | I12: 0 | K12: 0 | L12: =I12-K12 -> 0
C13: 1주차 | D13: 셀트리온제약 | E13: 용역 | F13: CMO용역_LCM | G13: 0 | H13: ='[1]2024년 계획_변경적용'!F53 -> 490500000 | I13: 0 | J13: =+I13/H13 -> 0 | K13: 0 | L13: =I13-K13 -> 0
C14: 1주차 | D14: 셀트리온제약 | E14: 용역 | F14: CMO용역_PFS | G14: 439139429 | H14: ='[1]2024년 계획_변경적용'!F51 -> 0 | I14: 439139429 | K14: 404210000 | L14: =I14-K14 -> 34929429
C15: 1주차 | D15: 셀트리온제약 | E15: 용역 | F15: CMO용역_내재화 | G15: 67266666 | H15: ='[1]2024년 계획_변경적용'!F52 -> 0 | I15: 67266666 | K15: 42700000 | L15: =I15-K15 -> 24566666
C16: 1주차 | D16: 셀트리온제약 | E16: 용역 | F16: 용역_QA위임 | G16: 39867000 | H16: 0 | I16: 39867000 | K16: 39867000 | L16: =I16-K16 -> 0
C17: 1월 예상 실적 | G17: =SUM(G7:G16) -> 6732515545 | H17: =SUM(H7:H16) -> 6.5918633e+09 | I17: =SUM(I7:I16) -> 6732515545 | J17: =G17/H17 -> 1.0213372 | K17: =SUM(K7:K16) -> 6660855700 | L17: =SUM(L7:L16) -> 71659845
B18: 2월 | C18: 1주차 | D18: 셀트리온제약 | E18: 용역 | F18: CMO상업_조달 | G18: 5372064744 | H18: ='[1]2024년 계획_변경적용'!G45 -> 3253527000 | I18: 5372064744 | J18: =+G18/H18 -> 1.6511511 | K18: 5372064744 | L18: =I18-K18 -> 0
C19: 1주차 | D19: 셀트리온제약 | E19: 용역 | F19: CMO상업_미국 | G19: 0 | H19: ='[1]2024년 계획_변경적용'!G44 -> 0 | I19: 0 | K19: 0 | L19: =I19-K19 -> 0
C20: 1주차 | D20: 셀트리온제약 | E20: 용역 | F20: CMO상업_내재화 | G20: 0 | H20: ='[1]2024년 계획_변경적용'!G48 -> 0 | I20: 0 | K20: 0 | L20: =I20-K20 -> 0
C21: 1주차 | D21: 셀트리온제약 | E21: 용역 | F21: CMO상업_L&P | G21: 684982200 | H21: ='[1]2024년 계획_변경적용'!G46 -> 9.5931083e+08 | I21: 684982200 | J21: =+G21/H21 -> 0.71403572 | K21: 684982200 | L21: =I21-K21 -> 0
C22: 1주차 | D22: 셀트리온제약 | E22: 용역 | F22: CMO상업_PFS | G22: 4437683550 | H22: ='[1]2024년 계획_변경적용'!G47 -> 4.7866246e+08 | I22: 4437683550 | K22: 4437583550 | L22: =I22-K22 -> 100000
C23: 1주차 | D23: 셀트리온제약 | E23: 용역 | F23: CMO용역_GCP | G23: 40000000 | H23: ='[1]2024년 계획_변경적용'!G50 -> 40000000 | I23: 40000000 | J23: =+G23/H23 -> 1 | K23: 40000000 | L23: =I23-K23 -> 0
C24: 1주차 | D24: 셀트리온제약 | E24: 용역 | F24: CMO용역_LCM | G24: 0 | H24: ='[1]2024년 계획_변경적용'!G53 -> 766500000 | I24: 0 | J24: =+G24/H24 -> 0 | K24: 0 | L24: =I24-K24 -> 0
C25: 1주차 | D25: 셀트리온제약 | E25: 용역 | F25: CMO용역_PFS | G25: 14069429 | H25: ='[1]2024년 계획_변경적용'!G51 -> 162000000 | I25: 14069429 | J25: =+G25/H25 -> 0.086848327 | K25: 0 | L25: =I25-K25 -> 14069429
C26: 1주차 | D26: 셀트리온제약 | E26: 용역 | F26: CMO용역_내재화 | G26: 119041667 | H26: ='[1]2024년 계획_변경적용'!G52 -> 93750000 | I26: 119041667 | J26: =+G26/H26 -> 1.2697778 | K26: 93750000 | L26: =I26-K26 -> 25291667
C27: 1주차 | D27: 셀트리온제약 | E27: 용역 | F27: 용역_QA위임 | G27: 31089600 | H27: 0 | I27: 31089600 | K27: 0 | L27: =I27-K27 -> 31089600
C28: 2월 실적 | G28: =SUM(G18:G27) -> 10698931190 | H28: =SUM(H18:H27) -> 5.7537503e+09 | I28: =SUM(I18:I27) -> 10698931190 | J28: =G28/H28 -> 1.8594709 | K28: =SUM(K18:K27) -> 10628380494 | L28: =SUM(L18:L27) -> 70550696
B29: 3월 | C29: 4주차 | D29: 셀트리온제약 | E29: 용역 | F29: CMO상업_조달 | G29: 2967439150 | H29: 2762644500 | I29: 2967439150 | J29: =+G29/H29 -> 1.0741299 | K29: 2953104000 | L29: =I29-K29 -> 14335150
C30: 4주차 | D30: 셀트리온제약 | E30: 용역 | F30: CMO상업_미국 | G30: 0 | H30: 0 | I30: 0 | J30: =+G30/H30 -> #DIV/0! | K30: 0 | L30: =I30-K30 -> 0
C31: 1주차 | D31: 셀트리온제약 | E31: 용역 | F31: CMO상업_내재화 | G31: 0 | H31: 0 | I31: 0 | K31: 0 | L31: =I31-K31 -> 0
C32: 4주차 | D32: 셀트리온제약 | E32: 용역 | F32: CMO상업_L&P | G32: 1047403520 | H32: 9.5931083e+08 | I32: 1047403520 | J32: =+G32/H32 -> 1.0918291 | K32: 9.5931083e+08 | L32: =I32-K32 -> 88092692
C33: 4주차 | D33: 셀트리온제약 | E33: 용역 | F33: CMO상업_PFS | G33: 4508694300 | H33: 4.7344899e+09 | I33: 4508694300 | J33: =+G33/H33 -> 0.95230835 | K33: 4275201700 | L33: =I33-K33 -> 233492600
C34: 4주차 | D34: 셀트리온제약 | E34: 용역 | F34: CMO용역_GCP | G34: 0 | H34: 0 | I34: 0 | K34: 0 | L34: =I34-K34 -> 0
C35: 4주차 | D35: 셀트리온제약 | E35: 용역 | F35: CMO용역_LCM | G35: 520375000 | H35: 1666750000 | I35: 520375000 | J35: =+G35/H35 -> 0.31220939 | K35: 520375000 | L35: =I35-K35 -> 0
C36: 4주차 | D36: 셀트리온제약 | E36: 용역 | F36: CMO용역_PFS | G36: 421269829 | H36: 5.06e+08 | I36: 421269829 | J36: =+G36/H36 -> 0.83254907 | K36: 422269429 | L36: =I36-K36 -> -999600
C37: 4주차 | D37: 셀트리온제약 | E37: 용역 | F37: CMO용역_내재화 | G37: 25291667 | H37: 361875000 | I37: 25291667 | J37: =+G37/H37 -> 0.069890617 | K37: 212791667 | L37: =I37-K37 -> -187500000
C38: 1주차 | D38: 셀트리온제약 | E38: 용역 | F38: 용역_QA위임 | G38: 41874000 | H38: 0 | I38: 41874000 | J38: =+I38/H38 -> #DIV/0! | K38: 0 | L38: =I38-K38 -> 41874000
C39: 3월 실적 | G39: =SUM(G29:G38) -> 9532347466 | H39: =SUM(H29:H38) -> 1.099107e+10 | I39: =SUM(I29:I38) -> 9532347466 | J39: =G39/H39 -> 0.8672811 | K39: =SUM(K29:K38) -> 9.3430526e+09 | L39: =SUM(L29:L38) -> 1.8929484e+08
B40: 1분기 실적 | G40: =G28+G17+G39 -> 26963794201 | H40: =H39+H28+H17 -> 2.3336684e+10 | I40: =I39+I28+I17 -> 26963794201 | J40: =I40/H40 -> 1.1554253 | K40: =K39+K28+K17 -> 2.6632289e+10 | L40: =L39+L28+L17 -> 3.3150538e+08
...

Sheet 2024년 계획_변경적용
B2: □ 2024년 매출 계획
B4: 사업계획_구분1 | C4: 경영정보통합 | D4: 사업계획_구분3 | E4: 사업계획_구분4 | F4: 1월 | G4: 2월 | H4: 3월 | I4: 4월 | J4: 5월 | K4: 6월 | L4: 7월 | M4: 8월 | N4: 9월 | O4: 10월 | P4: 11월 | Q4: 12월 | R4: 2024년 계획 합계 | T4: 2월 누계 | U4: 3월 누계 | V4: 4월 누계 | W4: 5월 누계 | X4: 6월 누계 | Y4: 7월 누계 | Z4: 8월 누계 | AA4: 9월 누계 | AB4: 10월 누계 | AC4: 11월 누계 | AE4: 1분기 | AF4: 2분기 | AG4: 3분기 | AH4: 4분기
B5: 케미컬 | C5: 고덱스 | D5: 고덱스 | E5: 고덱스캡슐 | F5: 2.8215448e+09 | G5: 4.2323172e+09 | H5: 7.0538621e+09 | I5: 3.775695e+09 | J5: 5.6635424e+09 | K5: 9.4392374e+09 | L5: 3.0837976e+09 | M5: 4.6256963e+09 | N5: 7.7094939e+09 | O5: 3.3189627e+09 | P5: 4.978444e+09 | Q5: 8.2974066e+09 | R5: =SUM(F5:Q5) -> 6.5e+10 | T5: =SUM(F5:G5) -> 7.0538621e+09 | U5: =T5+H5 -> 1.4107724e+10 | V5: =U5+I5 -> 1.7883419e+10 | W5: =V5+J5 -> 2.3546962e+10 | X5: =W5+K5 -> 3.2986199e+10 | Y5: =X5+L5 -> 3.6069996e+10 | Z5: =Y5+M5 -> 4.0695693e+10 | AA5: =Z5+N5 -> 4.8405187e+10 | AB5: =AA5+O5 -> 5.1724149e+10 | AC5: =AB5+P5 -> 5.6702593e+10 | AE5: =SUM(F5:H5) -> 1.4107724e+10 | AF5: =SUM(I5:K5) -> 1.8878475e+10 | AG5: =SUM(L5:N5) -> 1.5418988e+10 | AH5: =SUM(O5:Q5) -> 1.6594813e+10
B6: 케미컬 | C6: 고덱스 | D6: 고덱스 | E6: 고덱스정 | F6: 0 | G6: 0 | H6: 0 | I6: 0 | J6: 0 | K6: 0 | L6: 0 | M6: 0 | N6: 0 | O6: 0 | P6: 0 | Q6: 0 | R6: =SUM(F6:Q6) -> 0 | T6: =SUM(F6:G6) -> 0 | U6: =T6+H6 -> 0 | V6: =U6+I6 -> 0 | W6: =V6+J6 -> 0 | X6: =W6+K6 -> 0 | Y6: =X6+L6 -> 0 | Z6: =Y6+M6 -> 0 | AA6: =Z6+N6 -> 0 | AB6: =AA6+O6 -> 0 | AC6: =AB6+P6 -> 0 | AE6: =SUM(F6:H6) -> 0 | AF6: =SUM(I6:K6) -> 0 | AG6: =SUM(L6:N6) -> 0 | AH6: =SUM(O6:Q6) -> 0
B7: 케미컬 | C7: 제품기타 | D7: 약가보상(케미컬) | E7: 약가보상(케미컬) | F7: 0 | G7: 0 | H7: 0 | I7: 0 | J7: 0 | K7: 0 | L7: 0 | M7: 0 | N7: 0 | O7: 0 | P7: 0 | Q7: 0 | R7: =SUM(F7:Q7) -> 0 | T7: =SUM(F7:G7) -> 0 | U7: =T7+H7 -> 0 | V7: =U7+I7 -> 0 | W7: =V7+J7 -> 0 | X7: =W7+K7 -> 0 | Y7: =X7+L7 -> 0 | Z7: =Y7+M7 -> 0 | AA7: =Z7+N7 -> 0 | AB7: =AA7+O7 -> 0 | AC7: =AB7+P7 -> 0 | AE7: =SUM(F7:H7) -> 0 | AF7: =SUM(I7:K7) -> 0 | AG7: =SUM(L7:N7) -> 0 | AH7: =SUM(O7:Q7) -> 0
B8: 케미컬 | C8: 도네리온 | D8: 도네리온 | E8: 도네리온 | F8: 99309184 | G8: 1.4896378e+08 | H8: 2.4827296e+08 | I8: 1.3289216e+08 | J8: 1.9933824e+08 | K8: 3.322304e+08 | L8: 1.0853963e+08 | M8: 1.6280944e+08 | N8: 2.7134907e+08 | O8: 1.1686812e+08 | P8: 1.7530218e+08 | Q8: 2.921703e+08 | R8: =SUM(F8:Q8) -> 2.2880455e+09 | T8: =SUM(F8:G8) -> 2.4827296e+08 | U8: =T8+H8 -> 4.9654592e+08 | V8: =U8+I8 -> 6.2943808e+08 | W8: =V8+J8 -> 8.2877632e+08 | X8: =W8+K8 -> 1.1610067e+09 | Y8: =X8+L8 -> 1.2695463e+09 | Z8: =Y8+M8 -> 1.4323558e+09 | AA8: =Z8+N8 -> 1.7037049e+09 | AB8: =AA8+O8 -> 1.820573e+09 | AC8: =AB8+P8 -> 1.9958752e+09 | AE8: =SUM(F8:H8) -> 4.9654592e+08 | AF8: =SUM(I8:K8) -> 6.644608e+08 | AG8: =SUM(L8:N8) -> 5.4269813e+08 | AH8: =SUM(O8:Q8) -> 5.843406e+08
