Workbook
Name _: #N/A
Name _____________________________BRD1: #REF!
Name _____________________________BRD2: #REF!
Name _____________________________BRD3: #REF!
Name _____________________________BRD4: #REF!
Name _____________________________BRD5: #REF!
Name _____________________________BRD6: #REF!
Name _____________________________BRD7: #REF!
Name _____________________________INT1: #REF!
Name _____________________________INT2: #REF!
Name _____________________________INT3: #REF!
Name _____________________________INT4: #REF!
Name _____________________________INT5: #REF!
Name _____________________________INT6: #REF!
Name _____________________________INT7: #REF!
Name _____________________________LIC1: #REF!
Name _____________________________LIC2: #REF!
Name _____________________________LIC3: #REF!
Name _____________________________LIC4: #REF!
Name _____________________________LIC5: #REF!
Name _____________________________LIC6: #REF!
Name _____________________________LIC7: #REF!
Name _____________________________PG1: #REF!
Name _____________________________PG11: #REF!
Name _____________________________PG13: #REF!
Name _____________________________PG17: #REF!
Name _____________________________PG2: #REF!
Name _____________________________PG3: #REF!
Name _____________________________PG4: #REF!
Name _____________________________PG5: #REF!
Name _____________________________PG6: #REF!
Name _____________________________PG7: #REF!
Name _____________________________PG9: #REF!
Name _____________________________SUM25: #REF!
Name ____________________________BRD1: #REF!
Name ____________________________BRD2: #REF!
Name ____________________________BRD3: #REF!
Name ____________________________BRD4: #REF!
Name ____________________________BRD5: #REF!
Name ____________________________BRD6: #REF!
Name ____________________________BRD7: #REF!
Name ____________________________INT1: #REF!
Name ____________________________INT2: #REF!
Name ____________________________INT3: #REF!
Name ____________________________INT4: #REF!
Name ____________________________INT5: #REF!
Name ____________________________INT6: #REF!
Name ____________________________INT7: #REF!
Name ____________________________LIC1: #REF!
Name ____________________________LIC2: #REF!
Name ____________________________LIC3: #REF!
Name ____________________________LIC4: #REF!
Name ____________________________LIC5: #REF!
Name ____________________________LIC6: #REF!
Name ____________________________LIC7: #REF!
Name ____________________________PG1: #REF!
Name ____________________________PG11: #REF!
Name ____________________________PG13: #REF!
Name ____________________________PG17: #REF!
Name ____________________________PG2: #REF!

Sheet 요약(보고)
A1: 26년 CMO 매출 예상실적
Y2: 2026.03.26
A3: ■ 1분기 매출 | F3: 2분기
F4: 1분기 | J4: 1월 | N4: 2월 | R4: 3월 | Y4: 단위 : 억원
A5: 구분 | D5: 25년 실적 | E5: 26년 목표 | F5: 25년 1분기 누계 | J5: 1분기 | V5: 1분기 소계 | Z5: 26년 예상 실적
J6: 1월 | N6: 2월 | R6: 3월
F7: 25년 실적 | G7: 사업 계획 | H7: 실적 | I7: 차이 | J7: 25년 실적 | K7: 사업 계획 | L7: 실적 | M7: 차이 | N7: 25년 실적 | O7: 사업 계획 | P7: 실적 | Q7: 차이 | R7: 25년 실적 | S7: 사업 계획 | T7: 실적 | U7: 차이 | V7: 25년 실적 | W7: 사업 계획 | X7: 실적 | Y7: 차이 | Z7: 25년 실적 | AA7: 사업 계획 | AB7: 실적 | AC7: 차이
B8: CMO 합계 | D8: =SUM(D15,D12,D9) -> 1392.7058 | E8: =AA8 -> 1559.2256 | F8: =V8 -> 275.49898 | G8: =W8 -> 313.38771 | H8: =X8 -> 333.85101 | I8: =Y8 -> 20.463298 | J8: =J9+J12+J15 -> 112.83448 | K8: =K9+K12+K15 -> 100.91695 | L8: =L9+L12+L15 -> 101.87285 | M8: =L8-K8 -> 0.9559079 | N8: =N9+N12+N15 -> 67.616613 | O8: =O9+O12+O15 -> 107.7245 | P8: =P9+P12+P15 -> 117.68066 | Q8: =P8-O8 -> 9.9561553 | R8: =R9+R12+R15 -> 95.047888 | S8: =S9+S12+S15 -> 104.74626 | T8: =T9+T12+T15 -> 114.2975 | U8: =T8-S8 -> 9.5512351 | V8: =V9+V12+V15 -> 275.49898 | W8: =W9+W12+W15 -> 313.38771 | X8: =X9+X12+X15 -> 333.85101 | Y8: =X8-W8 -> 20.463298 | Z8: =Z9+Z12+Z15 -> 1393.0161 | AA8: =AA9+AA12+AA15 -> 1559.2256 | AB8: =AB9+AB12+AB15 -> 1668.2024 | AC8: =AB8-AA8 -> 108.97675 | AE8: 24년
B9: 케미컬 상업 | D9: =SUM(D10:D11) -> 152.99419 | E9: =AA9 -> 170.99974 | F9: =V9 -> 17.979459 | G9: =W9 -> 25.134453 | H9: =X9 -> 27.58882 | I9: =Y9 -> 2.4543664 | J9: =SUM(J10:J11) -> 3.0051884 | K9: =SUM(K10:K11) -> 3.2706278 | L9: =SUM(L10:L11) -> 3.1851236 | M9: =SUM(M10:M11) -> -0.085504183 | N9: =SUM(N10:N11) -> 12.609455 | O9: =SUM(O10:O11) -> 12.254069 | P9: =SUM(P10:P11) -> 9.6746168 | Q9: =SUM(Q10:Q11) -> -2.5794522 | ... AC9: =SUM(AC10:AC11) -> 5.5079186 | AE9: 25년
C10: 내재화 | D10: 152.99419 | E10: =AA10 -> 168.95436 | F10: =SUMIFS('상세 자료 작성'!$I:$I,'상세 자료 작성'!$C:$C,'요약(보고)'!$C10,'상세 자료 작성'!$A:$A,'요약(보고)'!$AE$9,'상세 자료 작성'!$B:$B,'요약(보고)'!$F$4)/10^8 -> 17.979459 | G10: =SUMIFS('상세 자료 작성'!$J:$J,'상세 자료 작성'!$C:$C,'요약(보고)'!$C10,'상세 자료 작성'!$A:$A,$AE$11,'상세 자료 작성'!$B:$B,'요약(보고)'!$F$4)/10^8 -> 24.623108 | H10: =SUMIFS('상세 자료 작성'!$K:$K,'상세 자료 작성'!$C:$C,'요약(보고)'!$C10,'상세 자료 작성'!$A:$A,$AE$11,'상세 자료 작성'!$B:$B,'요약(보고)'!$F$4)/10^8 -> 27.58882 | I10: =Y10 -> 2.9657114 | J10: =SUMIFS('상세 자료 작성'!$I:$I,'상세 자료 작성'!$C:$C,'요약(보고)'!$C10,'상세 자료 작성'!$A:$A,'요약(보고)'!$AE$9,'상세 자료 작성'!$D:$D,$J$4)/10^8 -> 3.0051884 | K10: =SUMIFS('상세 자료 작성'!$J:$J,'상세 자료 작성'!$C:$C,'요약(보고)'!$C10,'상세 자료 작성'!$A:$A,$AE$11,'상세 자료 작성'!$D:$D,'요약(보고)'!$J$4)/10^8 -> 3.1001795 | L10: =SUMIFS('상세 자료 작성'!$K:$K,'상세 자료 작성'!$C:$C,'요약(보고)'!$C10,'상세 자료 작성'!$A:$A,$AE$11,'상세 자료 작성'!$D:$D,$J$4)/10^8 -> 3.1851236 | M10: =L10-K10 -> 0.08494415 | N10: =SUMIFS('상세 자료 작성'!$I:$I,'상세 자료 작성'!$C:$C,'요약(보고)'!$C10,'상세 자료 작성'!$A:$A,'요약(보고)'!$AE$9,'상세 자료 작성'!$D:$D,$N$4)/10^8 -> 12.609455 | O10: =SUMIFS('상세 자료 작성'!$J:$J,'상세 자료 작성'!$C:$C,'요약(보고)'!$C10,'상세 자료 작성'!$A:$A,$AE$11,'상세 자료 작성'!$D:$D,$N$4)/10^8 -> 12.083621 | P10: =SUMIFS('상세 자료 작성'!$K:$K,'상세 자료 작성'!$C:$C,'요약(보고)'!$C10,'상세 자료 작성'!$A:$A,$AE$11,'상세 자료 작성'!$D:$D,$N$4)/10^8 -> 9.6746168 | Q10: =P10-O10 -> -2.4090038 | R10: =SUMIFS('상세 자료 작성'!$I:$I,'상세 자료 작성'!$C:$C,'요약(보고)'!$C10,'상세 자료 작성'!$A:$A,'요약(보고)'!$AE$9,'상세 자료 작성'!$D:$D,$R$4)/10^8 -> 2.3648161 | S10: =SUMIFS('상세 자료 작성'!$J:$J,'상세 자료 작성'!$C:$C,'요약(보고)'!$C10,'상세 자료 작성'!$A:$A,$AE$11,'상세 자료 작성'!$D:$D,$R$4)/10^8 -> 9.439308 | T10: =SUMIFS('상세 자료 작성'!$K:$K,'상세 자료 작성'!$C:$C,'요약(보고)'!$C10,'상세 자료 작성'!$A:$A,$AE$11,'상세 자료 작성'!$D:$D,$R$4)/10^8 -> 14.729079 | U10: =T10-S10 -> 5.2897711 | V10: =R10+J10+N10 -> 17.979459 | W10: =S10+K10+O10 -> 24.623108 | X10: =T10+L10+P10 -> 27.58882 | Y10: =X10-W10 -> 2.9657114 | Z10: =SUMIFS('상세 자료 작성'!$I:$I,'상세 자료 작성'!$C:$C,'요약(보고)'!$C10,'상세 자료 작성'!$A:$A,'요약(보고)'!$AE$9)/10^8 -> 152.99419 | AA10: =SUMIFS('상세 자료 작성'!$J:$J,'상세 자료 작성'!$C:$C,'요약(보고)'!$C10,'상세 자료 작성'!$A:$A,'요약(보고)'!$AE$11)/10^8 -> 168.95436 | AB10: =SUMIFS('상세 자료 작성'!$K:$K,'상세 자료 작성'!$C:$C,'요약(보고)'!$C10,'상세 자료 작성'!$A:$A,'요약(보고)'!$AE$11)/10^8 -> 174.97362 | AC10: =AB10-AA10 -> 6.0192636
C11: 기타(위임형 등) | D11: 0 | E11: =AA11 -> 2.04538 | F11: =SUMIFS('상세 자료 작성'!$I:$I,'상세 자료 작성'!$C:$C,'요약(보고)'!$C11,'상세 자료 작성'!$A:$A,'요약(보고)'!$AE$9,'상세 자료 작성'!$B:$B,'요약(보고)'!$F$4)/10^8 -> 0 | G11: =SUMIFS('상세 자료 작성'!$J:$J,'상세 자료 작성'!$C:$C,'요약(보고)'!$C11,'상세 자료 작성'!$A:$A,$AE$11,'상세 자료 작성'!$B:$B,'요약(보고)'!$F$4)/10^8 -> 0.511345 | H11: =SUMIFS('상세 자료 작성'!$K:$K,'상세 자료 작성'!$C:$C,'요약(보고)'!$C11,'상세 자료 작성'!$A:$A,$AE$11,'상세 자료 작성'!$B:$B,'요약(보고)'!$F$4)/10^8 -> 0 | I11: =Y11 -> -0.511345 | J11: =SUMIFS('상세 자료 작성'!$I:$I,'상세 자료 작성'!$C:$C,'요약(보고)'!$C11,'상세 자료 작성'!$A:$A,'요약(보고)'!$AE$9,'상세 자료 작성'!$D:$D,$J$4)/10^8 -> 0 | K11: =SUMIFS('상세 자료 작성'!$J:$J,'상세 자료 작성'!$C:$C,'요약(보고)'!$C11,'상세 자료 작성'!$A:$A,$AE$11,'상세 자료 작성'!$D:$D,'요약(보고)'!$J$4)/10^8 -> 0.17044833 | L11: =SUMIFS('상세 자료 작성'!$K:$K,'상세 자료 작성'!$C:$C,'요약(보고)'!$C11,'상세 자료 작성'!$A:$A,$AE$11,'상세 자료 작성'!$D:$D,$J$4)/10^8 -> 0 | M11: =L11-K11 -> -0.17044833 | N11: =SUMIFS('상세 자료 작성'!$I:$I,'상세 자료 작성'!$C:$C,'요약(보고)'!$C11,'상세 자료 작성'!$A:$A,'요약(보고)'!$AE$9,'상세 자료 작성'!$D:$D,$N$4)/10^8 -> 0 | O11: =SUMIFS('상세 자료 작성'!$J:$J,'상세 자료 작성'!$C:$C,'요약(보고)'!$C11,'상세 자료 작성'!$A:$A,$AE$11,'상세 자료 작성'!$D:$D,$N$4)/10^8 -> 0.17044833 | P11: =SUMIFS('상세 자료 작성'!$K:$K,'상세 자료 작성'!$C:$C,'요약(보고)'!$C11,'상세 자료 작성'!$A:$A,$AE$11,'상세 자료 작성'!$D:$D,$N$4)/10^8 -> 0 | Q11: =P11-O11 -> -0.17044833 | R11: =SUMIFS('상세 자료 작성'!$I:$I,'상세 자료 작성'!$C:$C,'요약(보고)'!$C11,'상세 자료 작성'!$A:$A,'요약(보고)'!$AE$9,'상세 자료 작성'!$D:$D,$R$4)/10^8 -> 0 | S11: =SUMIFS('상세 자료 작성'!$J:$J,'상세 자료 작성'!$C:$C,'요약(보고)'!$C11,'상세 자료 작성'!$A:$A,$AE$11,'상세 자료 작성'!$D:$D,$R$4)/10^8 -> 0.17044833 | T11: =SUMIFS('상세 자료 작성'!$K:$K,'상세 자료 작성'!$C:$C,'요약(보고)'!$C11,'상세 자료 작성'!$A:$A,$AE$11,'상세 자료 작성'!$D:$D,$R$4)/10^8 -> 0 | U11: =T11-S11 -> -0.17044833 | V11: =R11+J11+N11 -> 0 | W11: =S11+K11+O11 -> 0.511345 | X11: =T11+L11+P11 -> 0 | Y11: =X11-W11 -> -0.511345 | Z11: =SUMIFS('상세 자료 작성'!$I:$I,'상세 자료 작성'!$C:$C,'요약(보고)'!$C11,'상세 자료 작성'!$A:$A,'요약(보고)'!$AE$9)/10^8 -> 0 | AA11: =SUMIFS('상세 자료 작성'!$J:$J,'상세 자료 작성'!$C:$C,'요약(보고)'!$C11,'상세 자료 작성'!$A:$A,'요약(보고)'!$AE$11)/10^8 -> 2.04538 | AB11: =SUMIFS('상세 자료 작성'!$K:$K,'상세 자료 작성'!$C:$C,'요약(보고)'!$C11,'상세 자료 작성'!$A:$A,'요약(보고)'!$AE$11)/10^8 -> 1.534035 | AC11: =AB11-AA11 -> -0.511345 | AE11: 26년
B12: 바이오 상업 | D12: =SUM(D13:D14) -> 1088.9227 | E12: =AA12 -> 1191.1256 | F12: =V12 -> 203.6367 | G12: =W12 -> 246.45126 | H12: =X12 -> 266.20901 | I12: =Y12 -> 19.75775 | J12: =SUM(J13:J14) -> 76.029623 | K12: =SUM(K13:K14) -> 71.643068 | L12: =SUM(L13:L14) -> 71.637462 | M12: =SUM(M13:M14) -> -0.0056064 | N12: =SUM(N13:N14) -> 54.348994 | O12: =SUM(O13:O14) -> 90.822934 | P12: =SUM(P13:P14) -> 102.89946 | Q12: =SUM(Q13:Q14) -> 12.076528 | ... AC12: =SUM(AC13:AC14) -> 120.46395
C13: PFS | D13: 1041.7819 | E13: =AA13 -> 1143.4515 | F13: =SUMIFS('상세 자료 작성'!$I:$I,'상세 자료 작성'!$C:$C,'요약(보고)'!$C13,'상세 자료 작성'!$A:$A,'요약(보고)'!$AE$9,'상세 자료 작성'!$B:$B,'요약(보고)'!$F$4)/10^8 -> 189.04806 | G13: =SUMIFS('상세 자료 작성'!$J:$J,'상세 자료 작성'!$C:$C,'요약(보고)'!$C13,'상세 자료 작성'!$A:$A,$AE$11,'상세 자료 작성'!$B:$B,'요약(보고)'!$F$4)/10^8 -> 238.39926 | H13: =SUMIFS('상세 자료 작성'!$K:$K,'상세 자료 작성'!$C:$C,'요약(보고)'!$C13,'상세 자료 작성'!$A:$A,$AE$11,'상세 자료 작성'!$B:$B,'요약(보고)'!$F$4)/10^8 -> 256.66706 | I13: =Y13 -> 18.267803 | J13: =SUMIFS('상세 자료 작성'!$I:$I,'상세 자료 작성'!$C:$C,'요약(보고)'!$C13,'상세 자료 작성'!$A:$A,'요약(보고)'!$AE$9,'상세 자료 작성'!$D:$D,$J$4)/10^8 -> 69.842789 | K13: =SUMIFS('상세 자료 작성'!$J:$J,'상세 자료 작성'!$C:$C,'요약(보고)'!$C13,'상세 자료 작성'!$A:$A,$AE$11,'상세 자료 작성'!$D:$D,'요약(보고)'!$J$4)/10^8 -> 68.990503 | L13: =SUMIFS('상세 자료 작성'!$K:$K,'상세 자료 작성'!$C:$C,'요약(보고)'!$C13,'상세 자료 작성'!$A:$A,$AE$11,'상세 자료 작성'!$D:$D,$J$4)/10^8 -> 69.064124 | M13: =L13-K13 -> 0.073621 | N13: =SUMIFS('상세 자료 작성'!$I:$I,'상세 자료 작성'!$C:$C,'요약(보고)'!$C13,'상세 자료 작성'!$A:$A,'요약(보고)'!$AE$9,'상세 자료 작성'!$D:$D,$N$4)/10^8 -> 49.969541 | O13: =SUMIFS('상세 자료 작성'!$J:$J,'상세 자료 작성'!$C:$C,'요약(보고)'!$C13,'상세 자료 작성'!$A:$A,$AE$11,'상세 자료 작성'!$D:$D,$N$4)/10^8 -> 88.077118 | P13: =SUMIFS('상세 자료 작성'!$K:$K,'상세 자료 작성'!$C:$C,'요약(보고)'!$C13,'상세 자료 작성'!$A:$A,$AE$11,'상세 자료 작성'!$D:$D,$N$4)/10^8 -> 100.10609 | Q13: =P13-O13 -> 12.028973 | R13: =SUMIFS('상세 자료 작성'!$I:$I,'상세 자료 작성'!$C:$C,'요약(보고)'!$C13,'상세 자료 작성'!$A:$A,'요약(보고)'!$AE$9,'상세 자료 작성'!$D:$D,$R$4)/10^8 -> 69.235728 | S13: =SUMIFS('상세 자료 작성'!$J:$J,'상세 자료 작성'!$C:$C,'요약(보고)'!$C13,'상세 자료 작성'!$A:$A,$AE$11,'상세 자료 작성'!$D:$D,$R$4)/10^8 -> 81.331637 | T13: =SUMIFS('상세 자료 작성'!$K:$K,'상세 자료 작성'!$C:$C,'요약(보고)'!$C13,'상세 자료 작성'!$A:$A,$AE$11,'상세 자료 작성'!$D:$D,$R$4)/10^8 -> 87.496846 | U13: =T13-S13 -> 6.1652085 | V13: =R13+J13+N13 -> 189.04806 | W13: =S13+K13+O13 -> 238.39926 | X13: =T13+L13+P13 -> 256.66706 | Y13: =X13-W13 -> 18.267803 | Z13: =SUMIFS('상세 자료 작성'!$I:$I,'상세 자료 작성'!$C:$C,'요약(보고)'!$C13,'상세 자료 작성'!$A:$A,'요약(보고)'!$AE$9)/10^8 -> 1041.7819 | AA13: =SUMIFS('상세 자료 작성'!$J:$J,'상세 자료 작성'!$C:$C,'요약(보고)'!$C13,'상세 자료 작성'!$A:$A,'요약(보고)'!$AE$11)/10^8 -> 1143.4515 | AB13: =SUMIFS('상세 자료 작성'!$K:$K,'상세 자료 작성'!$C:$C,'요약(보고)'!$C13,'상세 자료 작성'!$A:$A,'요약(보고)'!$AE$11)/10^8 -> 1262.4489 | AC13: =AB13-AA13 -> 118.99743
C14: L&P | D14: 47.140793 | E14: =AA14 -> 47.674149 | F14: =SUMIFS('상세 자료 작성'!$I:$I,'상세 자료 작성'!$C:$C,'요약(보고)'!$C14,'상세 자료 작성'!$A:$A,'요약(보고)'!$AE$9,'상세 자료 작성'!$B:$B,'요약(보고)'!$F$4)/10^8 -> 14.588646 | G14: =SUMIFS('상세 자료 작성'!$J:$J,'상세 자료 작성'!$C:$C,'요약(보고)'!$C14,'상세 자료 작성'!$A:$A,$AE$11,'상세 자료 작성'!$B:$B,'요약(보고)'!$F$4)/10^8 -> 8.0520014 | H14: =SUMIFS('상세 자료 작성'!$K:$K,'상세 자료 작성'!$C:$C,'요약(보고)'!$C14,'상세 자료 작성'!$A:$A,$AE$11,'상세 자료 작성'!$B:$B,'요약(보고)'!$F$4)/10^8 -> 9.5419484 | I14: =Y14 -> 1.489947 | J14: =SUMIFS('상세 자료 작성'!$I:$I,'상세 자료 작성'!$C:$C,'요약(보고)'!$C14,'상세 자료 작성'!$A:$A,'요약(보고)'!$AE$9,'상세 자료 작성'!$D:$D,$J$4)/10^8 -> 6.1868338 | K14: =SUMIFS('상세 자료 작성'!$J:$J,'상세 자료 작성'!$C:$C,'요약(보고)'!$C14,'상세 자료 작성'!$A:$A,$AE$11,'상세 자료 작성'!$D:$D,'요약(보고)'!$J$4)/10^8 -> 2.652565 | L14: =SUMIFS('상세 자료 작성'!$K:$K,'상세 자료 작성'!$C:$C,'요약(보고)'!$C14,'상세 자료 작성'!$A:$A,$AE$11,'상세 자료 작성'!$D:$D,$J$4)/10^8 -> 2.5733376 | M14: =L14-K14 -> -0.0792274 | N14: =SUMIFS('상세 자료 작성'!$I:$I,'상세 자료 작성'!$C:$C,'요약(보고)'!$C14,'상세 자료 작성'!$A:$A,'요약(보고)'!$AE$9,'상세 자료 작성'!$D:$D,$N$4)/10^8 -> 4.3794528 | O14: =SUMIFS('상세 자료 작성'!$J:$J,'상세 자료 작성'!$C:$C,'요약(보고)'!$C14,'상세 자료 작성'!$A:$A,$AE$11,'상세 자료 작성'!$D:$D,$N$4)/10^8 -> 2.7458164 | P14: =SUMIFS('상세 자료 작성'!$K:$K,'상세 자료 작성'!$C:$C,'요약(보고)'!$C14,'상세 자료 작성'!$A:$A,$AE$11,'상세 자료 작성'!$D:$D,$N$4)/10^8 -> 2.7933716 | Q14: =P14-O14 -> 0.0475552 | R14: =SUMIFS('상세 자료 작성'!$I:$I,'상세 자료 작성'!$C:$C,'요약(보고)'!$C14,'상세 자료 작성'!$A:$A,'요약(보고)'!$AE$9,'상세 자료 작성'!$D:$D,$R$4)/10^8 -> 4.0223598 | S14: =SUMIFS('상세 자료 작성'!$J:$J,'상세 자료 작성'!$C:$C,'요약(보고)'!$C14,'상세 자료 작성'!$A:$A,$AE$11,'상세 자료 작성'!$D:$D,$R$4)/10^8 -> 2.65362 | T14: =SUMIFS('상세 자료 작성'!$K:$K,'상세 자료 작성'!$C:$C,'요약(보고)'!$C14,'상세 자료 작성'!$A:$A,$AE$11,'상세 자료 작성'!$D:$D,$R$4)/10^8 -> 4.1752392 | U14: =T14-S14 -> 1.5216192 | V14: =R14+J14+N14 -> 14.588646 | W14: =S14+K14+O14 -> 8.0520014 | X14: =T14+L14+P14 -> 9.5419484 | Y14: =X14-W14 -> 1.489947 | Z14: =SUMIFS('상세 자료 작성'!$I:$I,'상세 자료 작성'!$C:$C,'요약(보고)'!$C14,'상세 자료 작성'!$A:$A,'요약(보고)'!$AE$9)/10^8 -> 48.130793 | AA14: =SUMIFS('상세 자료 작성'!$J:$J,'상세 자료 작성'!$C:$C,'요약(보고)'!$C14,'상세 자료 작성'!$A:$A,'요약(보고)'!$AE$11)/10^8 -> 47.674149 | AB14: =SUMIFS('상세 자료 작성'!$K:$K,'상세 자료 작성'!$C:$C,'요약(보고)'!$C14,'상세 자료 작성'!$A:$A,'요약(보고)'!$AE$11)/10^8 -> 49.140677 | AC14: =AB14-AA14 -> 1.4665282
B15: 개발 용역 | D15: =SUM(D16:D19) -> 150.78896 | E15: =AA15 -> 197.10025 | F15: =V15 -> 53.882818 | G15: =W15 -> 41.802 | H15: =X15 -> 40.053182 | I15: =Y15 -> -1.7488176 | J15: =SUM(J16:J19) -> 33.799671 | K15: =SUM(K16:K19) -> 26.00325 | L15: =SUM(L16:L19) -> 27.050268 | M15: =SUM(M16:M19) -> 1.0470185 | N15: =SUM(N16:N19) -> 0.65816414 | O15: =SUM(O16:O19) -> 4.6475 | P15: =SUM(P16:P19) -> 5.1065793 | Q15: =SUM(Q16:Q19) -> 0.45907929 | ... AC15: =SUM(AC16:AC19) -> -16.995118
C16: PFS 개발 | D16: 116.21935 | E16: =AA16 -> 179.7765 | F16: =SUMIFS('상세 자료 작성'!$I:$I,'상세 자료 작성'!$C:$C,'요약(보고)'!$C16,'상세 자료 작성'!$A:$A,'요약(보고)'!$AE$9,'상세 자료 작성'!$B:$B,'요약(보고)'!$F$4)/10^8 -> 42.27486 | G16: =SUMIFS('상세 자료 작성'!$J:$J,'상세 자료 작성'!$C:$C,'요약(보고)'!$C16,'상세 자료 작성'!$A:$A,$AE$11,'상세 자료 작성'!$B:$B,'요약(보고)'!$F$4)/10^8 -> 35.327 | H16: =SUMIFS('상세 자료 작성'!$K:$K,'상세 자료 작성'!$C:$C,'요약(보고)'!$C16,'상세 자료 작성'!$A:$A,$AE$11,'상세 자료 작성'!$B:$B,'요약(보고)'!$F$4)/10^8 -> 34.321651 | I16: =Y16 -> -1.0053493 | J16: =SUMIFS('상세 자료 작성'!$I:$I,'상세 자료 작성'!$C:$C,'요약(보고)'!$C16,'상세 자료 작성'!$A:$A,'요약(보고)'!$AE$9,'상세 자료 작성'!$D:$D,$J$4)/10^8 -> 29.878953 | K16: =SUMIFS('상세 자료 작성'!$J:$J,'상세 자료 작성'!$C:$C,'요약(보고)'!$C16,'상세 자료 작성'!$A:$A,$AE$11,'상세 자료 작성'!$D:$D,'요약(보고)'!$J$4)/10^8 -> 24.597 | L16: =SUMIFS('상세 자료 작성'!$K:$K,'상세 자료 작성'!$C:$C,'요약(보고)'!$C16,'상세 자료 작성'!$A:$A,$AE$11,'상세 자료 작성'!$D:$D,$J$4)/10^8 -> 24.908658 | M16: =L16-K16 -> 0.31165804 | N16: =SUMIFS('상세 자료 작성'!$I:$I,'상세 자료 작성'!$C:$C,'요약(보고)'!$C16,'상세 자료 작성'!$A:$A,'요약(보고)'!$AE$9,'상세 자료 작성'!$D:$D,$N$4)/10^8 -> 0.26295337 | O16: =SUMIFS('상세 자료 작성'!$J:$J,'상세 자료 작성'!$C:$C,'요약(보고)'!$C16,'상세 자료 작성'!$A:$A,$AE$11,'상세 자료 작성'!$D:$D,$N$4)/10^8 -> 3.71 | P16: =SUMIFS('상세 자료 작성'!$K:$K,'상세 자료 작성'!$C:$C,'요약(보고)'!$C16,'상세 자료 작성'!$A:$A,$AE$11,'상세 자료 작성'!$D:$D,$N$4)/10^8 -> 4.6912414 | Q16: =P16-O16 -> 0.98124138 | R16: =SUMIFS('상세 자료 작성'!$I:$I,'상세 자료 작성'!$C:$C,'요약(보고)'!$C16,'상세 자료 작성'!$A:$A,'요약(보고)'!$AE$9,'상세 자료 작성'!$D:$D,$R$4)/10^8 -> 12.132953 | S16: =SUMIFS('상세 자료 작성'!$J:$J,'상세 자료 작성'!$C:$C,'요약(보고)'!$C16,'상세 자료 작성'!$A:$A,$AE$11,'상세 자료 작성'!$D:$D,$R$4)/10^8 -> 7.02 | T16: =SUMIFS('상세 자료 작성'!$K:$K,'상세 자료 작성'!$C:$C,'요약(보고)'!$C16,'상세 자료 작성'!$A:$A,$AE$11,'상세 자료 작성'!$D:$D,$R$4)/10^8 -> 4.7217513 | U16: =T16-S16 -> -2.2982487 | V16: =R16+J16+N16 -> 42.27486 | W16: =S16+K16+O16 -> 35.327 | X16: =T16+L16+P16 -> 34.321651 | Y16: =X16-W16 -> -1.0053493 | Z16: =SUMIFS('상세 자료 작성'!$I:$I,'상세 자료 작성'!$C:$C,'요약(보고)'!$C16,'상세 자료 작성'!$A:$A,'요약(보고)'!$AE$9)/10^8 -> 116.73362 | AA16: =SUMIFS('상세 자료 작성'!$J:$J,'상세 자료 작성'!$C:$C,'요약(보고)'!$C16,'상세 자료 작성'!$A:$A,'요약(보고)'!$AE$11)/10^8 -> 179.7765 | AB16: =SUMIFS('상세 자료 작성'!$K:$K,'상세 자료 작성'!$C:$C,'요약(보고)'!$C16,'상세 자료 작성'!$A:$A,'요약(보고)'!$AE$11)/10^8 -> 164.05285 | AC16: =AB16-AA16 -> -15.723649
C17: LCM | D17: 14.12375 | E17: =AA17 -> 11.23 | F17: =SUMIFS('상세 자료 작성'!$I:$I,'상세 자료 작성'!$C:$C,'요약(보고)'!$C17,'상세 자료 작성'!$A:$A,'요약(보고)'!$AE$9,'상세 자료 작성'!$B:$B,'요약(보고)'!$F$4)/10^8 -> 3.66 | G17: =SUMIFS('상세 자료 작성'!$J:$J,'상세 자료 작성'!$C:$C,'요약(보고)'!$C17,'상세 자료 작성'!$A:$A,$AE$11,'상세 자료 작성'!$B:$B,'요약(보고)'!$F$4)/10^8 -> 1.7875 | H17: =SUMIFS('상세 자료 작성'!$K:$K,'상세 자료 작성'!$C:$C,'요약(보고)'!$C17,'상세 자료 작성'!$A:$A,$AE$11,'상세 자료 작성'!$B:$B,'요약(보고)'!$F$4)/10^8 -> 0 | I17: =Y17 -> -1.7875 | J17: =SUMIFS('상세 자료 작성'!$I:$I,'상세 자료 작성'!$C:$C,'요약(보고)'!$C17,'상세 자료 작성'!$A:$A,'요약(보고)'!$AE$9,'상세 자료 작성'!$D:$D,$J$4)/10^8 -> 0 | K17: =SUMIFS('상세 자료 작성'!$J:$J,'상세 자료 작성'!$C:$C,'요약(보고)'!$C17,'상세 자료 작성'!$A:$A,$AE$11,'상세 자료 작성'!$D:$D,'요약(보고)'!$J$4)/10^8 -> 0 | L17: =SUMIFS('상세 자료 작성'!$K:$K,'상세 자료 작성'!$C:$C,'요약(보고)'!$C17,'상세 자료 작성'!$A:$A,$AE$11,'상세 자료 작성'!$D:$D,$J$4)/10^8 -> 0 | M17: =L17-K17 -> 0 | N17: =SUMIFS('상세 자료 작성'!$I:$I,'상세 자료 작성'!$C:$C,'요약(보고)'!$C17,'상세 자료 작성'!$A:$A,'요약(보고)'!$AE$9,'상세 자료 작성'!$D:$D,$N$4)/10^8 -> 0 | O17: =SUMIFS('상세 자료 작성'!$J:$J,'상세 자료 작성'!$C:$C,'요약(보고)'!$C17,'상세 자료 작성'!$A:$A,$AE$11,'상세 자료 작성'!$D:$D,$N$4)/10^8 -> 0.46875 | P17: =SUMIFS('상세 자료 작성'!$K:$K,'상세 자료 작성'!$C:$C,'요약(보고)'!$C17,'상세 자료 작성'!$A:$A,$AE$11,'상세 자료 작성'!$D:$D,$N$4)/10^8 -> 0 | Q17: =P17-O17 -> -0.46875 | R17: =SUMIFS('상세 자료 작성'!$I:$I,'상세 자료 작성'!$C:$C,'요약(보고)'!$C17,'상세 자료 작성'!$A:$A,'요약(보고)'!$AE$9,'상세 자료 작성'!$D:$D,$R$4)/10^8 -> 3.66 | S17: =SUMIFS('상세 자료 작성'!$J:$J,'상세 자료 작성'!$C:$C,'요약(보고)'!$C17,'상세 자료 작성'!$A:$A,$AE$11,'상세 자료 작성'!$D:$D,$R$4)/10^8 -> 1.31875 | T17: =SUMIFS('상세 자료 작성'!$K:$K,'상세 자료 작성'!$C:$C,'요약(보고)'!$C17,'상세 자료 작성'!$A:$A,$AE$11,'상세 자료 작성'!$D:$D,$R$4)/10^8 -> 0 | U17: =T17-S17 -> -1.31875 | V17: =R17+J17+N17 -> 3.66 | W17: =S17+K17+O17 -> 1.7875 | X17: =T17+L17+P17 -> 0 | Y17: =X17-W17 -> -1.7875 | Z17: =SUMIFS('상세 자료 작성'!$I:$I,'상세 자료 작성'!$C:$C,'요약(보고)'!$C17,'상세 자료 작성'!$A:$A,'요약(보고)'!$AE$9)/10^8 -> 14.12375 | AA17: =SUMIFS('상세 자료 작성'!$J:$J,'상세 자료 작성'!$C:$C,'요약(보고)'!$C17,'상세 자료 작성'!$A:$A,'요약(보고)'!$AE$11)/10^8 -> 11.23 | AB17: =SUMIFS('상세 자료 작성'!$K:$K,'상세 자료 작성'!$C:$C,'요약(보고)'!$C17,'상세 자료 작성'!$A:$A,'요약(보고)'!$AE$11)/10^8 -> 8.9145 | AC17: =AB17-AA17 -> -2.3155
C18: 내재화 개발 | D18: 13.015667 | E18: =AA18 -> 6.09375 | F18: =SUMIFS('상세 자료 작성'!$I:$I,'상세 자료 작성'!$C:$C,'요약(보고)'!$C18,'상세 자료 작성'!$A:$A,'요약(보고)'!$AE$9,'상세 자료 작성'!$B:$B,'요약(보고)'!$F$4)/10^8 -> 5.2999167 | G18: =SUMIFS('상세 자료 작성'!$J:$J,'상세 자료 작성'!$C:$C,'요약(보고)'!$C18,'상세 자료 작성'!$A:$A,$AE$11,'상세 자료 작성'!$B:$B,'요약(보고)'!$F$4)/10^8 -> 4.6875 | H18: =SUMIFS('상세 자료 작성'!$K:$K,'상세 자료 작성'!$C:$C,'요약(보고)'!$C18,'상세 자료 작성'!$A:$A,$AE$11,'상세 자료 작성'!$B:$B,'요약(보고)'!$F$4)/10^8 -> 4.9429167 | I18: =Y18 -> 0.25541668 | J18: =SUMIFS('상세 자료 작성'!$I:$I,'상세 자료 작성'!$C:$C,'요약(보고)'!$C18,'상세 자료 작성'!$A:$A,'요약(보고)'!$AE$9,'상세 자료 작성'!$D:$D,$J$4)/10^8 -> 2.7467917 | K18: =SUMIFS('상세 자료 작성'!$J:$J,'상세 자료 작성'!$C:$C,'요약(보고)'!$C18,'상세 자료 작성'!$A:$A,$AE$11,'상세 자료 작성'!$D:$D,'요약(보고)'!$J$4)/10^8 -> 1.40625 | L18: =SUMIFS('상세 자료 작성'!$K:$K,'상세 자료 작성'!$C:$C,'요약(보고)'!$C18,'상세 자료 작성'!$A:$A,$AE$11,'상세 자료 작성'!$D:$D,$J$4)/10^8 -> 1.7683333 | M18: =L18-K18 -> 0.36208334 | N18: =SUMIFS('상세 자료 작성'!$I:$I,'상세 자료 작성'!$C:$C,'요약(보고)'!$C18,'상세 자료 작성'!$A:$A,'요약(보고)'!$AE$9,'상세 자료 작성'!$D:$D,$N$4)/10^8 -> 0.31604167 | O18: =SUMIFS('상세 자료 작성'!$J:$J,'상세 자료 작성'!$C:$C,'요약(보고)'!$C18,'상세 자료 작성'!$A:$A,$AE$11,'상세 자료 작성'!$D:$D,$N$4)/10^8 -> 0.46875 | P18: =SUMIFS('상세 자료 작성'!$K:$K,'상세 자료 작성'!$C:$C,'요약(보고)'!$C18,'상세 자료 작성'!$A:$A,$AE$11,'상세 자료 작성'!$D:$D,$N$4)/10^8 -> 0 | Q18: =P18-O18 -> -0.46875 | R18: =SUMIFS('상세 자료 작성'!$I:$I,'상세 자료 작성'!$C:$C,'요약(보고)'!$C18,'상세 자료 작성'!$A:$A,'요약(보고)'!$AE$9,'상세 자료 작성'!$D:$D,$R$4)/10^8 -> 2.2370833 | S18: =SUMIFS('상세 자료 작성'!$J:$J,'상세 자료 작성'!$C:$C,'요약(보고)'!$C18,'상세 자료 작성'!$A:$A,$AE$11,'상세 자료 작성'!$D:$D,$R$4)/10^8 -> 2.8125 | T18: =SUMIFS('상세 자료 작성'!$K:$K,'상세 자료 작성'!$C:$C,'요약(보고)'!$C18,'상세 자료 작성'!$A:$A,$AE$11,'상세 자료 작성'!$D:$D,$R$4)/10^8 -> 3.1745833 | U18: =T18-S18 -> 0.36208334 | V18: =R18+J18+N18 -> 5.2999167 | W18: =S18+K18+O18 -> 4.6875 | X18: =T18+L18+P18 -> 4.9429167 | Y18: =X18-W18 -> 0.25541668 | Z18: =SUMIFS('상세 자료 작성'!$I:$I,'상세 자료 작성'!$C:$C,'요약(보고)'!$C18,'상세 자료 작성'!$A:$A,'요약(보고)'!$AE$9)/10^8 -> 12.811667 | AA18: =SUMIFS('상세 자료 작성'!$J:$J,'상세 자료 작성'!$C:$C,'요약(보고)'!$C18,'상세 자료 작성'!$A:$A,'요약(보고)'!$AE$11)/10^8 -> 6.09375 | AB18: =SUMIFS('상세 자료 작성'!$K:$K,'상세 자료 작성'!$C:$C,'요약(보고)'!$C18,'상세 자료 작성'!$A:$A,'요약(보고)'!$AE$11)/10^8 -> 6.3491667 | AC18: =AB18-AA18 -> 0.25541668
C19: 기타(QA위임등)* | D19: 7.4302005 | E19: =AA19 -> 0 | F19: =SUMIFS('상세 자료 작성'!$I:$I,'상세 자료 작성'!$C:$C,'요약(보고)'!$C19,'상세 자료 작성'!$A:$A,'요약(보고)'!$AE$9,'상세 자료 작성'!$B:$B,'요약(보고)'!$F$4)/10^8 -> 2.6480417 | G19: =SUMIFS('상세 자료 작성'!$J:$J,'상세 자료 작성'!$C:$C,'요약(보고)'!$C19,'상세 자료 작성'!$A:$A,$AE$11,'상세 자료 작성'!$B:$B,'요약(보고)'!$F$4)/10^8 -> 0 | H19: =SUMIFS('상세 자료 작성'!$K:$K,'상세 자료 작성'!$C:$C,'요약(보고)'!$C19,'상세 자료 작성'!$A:$A,$AE$11,'상세 자료 작성'!$B:$B,'요약(보고)'!$F$4)/10^8 -> 0.78861501 | I19: =Y19 -> 0.78861501 | J19: =SUMIFS('상세 자료 작성'!$I:$I,'상세 자료 작성'!$C:$C,'요약(보고)'!$C19,'상세 자료 작성'!$A:$A,'요약(보고)'!$AE$9,'상세 자료 작성'!$D:$D,$J$4)/10^8 -> 1.1739256 | K19: =SUMIFS('상세 자료 작성'!$J:$J,'상세 자료 작성'!$C:$C,'요약(보고)'!$C19,'상세 자료 작성'!$A:$A,$AE$11,'상세 자료 작성'!$D:$D,'요약(보고)'!$J$4)/10^8 -> 0 | L19: =SUMIFS('상세 자료 작성'!$K:$K,'상세 자료 작성'!$C:$C,'요약(보고)'!$C19,'상세 자료 작성'!$A:$A,$AE$11,'상세 자료 작성'!$D:$D,$J$4)/10^8 -> 0.3732771 | M19: =L19-K19 -> 0.3732771 | N19: =SUMIFS('상세 자료 작성'!$I:$I,'상세 자료 작성'!$C:$C,'요약(보고)'!$C19,'상세 자료 작성'!$A:$A,'요약(보고)'!$AE$9,'상세 자료 작성'!$D:$D,$N$4)/10^8 -> 0.0791691 | O19: =SUMIFS('상세 자료 작성'!$J:$J,'상세 자료 작성'!$C:$C,'요약(보고)'!$C19,'상세 자료 작성'!$A:$A,$AE$11,'상세 자료 작성'!$D:$D,$N$4)/10^8 -> 0 | P19: =SUMIFS('상세 자료 작성'!$K:$K,'상세 자료 작성'!$C:$C,'요약(보고)'!$C19,'상세 자료 작성'!$A:$A,$AE$11,'상세 자료 작성'!$D:$D,$N$4)/10^8 -> 0.41533791 | Q19: =P19-O19 -> 0.41533791 | R19: =SUMIFS('상세 자료 작성'!$I:$I,'상세 자료 작성'!$C:$C,'요약(보고)'!$C19,'상세 자료 작성'!$A:$A,'요약(보고)'!$AE$9,'상세 자료 작성'!$D:$D,$R$4)/10^8 -> 1.394947 | S19: =SUMIFS('상세 자료 작성'!$J:$J,'상세 자료 작성'!$C:$C,'요약(보고)'!$C19,'상세 자료 작성'!$A:$A,$AE$11,'상세 자료 작성'!$D:$D,$R$4)/10^8 -> 0 | T19: =SUMIFS('상세 자료 작성'!$K:$K,'상세 자료 작성'!$C:$C,'요약(보고)'!$C19,'상세 자료 작성'!$A:$A,$AE$11,'상세 자료 작성'!$D:$D,$R$4)/10^8 -> 0 | U19: =T19-S19 -> 0 | V19: =R19+J19+N19 -> 2.6480417 | W19: =S19+K19+O19 -> 0 | X19: =T19+L19+P19 -> 0.78861501 | Y19: =X19-W19 -> 0.78861501 | Z19: =SUMIFS('상세 자료 작성'!$I:$I,'상세 자료 작성'!$C:$C,'요약(보고)'!$C19,'상세 자료 작성'!$A:$A,'요약(보고)'!$AE$9)/10^8 -> 6.4402005 | AA19: =SUMIFS('상세 자료 작성'!$J:$J,'상세 자료 작성'!$C:$C,'요약(보고)'!$C19,'상세 자료 작성'!$A:$A,'요약(보고)'!$AE$11)/10^8 -> 0 | AB19: =SUMIFS('상세 자료 작성'!$K:$K,'상세 자료 작성'!$C:$C,'요약(보고)'!$C19,'상세 자료 작성'!$A:$A,'요약(보고)'!$AE$11)/10^8 -> 0.78861501 | AC19: =AB19-AA19 -> 0.78861501
B20: 국내영업 | D20: =SUM(D21:D23) -> 0 | E20: =SUM(E21:E23) -> 3392.2517 | F20: =SUM(F21:F23) -> 0 | G20: =SUM(G21:G23) -> 672.24237 | H20: =SUM(H21:H23) -> 672.24237 | I20: =SUM(I21:I23) -> 0 | J20: =SUM(J21:J23) -> 0 | K20: =SUM(K21:K23) -> 236.81199 | ... Q20: =SUM(Q21:Q23) -> 0 | R20: ='상세 자료 작성'!I39 -> 9532347466 | S20: =SUM(S21:S23) -> 364.64057 | T20: =SUM(T21:T23) -> 364.64057 | U20: =SUM(U21:U23) -> 0 | V20: =SUM(V21:V23) -> 0 | W20: =SUM(W21:W23) -> 882.06849 | X20: =SUM(X21:X23) -> 882.06849 | Y20: =SUM(Y21:Y23) -> 0
C21: 케미컬 | D21: 0 | E21: 1869.8805 | F21: 0 | G21: 404.56184 | H21: 404.56184 | I21: =H21-G21 -> 0 | J21: 0 | K21: 157.15481 | L21: 157.15481 | M21: =L21-K21 -> 0 | N21: 0 | O21: 170.53756 | P21: 170.53756 | Q21: =P21-O21 -> 0 | R21: ='상세 자료 작성'!I40 -> 26963794201 | S21: 194.32657 | T21: 194.32657 | U21: =T21-S21 -> 0 | V21: 0 | W21: =K21+O21+S21 -> 522.01894 | X21: =L21+P21+T21 -> 522.01894 | Y21: =X21-W21 -> 0
C22: 바이오 | D22: 0 | E22: 1000 | F22: 0 | G22: 214.70497 | H22: 214.70497 | I22: =H22-G22 -> 0 | J22: 0 | K22: 57.938842 | L22: 57.938842 | M22: =L22-K22 -> 0 | N22: 0 | O22: 86.908263 | P22: 86.908263 | Q22: =P22-O22 -> 0 | R22: ='상세 자료 작성'!I41 -> 1151454672 | S22: 144.97406 | T22: 144.97406 | U22: =T22-S22 -> 0 | V22: 0 | W22: =K22+O22+S22 -> 289.82116 | X22: =L22+P22+T22 -> 289.82116 | Y22: =X22-W22 -> 0
C23: APAC | D23: 0 | E23: 522.37127 | F23: 0 | G23: 52.975551 | H23: 52.975551 | I23: =H23-G23 -> 0 | J23: 0 | K23: 21.718335 | L23: 21.718335 | M23: =L23-K23 -> 0 | N23: 0 | O23: 23.17011 | P23: 23.17011 | Q23: =P23-O23 -> 0 | R23: ='상세 자료 작성'!I42 -> 0 | S23: 25.339943 | T23: 25.339943 | U23: =T23-S23 -> 0 | V23: 0 | W23: =K23+O23+S23 -> 70.228388 | X23: =L23+P23+T23 -> 70.228388 | Y23: =X23-W23 -> 0
B24: *기타 : 약물감시, IIT 용역 추가 반영
B26: 1) 3월 매출 특이사항 | F26: 3월 | W26: * : 매출 미반영
B27: 구분 | E27: 계획 | G27: 전주 보고 (경영회의) | I27: 금주 보고 (경영회의) | K27: 전주 대비 | M27: 변경사유 / 특이사항
B28: 케미컬 상업 | E28: =(SUMIFS('상세 자료 작성'!$J:$J,'상세 자료 작성'!$A:$A,'요약(보고)'!$AE$11,'상세 자료 작성'!$D:$D,'요약(보고)'!$F$26,'상세 자료 작성'!$C:$C,'요약(보고)'!#REF!)+SUMIFS('상세 자료 작성'!$J:$J,'상세 자료 작성'!$A:$A,'요약(보고)'!$AE$11,'상세 자료 작성'!$D:$D,'요약(보고)'!$F$26,'상세 자료 작성'!$C:$C,'요약(보고)'!$C$10)+SUMIFS('상세 자료 작성'!$J:$J,'상세 자료 작성'!$A:$A,'요약(보고)'!$AE$11,'상세 자료 작성'!$D:$D,'요약(보고)'!$F$26,'상세 자료 작성'!$C:$C,'요약(보고)'!$C$11))/10^8 -> 9.6097563 | G28: =(SUMIFS('상세 자료 작성'!$M:$M,'상세 자료 작성'!$A:$A,'요약(보고)'!$AE$11,'상세 자료 작성'!$D:$D,'요약(보고)'!$F$26,'상세 자료 작성'!$C:$C,'요약(보고)'!#REF!)+SUMIFS('상세 자료 작성'!$M:$M,'상세 자료 작성'!$A:$A,'요약(보고)'!$AE$11,'상세 자료 작성'!$D:$D,'요약(보고)'!$F$26,'상세 자료 작성'!$C:$C,'요약(보고)'!C10)+SUMIFS('상세 자료 작성'!$M:$M,'상세 자료 작성'!$A:$A,'요약(보고)'!$AE$11,'상세 자료 작성'!$D:$D,'요약(보고)'!$F$26,'상세 자료 작성'!$C:$C,'요약(보고)'!C11))/10^8 -> 14.899527 | I28: =(SUMIFS('상세 자료 작성'!$K:$K,'상세 자료 작성'!$A:$A,'요약(보고)'!$AE$11,'상세 자료 작성'!$D:$D,'요약(보고)'!$F$26,'상세 자료 작성'!$C:$C,'요약(보고)'!#REF!)+SUMIFS('상세 자료 작성'!$K:$K,'상세 자료 작성'!$A:$A,'요약(보고)'!$AE$11,'상세 자료 작성'!$D:$D,'요약(보고)'!$F$26,'상세 자료 작성'!$C:$C,'요약(보고)'!$C$10)+SUMIFS('상세 자료 작성'!$K:$K,'상세 자료 작성'!$A:$A,'요약(보고)'!$AE$11,'상세 자료 작성'!$D:$D,'요약(보고)'!$F$26,'상세 자료 작성'!$C:$C,'요약(보고)'!$C$11))/10^8 -> 14.729079 | K28: =I28-G28 -> -0.17044833 | M28: - 위임형(로제핀정) 4월부터 300만원씩 선수금 매출 발생 예정
B29: 바이오상업 | E29: =SUM(E30:F31) -> 83.985258 | G29: =SUM(G30:H31) -> 93.466865 | I29: =SUM(I30:J31) -> 91.672085 | K29: =I29-G29 -> -1.79478
C30: PFS | E30: =SUMIFS('상세 자료 작성'!$J:$J,'상세 자료 작성'!$A:$A,'요약(보고)'!$AE$11,'상세 자료 작성'!$D:$D,'요약(보고)'!$F$26,'상세 자료 작성'!$C:$C,'요약(보고)'!$C$13)/10^8 -> 81.331637 | G30: =SUMIFS('상세 자료 작성'!$M:$M,'상세 자료 작성'!$A:$A,'요약(보고)'!$AE$11,'상세 자료 작성'!$D:$D,'요약(보고)'!$F$26,'상세 자료 작성'!$C:$C,'요약(보고)'!$C$13)/10^8 -> 89.291626 | I30: =SUMIFS('상세 자료 작성'!$K:$K,'상세 자료 작성'!$A:$A,'요약(보고)'!$AE$11,'상세 자료 작성'!$D:$D,'요약(보고)'!$F$26,'상세 자료 작성'!$C:$C,'요약(보고)'!$C$13)/10^8 -> 87.496846 | K30: =I30-G30 -> -1.79478 | M30: [증가] 전주 대비 : +0.6억 (수율 반영) [감소] PFS 국내향(스토보클로) 포장 ATTP(일련번호시스템) 오류 발생으로 출하 지연(-2.4억원)
C31: L&P | E31: =SUMIFS('상세 자료 작성'!$J:$J,'상세 자료 작성'!$A:$A,'요약(보고)'!$AE$11,'상세 자료 작성'!$D:$D,'요약(보고)'!$F$26,'상세 자료 작성'!$C:$C,'요약(보고)'!$C$14)/10^8 -> 2.65362 | G31: =SUMIFS('상세 자료 작성'!$M:$M,'상세 자료 작성'!$A:$A,'요약(보고)'!$AE$11,'상세 자료 작성'!$D:$D,'요약(보고)'!$F$26,'상세 자료 작성'!$C:$C,'요약(보고)'!$C$14)/10^8 -> 4.1752392 | I31: =SUMIFS('상세 자료 작성'!$K:$K,'상세 자료 작성'!$A:$A,'요약(보고)'!$AE$11,'상세 자료 작성'!$D:$D,'요약(보고)'!$F$26,'상세 자료 작성'!$C:$C,$C$14)/10^8 -> 4.1752392 | K31: =I31-G31 -> 0
B32: 개발용역 | E32: =SUM(E33:F36) -> 11.15125 | G32: =SUM(G33:H36) -> 8.56725 | I32: =SUM(I33:J36) -> 7.8963346 | K32: =I32-G32 -> -0.67091536
C33: PFS 개발 | E33: =SUMIFS('상세 자료 작성'!$J:$J,'상세 자료 작성'!$A:$A,'요약(보고)'!$AE$11,'상세 자료 작성'!$D:$D,'요약(보고)'!$F$26,'상세 자료 작성'!$C:$C,$C16)/10^8 -> 7.02 | G33: =SUMIFS('상세 자료 작성'!$M:$M,'상세 자료 작성'!$A:$A,'요약(보고)'!$AE$11,'상세 자료 작성'!$D:$D,'요약(보고)'!$F$26,'상세 자료 작성'!$C:$C,$C16)/10^8 -> 4.436 | I33: =SUMIFS('상세 자료 작성'!$K:$K,'상세 자료 작성'!$A:$A,'요약(보고)'!$AE$11,'상세 자료 작성'!$D:$D,'요약(보고)'!$F$26,'상세 자료 작성'!$C:$C,$C16)/10^8 -> 4.7217513 | K33: =I33-G33 -> 0.2857513 | M33: - 선수금 반영(0.3억)
C34: LCM | E34: =SUMIFS('상세 자료 작성'!$J:$J,'상세 자료 작성'!$A:$A,'요약(보고)'!$AE$11,'상세 자료 작성'!$D:$D,'요약(보고)'!$F$26,'상세 자료 작성'!$C:$C,$C17)/10^8 -> 1.31875 | G34: =SUMIFS('상세 자료 작성'!$M:$M,'상세 자료 작성'!$A:$A,'요약(보고)'!$AE$11,'상세 자료 작성'!$D:$D,'요약(보고)'!$F$26,'상세 자료 작성'!$C:$C,$C17)/10^8 -> 1.31875 | I34: =SUMIFS('상세 자료 작성'!$K:$K,'상세 자료 작성'!$A:$A,'요약(보고)'!$AE$11,'상세 자료 작성'!$D:$D,'요약(보고)'!$F$26,'상세 자료 작성'!$C:$C,$C17)/10^8 -> 0 | K34: =I34-G34 -> -1.31875 | M34: - 전주 대비 : -1.3억 1) L02 EBP 청구 증빙문서 수정사항 발생에 따른 청구월 이월 2) L06 안정성 시험일정 지연에 따른 이월
C35: 내재화 개발 | E35: =SUMIFS('상세 자료 작성'!$J:$J,'상세 자료 작성'!$A:$A,'요약(보고)'!$AE$11,'상세 자료 작성'!$D:$D,'요약(보고)'!$F$26,'상세 자료 작성'!$C:$C,$C18)/10^8 -> 2.8125 | G35: =SUMIFS('상세 자료 작성'!$M:$M,'상세 자료 작성'!$A:$A,'요약(보고)'!$AE$11,'상세 자료 작성'!$D:$D,'요약(보고)'!$F$26,'상세 자료 작성'!$C:$C,$C18)/10^8 -> 2.8125 | I35: =SUMIFS('상세 자료 작성'!$K:$K,'상세 자료 작성'!$A:$A,'요약(보고)'!$AE$11,'상세 자료 작성'!$D:$D,'요약(보고)'!$F$26,'상세 자료 작성'!$C:$C,$C18)/10^8 -> 3.1745833 | K35: =I35-G35 -> 0.36208334 | M35: - 선수금 반영(0.2억)
C36: 기타(QA위임등)* | E36: =SUMIFS('상세 자료 작성'!$J:$J,'상세 자료 작성'!$A:$A,'요약(보고)'!$AE$11,'상세 자료 작성'!$D:$D,'요약(보고)'!$F$26,'상세 자료 작성'!$C:$C,$C19)/10^8 -> 0 | G36: =SUMIFS('상세 자료 작성'!$M:$M,'상세 자료 작성'!$A:$A,'요약(보고)'!$AE$11,'상세 자료 작성'!$D:$D,'요약(보고)'!$F$26,'상세 자료 작성'!$C:$C,$C19)/10^8 -> 0 | I36: =SUMIFS('상세 자료 작성'!$K:$K,'상세 자료 작성'!$A:$A,'요약(보고)'!$AE$11,'상세 자료 작성'!$D:$D,'요약(보고)'!$F$26,'상세 자료 작성'!$C:$C,$C19)/10^8 -> 0 | K36: =I36-G36 -> 0
B37: 총합 | E37: =E28+E29+E32 -> 104.74626 | G37: =SUM(G28,G29,G32) -> 116.93364 | I37: =I28+I29+I32 -> 114.2975 | K37: =I37-G37 -> -2.6361437 | M37: 사업계획 대비 +10.9억원
B39: 2) 3분기 매출 특이사항
B40: 구분 | E40: 계획 | G40: 전주 보고 (경영회의) | I40: 금주 보고 (경영회의) | K40: 전주 대비 | M40: 변경사유 / 특이사항
B41: 케미컬 상업 | E41: =W9 -> 25.134453 | G41: =SUM('상세 자료 작성'!M215:M217,'상세 자료 작성'!M226:M228,'상세 자료 작성'!M237:M239)/10^8 -> 44.626386 | I41: =X9 -> 27.58882 | K41: =I41-G41 -> -17.037566 | M41: 상동
B42: 바이오상업 | E42: =SUM(E43:F44) -> 246.45126 | G42: =SUM(G43:H44) -> 286.88217 | I42: =SUM(I43:J44) -> 266.20901 | K42: =I42-G42 -> -20.673158
...

Sheet 상세 자료 작성
D1: ■ 주간 매출보고 자료
D2: 1) PO 기준 : | F2: 케미컬상업 | G2: 실질 PO 접수 기준
F3: PFS 상업 | G3: 2개월 100% Binding FCST 기준
F4: L&P 상업 | G4: 2개월 100% Binding FCST 기준
N5: 기준일자 : 2025-06-26
A6: 연 | B6: 분기 | D6: 월 | E6: 주차 | F6: 법인 | G6: 구분 | H6: 상세구분 | I6: 매출실적 | J6: 사업계획 | K6: 예상마감 | L6: 달성률 | M6: 전주 예상 실적 | N6: Gap
A7: 24년 | B7: 1분기 | C7: G07 | D7: 1월 | E7: 1주차 | F7: 셀트리온제약 | G7: 용역 | H7: CMO상업_조달 | I7: 302597280 | J7: 736312500 | K7: 302597280 | L7: 0.41096312 | M7: 302597280 | N7: 0 | P7: 302597280 | Q7: =P7-I7 -> 0
A8: 24년 | B8: 1분기 | C8: 기타 | D8: 1월 | E8: 1주차 | F8: 셀트리온제약 | G8: 용역 | H8: CMO상업_미국 | I8: 0 | J8: 0 | K8: 0 | M8: 0 | N8: 0 | P8: 0 | Q8: =P8-I8 -> 0
A9: 24년 | B9: 1분기 | C9: 내재화 | D9: 1월 | E9: 1주차 | F9: 셀트리온제약 | G9: 용역 | H9: CMO상업_내재화 | I9: 0 | J9: 0 | K9: 0 | M9: 0 | N9: 0 | P9: 0 | Q9: =P9-I9 -> 0
A10: 24년 | B10: 1분기 | C10: L&P | D10: 1월 | E10: 1주차 | F10: 셀트리온제약 | G10: 용역 | H10: CMO상업_L&P | I10: 1013747020 | J10: 9.5931083e+08 | K10: 1013747020 | L10: 1.0567451 | M10: 1013747020 | N10: 0 | P10: 1013747020 | Q10: =P10-I10 -> 0
A11: 24년 | B11: 1분기 | C11: PFS | D11: 1월 | E11: 1주차 | F11: 셀트리온제약 | G11: 용역 | H11: CMO상업_PFS | I11: 4869898150 | J11: 4405740000 | K11: 4869898150 | L11: 1.1053531 | M11: 4869898150 | N11: 0 | P11: 4869898150 | Q11: =P11-I11 -> 0 | R11: =R12-K133 -> 0 | S11: =S12-K144 -> 0
A12: 24년 | B12: 1분기 | C12: GCP | D12: 1월 | E12: 1주차 | F12: 셀트리온제약 | G12: 용역 | H12: CMO용역_GCP | I12: 0 | J12: 0 | K12: 0 | M12: 0 | N12: 0 | P12: 0 | Q12: =P12-I12 -> 0 | R12: =SUM(R14:R25) -> 12361988503 | S12: =SUM(S14:S25) -> 15101542896 | T12: =SUM(T14:T25) -> 27463531399
A13: 24년 | B13: 1분기 | C13: LCM | D13: 1월 | E13: 1주차 | F13: 셀트리온제약 | G13: 용역 | H13: CMO용역_LCM | I13: 0 | J13: 490500000 | K13: 0 | L13: 0 | M13: 0 | N13: 0 | P13: 0 | Q13: =P13-I13 -> 0 | R13: 11월 | S13: 12월 | T13: 합계
A14: 24년 | B14: 1분기 | C14: PFS 개발 | D14: 1월 | E14: 1주차 | F14: 셀트리온제약 | G14: 용역 | H14: CMO용역_PFS | I14: 439139429 | J14: 0 | K14: 439139429 | M14: 439139429 | N14: 0 | P14: 439139429 | Q14: =P14-I14 -> 0 | R14: =SUM(K123:K124) -> 0 | S14: =SUM(K134:K135) -> 0 | T14: =SUM(R14:S14) -> 0
A15: 24년 | B15: 1분기 | C15: 내재화 개발 | D15: 1월 | E15: 1주차 | F15: 셀트리온제약 | G15: 용역 | H15: CMO용역_내재화 | I15: 67266666 | J15: 0 | K15: 67266666 | M15: 67266666 | N15: 0 | P15: 67266666 | Q15: =P15-I15 -> 0 | R15: =K126 -> 166471840 | S15: =K137 -> 190623740 | T15: =SUM(R15:S15) -> 357095580
A16: 24년 | B16: 1분기 | C16: 기타(QA위임등)* | D16: 1월 | E16: 1주차 | F16: 셀트리온제약 | G16: 용역 | H16: 용역_QA위임 | I16: 39867000 | J16: 0 | K16: 39867000 | M16: 39867000 | N16: 0 | P16: 39867000 | Q16: =P16-I16 -> 0 | R16: =K127 -> 7377697800 | S16: =K138 -> 8035017050 | T16: =SUM(R16:S16) -> 15412714850
E17: 1월 예상 실적 | I17: 6732515545 | J17: 6.5918633e+09 | K17: 6732515545 | L17: 1.0213372 | M17: 6732515545 | N17: 0 | P17: 6732515545 | Q17: =P17-I17 -> 0 | R17: =K125 -> 4528225660 | S17: =K136 -> 6019051822 | T17: =SUM(R17:S17) -> 10547277482
A18: 24년 | B18: 1분기 | C18: G07 | D18: 2월 | E18: 1주차 | F18: 셀트리온제약 | G18: 용역 | H18: CMO상업_조달 | I18: 5372064744 | J18: 3253527000 | K18: 5372064744 | L18: 1.6511511 | M18: 5372064744 | N18: 0 | P18: 5372064744 | Q18: =P18-I18 -> 0 | R18: =K128 -> 0 | S18: =K139 -> 134600000 | T18: =SUM(R18:S18) -> 134600000
A19: 24년 | B19: 1분기 | C19: 기타 | D19: 2월 | E19: 1주차 | F19: 셀트리온제약 | G19: 용역 | H19: CMO상업_미국 | I19: 0 | J19: 0 | K19: 0 | M19: 0 | N19: 0 | P19: 0 | Q19: =P19-I19 -> 0 | R19: =K129 -> 38500000 | S19: =K140 -> 46875000 | T19: =SUM(R19:S19) -> 85375000
A20: 24년 | B20: 1분기 | C20: 내재화 | D20: 2월 | E20: 1주차 | F20: 셀트리온제약 | G20: 용역 | H20: CMO상업_내재화 | I20: 0 | J20: 0 | K20: 0 | M20: 0 | N20: 0 | P20: 0 | Q20: =P20-I20 -> 0 | R20: =K130 -> 110001036 | S20: =K141 -> 476323136 | T20: =SUM(R20:S20) -> 586324172
A21: 24년 | B21: 1분기 | C21: L&P | D21: 2월 | E21: 1주차 | F21: 셀트리온제약 | G21: 용역 | H21: CMO상업_L&P | I21: 684982200 | J21: 9.5931083e+08 | K21: 684982200 | L21: 0.71403572 | M21: 684982200 | N21: 0 | P21: 684982200 | Q21: =P21-I21 -> 0 | R21: =K131 -> 125354167 | S21: =K142 -> 31604167 | T21: =SUM(R21:S21) -> 156958334
A22: 24년 | B22: 1분기 | C22: PFS | D22: 2월 | E22: 1주차 | F22: 셀트리온제약 | G22: 용역 | H22: CMO상업_PFS | I22: 4437683550 | J22: 4.7866246e+08 | K22: 4437683550 | M22: 4437683550 | N22: 0 | P22: 4437683550 | Q22: =P22-I22 -> 0 | R22: =K132 -> 15738000 | S22: =K143 -> 167447981 | T22: =SUM(R22:S22) -> 183185981
A23: 24년 | B23: 1분기 | C23: GCP | D23: 2월 | E23: 1주차 | F23: 셀트리온제약 | G23: 용역 | H23: CMO용역_GCP | I23: 40000000 | J23: 40000000 | K23: 40000000 | L23: 1 | M23: 40000000 | N23: 0 | P23: 40000000 | Q23: =P23-I23 -> 0 | T23: =SUM(R23:S23) -> 0
A24: 24년 | B24: 1분기 | C24: LCM | D24: 2월 | E24: 1주차 | F24: 셀트리온제약 | G24: 용역 | H24: CMO용역_LCM | I24: 0 | J24: 766500000 | K24: 0 | L24: 0 | M24: 0 | N24: 0 | P24: 0 | Q24: =P24-I24 -> 0
A25: 24년 | B25: 1분기 | C25: PFS 개발 | D25: 2월 | E25: 1주차 | F25: 셀트리온제약 | G25: 용역 | H25: CMO용역_PFS | I25: 14069429 | J25: 162000000 | K25: 14069429 | L25: 0.086848327 | M25: 14069429 | N25: 0 | P25: 14069429 | Q25: =P25-I25 -> 0
A26: 24년 | B26: 1분기 | C26: 내재화 개발 | D26: 2월 | E26: 1주차 | F26: 셀트리온제약 | G26: 용역 | H26: CMO용역_내재화 | I26: 119041667 | J26: 93750000 | K26: 119041667 | L26: 1.2697778 | M26: 119041667 | N26: 0 | P26: 119041667 | Q26: =P26-I26 -> 0
A27: 24년 | B27: 1분기 | C27: 기타(QA위임등)* | D27: 2월 | E27: 1주차 | F27: 셀트리온제약 | G27: 용역 | H27: 용역_QA위임 | I27: 31089600 | J27: 0 | K27: 31089600 | M27: 31089600 | N27: 0 | P27: 31089600 | Q27: =P27-I27 -> 0
E28: 2월 실적 | I28: 10698931190 | J28: 5.7537503e+09 | K28: 10698931190 | L28: 1.8594709 | M28: 10698931190 | N28: 0 | P28: 10698931190 | Q28: =P28-I28 -> 0
A29: 24년 | B29: 1분기 | C29: G07 | D29: 3월 | E29: 4주차 | F29: 셀트리온제약 | G29: 용역 | H29: CMO상업_조달 | I29: 2967439150 | J29: 2762644500 | K29: 2967439150 | L29: 1.0741299 | M29: 2967439150 | N29: 0 | P29: 2967439150 | Q29: =P29-I29 -> 0
A30: 24년 | B30: 1분기 | C30: 기타 | D30: 3월 | E30: 4주차 | F30: 셀트리온제약 | G30: 용역 | H30: CMO상업_미국 | I30: 0 | J30: 0 | K30: 0 | L30: #DIV/0! | M30: 0 | N30: 0 | P30: 0 | Q30: =P30-I30 -> 0
A31: 24년 | B31: 1분기 | C31: 내재화 | D31: 3월 | E31: 1주차 | F31: 셀트리온제약 | G31: 용역 | H31: CMO상업_내재화 | I31: 0 | J31: 0 | K31: 0 | M31: 0 | N31: 0 | P31: 0 | Q31: =P31-I31 -> 0
A32: 24년 | B32: 1분기 | C32: L&P | D32: 3월 | E32: 4주차 | F32: 셀트리온제약 | G32: 용역 | H32: CMO상업_L&P | I32: 1047403520 | J32: 9.5931083e+08 | K32: 1047403520 | L32: 1.0918291 | M32: 1047403520 | N32: 0 | P32: 1047403520 | Q32: =P32-I32 -> 0
A33: 24년 | B33: 1분기 | C33: PFS | D33: 3월 | E33: 4주차 | F33: 셀트리온제약 | G33: 용역 | H33: CMO상업_PFS | I33: 4508694300 | J33: 4.7344899e+09 | K33: 4508694300 | L33: 0.95230835 | M33: 4508694300 | N33: 0 | P33: 4508694300 | Q33: =P33-I33 -> 0
A34: 24년 | B34: 1분기 | C34: GCP | D34: 3월 | E34: 4주차 | F34: 셀트리온제약 | G34: 용역 | H34: CMO용역_GCP | I34: 0 | J34: 0 | K34: 0 | M34: 0 | N34: 0 | P34: 0 | Q34: =P34-I34 -> 0 | R34: =R14/10^8 -> 0 | S34: =S14/10^8 -> 0 | T34: =T14/10^8 -> 0
A35: 24년 | B35: 1분기 | C35: LCM | D35: 3월 | E35: 4주차 | F35: 셀트리온제약 | G35: 용역 | H35: CMO용역_LCM | I35: 520375000 | J35: 1666750000 | K35: 520375000 | L35: 0.31220939 | M35: 520375000 | N35: 0 | P35: 520375000 | Q35: =P35-I35 -> 0 | R35: =R15/10^8 -> 1.6647184 | S35: =S15/10^8 -> 1.9062374 | T35: =T15/10^8 -> 3.5709558
A36: 24년 | B36: 1분기 | C36: PFS 개발 | D36: 3월 | E36: 4주차 | F36: 셀트리온제약 | G36: 용역 | H36: CMO용역_PFS | I36: 421269829 | J36: 5.06e+08 | K36: 421269829 | L36: 0.83254907 | M36: 421269829 | N36: 0 | P36: 421269829 | Q36: =P36-I36 -> 0 | R36: =R16/10^8 -> 73.776978 | S36: =S16/10^8 -> 80.350171 | T36: =T16/10^8 -> 154.12715
A37: 24년 | B37: 1분기 | C37: 내재화 개발 | D37: 3월 | E37: 4주차 | F37: 셀트리온제약 | G37: 용역 | H37: CMO용역_내재화 | I37: 25291667 | J37: 361875000 | K37: 25291667 | L37: 0.069890617 | M37: 25291667 | N37: 0 | P37: 25291667 | Q37: =P37-I37 -> 0 | R37: =R17/10^8 -> 45.282257 | S37: =S17/10^8 -> 60.190518 | T37: =T17/10^8 -> 105.47277
A38: 24년 | B38: 1분기 | C38: 기타(QA위임등)* | D38: 3월 | E38: 1주차 | F38: 셀트리온제약 | G38: 용역 | H38: 용역_QA위임 | I38: 41874000 | J38: 0 | K38: 41874000 | L38: #DIV/0! | M38: 41874000 | N38: 0 | P38: 41874000 | Q38: =P38-I38 -> 0 | R38: =R18/10^8 -> 0 | S38: =S18/10^8 -> 1.346 | T38: =T18/10^8 -> 1.346
E39: 3월 실적 | I39: 9532347466 | J39: 1.099107e+10 | K39: 9532347466 | L39: 0.8672811 | M39: 9532347466 | N39: 0 | P39: 9532347466 | Q39: =P39-I39 -> 0 | R39: =R19/10^8 -> 0.385 | S39: =S19/10^8 -> 0.46875 | T39: =T19/10^8 -> 0.85375
D40: 1분기 실적 | I40: 26963794201 | J40: 2.3336684e+10 | K40: 26963794201 | L40: 1.1554253 | M40: 26963794201 | N40: 0 | P40: 26963794201 | Q40: =P40-I40 -> 0 | R40: =R20/10^8 -> 1.1000104 | S40: =S20/10^8 -> 4.7632314 | T40: =T20/10^8 -> 5.8632417
...

Sheet 2024년 계획
B2: □ 2024년 매출 계획
B4: 사업계획_구분1 | C4: 경영정보통합 | D4: 사업계획_구분3 | E4: 사업계획_구분4 | F4: 1월 | G4: 2월 | H4: 3월 | I4: 4월 | J4: 5월 | K4: 6월 | L4: 7월 | M4: 8월 | N4: 9월 | O4: 10월 | P4: 11월 | Q4: 12월 | R4: 2024년 계획 합계 | T4: 2월 누계 | U4: 3월 누계 | V4: 4월 누계 | W4: 5월 누계 | X4: 6월 누계 | Y4: 7월 누계 | Z4: 8월 누계 | AA4: 9월 누계 | AB4: 10월 누계 | AC4: 11월 누계 | AE4: 1분기 | AF4: 2분기 | AG4: 3분기 | AH4: 4분기
B5: 케미컬 | C5: 고덱스 | D5: 고덱스 | E5: 고덱스캡슐 | F5: 2.8215448e+09 | G5: 4.2323172e+09 | H5: 7.0538621e+09 | I5: 3.775695e+09 | J5: 5.6635424e+09 | K5: 9.4392374e+09 | L5: 3.0837976e+09 | M5: 4.6256963e+09 | N5: 7.7094939e+09 | O5: 3.3189627e+09 | P5: 4.978444e+09 | Q5: 8.2974066e+09 | R5: =SUM(F5:Q5) -> 6.5e+10 | T5: =SUM(F5:G5) -> 7.0538621e+09 | U5: =T5+H5 -> 1.4107724e+10 | V5: =U5+I5 -> 1.7883419e+10 | W5: =V5+J5 -> 2.3546962e+10 | X5: =W5+K5 -> 3.2986199e+10 | Y5: =X5+L5 -> 3.6069996e+10 | Z5: =Y5+M5 -> 4.0695693e+10 | AA5: =Z5+N5 -> 4.8405187e+10 | AB5: =AA5+O5 -> 5.1724149e+10 | AC5: =AB5+P5 -> 5.6702593e+10 | AE5: =SUM(F5:H5) -> 1.4107724e+10 | AF5: =SUM(I5:K5) -> 1.8878475e+10 | AG5: =SUM(L5:N5) -> 1.5418988e+10 | AH5: =SUM(O5:Q5) -> 1.6594813e+10
B6: 케미컬 | C6: 고덱스 | D6: 고덱스 | E6: 고덱스정 | F6: 0 | G6: 0 | H6: 0 | I6: 0 | J6: 0 | K6: 0 | L6: 0 | M6: 0 | N6: 0 | O6: 0 | P6: 0 | Q6: 0 | R6: =SUM(F6:Q6) -> 0 | T6: =SUM(F6:G6) -> 0 | U6: =T6+H6 -> 0 | V6: =U6+I6 -> 0 | W6: =V6+J6 -> 0 | X6: =W6+K6 -> 0 | Y6: =X6+L6 -> 0 | Z6: =Y6+M6 -> 0 | AA6: =Z6+N6 -> 0 | AB6: =AA6+O6 -> 0 | AC6: =AB6+P6 -> 0 | AE6: =SUM(F6:H6) -> 0 | AF6: =SUM(I6:K6) -> 0 | AG6: =SUM(L6:N6) -> 0 | AH6: =SUM(O6:Q6) -> 0
B7: 케미컬 | C7: 제품기타 | D7: 약가보상(케미컬) | E7: 약가보상(케미컬) | F7: 0 | G7: 0 | H7: 0 | I7: 0 | J7: 0 | K7: 0 | L7: 0 | M7: 0 | N7: 0 | O7: 0 | P7: 0 | Q7: 0 | R7: =SUM(F7:Q7) -> 0 | T7: =SUM(F7:G7) -> 0 | U7: =T7+H7 -> 0 | V7: =U7+I7 -> 0 | W7: =V7+J7 -> 0 | X7: =W7+K7 -> 0 | Y7: =X7+L7 -> 0 | Z7: =Y7+M7 -> 0 | AA7: =Z7+N7 -> 0 | AB7: =AA7+O7 -> 0 | AC7: =AB7+P7 -> 0 | AE7: =SUM(F7:H7) -> 0 | AF7: =SUM(I7:K7) -> 0 | AG7: =SUM(L7:N7) -> 0 | AH7: =SUM(O7:Q7) -> 0
B8: 케미컬 | C8: 도네리온 | D8: 도네리온 | E8: 도네리온 | F8: 99309184 | G8: 1.4896378e+08 | H8: 2.4827296e+08 | I8: 1.3289216e+08 | J8: 1.9933824e+08 | K8: 3.322304e+08 | L8: 1.0853963e+08 | M8: 1.6280944e+08 | N8: 2.7134907e+08 | O8: 1.1686812e+08 | P8: 1.7530218e+08 | Q8: 2.921703e+08 | R8: =SUM(F8:Q8) -> 2.2880455e+09 | T8: =SUM(F8:G8) -> 2.4827296e+08 | U8: =T8+H8 -> 4.9654592e+08 | V8: =U8+I8 -> 6.2943808e+08 | W8: =V8+J8 -> 8.2877632e+08 | X8: =W8+K8 -> 1.1610067e+09 | Y8: =X8+L8 -> 1.2695463e+09 | Z8: =Y8+M8 -> 1.4323558e+09 | AA8: =Z8+N8 -> 1.7037049e+09 | AB8: =AA8+O8 -> 1.820573e+09 | AC8: =AB8+P8 -> 1.9958752e+09 | AE8: =SUM(F8:H8) -> 4.9654592e+08 | AF8: =SUM(I8:K8) -> 6.644608e+08 | AG8: =SUM(L8:N8) -> 5.4269813e+08 | AH8: =SUM(O8:Q8) -> 5.843406e+08
B9: 케미컬 | C9: 공동판매 | D9: 케미컬쌍방코프로 | E9: 케미컬쌍방코프로 | F9: 9.1157602e+08 | G9: 1.367364e+09 | H9: 2.27894e+09 | I9: 1.2198399e+09 | J9: 1.8297599e+09 | K9: 3.0495998e+09 | L9: 9.9630383e+08 | M9: 1.4944557e+09 | N9: 2.4907596e+09 | O9: 1.0722802e+09 | P9: 1.6084204e+09 | Q9: 2.6807006e+09 | R9: =SUM(F9:Q9) -> 2.1e+10 | T9: =SUM(F9:G9) -> 2.27894e+09 | U9: =T9+H9 -> 4.5578801e+09 | V9: =U9+I9 -> 5.77772e+09 | W9: =V9+J9 -> 7.6074799e+09 | X9: =W9+K9 -> 1.065708e+10 | Y9: =X9+L9 -> 1.1653383e+10 | Z9: =Y9+M9 -> 1.3147839e+10 | AA9: =Z9+N9 -> 1.5638599e+10 | AB9: =AA9+O9 -> 1.6710879e+10 | AC9: =AB9+P9 -> 1.8319299e+10 | AE9: =SUM(F9:H9) -> 4.5578801e+09 | AF9: =SUM(I9:K9) -> 6.0991996e+09 | AG9: =SUM(L9:N9) -> 4.9815191e+09 | AH9: =SUM(O9:Q9) -> 5.3614012e+09
B10: 케미컬 | C10: CSO | D10: CSO | E10: CSO-자사 | F10: 1.5840357e+09 | G10: 2.3760535e+09 | H10: 3.8386408e+09 | I10: 2.1197025e+09 | J10: 3.1795537e+09 | K10: 4.2262497e+09 | L10: 1.7312663e+09 | M10: 2.5968994e+09 | N10: 4.3281657e+09 | O10: 2.2217791e+09 | P10: 3.1538343e+09 | Q10: 4.4107027e+09 | R10: =SUM(F10:Q10) -> 3.5766883e+10 | T10: =SUM(F10:G10) -> 3.9600892e+09 | U10: =T10+H10 -> 7.79873e+09 | V10: =U10+I10 -> 9.9184325e+09 | W10: =V10+J10 -> 1.3097986e+10 | X10: =W10+K10 -> 1.7324236e+10 | Y10: =X10+L10 -> 1.9055502e+10 | Z10: =Y10+M10 -> 2.1652402e+10 | AA10: =Z10+N10 -> 2.5980567e+10 | AB10: =AA10+O10 -> 2.8202346e+10 | AC10: =AB10+P10 -> 3.1356181e+10 | AE10: =SUM(F10:H10) -> 7.79873e+09 | AF10: =SUM(I10:K10) -> 9.5255059e+09 | AG10: =SUM(L10:N10) -> 8.6563313e+09 | AH10: =SUM(O10:Q10) -> 9.7863161e+09
B11: 케미컬 | C11: CSO | D11: CSO | E11: CSO-위탁 | F11: 2.3751765e+09 | G11: 3.5331353e+09 | H11: 5.6835746e+09 | I11: 3.1562229e+09 | J11: 4.7086872e+09 | K11: 6.2476423e+09 | L11: 2.579273e+09 | M11: 3.8520117e+09 | N11: 6.3636937e+09 | O11: 3.2666776e+09 | P11: 4.6370765e+09 | Q11: 6.4850477e+09 | R11: =SUM(F11:Q11) -> 5.2888219e+10 | T11: =SUM(F11:G11) -> 5.9083118e+09 | U11: =T11+H11 -> 1.1591886e+10 | V11: =U11+I11 -> 1.4748109e+10 | W11: =V11+J11 -> 1.9456796e+10 | X11: =W11+K11 -> 2.5704439e+10 | Y11: =X11+L11 -> 2.8283712e+10 | Z11: =Y11+M11 -> 3.2135723e+10 | AA11: =Z11+N11 -> 3.8499417e+10 | AB11: =AA11+O11 -> 4.1766095e+10 | AC11: =AB11+P11 -> 4.6403171e+10 | AE11: =SUM(F11:H11) -> 1.1591886e+10 | AF11: =SUM(I11:K11) -> 1.4112552e+10 | AG11: =SUM(L11:N11) -> 1.2794978e+10 | AH11: =SUM(O11:Q11) -> 1.4388802e+10
B12: 케미컬 | C12: CSO | D12: 약가보상(전략) | E12: 약가보상(전략) | F12: -1.5083263e+08 | G12: 0 | H12: 0 | I12: 0 | J12: 0 | K12: 0 | L12: 0 | M12: 0 | N12: 0 | O12: 0 | P12: 0 | Q12: 0 | R12: =SUM(F12:Q12) -> -1.5083263e+08 | T12: =SUM(F12:G12) -> -1.5083263e+08 | U12: =T12+H12 -> -1.5083263e+08 | V12: =U12+I12 -> -1.5083263e+08 | W12: =V12+J12 -> -1.5083263e+08 | X12: =W12+K12 -> -1.5083263e+08 | Y12: =X12+L12 -> -1.5083263e+08 | Z12: =Y12+M12 -> -1.5083263e+08 | AA12: =Z12+N12 -> -1.5083263e+08 | AB12: =AA12+O12 -> -1.5083263e+08 | AC12: =AB12+P12 -> -1.5083263e+08 | AE12: =SUM(F12:H12) -> -1.5083263e+08 | AF12: =SUM(I12:K12) -> 0 | AG12: =SUM(L12:N12) -> 0 | AH12: =SUM(O12:Q12) -> 0
B13: 케미컬 | C13: 제품기타 | D13: 트레블정 | E13: 트레블정 | F13: 66242577 | G13: 99363865 | H13: 1.6052761e+08 | I13: 88643555 | J13: 1.3296533e+08 | K13: 1.7673697e+08 | L13: 72399593 | M13: 1.0859939e+08 | N13: 1.8099898e+08 | O13: 92912285 | P13: 1.3188977e+08 | Q13: 1.8445059e+08 | R13: =SUM(F13:Q13) -> 1.4957305e+09 | T13: =SUM(F13:G13) -> 1.6560644e+08 | U13: =T13+H13 -> 3.2613405e+08 | V13: =U13+I13 -> 4.147776e+08 | W13: =V13+J13 -> 5.4774294e+08 | X13: =W13+K13 -> 7.2447991e+08 | Y13: =X13+L13 -> 7.968795e+08 | Z13: =Y13+M13 -> 9.0547889e+08 | AA13: =Z13+N13 -> 1.0864779e+09 | AB13: =AA13+O13 -> 1.1793902e+09 | AC13: =AB13+P13 -> 1.3112799e+09 | AE13: =SUM(F13:H13) -> 3.2613405e+08 | AF13: =SUM(I13:K13) -> 3.9834586e+08 | AG13: =SUM(L13:N13) -> 3.6199796e+08 | AH13: =SUM(O13:Q13) -> 4.0925265e+08
B14: 케미컬 | C14: 제품기타 | D14: 제품기타 | E14: 기타-자사 | F14: 79656086 | G14: 1.1948413e+08 | H14: 1.9914021e+08 | I14: 1.0659305e+08 | J14: 1.5988958e+08 | K14: 2.6648264e+08 | L14: 87059841 | M14: 1.3058976e+08 | N14: 2.176496e+08 | O14: 93698874 | P14: 1.4054831e+08 | Q14: 2.3424719e+08 | R14: =SUM(F14:Q14) -> 1.8350393e+09 | T14: =SUM(F14:G14) -> 1.9914021e+08 | U14: =T14+H14 -> 3.9828043e+08 | V14: =U14+I14 -> 5.0487348e+08 | W14: =V14+J14 -> 6.6476307e+08 | X14: =W14+K14 -> 9.312457e+08 | Y14: =X14+L14 -> 1.0183055e+09 | Z14: =Y14+M14 -> 1.1488953e+09 | AA14: =Z14+N14 -> 1.3665449e+09 | AB14: =AA14+O14 -> 1.4602438e+09 | AC14: =AB14+P14 -> 1.6007921e+09 | AE14: =SUM(F14:H14) -> 3.9828043e+08 | AF14: =SUM(I14:K14) -> 5.3296527e+08 | AG14: =SUM(L14:N14) -> 4.352992e+08 | AH14: =SUM(O14:Q14) -> 4.6849437e+08
B15: 케미컬 | C15: 제품기타 | D15: 제품기타 | E15: 기타-위탁 | F15: 1.9381672e+08 | G15: 2.9072508e+08 | H15: 4.845418e+08 | I15: 2.5935892e+08 | J15: 3.8903838e+08 | K15: 6.483973e+08 | L15: 2.1183131e+08 | M15: 3.1774696e+08 | N15: 5.2957827e+08 | O15: 2.279852e+08 | P15: 3.419778e+08 | Q15: 5.69963e+08 | R15: =SUM(F15:Q15) -> 4.4649607e+09 | T15: =SUM(F15:G15) -> 4.845418e+08 | U15: =T15+H15 -> 9.690836e+08 | V15: =U15+I15 -> 1.2284425e+09 | W15: =V15+J15 -> 1.6174809e+09 | X15: =W15+K15 -> 2.2658782e+09 | Y15: =X15+L15 -> 2.4777095e+09 | Z15: =Y15+M15 -> 2.7954565e+09 | AA15: =Z15+N15 -> 3.3250347e+09 | AB15: =AA15+O15 -> 3.5530199e+09 | AC15: =AB15+P15 -> 3.8949977e+09 | AE15: =SUM(F15:H15) -> 9.690836e+08 | AF15: =SUM(I15:K15) -> 1.2967946e+09 | AG15: =SUM(L15:N15) -> 1.0591565e+09 | AH15: =SUM(O15:Q15) -> 1.139926e+09
B16: 케미컬 | C16: 제품기타 | D16: OTC | E16: OTC-가네진 | F16: 66819000 | G16: 66819000 | H16: 106910400 | I16: 22273000 | J16: 60600938 | K16: 51691738 | L16: 69510138 | M16: 69510138 | N16: 69510138 | O16: 71737438 | P16: 71737438 | Q16: 71737438 | R16: =SUM(F16:Q16) -> 798856800 | T16: =SUM(F16:G16) -> 133638000 | U16: =T16+H16 -> 240548400 | V16: =U16+I16 -> 262821400 | W16: =V16+J16 -> 3.2342234e+08 | X16: =W16+K16 -> 375114075 | Y16: =X16+L16 -> 4.4462421e+08 | Z16: =Y16+M16 -> 514134350 | AA16: =Z16+N16 -> 5.8364449e+08 | AB16: =AA16+O16 -> 655381925 | AC16: =AB16+P16 -> 7.2711936e+08 | AE16: =SUM(F16:H16) -> 240548400 | AF16: =SUM(I16:K16) -> 134565675 | AG16: =SUM(L16:N16) -> 2.0853041e+08 | AH16: =SUM(O16:Q16) -> 2.1521231e+08
... B55: 기타 | C55: 제품기타 | D55: 반품부채 | E55: 반품부채 | F55: 0 | G55: 0 | H55: -100000000 | I55: 0 | J55: 0 | K55: -100000000 | L55: 0 | M55: 0 | N55: -100000000 | O55: 0 | P55: 0 | Q55: -100000000 | R55: =SUM(F55:Q55) -> -400000000 | T55: =SUM(F55:G55) -> 0 | U55: =T55+H55 -> -100000000 | V55: =U55+I55 -> -100000000 | W55: =V55+J55 -> -100000000 | X55: =W55+K55 -> -200000000 | Y55: =X55+L55 -> -200000000 | Z55: =Y55+M55 -> -200000000 | AA55: =Z55+N55 -> -300000000 | AB55: =AA55+O55 -> -300000000 | AC55: =AB55+P55 -> -300000000 | AE55: =SUM(F55:H55) -> -100000000 | AF55: =SUM(I55:K55) -> -100000000 | AG55: =SUM(L55:N55) -> -100000000 | AH55: =SUM(O55:Q55) -> -100000000
B56: 합계 | F56: =SUM(F5:F55) -> 1.986792e+10 | G56: =SUM(G5:G55) -> 2.6258909e+10 | H56: =SUM(H5:H55) -> 4.4234092e+10 | I56: =SUM(I5:I55) -> 2.3663557e+10 | J56: =SUM(J5:J55) -> 3.2515276e+10 | K56: =SUM(K5:K55) -> 5.2768862e+10 | L56: =SUM(L5:L55) -> 2.2305237e+10 | M56: =SUM(M5:M55) -> 3.8465807e+10 | ... R56: =SUM(R5:R55) -> 4.4852408e+11 | T56: =SUM(T5:T55) -> 4.6126829e+10 | U56: =SUM(U5:U55) -> 9.0360921e+10 | V56: =SUM(V5:V55) -> 1.1402448e+11 | W56: =SUM(W5:W55) -> 1.4653975e+11 | X56: =SUM(X5:X55) -> 1.9930861e+11 | Y56: =SUM(Y5:Y55) -> 2.2161385e+11 | Z56: =SUM(Z5:Z55) -> 2.6007966e+11 | AA56: =SUM(AA5:AA55) -> 3.1553611e+11 | ... AC56: =SUM(AC5:AC55) -> 3.8536578e+11 | AE56: =SUM(AE5:AE55) -> 9.0360921e+10 | AF56: =SUM(AF5:AF55) -> 1.0894769e+11 | AG56: =SUM(AG5:AG55) -> 1.1622749e+11 | AH56: =SUM(AH5:AH55) -> 1.3298797e+11
T57: =ROUND(T56,0)=ROUND(SUM($F$56:G$56),0) -> TRUE | U57: =ROUND(U56,0)=ROUND(SUM($F$56:H$56),0) -> TRUE | V57: =ROUND(V56,0)=ROUND(SUM($F$56:I$56),0) -> TRUE | W57: =ROUND(W56,0)=ROUND(SUM($F$56:J$56),0) -> TRUE | X57: =ROUND(X56,0)=ROUND(SUM($F$56:K$56),0) -> TRUE | Y57: =ROUND(Y56,0)=ROUND(SUM($F$56:L$56),0) -> TRUE | Z57: =ROUND(Z56,0)=ROUND(SUM($F$56:M$56),0) -> TRUE | AA57: =ROUND(AA56,0)=ROUND(SUM($F$56:N$56),0) -> TRUE | ... AC57: =ROUND(AC56,0)=ROUND(SUM($F$56:P$56),0) -> TRUE | AE57: =ROUND(AE56,0)=ROUND(SUM(F56:H56),0) -> TRUE | AF57: =ROUND(AF56,0)=ROUND(SUM(I56:K56),0) -> TRUE | AG57: =ROUND(AG56,0)=ROUND(SUM(L56:N56),0) -> TRUE | AH57: =ROUND(AH56,0)=ROUND(SUM(O56:Q56),0) -> TRUE

Sheet 2023년 실적
B2: □ 2023년 매출 실적
B4: 사업계획_구분1 | C4: 경영정보통합 | D4: 사업계획_구분3 | E4: 사업계획_구분4 | F4: 1월 | G4: 2월 | H4: 3월 | I4: 4월 | J4: 5월 | K4: 6월 | L4: 7월 | M4: 8월 | N4: 9월 | O4: 10월 | P4: 11월 | Q4: 12월 | R4: 2023년 실적 합계 | T4: 2월 누계 | U4: 3월 누계 | V4: 4월 누계 | W4: 5월 누계 | X4: 6월 누계 | Y4: 7월 누계 | Z4: 8월 누계 | AA4: 9월 누계 | AB4: 10월 누계 | AC4: 11월 누계 | AE4: 1분기 | AF4: 2분기 | AG4: 3분기 | AH4: 4분기
B5: 케미컬 | C5: 고덱스 | D5: 고덱스 | E5: 고덱스캡슐 | F5: 3687570806 | G5: 5128395870 | H5: 6281751224 | I5: 5798431443 | J5: 5901964958 | K5: 7051975865 | L5: 5400074996 | M5: 5200429656 | N5: 7001025491 | O5: 4656527400 | P5: 6000933183 | Q5: 7006565759 | R5: =SUM(F5:Q5) -> 69115646651 | T5: =SUM(F5:G5) -> 8815966676 | U5: =SUM(T5, H5) -> 15097717900 | V5: =SUM(U5, I5) -> 20896149343 | W5: =SUM(V5, J5) -> 26798114301 | X5: =SUM(W5, K5) -> 33850090166 | Y5: =SUM(X5, L5) -> 39250165162 | Z5: =SUM(Y5, M5) -> 44450594818 | AA5: =SUM(Z5, N5) -> 51451620309 | AB5: =SUM(AA5, O5) -> 56108147709 | AC5: =SUM(AB5, P5) -> 62109080892 | AE5: =SUM(F5:H5) -> 15097717900 | AF5: =SUM(I5:K5) -> 18752372266 | AG5: =SUM(L5:N5) -> 17601530143 | AH5: =SUM(O5:Q5) -> 17664026342
B6: 케미컬 | C6: 고덱스 | D6: 고덱스 | E6: 고덱스정 | F6: 0 | G6: 0 | H6: 0 | I6: 0 | J6: 0 | K6: 0 | L6: 0 | M6: 0 | N6: 0 | O6: 0 | P6: 0 | Q6: 0 | R6: =SUM(F6:Q6) -> 0 | T6: =SUM(F6:G6) -> 0 | U6: =SUM(T6, H6) -> 0 | V6: =SUM(U6, I6) -> 0 | W6: =SUM(V6, J6) -> 0 | X6: =SUM(W6, K6) -> 0 | Y6: =SUM(X6, L6) -> 0 | Z6: =SUM(Y6, M6) -> 0 | AA6: =SUM(Z6, N6) -> 0 | AB6: =SUM(AA6, O6) -> 0 | AC6: =SUM(AB6, P6) -> 0 | AE6: =SUM(F6:H6) -> 0 | AF6: =SUM(I6:K6) -> 0 | AG6: =SUM(L6:N6) -> 0 | AH6: =SUM(O6:Q6) -> 0
B7: 케미컬 | C7: 제품기타 | D7: 약가보상(케미컬) | E7: 약가보상(케미컬) | F7: 0 | G7: 0 | H7: 0 | I7: 0 | J7: 0 | K7: 0 | L7: 0 | M7: 0 | N7: 0 | O7: 0 | P7: 0 | Q7: 0 | R7: =SUM(F7:Q7) -> 0 | T7: =SUM(F7:G7) -> 0 | U7: =SUM(T7, H7) -> 0 | V7: =SUM(U7, I7) -> 0 | W7: =SUM(V7, J7) -> 0 | X7: =SUM(W7, K7) -> 0 | Y7: =SUM(X7, L7) -> 0 | Z7: =SUM(Y7, M7) -> 0 | AA7: =SUM(Z7, N7) -> 0 | AB7: =SUM(AA7, O7) -> 0 | AC7: =SUM(AB7, P7) -> 0 | AE7: =SUM(F7:H7) -> 0 | AF7: =SUM(I7:K7) -> 0 | AG7: =SUM(L7:N7) -> 0 | AH7: =SUM(O7:Q7) -> 0
B8: 케미컬 | C8: 도네리온 | D8: 도네리온 | E8: 도네리온 | F8: 78413972 | G8: 174469864 | H8: 97871605 | I8: 0 | J8: 152109262 | K8: 235302271 | L8: 65189684 | M8: 1629519 | N8: -146768102 | O8: 0 | P8: 87360761 | Q8: 198189177 | R8: =SUM(F8:Q8) -> 943768013 | T8: =SUM(F8:G8) -> 252883836 | U8: =SUM(T8, H8) -> 350755441 | V8: =SUM(U8, I8) -> 350755441 | W8: =SUM(V8, J8) -> 502864703 | X8: =SUM(W8, K8) -> 738166974 | Y8: =SUM(X8, L8) -> 803356658 | Z8: =SUM(Y8, M8) -> 804986177 | AA8: =SUM(Z8, N8) -> 658218075 | AB8: =SUM(AA8, O8) -> 658218075 | AC8: =SUM(AB8, P8) -> 745578836 | AE8: =SUM(F8:H8) -> 350755441 | AF8: =SUM(I8:K8) -> 387411533 | AG8: =SUM(L8:N8) -> -79948899 | AH8: =SUM(O8:Q8) -> 285549938
B9: 케미컬 | C9: 공동판매 | D9: 케미컬쌍방코프로 | E9: 케미컬쌍방코프로 | F9: 0 | G9: 0 | H9: 0 | I9: 0 | J9: 0 | K9: 0 | L9: 0 | M9: 0 | N9: 0 | O9: 0 | P9: 0 | Q9: 0 | R9: =SUM(F9:Q9) -> 0 | T9: =SUM(F9:G9) -> 0 | U9: =SUM(T9, H9) -> 0 | V9: =SUM(U9, I9) -> 0 | W9: =SUM(V9, J9) -> 0 | X9: =SUM(W9, K9) -> 0 | Y9: =SUM(X9, L9) -> 0 | Z9: =SUM(Y9, M9) -> 0 | AA9: =SUM(Z9, N9) -> 0 | AB9: =SUM(AA9, O9) -> 0 | AC9: =SUM(AB9, P9) -> 0 | AE9: =SUM(F9:H9) -> 0 | AF9: =SUM(I9:K9) -> 0 | AG9: =SUM(L9:N9) -> 0 | AH9: =SUM(O9:Q9) -> 0
B10: 케미컬 | C10: CSO | D10: CSO | E10: CSO-자사 | F10: 2082552804 | G10: 3078554523 | H10: 3374653549 | I10: 3421659154 | J10: 3818044303 | K10: 5453887816 | L10: 2440478062 | M10: 1763116059 | N10: 4365284485 | O10: 372233390 | P10: 1085193190 | Q10: 3727708513 | R10: =SUM(F10:Q10) -> 34983365848 | T10: =SUM(F10:G10) -> 5161107327 | U10: =SUM(T10, H10) -> 8535760876 | V10: =SUM(U10, I10) -> 11957420030 | W10: =SUM(V10, J10) -> 15775464333 | X10: =SUM(W10, K10) -> 21229352149 | Y10: =SUM(X10, L10) -> 23669830211 | Z10: =SUM(Y10, M10) -> 25432946270 | AA10: =SUM(Z10, N10) -> 29798230755 | AB10: =SUM(AA10, O10) -> 30170464145 | AC10: =SUM(AB10, P10) -> 31255657335 | AE10: =SUM(F10:H10) -> 8535760876 | AF10: =SUM(I10:K10) -> 12693591273 | AG10: =SUM(L10:N10) -> 8568878606 | AH10: =SUM(O10:Q10) -> 5185135093
B11: 케미컬 | C11: CSO | D11: CSO | E11: CSO-위탁 | F11: 3550311181 | G11: 4314388140 | H11: 4706859695 | I11: 3622453855 | J11: 3353317521 | K11: 7767470382 | L11: 3577063318 | M11: 1210863033 | N11: 5161208709 | O11: 5561380944 | P11: 6283475731 | Q11: 2637064333 | R11: =SUM(F11:Q11) -> 51745856842 | T11: =SUM(F11:G11) -> 7864699321 | U11: =SUM(T11, H11) -> 12571559016 | V11: =SUM(U11, I11) -> 16194012871 | W11: =SUM(V11, J11) -> 19547330392 | X11: =SUM(W11, K11) -> 27314800774 | Y11: =SUM(X11, L11) -> 30891864092 | Z11: =SUM(Y11, M11) -> 32102727125 | AA11: =SUM(Z11, N11) -> 37263935834 | AB11: =SUM(AA11, O11) -> 42825316778 | AC11: =SUM(AB11, P11) -> 49108792509 | AE11: =SUM(F11:H11) -> 12571559016 | AF11: =SUM(I11:K11) -> 14743241758 | AG11: =SUM(L11:N11) -> 9949135060 | AH11: =SUM(O11:Q11) -> 14481921008
B12: 케미컬 | C12: CSO | D12: 약가보상(전략) | E12: 약가보상(전략) | F12: 0 | G12: 0 | H12: 0 | I12: 0 | J12: 0 | K12: 0 | L12: 0 | M12: 0 | N12: 0 | O12: 0 | P12: 0 | Q12: 0 | R12: =SUM(F12:Q12) -> 0 | T12: =SUM(F12:G12) -> 0 | U12: =SUM(T12, H12) -> 0 | V12: =SUM(U12, I12) -> 0 | W12: =SUM(V12, J12) -> 0 | X12: =SUM(W12, K12) -> 0 | Y12: =SUM(X12, L12) -> 0 | Z12: =SUM(Y12, M12) -> 0 | AA12: =SUM(Z12, N12) -> 0 | AB12: =SUM(AA12, O12) -> 0 | AC12: =SUM(AB12, P12) -> 0 | AE12: =SUM(F12:H12) -> 0 | AF12: =SUM(I12:K12) -> 0 | AG12: =SUM(L12:N12) -> 0 | AH12: =SUM(O12:Q12) -> 0
B13: 케미컬 | C13: 제품기타 | D13: 트레블정 | E13: 트레블정 | F13: 122256299 | G13: 115002196 | H13: 160733439 | I13: 151488284 | J13: 132601048 | K13: 155419708 | L13: 123640163 | M13: 154064407 | N13: 132619393 | O13: 577824845 | P13: 48540053 | Q13: -3296712 | R13: =SUM(F13:Q13) -> 1870893123 | T13: =SUM(F13:G13) -> 237258495 | U13: =SUM(T13, H13) -> 397991934 | V13: =SUM(U13, I13) -> 549480218 | W13: =SUM(V13, J13) -> 682081266 | X13: =SUM(W13, K13) -> 837500974 | Y13: =SUM(X13, L13) -> 961141137 | Z13: =SUM(Y13, M13) -> 1115205544 | AA13: =SUM(Z13, N13) -> 1247824937 | AB13: =SUM(AA13, O13) -> 1825649782 | AC13: =SUM(AB13, P13) -> 1874189835 | AE13: =SUM(F13:H13) -> 397991934 | AF13: =SUM(I13:K13) -> 439509040 | AG13: =SUM(L13:N13) -> 410323963 | AH13: =SUM(O13:Q13) -> 623068186
B14: 케미컬 | C14: 제품기타 | D14: 제품기타 | E14: 기타-자사 | F14: 993095217 | G14: 111229065 | H14: 152159254 | I14: 132642303 | J14: 106199151 | K14: 159502544 | L14: 150908911 | M14: 161877803 | N14: 158616763 | O14: 123596675 | P14: 159663857 | Q14: 193618626 | R14: =SUM(F14:Q14) -> 2603110169 | T14: =SUM(F14:G14) -> 1104324282 | U14: =SUM(T14, H14) -> 1256483536 | V14: =SUM(U14, I14) -> 1389125839 | W14: =SUM(V14, J14) -> 1495324990 | X14: =SUM(W14, K14) -> 1654827534 | Y14: =SUM(X14, L14) -> 1805736445 | Z14: =SUM(Y14, M14) -> 1967614248 | AA14: =SUM(Z14, N14) -> 2126231011 | AB14: =SUM(AA14, O14) -> 2249827686 | AC14: =SUM(AB14, P14) -> 2409491543 | AE14: =SUM(F14:H14) -> 1256483536 | AF14: =SUM(I14:K14) -> 398343998 | AG14: =SUM(L14:N14) -> 471403477 | AH14: =SUM(O14:Q14) -> 476879158
B15: 케미컬 | C15: 제품기타 | D15: 제품기타 | E15: 기타-위탁 | F15: 377237676 | G15: 305394957 | H15: 265246016 | I15: 351047272 | J15: 358518885 | K15: 364448917 | L15: 392769844 | M15: 356446483 | N15: 373624129 | O15: 294627291 | P15: 205841671 | Q15: 502333703 | R15: =SUM(F15:Q15) -> 4147536844 | T15: =SUM(F15:G15) -> 682632633 | U15: =SUM(T15, H15) -> 947878649 | V15: =SUM(U15, I15) -> 1298925921 | W15: =SUM(V15, J15) -> 1657444806 | X15: =SUM(W15, K15) -> 2021893723 | Y15: =SUM(X15, L15) -> 2414663567 | Z15: =SUM(Y15, M15) -> 2771110050 | AA15: =SUM(Z15, N15) -> 3144734179 | AB15: =SUM(AA15, O15) -> 3439361470 | AC15: =SUM(AB15, P15) -> 3645203141 | AE15: =SUM(F15:H15) -> 947878649 | AF15: =SUM(I15:K15) -> 1074015074 | AG15: =SUM(L15:N15) -> 1122840456 | AH15: =SUM(O15:Q15) -> 1002802665
B16: 케미컬 | C16: 제품기타 | D16: OTC | E16: OTC-가네진 | F16: 57082000 | G16: 33409500 | H16: 12080069 | I16: 34809000 | J16: 3734212 | K16: 31048200 | L16: 54500000 | M16: 67901300 | N16: 74340600 | O16: 93291560 | P16: 43877810 | Q16: 44546000 | R16: =SUM(F16:Q16) -> 5.5062025e+08 | T16: =SUM(F16:G16) -> 90491500 | U16: =SUM(T16, H16) -> 1.0257157e+08 | V16: =SUM(U16, I16) -> 1.3738057e+08 | W16: =SUM(V16, J16) -> 1.4111478e+08 | X16: =SUM(W16, K16) -> 1.7216298e+08 | Y16: =SUM(X16, L16) -> 2.2666298e+08 | Z16: =SUM(Y16, M16) -> 2.9456428e+08 | AA16: =SUM(Z16, N16) -> 3.6890488e+08 | AB16: =SUM(AA16, O16) -> 4.6219644e+08 | AC16: =SUM(AB16, P16) -> 5.0607425e+08 | AE16: =SUM(F16:H16) -> 1.0257157e+08 | AF16: =SUM(I16:K16) -> 69591412 | AG16: =SUM(L16:N16) -> 196741900 | AH16: =SUM(O16:Q16) -> 181715370
... B61: 기타 | C61: 제품기타 | D61: 반품부채 | E61: 반품부채 | F61: 0 | G61: 0 | H61: -51496272 | I61: 0 | J61: 0 | K61: -30026898 | L61: 0 | M61: 0 | N61: -56641149 | O61: 0 | P61: 0 | Q61: -9511381 | R61: =SUM(F61:Q61) -> -147675700 | T61: =SUM(F61:G61) -> 0 | U61: =SUM(T61, H61) -> -51496272 | V61: =SUM(U61, I61) -> -51496272 | W61: =SUM(V61, J61) -> -51496272 | X61: =SUM(W61, K61) -> -81523170 | Y61: =SUM(X61, L61) -> -81523170 | Z61: =SUM(Y61, M61) -> -81523170 | AA61: =SUM(Z61, N61) -> -138164319 | AB61: =SUM(AA61, O61) -> -138164319 | AC61: =SUM(AB61, P61) -> -138164319 | AE61: =SUM(F61:H61) -> -51496272 | AF61: =SUM(I61:K61) -> -30026898 | AG61: =SUM(L61:N61) -> -56641149 | AH61: =SUM(O61:Q61) -> -9511381
